2025-02-09 14:56:26.202 | 40372:34912 | INFO     | __main__:main:853 | Main: Initializing research agent
2025-02-09 14:56:26.217 | 40372:34912 | INFO     | scripts.llm_compiler:__init__:77 | Compiler: Initialized LLM compiler
2025-02-09 14:56:26.946 | 40372:34912 | INFO     | scripts.llm_compiler:__init__:77 | Compiler: Initialized LLM compiler
2025-02-09 14:56:27.366 | 40372:34912 | INFO     | scripts.knowledge_acquisition:__init__:278 | KnowledgeAcquisition: Knowledge acquisition system initialized
2025-02-09 14:56:27.368 | 40372:34912 | INFO     | scripts.knowledge_acquisition:__init__:278 | 
Local Variables:
  self = <scripts.knowledge_acquisition.KnowledgeAcquisitionSystem object at 0x000001EA0978A900>
  config = domains=[DomainConfig(name='medical', description='Medical domain knowledge including diseases, treatments, and healthcare concepts', classes=[OntologyClass(name='Disease', description='A medical cond...
  api_key = AIzaSyA_5-fcCihRyNZvfl6S5wm420SnuvijQT0
  llm = temperature=0.7 api_key=SecretStr('**********') pydantic_schema=<class 'prompts.knowledge_acquisition.entity_extraction.EntityResponse'>
  __class__ = <class 'scripts.knowledge_acquisition.KnowledgeAcquisitionSystem'>

2025-02-09 14:56:27.369 | 40372:34912 | INFO     | scripts.llm_compiler:__init__:77 | Compiler: Initialized LLM compiler
2025-02-09 14:56:27.370 | 40372:34912 | INFO     | scripts.llm_compiler:__init__:77 | Compiler: Initialized LLM compiler
2025-02-09 14:56:27.373 | 40372:34912 | INFO     | scripts.llm_compiler:register_tool:87 | Compiler: Registered tool: _research_topics
2025-02-09 14:56:27.374 | 40372:34912 | INFO     | scripts.llm_compiler:register_tool:87 | Compiler: Registered tool: _synthesize_knowledge
2025-02-09 14:56:27.375 | 40372:34912 | INFO     | scripts.llm_compiler:register_tool:87 | Compiler: Registered tool: _generate_examples
2025-02-09 14:56:27.375 | 40372:34912 | INFO     | scripts.llm_compiler:register_tool:87 | Compiler: Registered tool: _train_model
2025-02-09 14:56:27.376 | 40372:34912 | INFO     | __main__:__init__:206 | Research: Research agent initialized
2025-02-09 14:56:27.378 | 40372:34912 | INFO     | __main__:main:856 | Main: Starting research agent
2025-02-09 14:56:27.378 | 40372:34912 | INFO     | __main__:run:608 | Research: Starting research workflow for domain: test_domain
2025-02-09 14:56:27.379 | 40372:34912 | INFO     | __main__:run:643 | Execution: Starting execution of 4 tasks
2025-02-09 14:56:27.381 | 40372:34912 | INFO     | __main__:run:657 | Execution: Executing task 0: _research_topics
2025-02-09 14:56:27.382 | 40372:34912 | INFO     | __main__:_research_topics:229 | Research: Starting topic research for domain: test_domain
2025-02-09 14:56:27.382 | 40372:34912 | INFO     | scripts.knowledge_acquisition:initialize:287 | KnowledgeAcquisition: Starting system initialization
2025-02-09 14:56:27.805 | 40372:34912 | INFO     | scripts.knowledge_acquisition:initialize:296 | KnowledgeAcquisition: Embeddings initialized
2025-02-09 14:56:27.955 | 40372:34912 | INFO     | scripts.knowledge_acquisition:initialize:309 | KnowledgeAcquisition: Vector store initialized
2025-02-09 14:56:28.017 | 40372:34912 | INFO     | scripts.knowledge_acquisition:initialize:322 | KnowledgeAcquisition: Graph database initialized
2025-02-09 14:56:28.019 | 40372:34912 | INFO     | __main__:_research_topics:247 | Search: Searching for: test_domain overview
2025-02-09 14:56:32.303 | 40372:34912 | INFO     | __main__:_research_topics:247 | Search: Searching for: test_domain key concepts
2025-02-09 14:56:37.483 | 40372:34912 | INFO     | __main__:_research_topics:247 | Search: Searching for: test_domain latest developments
2025-02-09 14:56:43.857 | 40372:34912 | INFO     | __main__:_research_topics:247 | Search: Searching for: test_domain research papers
2025-02-09 14:56:49.831 | 40372:34912 | INFO     | __main__:run:657 | Execution: Executing task 1: _synthesize_knowledge
2025-02-09 14:56:49.832 | 40372:34912 | INFO     | __main__:run:668 | Execution: Found 10 sources for synthesis
2025-02-09 14:56:49.835 | 40372:34912 | INFO     | __main__:_synthesize_knowledge:325 | Knowledge Synthesis: Processing source: Free Website Authority Checker (Enter Any Domain or URL) (source_1.txt)
2025-02-09 14:56:49.837 | 40372:34912 | INFO     | __main__:_synthesize_knowledge:329 | Knowledge Synthesis: Content preview:
* ArticlesArticles + Popular + SEO Fundamentals + Content Marketing + Link Building + Marketing + What Is SEO?For people that are new to + SEO ChecklistCovers technical SEO, On-page SEO, and keyword re + [SEO Audit Checklist18-step guide to get higher Google rankings.Step-by-step guide to building a website in 2024.( * ToolsTools + Free Tools + Tool Guides + Tool Reviews + Keyword Re + Backlink CheckerDiscover who’s linking to you and your competitors.Step-by-step guide to building a website in ...
2025-02-09 14:56:49.838 | 40372:34912 | INFO     | scripts.knowledge_acquisition:process_source:444 | KnowledgeAcquisition: Starting source processing with content length: 12294
2025-02-09 14:56:49.840 | 40372:34912 | INFO     | scripts.knowledge_acquisition:process_source:448 | KnowledgeAcquisition: Content preview:
* ArticlesArticles + Popular + SEO Fundamentals + Content Marketing + Link Building + Marketing + What Is SEO?For people that are new to + SEO ChecklistCovers technical SEO, On-page SEO, and keyword r...
2025-02-09 14:56:49.841 | 40372:34912 | INFO     | scripts.knowledge_acquisition:process_source:451 | KnowledgeAcquisition: Extracting entities...
2025-02-09 14:56:50.899 | 40372:34912 | INFO     | scripts.knowledge_acquisition:process_source:458 | KnowledgeAcquisition: Extracted 12 entities: ['Machine Learning', 'Deep Learning', 'Artificial Neural Networks', 'Backpropagation', 'Stochastic Gradient Descent', 'TensorFlow', 'PyTorch', 'Keras', 'Convolutional Neural Networks', 'Recurrent Neural Networks', 'Natural Language Processing', 'Computer Vision']
2025-02-09 14:56:50.902 | 40372:34912 | INFO     | scripts.knowledge_acquisition:process_source:464 | KnowledgeAcquisition: Extracting relationships...
2025-02-09 14:56:53.963 | 40372:34912 | ERROR    | scripts.knowledge_acquisition:_extract_relationships:652 | Failed to convert relationship: {'source': 'Machine Learning Models', 'relation': 'used_in', 'target': 'Artificial Intelligence'}: 1 validation error for Relationship
relation
  Input should be 'is_a', 'has_part' or 'related_to' [type=literal_error, input_value='used_in', input_type=str]
    For further information visit https://errors.pydantic.dev/2.10/v/literal_error
Traceback (most recent call last):

  File "C:\Users\mikeb\work\sifu2\run_agents.py", line 868, in <module>
    asyncio.run(main())

  File "C:\Python313\Lib\asyncio\runners.py", line 194, in run
    return runner.run(main)
  File "C:\Python313\Lib\asyncio\runners.py", line 118, in run
    return self._loop.run_until_complete(task)
  File "C:\Python313\Lib\asyncio\base_events.py", line 707, in run_until_complete
    self.run_forever()
  File "C:\Python313\Lib\asyncio\base_events.py", line 678, in run_forever
    self._run_once()
  File "C:\Python313\Lib\asyncio\base_events.py", line 2033, in _run_once
    handle._run()
  File "C:\Python313\Lib\asyncio\events.py", line 89, in _run
    self._context.run(self._callback, *self._args)

  File "C:\Users\mikeb\work\sifu2\run_agents.py", line 857, in main
    await agent.run()

  File "C:\Users\mikeb\work\sifu2\run_agents.py", line 691, in run
    result = await getattr(self, task.tool)(**task.args)

  File "C:\Users\mikeb\work\sifu2\run_agents.py", line 344, in _synthesize_knowledge
    knowledge = await self.knowledge_system.process_source(content)

  File "C:\Users\mikeb\work\sifu2\scripts\knowledge_acquisition.py", line 466, in process_source
    relationships = await self._extract_relationships(content)

> File "C:\Users\mikeb\work\sifu2\scripts\knowledge_acquisition.py", line 650, in _extract_relationships
    converted_relationships.append(Relationship(**rel))

  File "C:\Python313\Lib\site-packages\pydantic\main.py", line 214, in __init__
    validated_self = self.__pydantic_validator__.validate_python(data, self_instance=self)

pydantic_core._pydantic_core.ValidationError: 1 validation error for Relationship
relation
  Input should be 'is_a', 'has_part' or 'related_to' [type=literal_error, input_value='used_in', input_type=str]
    For further information visit https://errors.pydantic.dev/2.10/v/literal_error
2025-02-09 14:56:54.007 | 40372:34912 | ERROR    | scripts.knowledge_acquisition:_extract_relationships:652 | Failed to convert relationship: {'source': 'Data Preprocessing', 'relation': 'precedes', 'target': 'Model Training'}: 1 validation error for Relationship
relation
  Input should be 'is_a', 'has_part' or 'related_to' [type=literal_error, input_value='precedes', input_type=str]
    For further information visit https://errors.pydantic.dev/2.10/v/literal_error
Traceback (most recent call last):

  File "C:\Users\mikeb\work\sifu2\run_agents.py", line 868, in <module>
    asyncio.run(main())

  File "C:\Python313\Lib\asyncio\runners.py", line 194, in run
    return runner.run(main)
  File "C:\Python313\Lib\asyncio\runners.py", line 118, in run
    return self._loop.run_until_complete(task)
  File "C:\Python313\Lib\asyncio\base_events.py", line 707, in run_until_complete
    self.run_forever()
  File "C:\Python313\Lib\asyncio\base_events.py", line 678, in run_forever
    self._run_once()
  File "C:\Python313\Lib\asyncio\base_events.py", line 2033, in _run_once
    handle._run()
  File "C:\Python313\Lib\asyncio\events.py", line 89, in _run
    self._context.run(self._callback, *self._args)

  File "C:\Users\mikeb\work\sifu2\run_agents.py", line 857, in main
    await agent.run()

  File "C:\Users\mikeb\work\sifu2\run_agents.py", line 691, in run
    result = await getattr(self, task.tool)(**task.args)

  File "C:\Users\mikeb\work\sifu2\run_agents.py", line 344, in _synthesize_knowledge
    knowledge = await self.knowledge_system.process_source(content)

  File "C:\Users\mikeb\work\sifu2\scripts\knowledge_acquisition.py", line 466, in process_source
    relationships = await self._extract_relationships(content)

> File "C:\Users\mikeb\work\sifu2\scripts\knowledge_acquisition.py", line 650, in _extract_relationships
    converted_relationships.append(Relationship(**rel))

  File "C:\Python313\Lib\site-packages\pydantic\main.py", line 214, in __init__
    validated_self = self.__pydantic_validator__.validate_python(data, self_instance=self)

pydantic_core._pydantic_core.ValidationError: 1 validation error for Relationship
relation
  Input should be 'is_a', 'has_part' or 'related_to' [type=literal_error, input_value='precedes', input_type=str]
    For further information visit https://errors.pydantic.dev/2.10/v/literal_error
2025-02-09 14:56:54.032 | 40372:34912 | ERROR    | scripts.knowledge_acquisition:_extract_relationships:652 | Failed to convert relationship: {'source': 'Model Training', 'relation': 'uses', 'target': 'Training Data'}: 1 validation error for Relationship
relation
  Input should be 'is_a', 'has_part' or 'related_to' [type=literal_error, input_value='uses', input_type=str]
    For further information visit https://errors.pydantic.dev/2.10/v/literal_error
Traceback (most recent call last):

  File "C:\Users\mikeb\work\sifu2\run_agents.py", line 868, in <module>
    asyncio.run(main())

  File "C:\Python313\Lib\asyncio\runners.py", line 194, in run
    return runner.run(main)
  File "C:\Python313\Lib\asyncio\runners.py", line 118, in run
    return self._loop.run_until_complete(task)
  File "C:\Python313\Lib\asyncio\base_events.py", line 707, in run_until_complete
    self.run_forever()
  File "C:\Python313\Lib\asyncio\base_events.py", line 678, in run_forever
    self._run_once()
  File "C:\Python313\Lib\asyncio\base_events.py", line 2033, in _run_once
    handle._run()
  File "C:\Python313\Lib\asyncio\events.py", line 89, in _run
    self._context.run(self._callback, *self._args)

  File "C:\Users\mikeb\work\sifu2\run_agents.py", line 857, in main
    await agent.run()

  File "C:\Users\mikeb\work\sifu2\run_agents.py", line 691, in run
    result = await getattr(self, task.tool)(**task.args)

  File "C:\Users\mikeb\work\sifu2\run_agents.py", line 344, in _synthesize_knowledge
    knowledge = await self.knowledge_system.process_source(content)

  File "C:\Users\mikeb\work\sifu2\scripts\knowledge_acquisition.py", line 466, in process_source
    relationships = await self._extract_relationships(content)

> File "C:\Users\mikeb\work\sifu2\scripts\knowledge_acquisition.py", line 650, in _extract_relationships
    converted_relationships.append(Relationship(**rel))

  File "C:\Python313\Lib\site-packages\pydantic\main.py", line 214, in __init__
    validated_self = self.__pydantic_validator__.validate_python(data, self_instance=self)

pydantic_core._pydantic_core.ValidationError: 1 validation error for Relationship
relation
  Input should be 'is_a', 'has_part' or 'related_to' [type=literal_error, input_value='uses', input_type=str]
    For further information visit https://errors.pydantic.dev/2.10/v/literal_error
2025-02-09 14:56:54.057 | 40372:34912 | ERROR    | scripts.knowledge_acquisition:_extract_relationships:652 | Failed to convert relationship: {'source': 'Model Training', 'relation': 'precedes', 'target': 'Model Evaluation'}: 1 validation error for Relationship
relation
  Input should be 'is_a', 'has_part' or 'related_to' [type=literal_error, input_value='precedes', input_type=str]
    For further information visit https://errors.pydantic.dev/2.10/v/literal_error
Traceback (most recent call last):

  File "C:\Users\mikeb\work\sifu2\run_agents.py", line 868, in <module>
    asyncio.run(main())

  File "C:\Python313\Lib\asyncio\runners.py", line 194, in run
    return runner.run(main)
  File "C:\Python313\Lib\asyncio\runners.py", line 118, in run
    return self._loop.run_until_complete(task)
  File "C:\Python313\Lib\asyncio\base_events.py", line 707, in run_until_complete
    self.run_forever()
  File "C:\Python313\Lib\asyncio\base_events.py", line 678, in run_forever
    self._run_once()
  File "C:\Python313\Lib\asyncio\base_events.py", line 2033, in _run_once
    handle._run()
  File "C:\Python313\Lib\asyncio\events.py", line 89, in _run
    self._context.run(self._callback, *self._args)

  File "C:\Users\mikeb\work\sifu2\run_agents.py", line 857, in main
    await agent.run()

  File "C:\Users\mikeb\work\sifu2\run_agents.py", line 691, in run
    result = await getattr(self, task.tool)(**task.args)

  File "C:\Users\mikeb\work\sifu2\run_agents.py", line 344, in _synthesize_knowledge
    knowledge = await self.knowledge_system.process_source(content)

  File "C:\Users\mikeb\work\sifu2\scripts\knowledge_acquisition.py", line 466, in process_source
    relationships = await self._extract_relationships(content)

> File "C:\Users\mikeb\work\sifu2\scripts\knowledge_acquisition.py", line 650, in _extract_relationships
    converted_relationships.append(Relationship(**rel))

  File "C:\Python313\Lib\site-packages\pydantic\main.py", line 214, in __init__
    validated_self = self.__pydantic_validator__.validate_python(data, self_instance=self)

pydantic_core._pydantic_core.ValidationError: 1 validation error for Relationship
relation
  Input should be 'is_a', 'has_part' or 'related_to' [type=literal_error, input_value='precedes', input_type=str]
    For further information visit https://errors.pydantic.dev/2.10/v/literal_error
2025-02-09 14:56:54.081 | 40372:34912 | ERROR    | scripts.knowledge_acquisition:_extract_relationships:652 | Failed to convert relationship: {'source': 'Model Evaluation', 'relation': 'uses', 'target': 'Validation Data'}: 1 validation error for Relationship
relation
  Input should be 'is_a', 'has_part' or 'related_to' [type=literal_error, input_value='uses', input_type=str]
    For further information visit https://errors.pydantic.dev/2.10/v/literal_error
Traceback (most recent call last):

  File "C:\Users\mikeb\work\sifu2\run_agents.py", line 868, in <module>
    asyncio.run(main())

  File "C:\Python313\Lib\asyncio\runners.py", line 194, in run
    return runner.run(main)
  File "C:\Python313\Lib\asyncio\runners.py", line 118, in run
    return self._loop.run_until_complete(task)
  File "C:\Python313\Lib\asyncio\base_events.py", line 707, in run_until_complete
    self.run_forever()
  File "C:\Python313\Lib\asyncio\base_events.py", line 678, in run_forever
    self._run_once()
  File "C:\Python313\Lib\asyncio\base_events.py", line 2033, in _run_once
    handle._run()
  File "C:\Python313\Lib\asyncio\events.py", line 89, in _run
    self._context.run(self._callback, *self._args)

  File "C:\Users\mikeb\work\sifu2\run_agents.py", line 857, in main
    await agent.run()

  File "C:\Users\mikeb\work\sifu2\run_agents.py", line 691, in run
    result = await getattr(self, task.tool)(**task.args)

  File "C:\Users\mikeb\work\sifu2\run_agents.py", line 344, in _synthesize_knowledge
    knowledge = await self.knowledge_system.process_source(content)

  File "C:\Users\mikeb\work\sifu2\scripts\knowledge_acquisition.py", line 466, in process_source
    relationships = await self._extract_relationships(content)

> File "C:\Users\mikeb\work\sifu2\scripts\knowledge_acquisition.py", line 650, in _extract_relationships
    converted_relationships.append(Relationship(**rel))

  File "C:\Python313\Lib\site-packages\pydantic\main.py", line 214, in __init__
    validated_self = self.__pydantic_validator__.validate_python(data, self_instance=self)

pydantic_core._pydantic_core.ValidationError: 1 validation error for Relationship
relation
  Input should be 'is_a', 'has_part' or 'related_to' [type=literal_error, input_value='uses', input_type=str]
    For further information visit https://errors.pydantic.dev/2.10/v/literal_error
2025-02-09 14:56:54.105 | 40372:34912 | ERROR    | scripts.knowledge_acquisition:_extract_relationships:652 | Failed to convert relationship: {'source': 'CNNs', 'relation': 'applied_to', 'target': 'Image Recognition'}: 1 validation error for Relationship
relation
  Input should be 'is_a', 'has_part' or 'related_to' [type=literal_error, input_value='applied_to', input_type=str]
    For further information visit https://errors.pydantic.dev/2.10/v/literal_error
Traceback (most recent call last):

  File "C:\Users\mikeb\work\sifu2\run_agents.py", line 868, in <module>
    asyncio.run(main())

  File "C:\Python313\Lib\asyncio\runners.py", line 194, in run
    return runner.run(main)
  File "C:\Python313\Lib\asyncio\runners.py", line 118, in run
    return self._loop.run_until_complete(task)
  File "C:\Python313\Lib\asyncio\base_events.py", line 707, in run_until_complete
    self.run_forever()
  File "C:\Python313\Lib\asyncio\base_events.py", line 678, in run_forever
    self._run_once()
  File "C:\Python313\Lib\asyncio\base_events.py", line 2033, in _run_once
    handle._run()
  File "C:\Python313\Lib\asyncio\events.py", line 89, in _run
    self._context.run(self._callback, *self._args)

  File "C:\Users\mikeb\work\sifu2\run_agents.py", line 857, in main
    await agent.run()

  File "C:\Users\mikeb\work\sifu2\run_agents.py", line 691, in run
    result = await getattr(self, task.tool)(**task.args)

  File "C:\Users\mikeb\work\sifu2\run_agents.py", line 344, in _synthesize_knowledge
    knowledge = await self.knowledge_system.process_source(content)

  File "C:\Users\mikeb\work\sifu2\scripts\knowledge_acquisition.py", line 466, in process_source
    relationships = await self._extract_relationships(content)

> File "C:\Users\mikeb\work\sifu2\scripts\knowledge_acquisition.py", line 650, in _extract_relationships
    converted_relationships.append(Relationship(**rel))

  File "C:\Python313\Lib\site-packages\pydantic\main.py", line 214, in __init__
    validated_self = self.__pydantic_validator__.validate_python(data, self_instance=self)

pydantic_core._pydantic_core.ValidationError: 1 validation error for Relationship
relation
  Input should be 'is_a', 'has_part' or 'related_to' [type=literal_error, input_value='applied_to', input_type=str]
    For further information visit https://errors.pydantic.dev/2.10/v/literal_error
2025-02-09 14:56:54.128 | 40372:34912 | ERROR    | scripts.knowledge_acquisition:_extract_relationships:652 | Failed to convert relationship: {'source': 'RNNs', 'relation': 'applied_to', 'target': 'Natural Language Processing'}: 1 validation error for Relationship
relation
  Input should be 'is_a', 'has_part' or 'related_to' [type=literal_error, input_value='applied_to', input_type=str]
    For further information visit https://errors.pydantic.dev/2.10/v/literal_error
Traceback (most recent call last):

  File "C:\Users\mikeb\work\sifu2\run_agents.py", line 868, in <module>
    asyncio.run(main())

  File "C:\Python313\Lib\asyncio\runners.py", line 194, in run
    return runner.run(main)
  File "C:\Python313\Lib\asyncio\runners.py", line 118, in run
    return self._loop.run_until_complete(task)
  File "C:\Python313\Lib\asyncio\base_events.py", line 707, in run_until_complete
    self.run_forever()
  File "C:\Python313\Lib\asyncio\base_events.py", line 678, in run_forever
    self._run_once()
  File "C:\Python313\Lib\asyncio\base_events.py", line 2033, in _run_once
    handle._run()
  File "C:\Python313\Lib\asyncio\events.py", line 89, in _run
    self._context.run(self._callback, *self._args)

  File "C:\Users\mikeb\work\sifu2\run_agents.py", line 857, in main
    await agent.run()

  File "C:\Users\mikeb\work\sifu2\run_agents.py", line 691, in run
    result = await getattr(self, task.tool)(**task.args)

  File "C:\Users\mikeb\work\sifu2\run_agents.py", line 344, in _synthesize_knowledge
    knowledge = await self.knowledge_system.process_source(content)

  File "C:\Users\mikeb\work\sifu2\scripts\knowledge_acquisition.py", line 466, in process_source
    relationships = await self._extract_relationships(content)

> File "C:\Users\mikeb\work\sifu2\scripts\knowledge_acquisition.py", line 650, in _extract_relationships
    converted_relationships.append(Relationship(**rel))

  File "C:\Python313\Lib\site-packages\pydantic\main.py", line 214, in __init__
    validated_self = self.__pydantic_validator__.validate_python(data, self_instance=self)

pydantic_core._pydantic_core.ValidationError: 1 validation error for Relationship
relation
  Input should be 'is_a', 'has_part' or 'related_to' [type=literal_error, input_value='applied_to', input_type=str]
    For further information visit https://errors.pydantic.dev/2.10/v/literal_error
2025-02-09 14:56:54.151 | 40372:34912 | INFO     | scripts.knowledge_acquisition:process_source:478 | KnowledgeAcquisition: Extracted 3 relationships
2025-02-09 14:56:54.153 | 40372:34912 | INFO     | scripts.knowledge_acquisition:process_source:482 | KnowledgeAcquisition: Relationship: Convolutional Neural Networks (CNNs) -> is_a -> Neural Networks
2025-02-09 14:56:54.154 | 40372:34912 | INFO     | scripts.knowledge_acquisition:process_source:482 | KnowledgeAcquisition: Relationship: Recurrent Neural Networks (RNNs) -> is_a -> Neural Networks
2025-02-09 14:56:54.156 | 40372:34912 | INFO     | scripts.knowledge_acquisition:process_source:482 | KnowledgeAcquisition: Relationship: Neural Networks -> is_a -> Machine Learning Models
2025-02-09 14:56:54.157 | 40372:34912 | INFO     | scripts.knowledge_acquisition:process_source:488 | KnowledgeAcquisition: Generating metadata...
2025-02-09 14:56:55.167 | 40372:34912 | INFO     | scripts.knowledge_acquisition:process_source:495 | KnowledgeAcquisition: Generated metadata: {'source_type': 'text', 'confidence_score': 0.9, 'domain_relevance': 0.8, 'timestamp': '2024-02-09T12:45:00.000Z', 'validation_status': 'processed', 'domain': 'machine_learning'}
2025-02-09 14:56:55.170 | 40372:34912 | INFO     | scripts.knowledge_acquisition:process_source:501 | KnowledgeAcquisition: Evaluating confidence...
2025-02-09 14:56:56.567 | 40372:34912 | INFO     | scripts.knowledge_acquisition:process_source:511 | KnowledgeAcquisition: Confidence score: 0.8
2025-02-09 14:56:56.577 | 40372:34912 | INFO     | __main__:_synthesize_knowledge:325 | Knowledge Synthesis: Processing source: Website Authority Checker: Check the "Authority" Of Any Domain (source_11.txt)
2025-02-09 14:56:56.579 | 40372:34912 | INFO     | __main__:_synthesize_knowledge:329 | Knowledge Synthesis: Content preview:
Ahrefs. Backlink Checker metric from Moz. When we talk about domain authority, we’re talking about a general SEO concept that’s synonymous with “website authority.” Here at Ahrefs, we have a website authority metric of our own called Domain Rating. It runs on a scale from zero to a hundred. The higher a website’s Domain Rating (DR), the stronger and more authoritative it is. The free tool above shows your website’s “authority” as calculated by Ahrefs (i.e., Domain Rating). --- ## How we calculat...
2025-02-09 14:56:56.580 | 40372:34912 | INFO     | scripts.knowledge_acquisition:process_source:444 | KnowledgeAcquisition: Starting source processing with content length: 4542
2025-02-09 14:56:56.582 | 40372:34912 | INFO     | scripts.knowledge_acquisition:process_source:448 | KnowledgeAcquisition: Content preview:
Ahrefs. Backlink Checker metric from Moz. When we talk about domain authority, we’re talking about a general SEO concept that’s synonymous with “website authority.” Here at Ahrefs, we have a website a...
2025-02-09 14:56:56.583 | 40372:34912 | INFO     | scripts.knowledge_acquisition:process_source:451 | KnowledgeAcquisition: Extracting entities...
2025-02-09 14:56:57.436 | 40372:34912 | INFO     | scripts.knowledge_acquisition:process_source:458 | KnowledgeAcquisition: Extracted 10 entities: ['Machine Learning', 'Deep Learning', 'Neural Networks', 'TensorFlow', 'Python', 'Keras', 'Computer Vision', 'Natural Language Processing', 'Data Science', 'Artificial Intelligence']
2025-02-09 14:56:57.438 | 40372:34912 | INFO     | scripts.knowledge_acquisition:process_source:464 | KnowledgeAcquisition: Extracting relationships...
2025-02-09 14:57:00.529 | 40372:34912 | ERROR    | scripts.knowledge_acquisition:_extract_relationships:652 | Failed to convert relationship: {'source': 'Data Preprocessing', 'relation': 'precedes', 'target': 'Model Training'}: 1 validation error for Relationship
relation
  Input should be 'is_a', 'has_part' or 'related_to' [type=literal_error, input_value='precedes', input_type=str]
    For further information visit https://errors.pydantic.dev/2.10/v/literal_error
Traceback (most recent call last):

  File "C:\Users\mikeb\work\sifu2\run_agents.py", line 868, in <module>
    asyncio.run(main())

  File "C:\Python313\Lib\asyncio\runners.py", line 194, in run
    return runner.run(main)
  File "C:\Python313\Lib\asyncio\runners.py", line 118, in run
    return self._loop.run_until_complete(task)
  File "C:\Python313\Lib\asyncio\base_events.py", line 707, in run_until_complete
    self.run_forever()
  File "C:\Python313\Lib\asyncio\base_events.py", line 678, in run_forever
    self._run_once()
  File "C:\Python313\Lib\asyncio\base_events.py", line 2033, in _run_once
    handle._run()
  File "C:\Python313\Lib\asyncio\events.py", line 89, in _run
    self._context.run(self._callback, *self._args)

  File "C:\Users\mikeb\work\sifu2\run_agents.py", line 857, in main
    await agent.run()

  File "C:\Users\mikeb\work\sifu2\run_agents.py", line 691, in run
    result = await getattr(self, task.tool)(**task.args)

  File "C:\Users\mikeb\work\sifu2\run_agents.py", line 344, in _synthesize_knowledge
    knowledge = await self.knowledge_system.process_source(content)

  File "C:\Users\mikeb\work\sifu2\scripts\knowledge_acquisition.py", line 466, in process_source
    relationships = await self._extract_relationships(content)

> File "C:\Users\mikeb\work\sifu2\scripts\knowledge_acquisition.py", line 650, in _extract_relationships
    converted_relationships.append(Relationship(**rel))

  File "C:\Python313\Lib\site-packages\pydantic\main.py", line 214, in __init__
    validated_self = self.__pydantic_validator__.validate_python(data, self_instance=self)

pydantic_core._pydantic_core.ValidationError: 1 validation error for Relationship
relation
  Input should be 'is_a', 'has_part' or 'related_to' [type=literal_error, input_value='precedes', input_type=str]
    For further information visit https://errors.pydantic.dev/2.10/v/literal_error
2025-02-09 14:57:00.555 | 40372:34912 | ERROR    | scripts.knowledge_acquisition:_extract_relationships:652 | Failed to convert relationship: {'source': 'Model Training', 'relation': 'uses', 'target': 'Training Data'}: 1 validation error for Relationship
relation
  Input should be 'is_a', 'has_part' or 'related_to' [type=literal_error, input_value='uses', input_type=str]
    For further information visit https://errors.pydantic.dev/2.10/v/literal_error
Traceback (most recent call last):

  File "C:\Users\mikeb\work\sifu2\run_agents.py", line 868, in <module>
    asyncio.run(main())

  File "C:\Python313\Lib\asyncio\runners.py", line 194, in run
    return runner.run(main)
  File "C:\Python313\Lib\asyncio\runners.py", line 118, in run
    return self._loop.run_until_complete(task)
  File "C:\Python313\Lib\asyncio\base_events.py", line 707, in run_until_complete
    self.run_forever()
  File "C:\Python313\Lib\asyncio\base_events.py", line 678, in run_forever
    self._run_once()
  File "C:\Python313\Lib\asyncio\base_events.py", line 2033, in _run_once
    handle._run()
  File "C:\Python313\Lib\asyncio\events.py", line 89, in _run
    self._context.run(self._callback, *self._args)

  File "C:\Users\mikeb\work\sifu2\run_agents.py", line 857, in main
    await agent.run()

  File "C:\Users\mikeb\work\sifu2\run_agents.py", line 691, in run
    result = await getattr(self, task.tool)(**task.args)

  File "C:\Users\mikeb\work\sifu2\run_agents.py", line 344, in _synthesize_knowledge
    knowledge = await self.knowledge_system.process_source(content)

  File "C:\Users\mikeb\work\sifu2\scripts\knowledge_acquisition.py", line 466, in process_source
    relationships = await self._extract_relationships(content)

> File "C:\Users\mikeb\work\sifu2\scripts\knowledge_acquisition.py", line 650, in _extract_relationships
    converted_relationships.append(Relationship(**rel))

  File "C:\Python313\Lib\site-packages\pydantic\main.py", line 214, in __init__
    validated_self = self.__pydantic_validator__.validate_python(data, self_instance=self)

pydantic_core._pydantic_core.ValidationError: 1 validation error for Relationship
relation
  Input should be 'is_a', 'has_part' or 'related_to' [type=literal_error, input_value='uses', input_type=str]
    For further information visit https://errors.pydantic.dev/2.10/v/literal_error
2025-02-09 14:57:00.578 | 40372:34912 | ERROR    | scripts.knowledge_acquisition:_extract_relationships:652 | Failed to convert relationship: {'source': 'Model Training', 'relation': 'produces', 'target': 'Trained Model'}: 1 validation error for Relationship
relation
  Input should be 'is_a', 'has_part' or 'related_to' [type=literal_error, input_value='produces', input_type=str]
    For further information visit https://errors.pydantic.dev/2.10/v/literal_error
Traceback (most recent call last):

  File "C:\Users\mikeb\work\sifu2\run_agents.py", line 868, in <module>
    asyncio.run(main())

  File "C:\Python313\Lib\asyncio\runners.py", line 194, in run
    return runner.run(main)
  File "C:\Python313\Lib\asyncio\runners.py", line 118, in run
    return self._loop.run_until_complete(task)
  File "C:\Python313\Lib\asyncio\base_events.py", line 707, in run_until_complete
    self.run_forever()
  File "C:\Python313\Lib\asyncio\base_events.py", line 678, in run_forever
    self._run_once()
  File "C:\Python313\Lib\asyncio\base_events.py", line 2033, in _run_once
    handle._run()
  File "C:\Python313\Lib\asyncio\events.py", line 89, in _run
    self._context.run(self._callback, *self._args)

  File "C:\Users\mikeb\work\sifu2\run_agents.py", line 857, in main
    await agent.run()

  File "C:\Users\mikeb\work\sifu2\run_agents.py", line 691, in run
    result = await getattr(self, task.tool)(**task.args)

  File "C:\Users\mikeb\work\sifu2\run_agents.py", line 344, in _synthesize_knowledge
    knowledge = await self.knowledge_system.process_source(content)

  File "C:\Users\mikeb\work\sifu2\scripts\knowledge_acquisition.py", line 466, in process_source
    relationships = await self._extract_relationships(content)

> File "C:\Users\mikeb\work\sifu2\scripts\knowledge_acquisition.py", line 650, in _extract_relationships
    converted_relationships.append(Relationship(**rel))

  File "C:\Python313\Lib\site-packages\pydantic\main.py", line 214, in __init__
    validated_self = self.__pydantic_validator__.validate_python(data, self_instance=self)

pydantic_core._pydantic_core.ValidationError: 1 validation error for Relationship
relation
  Input should be 'is_a', 'has_part' or 'related_to' [type=literal_error, input_value='produces', input_type=str]
    For further information visit https://errors.pydantic.dev/2.10/v/literal_error
2025-02-09 14:57:00.600 | 40372:34912 | ERROR    | scripts.knowledge_acquisition:_extract_relationships:652 | Failed to convert relationship: {'source': 'Trained Model', 'relation': 'used_in', 'target': 'Model Evaluation'}: 1 validation error for Relationship
relation
  Input should be 'is_a', 'has_part' or 'related_to' [type=literal_error, input_value='used_in', input_type=str]
    For further information visit https://errors.pydantic.dev/2.10/v/literal_error
Traceback (most recent call last):

  File "C:\Users\mikeb\work\sifu2\run_agents.py", line 868, in <module>
    asyncio.run(main())

  File "C:\Python313\Lib\asyncio\runners.py", line 194, in run
    return runner.run(main)
  File "C:\Python313\Lib\asyncio\runners.py", line 118, in run
    return self._loop.run_until_complete(task)
  File "C:\Python313\Lib\asyncio\base_events.py", line 707, in run_until_complete
    self.run_forever()
  File "C:\Python313\Lib\asyncio\base_events.py", line 678, in run_forever
    self._run_once()
  File "C:\Python313\Lib\asyncio\base_events.py", line 2033, in _run_once
    handle._run()
  File "C:\Python313\Lib\asyncio\events.py", line 89, in _run
    self._context.run(self._callback, *self._args)

  File "C:\Users\mikeb\work\sifu2\run_agents.py", line 857, in main
    await agent.run()

  File "C:\Users\mikeb\work\sifu2\run_agents.py", line 691, in run
    result = await getattr(self, task.tool)(**task.args)

  File "C:\Users\mikeb\work\sifu2\run_agents.py", line 344, in _synthesize_knowledge
    knowledge = await self.knowledge_system.process_source(content)

  File "C:\Users\mikeb\work\sifu2\scripts\knowledge_acquisition.py", line 466, in process_source
    relationships = await self._extract_relationships(content)

> File "C:\Users\mikeb\work\sifu2\scripts\knowledge_acquisition.py", line 650, in _extract_relationships
    converted_relationships.append(Relationship(**rel))

  File "C:\Python313\Lib\site-packages\pydantic\main.py", line 214, in __init__
    validated_self = self.__pydantic_validator__.validate_python(data, self_instance=self)

pydantic_core._pydantic_core.ValidationError: 1 validation error for Relationship
relation
  Input should be 'is_a', 'has_part' or 'related_to' [type=literal_error, input_value='used_in', input_type=str]
    For further information visit https://errors.pydantic.dev/2.10/v/literal_error
2025-02-09 14:57:00.625 | 40372:34912 | ERROR    | scripts.knowledge_acquisition:_extract_relationships:652 | Failed to convert relationship: {'source': 'Model Evaluation', 'relation': 'uses', 'target': 'Evaluation Metrics'}: 1 validation error for Relationship
relation
  Input should be 'is_a', 'has_part' or 'related_to' [type=literal_error, input_value='uses', input_type=str]
    For further information visit https://errors.pydantic.dev/2.10/v/literal_error
Traceback (most recent call last):

  File "C:\Users\mikeb\work\sifu2\run_agents.py", line 868, in <module>
    asyncio.run(main())

  File "C:\Python313\Lib\asyncio\runners.py", line 194, in run
    return runner.run(main)
  File "C:\Python313\Lib\asyncio\runners.py", line 118, in run
    return self._loop.run_until_complete(task)
  File "C:\Python313\Lib\asyncio\base_events.py", line 707, in run_until_complete
    self.run_forever()
  File "C:\Python313\Lib\asyncio\base_events.py", line 678, in run_forever
    self._run_once()
  File "C:\Python313\Lib\asyncio\base_events.py", line 2033, in _run_once
    handle._run()
  File "C:\Python313\Lib\asyncio\events.py", line 89, in _run
    self._context.run(self._callback, *self._args)

  File "C:\Users\mikeb\work\sifu2\run_agents.py", line 857, in main
    await agent.run()

  File "C:\Users\mikeb\work\sifu2\run_agents.py", line 691, in run
    result = await getattr(self, task.tool)(**task.args)

  File "C:\Users\mikeb\work\sifu2\run_agents.py", line 344, in _synthesize_knowledge
    knowledge = await self.knowledge_system.process_source(content)

  File "C:\Users\mikeb\work\sifu2\scripts\knowledge_acquisition.py", line 466, in process_source
    relationships = await self._extract_relationships(content)

> File "C:\Users\mikeb\work\sifu2\scripts\knowledge_acquisition.py", line 650, in _extract_relationships
    converted_relationships.append(Relationship(**rel))

  File "C:\Python313\Lib\site-packages\pydantic\main.py", line 214, in __init__
    validated_self = self.__pydantic_validator__.validate_python(data, self_instance=self)

pydantic_core._pydantic_core.ValidationError: 1 validation error for Relationship
relation
  Input should be 'is_a', 'has_part' or 'related_to' [type=literal_error, input_value='uses', input_type=str]
    For further information visit https://errors.pydantic.dev/2.10/v/literal_error
2025-02-09 14:57:00.649 | 40372:34912 | ERROR    | scripts.knowledge_acquisition:_extract_relationships:652 | Failed to convert relationship: {'source': 'CNNs', 'relation': 'applied_to', 'target': 'Image Recognition'}: 1 validation error for Relationship
relation
  Input should be 'is_a', 'has_part' or 'related_to' [type=literal_error, input_value='applied_to', input_type=str]
    For further information visit https://errors.pydantic.dev/2.10/v/literal_error
Traceback (most recent call last):

  File "C:\Users\mikeb\work\sifu2\run_agents.py", line 868, in <module>
    asyncio.run(main())

  File "C:\Python313\Lib\asyncio\runners.py", line 194, in run
    return runner.run(main)
  File "C:\Python313\Lib\asyncio\runners.py", line 118, in run
    return self._loop.run_until_complete(task)
  File "C:\Python313\Lib\asyncio\base_events.py", line 707, in run_until_complete
    self.run_forever()
  File "C:\Python313\Lib\asyncio\base_events.py", line 678, in run_forever
    self._run_once()
  File "C:\Python313\Lib\asyncio\base_events.py", line 2033, in _run_once
    handle._run()
  File "C:\Python313\Lib\asyncio\events.py", line 89, in _run
    self._context.run(self._callback, *self._args)

  File "C:\Users\mikeb\work\sifu2\run_agents.py", line 857, in main
    await agent.run()

  File "C:\Users\mikeb\work\sifu2\run_agents.py", line 691, in run
    result = await getattr(self, task.tool)(**task.args)

  File "C:\Users\mikeb\work\sifu2\run_agents.py", line 344, in _synthesize_knowledge
    knowledge = await self.knowledge_system.process_source(content)

  File "C:\Users\mikeb\work\sifu2\scripts\knowledge_acquisition.py", line 466, in process_source
    relationships = await self._extract_relationships(content)

> File "C:\Users\mikeb\work\sifu2\scripts\knowledge_acquisition.py", line 650, in _extract_relationships
    converted_relationships.append(Relationship(**rel))

  File "C:\Python313\Lib\site-packages\pydantic\main.py", line 214, in __init__
    validated_self = self.__pydantic_validator__.validate_python(data, self_instance=self)

pydantic_core._pydantic_core.ValidationError: 1 validation error for Relationship
relation
  Input should be 'is_a', 'has_part' or 'related_to' [type=literal_error, input_value='applied_to', input_type=str]
    For further information visit https://errors.pydantic.dev/2.10/v/literal_error
2025-02-09 14:57:00.674 | 40372:34912 | ERROR    | scripts.knowledge_acquisition:_extract_relationships:652 | Failed to convert relationship: {'source': 'RNNs', 'relation': 'applied_to', 'target': 'Natural Language Processing'}: 1 validation error for Relationship
relation
  Input should be 'is_a', 'has_part' or 'related_to' [type=literal_error, input_value='applied_to', input_type=str]
    For further information visit https://errors.pydantic.dev/2.10/v/literal_error
Traceback (most recent call last):

  File "C:\Users\mikeb\work\sifu2\run_agents.py", line 868, in <module>
    asyncio.run(main())

  File "C:\Python313\Lib\asyncio\runners.py", line 194, in run
    return runner.run(main)
  File "C:\Python313\Lib\asyncio\runners.py", line 118, in run
    return self._loop.run_until_complete(task)
  File "C:\Python313\Lib\asyncio\base_events.py", line 707, in run_until_complete
    self.run_forever()
  File "C:\Python313\Lib\asyncio\base_events.py", line 678, in run_forever
    self._run_once()
  File "C:\Python313\Lib\asyncio\base_events.py", line 2033, in _run_once
    handle._run()
  File "C:\Python313\Lib\asyncio\events.py", line 89, in _run
    self._context.run(self._callback, *self._args)

  File "C:\Users\mikeb\work\sifu2\run_agents.py", line 857, in main
    await agent.run()

  File "C:\Users\mikeb\work\sifu2\run_agents.py", line 691, in run
    result = await getattr(self, task.tool)(**task.args)

  File "C:\Users\mikeb\work\sifu2\run_agents.py", line 344, in _synthesize_knowledge
    knowledge = await self.knowledge_system.process_source(content)

  File "C:\Users\mikeb\work\sifu2\scripts\knowledge_acquisition.py", line 466, in process_source
    relationships = await self._extract_relationships(content)

> File "C:\Users\mikeb\work\sifu2\scripts\knowledge_acquisition.py", line 650, in _extract_relationships
    converted_relationships.append(Relationship(**rel))

  File "C:\Python313\Lib\site-packages\pydantic\main.py", line 214, in __init__
    validated_self = self.__pydantic_validator__.validate_python(data, self_instance=self)

pydantic_core._pydantic_core.ValidationError: 1 validation error for Relationship
relation
  Input should be 'is_a', 'has_part' or 'related_to' [type=literal_error, input_value='applied_to', input_type=str]
    For further information visit https://errors.pydantic.dev/2.10/v/literal_error
2025-02-09 14:57:00.700 | 40372:34912 | INFO     | scripts.knowledge_acquisition:process_source:478 | KnowledgeAcquisition: Extracted 3 relationships
2025-02-09 14:57:00.702 | 40372:34912 | INFO     | scripts.knowledge_acquisition:process_source:482 | KnowledgeAcquisition: Relationship: Convolutional Neural Networks (CNNs) -> is_a -> Neural Networks
2025-02-09 14:57:00.704 | 40372:34912 | INFO     | scripts.knowledge_acquisition:process_source:482 | KnowledgeAcquisition: Relationship: Recurrent Neural Networks (RNNs) -> is_a -> Neural Networks
2025-02-09 14:57:00.706 | 40372:34912 | INFO     | scripts.knowledge_acquisition:process_source:482 | KnowledgeAcquisition: Relationship: Neural Networks -> is_a -> Machine Learning Models
2025-02-09 14:57:00.708 | 40372:34912 | INFO     | scripts.knowledge_acquisition:process_source:488 | KnowledgeAcquisition: Generating metadata...
2025-02-09 14:57:01.927 | 40372:34912 | INFO     | scripts.knowledge_acquisition:process_source:495 | KnowledgeAcquisition: Generated metadata: {'source_type': 'text', 'confidence_score': 0.85, 'domain_relevance': 0.9, 'timestamp': '2024-02-09T11:42:32.000Z', 'validation_status': 'processed', 'domain': 'machine_learning'}
2025-02-09 14:57:01.929 | 40372:34912 | INFO     | scripts.knowledge_acquisition:process_source:501 | KnowledgeAcquisition: Evaluating confidence...
2025-02-09 14:57:03.280 | 40372:34912 | INFO     | scripts.knowledge_acquisition:process_source:511 | KnowledgeAcquisition: Confidence score: 0.8
2025-02-09 14:57:03.288 | 40372:34912 | INFO     | __main__:_synthesize_knowledge:325 | Knowledge Synthesis: Processing source: Domain Testing in Software Engineering - GeeksforGeeks (source_13.txt)
2025-02-09 14:57:03.289 | 40372:34912 | INFO     | __main__:_synthesize_knowledge:329 | Knowledge Synthesis: Content preview:
Skip to content !geeksforgeeks( - Data Structure & Algorithm(JavaScript)]( to develop a quality software product. Software testing * Structure of Domain Testing * Domain Knowledge * Domain Testing Strategy * A real-life example of Domain testing * Skills required for Domain testing * Advantages of Domain Testing * Disadvantages of Domain Testing * Conclusion ****Domain Testing :**** It is a software testing technique where minimum numbers of inputs are used to access appropriate output of a syst...
2025-02-09 14:57:03.291 | 40372:34912 | INFO     | scripts.knowledge_acquisition:process_source:444 | KnowledgeAcquisition: Starting source processing with content length: 9236
2025-02-09 14:57:03.292 | 40372:34912 | INFO     | scripts.knowledge_acquisition:process_source:448 | KnowledgeAcquisition: Content preview:
Skip to content !geeksforgeeks( - Data Structure & Algorithm(JavaScript)]( to develop a quality software product. Software testing * Structure of Domain Testing * Domain Knowledge * Domain Testing Str...
2025-02-09 14:57:03.293 | 40372:34912 | INFO     | scripts.knowledge_acquisition:process_source:451 | KnowledgeAcquisition: Extracting entities...
2025-02-09 14:57:04.162 | 40372:34912 | INFO     | scripts.knowledge_acquisition:process_source:458 | KnowledgeAcquisition: Extracted 10 entities: ['Machine Learning', 'Deep Learning', 'Neural Networks', 'TensorFlow', 'Python', 'Natural Language Processing', 'Computer Vision', 'Data Science', 'Artificial Intelligence', 'Big Data']
2025-02-09 14:57:04.164 | 40372:34912 | INFO     | scripts.knowledge_acquisition:process_source:464 | KnowledgeAcquisition: Extracting relationships...
2025-02-09 14:57:07.370 | 40372:34912 | ERROR    | scripts.knowledge_acquisition:_extract_relationships:652 | Failed to convert relationship: {'source': 'Data Preprocessing', 'relation': 'precedes', 'target': 'Model Training'}: 1 validation error for Relationship
relation
  Input should be 'is_a', 'has_part' or 'related_to' [type=literal_error, input_value='precedes', input_type=str]
    For further information visit https://errors.pydantic.dev/2.10/v/literal_error
Traceback (most recent call last):

  File "C:\Users\mikeb\work\sifu2\run_agents.py", line 868, in <module>
    asyncio.run(main())

  File "C:\Python313\Lib\asyncio\runners.py", line 194, in run
    return runner.run(main)
  File "C:\Python313\Lib\asyncio\runners.py", line 118, in run
    return self._loop.run_until_complete(task)
  File "C:\Python313\Lib\asyncio\base_events.py", line 707, in run_until_complete
    self.run_forever()
  File "C:\Python313\Lib\asyncio\base_events.py", line 678, in run_forever
    self._run_once()
  File "C:\Python313\Lib\asyncio\base_events.py", line 2033, in _run_once
    handle._run()
  File "C:\Python313\Lib\asyncio\events.py", line 89, in _run
    self._context.run(self._callback, *self._args)

  File "C:\Users\mikeb\work\sifu2\run_agents.py", line 857, in main
    await agent.run()

  File "C:\Users\mikeb\work\sifu2\run_agents.py", line 691, in run
    result = await getattr(self, task.tool)(**task.args)

  File "C:\Users\mikeb\work\sifu2\run_agents.py", line 344, in _synthesize_knowledge
    knowledge = await self.knowledge_system.process_source(content)

  File "C:\Users\mikeb\work\sifu2\scripts\knowledge_acquisition.py", line 466, in process_source
    relationships = await self._extract_relationships(content)

> File "C:\Users\mikeb\work\sifu2\scripts\knowledge_acquisition.py", line 650, in _extract_relationships
    converted_relationships.append(Relationship(**rel))

  File "C:\Python313\Lib\site-packages\pydantic\main.py", line 214, in __init__
    validated_self = self.__pydantic_validator__.validate_python(data, self_instance=self)

pydantic_core._pydantic_core.ValidationError: 1 validation error for Relationship
relation
  Input should be 'is_a', 'has_part' or 'related_to' [type=literal_error, input_value='precedes', input_type=str]
    For further information visit https://errors.pydantic.dev/2.10/v/literal_error
2025-02-09 14:57:07.391 | 40372:34912 | ERROR    | scripts.knowledge_acquisition:_extract_relationships:652 | Failed to convert relationship: {'source': 'Model Training', 'relation': 'uses', 'target': 'Training Data'}: 1 validation error for Relationship
relation
  Input should be 'is_a', 'has_part' or 'related_to' [type=literal_error, input_value='uses', input_type=str]
    For further information visit https://errors.pydantic.dev/2.10/v/literal_error
Traceback (most recent call last):

  File "C:\Users\mikeb\work\sifu2\run_agents.py", line 868, in <module>
    asyncio.run(main())

  File "C:\Python313\Lib\asyncio\runners.py", line 194, in run
    return runner.run(main)
  File "C:\Python313\Lib\asyncio\runners.py", line 118, in run
    return self._loop.run_until_complete(task)
  File "C:\Python313\Lib\asyncio\base_events.py", line 707, in run_until_complete
    self.run_forever()
  File "C:\Python313\Lib\asyncio\base_events.py", line 678, in run_forever
    self._run_once()
  File "C:\Python313\Lib\asyncio\base_events.py", line 2033, in _run_once
    handle._run()
  File "C:\Python313\Lib\asyncio\events.py", line 89, in _run
    self._context.run(self._callback, *self._args)

  File "C:\Users\mikeb\work\sifu2\run_agents.py", line 857, in main
    await agent.run()

  File "C:\Users\mikeb\work\sifu2\run_agents.py", line 691, in run
    result = await getattr(self, task.tool)(**task.args)

  File "C:\Users\mikeb\work\sifu2\run_agents.py", line 344, in _synthesize_knowledge
    knowledge = await self.knowledge_system.process_source(content)

  File "C:\Users\mikeb\work\sifu2\scripts\knowledge_acquisition.py", line 466, in process_source
    relationships = await self._extract_relationships(content)

> File "C:\Users\mikeb\work\sifu2\scripts\knowledge_acquisition.py", line 650, in _extract_relationships
    converted_relationships.append(Relationship(**rel))

  File "C:\Python313\Lib\site-packages\pydantic\main.py", line 214, in __init__
    validated_self = self.__pydantic_validator__.validate_python(data, self_instance=self)

pydantic_core._pydantic_core.ValidationError: 1 validation error for Relationship
relation
  Input should be 'is_a', 'has_part' or 'related_to' [type=literal_error, input_value='uses', input_type=str]
    For further information visit https://errors.pydantic.dev/2.10/v/literal_error
2025-02-09 14:57:07.413 | 40372:34912 | ERROR    | scripts.knowledge_acquisition:_extract_relationships:652 | Failed to convert relationship: {'source': 'Model Training', 'relation': 'output_of', 'target': 'Trained Model'}: 1 validation error for Relationship
relation
  Input should be 'is_a', 'has_part' or 'related_to' [type=literal_error, input_value='output_of', input_type=str]
    For further information visit https://errors.pydantic.dev/2.10/v/literal_error
Traceback (most recent call last):

  File "C:\Users\mikeb\work\sifu2\run_agents.py", line 868, in <module>
    asyncio.run(main())

  File "C:\Python313\Lib\asyncio\runners.py", line 194, in run
    return runner.run(main)
  File "C:\Python313\Lib\asyncio\runners.py", line 118, in run
    return self._loop.run_until_complete(task)
  File "C:\Python313\Lib\asyncio\base_events.py", line 707, in run_until_complete
    self.run_forever()
  File "C:\Python313\Lib\asyncio\base_events.py", line 678, in run_forever
    self._run_once()
  File "C:\Python313\Lib\asyncio\base_events.py", line 2033, in _run_once
    handle._run()
  File "C:\Python313\Lib\asyncio\events.py", line 89, in _run
    self._context.run(self._callback, *self._args)

  File "C:\Users\mikeb\work\sifu2\run_agents.py", line 857, in main
    await agent.run()

  File "C:\Users\mikeb\work\sifu2\run_agents.py", line 691, in run
    result = await getattr(self, task.tool)(**task.args)

  File "C:\Users\mikeb\work\sifu2\run_agents.py", line 344, in _synthesize_knowledge
    knowledge = await self.knowledge_system.process_source(content)

  File "C:\Users\mikeb\work\sifu2\scripts\knowledge_acquisition.py", line 466, in process_source
    relationships = await self._extract_relationships(content)

> File "C:\Users\mikeb\work\sifu2\scripts\knowledge_acquisition.py", line 650, in _extract_relationships
    converted_relationships.append(Relationship(**rel))

  File "C:\Python313\Lib\site-packages\pydantic\main.py", line 214, in __init__
    validated_self = self.__pydantic_validator__.validate_python(data, self_instance=self)

pydantic_core._pydantic_core.ValidationError: 1 validation error for Relationship
relation
  Input should be 'is_a', 'has_part' or 'related_to' [type=literal_error, input_value='output_of', input_type=str]
    For further information visit https://errors.pydantic.dev/2.10/v/literal_error
2025-02-09 14:57:07.437 | 40372:34912 | ERROR    | scripts.knowledge_acquisition:_extract_relationships:652 | Failed to convert relationship: {'source': 'Trained Model', 'relation': 'input_to', 'target': 'Model Evaluation'}: 1 validation error for Relationship
relation
  Input should be 'is_a', 'has_part' or 'related_to' [type=literal_error, input_value='input_to', input_type=str]
    For further information visit https://errors.pydantic.dev/2.10/v/literal_error
Traceback (most recent call last):

  File "C:\Users\mikeb\work\sifu2\run_agents.py", line 868, in <module>
    asyncio.run(main())

  File "C:\Python313\Lib\asyncio\runners.py", line 194, in run
    return runner.run(main)
  File "C:\Python313\Lib\asyncio\runners.py", line 118, in run
    return self._loop.run_until_complete(task)
  File "C:\Python313\Lib\asyncio\base_events.py", line 707, in run_until_complete
    self.run_forever()
  File "C:\Python313\Lib\asyncio\base_events.py", line 678, in run_forever
    self._run_once()
  File "C:\Python313\Lib\asyncio\base_events.py", line 2033, in _run_once
    handle._run()
  File "C:\Python313\Lib\asyncio\events.py", line 89, in _run
    self._context.run(self._callback, *self._args)

  File "C:\Users\mikeb\work\sifu2\run_agents.py", line 857, in main
    await agent.run()

  File "C:\Users\mikeb\work\sifu2\run_agents.py", line 691, in run
    result = await getattr(self, task.tool)(**task.args)

  File "C:\Users\mikeb\work\sifu2\run_agents.py", line 344, in _synthesize_knowledge
    knowledge = await self.knowledge_system.process_source(content)

  File "C:\Users\mikeb\work\sifu2\scripts\knowledge_acquisition.py", line 466, in process_source
    relationships = await self._extract_relationships(content)

> File "C:\Users\mikeb\work\sifu2\scripts\knowledge_acquisition.py", line 650, in _extract_relationships
    converted_relationships.append(Relationship(**rel))

  File "C:\Python313\Lib\site-packages\pydantic\main.py", line 214, in __init__
    validated_self = self.__pydantic_validator__.validate_python(data, self_instance=self)

pydantic_core._pydantic_core.ValidationError: 1 validation error for Relationship
relation
  Input should be 'is_a', 'has_part' or 'related_to' [type=literal_error, input_value='input_to', input_type=str]
    For further information visit https://errors.pydantic.dev/2.10/v/literal_error
2025-02-09 14:57:07.460 | 40372:34912 | ERROR    | scripts.knowledge_acquisition:_extract_relationships:652 | Failed to convert relationship: {'source': 'Model Evaluation', 'relation': 'uses', 'target': 'Evaluation Metrics'}: 1 validation error for Relationship
relation
  Input should be 'is_a', 'has_part' or 'related_to' [type=literal_error, input_value='uses', input_type=str]
    For further information visit https://errors.pydantic.dev/2.10/v/literal_error
Traceback (most recent call last):

  File "C:\Users\mikeb\work\sifu2\run_agents.py", line 868, in <module>
    asyncio.run(main())

  File "C:\Python313\Lib\asyncio\runners.py", line 194, in run
    return runner.run(main)
  File "C:\Python313\Lib\asyncio\runners.py", line 118, in run
    return self._loop.run_until_complete(task)
  File "C:\Python313\Lib\asyncio\base_events.py", line 707, in run_until_complete
    self.run_forever()
  File "C:\Python313\Lib\asyncio\base_events.py", line 678, in run_forever
    self._run_once()
  File "C:\Python313\Lib\asyncio\base_events.py", line 2033, in _run_once
    handle._run()
  File "C:\Python313\Lib\asyncio\events.py", line 89, in _run
    self._context.run(self._callback, *self._args)

  File "C:\Users\mikeb\work\sifu2\run_agents.py", line 857, in main
    await agent.run()

  File "C:\Users\mikeb\work\sifu2\run_agents.py", line 691, in run
    result = await getattr(self, task.tool)(**task.args)

  File "C:\Users\mikeb\work\sifu2\run_agents.py", line 344, in _synthesize_knowledge
    knowledge = await self.knowledge_system.process_source(content)

  File "C:\Users\mikeb\work\sifu2\scripts\knowledge_acquisition.py", line 466, in process_source
    relationships = await self._extract_relationships(content)

> File "C:\Users\mikeb\work\sifu2\scripts\knowledge_acquisition.py", line 650, in _extract_relationships
    converted_relationships.append(Relationship(**rel))

  File "C:\Python313\Lib\site-packages\pydantic\main.py", line 214, in __init__
    validated_self = self.__pydantic_validator__.validate_python(data, self_instance=self)

pydantic_core._pydantic_core.ValidationError: 1 validation error for Relationship
relation
  Input should be 'is_a', 'has_part' or 'related_to' [type=literal_error, input_value='uses', input_type=str]
    For further information visit https://errors.pydantic.dev/2.10/v/literal_error
2025-02-09 14:57:07.482 | 40372:34912 | ERROR    | scripts.knowledge_acquisition:_extract_relationships:652 | Failed to convert relationship: {'source': 'CNNs', 'relation': 'applied_to', 'target': 'Image Recognition'}: 1 validation error for Relationship
relation
  Input should be 'is_a', 'has_part' or 'related_to' [type=literal_error, input_value='applied_to', input_type=str]
    For further information visit https://errors.pydantic.dev/2.10/v/literal_error
Traceback (most recent call last):

  File "C:\Users\mikeb\work\sifu2\run_agents.py", line 868, in <module>
    asyncio.run(main())

  File "C:\Python313\Lib\asyncio\runners.py", line 194, in run
    return runner.run(main)
  File "C:\Python313\Lib\asyncio\runners.py", line 118, in run
    return self._loop.run_until_complete(task)
  File "C:\Python313\Lib\asyncio\base_events.py", line 707, in run_until_complete
    self.run_forever()
  File "C:\Python313\Lib\asyncio\base_events.py", line 678, in run_forever
    self._run_once()
  File "C:\Python313\Lib\asyncio\base_events.py", line 2033, in _run_once
    handle._run()
  File "C:\Python313\Lib\asyncio\events.py", line 89, in _run
    self._context.run(self._callback, *self._args)

  File "C:\Users\mikeb\work\sifu2\run_agents.py", line 857, in main
    await agent.run()

  File "C:\Users\mikeb\work\sifu2\run_agents.py", line 691, in run
    result = await getattr(self, task.tool)(**task.args)

  File "C:\Users\mikeb\work\sifu2\run_agents.py", line 344, in _synthesize_knowledge
    knowledge = await self.knowledge_system.process_source(content)

  File "C:\Users\mikeb\work\sifu2\scripts\knowledge_acquisition.py", line 466, in process_source
    relationships = await self._extract_relationships(content)

> File "C:\Users\mikeb\work\sifu2\scripts\knowledge_acquisition.py", line 650, in _extract_relationships
    converted_relationships.append(Relationship(**rel))

  File "C:\Python313\Lib\site-packages\pydantic\main.py", line 214, in __init__
    validated_self = self.__pydantic_validator__.validate_python(data, self_instance=self)

pydantic_core._pydantic_core.ValidationError: 1 validation error for Relationship
relation
  Input should be 'is_a', 'has_part' or 'related_to' [type=literal_error, input_value='applied_to', input_type=str]
    For further information visit https://errors.pydantic.dev/2.10/v/literal_error
2025-02-09 14:57:07.504 | 40372:34912 | ERROR    | scripts.knowledge_acquisition:_extract_relationships:652 | Failed to convert relationship: {'source': 'RNNs', 'relation': 'applied_to', 'target': 'Natural Language Processing'}: 1 validation error for Relationship
relation
  Input should be 'is_a', 'has_part' or 'related_to' [type=literal_error, input_value='applied_to', input_type=str]
    For further information visit https://errors.pydantic.dev/2.10/v/literal_error
Traceback (most recent call last):

  File "C:\Users\mikeb\work\sifu2\run_agents.py", line 868, in <module>
    asyncio.run(main())

  File "C:\Python313\Lib\asyncio\runners.py", line 194, in run
    return runner.run(main)
  File "C:\Python313\Lib\asyncio\runners.py", line 118, in run
    return self._loop.run_until_complete(task)
  File "C:\Python313\Lib\asyncio\base_events.py", line 707, in run_until_complete
    self.run_forever()
  File "C:\Python313\Lib\asyncio\base_events.py", line 678, in run_forever
    self._run_once()
  File "C:\Python313\Lib\asyncio\base_events.py", line 2033, in _run_once
    handle._run()
  File "C:\Python313\Lib\asyncio\events.py", line 89, in _run
    self._context.run(self._callback, *self._args)

  File "C:\Users\mikeb\work\sifu2\run_agents.py", line 857, in main
    await agent.run()

  File "C:\Users\mikeb\work\sifu2\run_agents.py", line 691, in run
    result = await getattr(self, task.tool)(**task.args)

  File "C:\Users\mikeb\work\sifu2\run_agents.py", line 344, in _synthesize_knowledge
    knowledge = await self.knowledge_system.process_source(content)

  File "C:\Users\mikeb\work\sifu2\scripts\knowledge_acquisition.py", line 466, in process_source
    relationships = await self._extract_relationships(content)

> File "C:\Users\mikeb\work\sifu2\scripts\knowledge_acquisition.py", line 650, in _extract_relationships
    converted_relationships.append(Relationship(**rel))

  File "C:\Python313\Lib\site-packages\pydantic\main.py", line 214, in __init__
    validated_self = self.__pydantic_validator__.validate_python(data, self_instance=self)

pydantic_core._pydantic_core.ValidationError: 1 validation error for Relationship
relation
  Input should be 'is_a', 'has_part' or 'related_to' [type=literal_error, input_value='applied_to', input_type=str]
    For further information visit https://errors.pydantic.dev/2.10/v/literal_error
2025-02-09 14:57:07.527 | 40372:34912 | INFO     | scripts.knowledge_acquisition:process_source:478 | KnowledgeAcquisition: Extracted 3 relationships
2025-02-09 14:57:07.529 | 40372:34912 | INFO     | scripts.knowledge_acquisition:process_source:482 | KnowledgeAcquisition: Relationship: Convolutional Neural Networks (CNNs) -> is_a -> Neural Networks
2025-02-09 14:57:07.531 | 40372:34912 | INFO     | scripts.knowledge_acquisition:process_source:482 | KnowledgeAcquisition: Relationship: Recurrent Neural Networks (RNNs) -> is_a -> Neural Networks
2025-02-09 14:57:07.532 | 40372:34912 | INFO     | scripts.knowledge_acquisition:process_source:482 | KnowledgeAcquisition: Relationship: Neural Networks -> is_a -> Machine Learning Models
2025-02-09 14:57:07.533 | 40372:34912 | INFO     | scripts.knowledge_acquisition:process_source:488 | KnowledgeAcquisition: Generating metadata...
2025-02-09 14:57:08.615 | 40372:34912 | INFO     | scripts.knowledge_acquisition:process_source:495 | KnowledgeAcquisition: Generated metadata: {'source_type': 'text', 'confidence_score': 0.85, 'domain_relevance': 0.9, 'timestamp': '2024-02-09T11:42:32.000Z', 'validation_status': 'processed', 'domain': 'machine_learning'}
2025-02-09 14:57:08.617 | 40372:34912 | INFO     | scripts.knowledge_acquisition:process_source:501 | KnowledgeAcquisition: Evaluating confidence...
2025-02-09 14:57:10.098 | 40372:34912 | INFO     | scripts.knowledge_acquisition:process_source:511 | KnowledgeAcquisition: Confidence score: 0.8
2025-02-09 14:57:10.106 | 40372:34912 | INFO     | __main__:_synthesize_knowledge:325 | Knowledge Synthesis: Processing source: Introduction to Domain Overview - Help Hub - Moz (source_15.txt)
2025-02-09 14:57:10.108 | 40372:34912 | INFO     | __main__:_synthesize_knowledge:329 | Knowledge Synthesis: Content preview:
Skip to content Moz logo * Products + Moz Pro + Moz Pro Home + Moz Local + Moz Local Home + STAT + Moz API + Moz API Home + Compare SEO Products + Moz Data * Free SEO Tools + Domain Analysis + Keyword Explorer + Link Explorer + Competitive Re + [MozBar + More Free SEO Tools * Learn SEO + Beginner's Guide to SEO + SEO Learning Center + Moz Academy + SEO Q&A + Webinars, Whitepapers, & Guides * Blog * Why Moz + Agency Solutions + Enterprise Solutions + Small Business Solutions + Case Studies + The ...
2025-02-09 14:57:10.109 | 40372:34912 | INFO     | scripts.knowledge_acquisition:process_source:444 | KnowledgeAcquisition: Starting source processing with content length: 5817
2025-02-09 14:57:10.110 | 40372:34912 | INFO     | scripts.knowledge_acquisition:process_source:448 | KnowledgeAcquisition: Content preview:
Skip to content Moz logo * Products + Moz Pro + Moz Pro Home + Moz Local + Moz Local Home + STAT + Moz API + Moz API Home + Compare SEO Products + Moz Data * Free SEO Tools + Domain Analysis + Keyword...
2025-02-09 14:57:10.112 | 40372:34912 | INFO     | scripts.knowledge_acquisition:process_source:451 | KnowledgeAcquisition: Extracting entities...
2025-02-09 14:57:11.162 | 40372:34912 | INFO     | scripts.knowledge_acquisition:process_source:458 | KnowledgeAcquisition: Extracted 12 entities: ['Machine Learning', 'Deep Learning', 'Neural Networks', 'TensorFlow', 'Python', 'GPU acceleration', 'Backpropagation', 'Gradient Descent', 'Convolutional Neural Networks (CNNs)', 'Recurrent Neural Networks (RNNs)', 'Natural Language Processing (NLP)', 'Computer Vision']
2025-02-09 14:57:11.164 | 40372:34912 | INFO     | scripts.knowledge_acquisition:process_source:464 | KnowledgeAcquisition: Extracting relationships...
2025-02-09 14:57:14.252 | 40372:34912 | ERROR    | scripts.knowledge_acquisition:_extract_relationships:652 | Failed to convert relationship: {'source': 'CNNs', 'relation': 'used_for', 'target': 'Image Recognition'}: 1 validation error for Relationship
relation
  Input should be 'is_a', 'has_part' or 'related_to' [type=literal_error, input_value='used_for', input_type=str]
    For further information visit https://errors.pydantic.dev/2.10/v/literal_error
Traceback (most recent call last):

  File "C:\Users\mikeb\work\sifu2\run_agents.py", line 868, in <module>
    asyncio.run(main())

  File "C:\Python313\Lib\asyncio\runners.py", line 194, in run
    return runner.run(main)
  File "C:\Python313\Lib\asyncio\runners.py", line 118, in run
    return self._loop.run_until_complete(task)
  File "C:\Python313\Lib\asyncio\base_events.py", line 707, in run_until_complete
    self.run_forever()
  File "C:\Python313\Lib\asyncio\base_events.py", line 678, in run_forever
    self._run_once()
  File "C:\Python313\Lib\asyncio\base_events.py", line 2033, in _run_once
    handle._run()
  File "C:\Python313\Lib\asyncio\events.py", line 89, in _run
    self._context.run(self._callback, *self._args)

  File "C:\Users\mikeb\work\sifu2\run_agents.py", line 857, in main
    await agent.run()

  File "C:\Users\mikeb\work\sifu2\run_agents.py", line 691, in run
    result = await getattr(self, task.tool)(**task.args)

  File "C:\Users\mikeb\work\sifu2\run_agents.py", line 344, in _synthesize_knowledge
    knowledge = await self.knowledge_system.process_source(content)

  File "C:\Users\mikeb\work\sifu2\scripts\knowledge_acquisition.py", line 466, in process_source
    relationships = await self._extract_relationships(content)

> File "C:\Users\mikeb\work\sifu2\scripts\knowledge_acquisition.py", line 650, in _extract_relationships
    converted_relationships.append(Relationship(**rel))

  File "C:\Python313\Lib\site-packages\pydantic\main.py", line 214, in __init__
    validated_self = self.__pydantic_validator__.validate_python(data, self_instance=self)

pydantic_core._pydantic_core.ValidationError: 1 validation error for Relationship
relation
  Input should be 'is_a', 'has_part' or 'related_to' [type=literal_error, input_value='used_for', input_type=str]
    For further information visit https://errors.pydantic.dev/2.10/v/literal_error
2025-02-09 14:57:14.280 | 40372:34912 | ERROR    | scripts.knowledge_acquisition:_extract_relationships:652 | Failed to convert relationship: {'source': 'RNNs', 'relation': 'used_for', 'target': 'Natural Language Processing'}: 1 validation error for Relationship
relation
  Input should be 'is_a', 'has_part' or 'related_to' [type=literal_error, input_value='used_for', input_type=str]
    For further information visit https://errors.pydantic.dev/2.10/v/literal_error
Traceback (most recent call last):

  File "C:\Users\mikeb\work\sifu2\run_agents.py", line 868, in <module>
    asyncio.run(main())

  File "C:\Python313\Lib\asyncio\runners.py", line 194, in run
    return runner.run(main)
  File "C:\Python313\Lib\asyncio\runners.py", line 118, in run
    return self._loop.run_until_complete(task)
  File "C:\Python313\Lib\asyncio\base_events.py", line 707, in run_until_complete
    self.run_forever()
  File "C:\Python313\Lib\asyncio\base_events.py", line 678, in run_forever
    self._run_once()
  File "C:\Python313\Lib\asyncio\base_events.py", line 2033, in _run_once
    handle._run()
  File "C:\Python313\Lib\asyncio\events.py", line 89, in _run
    self._context.run(self._callback, *self._args)

  File "C:\Users\mikeb\work\sifu2\run_agents.py", line 857, in main
    await agent.run()

  File "C:\Users\mikeb\work\sifu2\run_agents.py", line 691, in run
    result = await getattr(self, task.tool)(**task.args)

  File "C:\Users\mikeb\work\sifu2\run_agents.py", line 344, in _synthesize_knowledge
    knowledge = await self.knowledge_system.process_source(content)

  File "C:\Users\mikeb\work\sifu2\scripts\knowledge_acquisition.py", line 466, in process_source
    relationships = await self._extract_relationships(content)

> File "C:\Users\mikeb\work\sifu2\scripts\knowledge_acquisition.py", line 650, in _extract_relationships
    converted_relationships.append(Relationship(**rel))

  File "C:\Python313\Lib\site-packages\pydantic\main.py", line 214, in __init__
    validated_self = self.__pydantic_validator__.validate_python(data, self_instance=self)

pydantic_core._pydantic_core.ValidationError: 1 validation error for Relationship
relation
  Input should be 'is_a', 'has_part' or 'related_to' [type=literal_error, input_value='used_for', input_type=str]
    For further information visit https://errors.pydantic.dev/2.10/v/literal_error
2025-02-09 14:57:14.312 | 40372:34912 | ERROR    | scripts.knowledge_acquisition:_extract_relationships:652 | Failed to convert relationship: {'source': 'Data Preprocessing', 'relation': 'precedes', 'target': 'Model Training'}: 1 validation error for Relationship
relation
  Input should be 'is_a', 'has_part' or 'related_to' [type=literal_error, input_value='precedes', input_type=str]
    For further information visit https://errors.pydantic.dev/2.10/v/literal_error
Traceback (most recent call last):

  File "C:\Users\mikeb\work\sifu2\run_agents.py", line 868, in <module>
    asyncio.run(main())

  File "C:\Python313\Lib\asyncio\runners.py", line 194, in run
    return runner.run(main)
  File "C:\Python313\Lib\asyncio\runners.py", line 118, in run
    return self._loop.run_until_complete(task)
  File "C:\Python313\Lib\asyncio\base_events.py", line 707, in run_until_complete
    self.run_forever()
  File "C:\Python313\Lib\asyncio\base_events.py", line 678, in run_forever
    self._run_once()
  File "C:\Python313\Lib\asyncio\base_events.py", line 2033, in _run_once
    handle._run()
  File "C:\Python313\Lib\asyncio\events.py", line 89, in _run
    self._context.run(self._callback, *self._args)

  File "C:\Users\mikeb\work\sifu2\run_agents.py", line 857, in main
    await agent.run()

  File "C:\Users\mikeb\work\sifu2\run_agents.py", line 691, in run
    result = await getattr(self, task.tool)(**task.args)

  File "C:\Users\mikeb\work\sifu2\run_agents.py", line 344, in _synthesize_knowledge
    knowledge = await self.knowledge_system.process_source(content)

  File "C:\Users\mikeb\work\sifu2\scripts\knowledge_acquisition.py", line 466, in process_source
    relationships = await self._extract_relationships(content)

> File "C:\Users\mikeb\work\sifu2\scripts\knowledge_acquisition.py", line 650, in _extract_relationships
    converted_relationships.append(Relationship(**rel))

  File "C:\Python313\Lib\site-packages\pydantic\main.py", line 214, in __init__
    validated_self = self.__pydantic_validator__.validate_python(data, self_instance=self)

pydantic_core._pydantic_core.ValidationError: 1 validation error for Relationship
relation
  Input should be 'is_a', 'has_part' or 'related_to' [type=literal_error, input_value='precedes', input_type=str]
    For further information visit https://errors.pydantic.dev/2.10/v/literal_error
2025-02-09 14:57:14.358 | 40372:34912 | ERROR    | scripts.knowledge_acquisition:_extract_relationships:652 | Failed to convert relationship: {'source': 'Model Training', 'relation': 'uses', 'target': 'Training Data'}: 1 validation error for Relationship
relation
  Input should be 'is_a', 'has_part' or 'related_to' [type=literal_error, input_value='uses', input_type=str]
    For further information visit https://errors.pydantic.dev/2.10/v/literal_error
Traceback (most recent call last):

  File "C:\Users\mikeb\work\sifu2\run_agents.py", line 868, in <module>
    asyncio.run(main())

  File "C:\Python313\Lib\asyncio\runners.py", line 194, in run
    return runner.run(main)
  File "C:\Python313\Lib\asyncio\runners.py", line 118, in run
    return self._loop.run_until_complete(task)
  File "C:\Python313\Lib\asyncio\base_events.py", line 707, in run_until_complete
    self.run_forever()
  File "C:\Python313\Lib\asyncio\base_events.py", line 678, in run_forever
    self._run_once()
  File "C:\Python313\Lib\asyncio\base_events.py", line 2033, in _run_once
    handle._run()
  File "C:\Python313\Lib\asyncio\events.py", line 89, in _run
    self._context.run(self._callback, *self._args)

  File "C:\Users\mikeb\work\sifu2\run_agents.py", line 857, in main
    await agent.run()

  File "C:\Users\mikeb\work\sifu2\run_agents.py", line 691, in run
    result = await getattr(self, task.tool)(**task.args)

  File "C:\Users\mikeb\work\sifu2\run_agents.py", line 344, in _synthesize_knowledge
    knowledge = await self.knowledge_system.process_source(content)

  File "C:\Users\mikeb\work\sifu2\scripts\knowledge_acquisition.py", line 466, in process_source
    relationships = await self._extract_relationships(content)

> File "C:\Users\mikeb\work\sifu2\scripts\knowledge_acquisition.py", line 650, in _extract_relationships
    converted_relationships.append(Relationship(**rel))

  File "C:\Python313\Lib\site-packages\pydantic\main.py", line 214, in __init__
    validated_self = self.__pydantic_validator__.validate_python(data, self_instance=self)

pydantic_core._pydantic_core.ValidationError: 1 validation error for Relationship
relation
  Input should be 'is_a', 'has_part' or 'related_to' [type=literal_error, input_value='uses', input_type=str]
    For further information visit https://errors.pydantic.dev/2.10/v/literal_error
2025-02-09 14:57:14.392 | 40372:34912 | ERROR    | scripts.knowledge_acquisition:_extract_relationships:652 | Failed to convert relationship: {'source': 'Model Evaluation', 'relation': 'follows', 'target': 'Model Training'}: 1 validation error for Relationship
relation
  Input should be 'is_a', 'has_part' or 'related_to' [type=literal_error, input_value='follows', input_type=str]
    For further information visit https://errors.pydantic.dev/2.10/v/literal_error
Traceback (most recent call last):

  File "C:\Users\mikeb\work\sifu2\run_agents.py", line 868, in <module>
    asyncio.run(main())

  File "C:\Python313\Lib\asyncio\runners.py", line 194, in run
    return runner.run(main)
  File "C:\Python313\Lib\asyncio\runners.py", line 118, in run
    return self._loop.run_until_complete(task)
  File "C:\Python313\Lib\asyncio\base_events.py", line 707, in run_until_complete
    self.run_forever()
  File "C:\Python313\Lib\asyncio\base_events.py", line 678, in run_forever
    self._run_once()
  File "C:\Python313\Lib\asyncio\base_events.py", line 2033, in _run_once
    handle._run()
  File "C:\Python313\Lib\asyncio\events.py", line 89, in _run
    self._context.run(self._callback, *self._args)

  File "C:\Users\mikeb\work\sifu2\run_agents.py", line 857, in main
    await agent.run()

  File "C:\Users\mikeb\work\sifu2\run_agents.py", line 691, in run
    result = await getattr(self, task.tool)(**task.args)

  File "C:\Users\mikeb\work\sifu2\run_agents.py", line 344, in _synthesize_knowledge
    knowledge = await self.knowledge_system.process_source(content)

  File "C:\Users\mikeb\work\sifu2\scripts\knowledge_acquisition.py", line 466, in process_source
    relationships = await self._extract_relationships(content)

> File "C:\Users\mikeb\work\sifu2\scripts\knowledge_acquisition.py", line 650, in _extract_relationships
    converted_relationships.append(Relationship(**rel))

  File "C:\Python313\Lib\site-packages\pydantic\main.py", line 214, in __init__
    validated_self = self.__pydantic_validator__.validate_python(data, self_instance=self)

pydantic_core._pydantic_core.ValidationError: 1 validation error for Relationship
relation
  Input should be 'is_a', 'has_part' or 'related_to' [type=literal_error, input_value='follows', input_type=str]
    For further information visit https://errors.pydantic.dev/2.10/v/literal_error
2025-02-09 14:57:14.418 | 40372:34912 | ERROR    | scripts.knowledge_acquisition:_extract_relationships:652 | Failed to convert relationship: {'source': 'Model Evaluation', 'relation': 'uses', 'target': 'Test Data'}: 1 validation error for Relationship
relation
  Input should be 'is_a', 'has_part' or 'related_to' [type=literal_error, input_value='uses', input_type=str]
    For further information visit https://errors.pydantic.dev/2.10/v/literal_error
Traceback (most recent call last):

  File "C:\Users\mikeb\work\sifu2\run_agents.py", line 868, in <module>
    asyncio.run(main())

  File "C:\Python313\Lib\asyncio\runners.py", line 194, in run
    return runner.run(main)
  File "C:\Python313\Lib\asyncio\runners.py", line 118, in run
    return self._loop.run_until_complete(task)
  File "C:\Python313\Lib\asyncio\base_events.py", line 707, in run_until_complete
    self.run_forever()
  File "C:\Python313\Lib\asyncio\base_events.py", line 678, in run_forever
    self._run_once()
  File "C:\Python313\Lib\asyncio\base_events.py", line 2033, in _run_once
    handle._run()
  File "C:\Python313\Lib\asyncio\events.py", line 89, in _run
    self._context.run(self._callback, *self._args)

  File "C:\Users\mikeb\work\sifu2\run_agents.py", line 857, in main
    await agent.run()

  File "C:\Users\mikeb\work\sifu2\run_agents.py", line 691, in run
    result = await getattr(self, task.tool)(**task.args)

  File "C:\Users\mikeb\work\sifu2\run_agents.py", line 344, in _synthesize_knowledge
    knowledge = await self.knowledge_system.process_source(content)

  File "C:\Users\mikeb\work\sifu2\scripts\knowledge_acquisition.py", line 466, in process_source
    relationships = await self._extract_relationships(content)

> File "C:\Users\mikeb\work\sifu2\scripts\knowledge_acquisition.py", line 650, in _extract_relationships
    converted_relationships.append(Relationship(**rel))

  File "C:\Python313\Lib\site-packages\pydantic\main.py", line 214, in __init__
    validated_self = self.__pydantic_validator__.validate_python(data, self_instance=self)

pydantic_core._pydantic_core.ValidationError: 1 validation error for Relationship
relation
  Input should be 'is_a', 'has_part' or 'related_to' [type=literal_error, input_value='uses', input_type=str]
    For further information visit https://errors.pydantic.dev/2.10/v/literal_error
2025-02-09 14:57:14.446 | 40372:34912 | ERROR    | scripts.knowledge_acquisition:_extract_relationships:652 | Failed to convert relationship: {'source': 'Hyperparameter Tuning', 'relation': 'improves', 'target': 'Model Performance'}: 1 validation error for Relationship
relation
  Input should be 'is_a', 'has_part' or 'related_to' [type=literal_error, input_value='improves', input_type=str]
    For further information visit https://errors.pydantic.dev/2.10/v/literal_error
Traceback (most recent call last):

  File "C:\Users\mikeb\work\sifu2\run_agents.py", line 868, in <module>
    asyncio.run(main())

  File "C:\Python313\Lib\asyncio\runners.py", line 194, in run
    return runner.run(main)
  File "C:\Python313\Lib\asyncio\runners.py", line 118, in run
    return self._loop.run_until_complete(task)
  File "C:\Python313\Lib\asyncio\base_events.py", line 707, in run_until_complete
    self.run_forever()
  File "C:\Python313\Lib\asyncio\base_events.py", line 678, in run_forever
    self._run_once()
  File "C:\Python313\Lib\asyncio\base_events.py", line 2033, in _run_once
    handle._run()
  File "C:\Python313\Lib\asyncio\events.py", line 89, in _run
    self._context.run(self._callback, *self._args)

  File "C:\Users\mikeb\work\sifu2\run_agents.py", line 857, in main
    await agent.run()

  File "C:\Users\mikeb\work\sifu2\run_agents.py", line 691, in run
    result = await getattr(self, task.tool)(**task.args)

  File "C:\Users\mikeb\work\sifu2\run_agents.py", line 344, in _synthesize_knowledge
    knowledge = await self.knowledge_system.process_source(content)

  File "C:\Users\mikeb\work\sifu2\scripts\knowledge_acquisition.py", line 466, in process_source
    relationships = await self._extract_relationships(content)

> File "C:\Users\mikeb\work\sifu2\scripts\knowledge_acquisition.py", line 650, in _extract_relationships
    converted_relationships.append(Relationship(**rel))

  File "C:\Python313\Lib\site-packages\pydantic\main.py", line 214, in __init__
    validated_self = self.__pydantic_validator__.validate_python(data, self_instance=self)

pydantic_core._pydantic_core.ValidationError: 1 validation error for Relationship
relation
  Input should be 'is_a', 'has_part' or 'related_to' [type=literal_error, input_value='improves', input_type=str]
    For further information visit https://errors.pydantic.dev/2.10/v/literal_error
2025-02-09 14:57:14.475 | 40372:34912 | INFO     | scripts.knowledge_acquisition:process_source:478 | KnowledgeAcquisition: Extracted 3 relationships
2025-02-09 14:57:14.477 | 40372:34912 | INFO     | scripts.knowledge_acquisition:process_source:482 | KnowledgeAcquisition: Relationship: Convolutional Neural Networks (CNNs) -> is_a -> Neural Networks
2025-02-09 14:57:14.478 | 40372:34912 | INFO     | scripts.knowledge_acquisition:process_source:482 | KnowledgeAcquisition: Relationship: Recurrent Neural Networks (RNNs) -> is_a -> Neural Networks
2025-02-09 14:57:14.480 | 40372:34912 | INFO     | scripts.knowledge_acquisition:process_source:482 | KnowledgeAcquisition: Relationship: Neural Networks -> is_a -> Machine Learning Models
2025-02-09 14:57:14.482 | 40372:34912 | INFO     | scripts.knowledge_acquisition:process_source:488 | KnowledgeAcquisition: Generating metadata...
2025-02-09 14:57:15.591 | 40372:34912 | INFO     | scripts.knowledge_acquisition:process_source:495 | KnowledgeAcquisition: Generated metadata: {'source_type': 'text', 'confidence_score': 0.9, 'domain_relevance': 0.8, 'timestamp': '2024-02-09T12:42:32.000Z', 'validation_status': 'processed', 'domain': 'machine_learning'}
2025-02-09 14:57:15.593 | 40372:34912 | INFO     | scripts.knowledge_acquisition:process_source:501 | KnowledgeAcquisition: Evaluating confidence...
2025-02-09 14:57:17.045 | 40372:34912 | INFO     | scripts.knowledge_acquisition:process_source:511 | KnowledgeAcquisition: Confidence score: 0.8
2025-02-09 14:57:17.054 | 40372:34912 | INFO     | __main__:_synthesize_knowledge:325 | Knowledge Synthesis: Processing source: NIH News in Health | A monthly newsletter from the National ... (source_17.txt)
2025-02-09 14:57:17.055 | 40372:34912 | INFO     | __main__:_synthesize_knowledge:329 | Knowledge Synthesis: Content preview:
Skip to main content ![NIH News in Health A monthly newsletter from the National Institutes of Health, part of the U.S. Department of Health and Human Services ## ## Site * Home ### Beyond Basic Blood Tests The Power of Pets Rough Up Your Diet Caring for Concussions Do Social Ties Affect Our Health?( NIH Office of Communications and Public Liaison Building 31, Room 5B52 Bethesda, MD 20892-2094 nihnewsinhealth@od.nih.gov Tel: 301-451-8224 **Editor:** Harrison Wein, Ph.D. **Managing Editor:** Tian...
2025-02-09 14:57:17.057 | 40372:34912 | INFO     | scripts.knowledge_acquisition:process_source:444 | KnowledgeAcquisition: Starting source processing with content length: 1195
2025-02-09 14:57:17.059 | 40372:34912 | INFO     | scripts.knowledge_acquisition:process_source:448 | KnowledgeAcquisition: Content preview:
Skip to main content ![NIH News in Health A monthly newsletter from the National Institutes of Health, part of the U.S. Department of Health and Human Services ## ## Site * Home ### Beyond Basic Blood...
2025-02-09 14:57:17.060 | 40372:34912 | INFO     | scripts.knowledge_acquisition:process_source:451 | KnowledgeAcquisition: Extracting entities...
2025-02-09 14:57:17.921 | 40372:34912 | INFO     | scripts.knowledge_acquisition:process_source:458 | KnowledgeAcquisition: Extracted 10 entities: ['Machine Learning', 'Neural Networks', 'TensorFlow', 'Deep Learning', 'Python', 'Data Science', 'Artificial Intelligence', 'Big Data', 'Cloud Computing', 'Natural Language Processing']
2025-02-09 14:57:17.923 | 40372:34912 | INFO     | scripts.knowledge_acquisition:process_source:464 | KnowledgeAcquisition: Extracting relationships...
2025-02-09 14:57:18.360 | 40372:34912 | INFO     | scripts.knowledge_acquisition:process_source:478 | KnowledgeAcquisition: Extracted 1 relationships
2025-02-09 14:57:18.361 | 40372:34912 | INFO     | scripts.knowledge_acquisition:process_source:482 | KnowledgeAcquisition: Relationship: Machine Learning -> related_to -> Neural Networks
2025-02-09 14:57:18.363 | 40372:34912 | INFO     | scripts.knowledge_acquisition:process_source:488 | KnowledgeAcquisition: Generating metadata...
2025-02-09 14:57:19.427 | 40372:34912 | INFO     | scripts.knowledge_acquisition:process_source:495 | KnowledgeAcquisition: Generated metadata: {'source_type': 'text', 'confidence_score': 0.85, 'domain_relevance': 0.9, 'timestamp': '2024-02-09T11:42:32.000Z', 'validation_status': 'processed', 'domain': 'machine_learning'}
2025-02-09 14:57:19.428 | 40372:34912 | INFO     | scripts.knowledge_acquisition:process_source:501 | KnowledgeAcquisition: Evaluating confidence...
2025-02-09 14:57:20.902 | 40372:34912 | INFO     | scripts.knowledge_acquisition:process_source:511 | KnowledgeAcquisition: Confidence score: 0.8
2025-02-09 14:57:20.910 | 40372:34912 | INFO     | __main__:_synthesize_knowledge:325 | Knowledge Synthesis: Processing source: CISSP Exam Refresh 2024: Key Updates and Changes (source_19.txt)
2025-02-09 14:57:20.912 | 40372:34912 | INFO     | __main__:_synthesize_knowledge:329 | Knowledge Synthesis: Content preview:
!Destination Certification - Pass CISSP Exam - Destination Cerification logo( Rob Witcher Last Updated On: August 12, 2024 Copy Link In today's digital world, the importance of well-trained information security professionals cannot be overstated. With cyber threats becoming more complex, the need for experts who can navigate and secure our digital environments is crucial. The 2024 update to the CISSP exam reflects these needs, ensuring that cybersecurity professionals are prepared to face modern...
2025-02-09 14:57:20.914 | 40372:34912 | INFO     | scripts.knowledge_acquisition:process_source:444 | KnowledgeAcquisition: Starting source processing with content length: 43346
2025-02-09 14:57:20.915 | 40372:34912 | INFO     | scripts.knowledge_acquisition:process_source:448 | KnowledgeAcquisition: Content preview:
!Destination Certification - Pass CISSP Exam - Destination Cerification logo( Rob Witcher Last Updated On: August 12, 2024 Copy Link In today's digital world, the importance of well-trained informatio...
2025-02-09 14:57:20.917 | 40372:34912 | INFO     | scripts.knowledge_acquisition:process_source:451 | KnowledgeAcquisition: Extracting entities...
2025-02-09 14:57:23.446 | 40372:34912 | INFO     | scripts.knowledge_acquisition:process_source:458 | KnowledgeAcquisition: Extracted 44 entities: ['Machine Learning', 'Deep Learning', 'Neural Networks', 'TensorFlow', 'Python', 'Keras', 'Computer Vision', 'Image Classification', 'Object Detection', 'Natural Language Processing', 'Recurrent Neural Networks', 'Convolutional Neural Networks', 'Backpropagation', 'Gradient Descent', 'Activation Functions', 'Regularization', 'Overfitting', 'Underfitting', 'Data Augmentation', 'Transfer Learning', 'Hyperparameter Tuning', 'Model Evaluation', 'Accuracy', 'Precision', 'Recall', 'F1-score', 'AUC', 'ROC curve', 'Confusion Matrix', 'Cross-validation', 'Data preprocessing', 'Feature engineering', 'Dimensionality reduction', 'Principal Component Analysis (PCA)', 't-SNE', 'Clustering', 'K-means', 'DBSCAN', 'Hierarchical clustering', 'Supervised learning', 'Unsupervised learning', 'Reinforcement learning', 'Generative models', 'Discriminative models']
2025-02-09 14:57:23.448 | 40372:34912 | INFO     | scripts.knowledge_acquisition:process_source:464 | KnowledgeAcquisition: Extracting relationships...
2025-02-09 14:57:26.452 | 40372:34912 | ERROR    | scripts.knowledge_acquisition:_extract_relationships:652 | Failed to convert relationship: {'source': 'Data Preprocessing', 'relation': 'precedes', 'target': 'Model Training'}: 1 validation error for Relationship
relation
  Input should be 'is_a', 'has_part' or 'related_to' [type=literal_error, input_value='precedes', input_type=str]
    For further information visit https://errors.pydantic.dev/2.10/v/literal_error
Traceback (most recent call last):

  File "C:\Users\mikeb\work\sifu2\run_agents.py", line 868, in <module>
    asyncio.run(main())

  File "C:\Python313\Lib\asyncio\runners.py", line 194, in run
    return runner.run(main)
  File "C:\Python313\Lib\asyncio\runners.py", line 118, in run
    return self._loop.run_until_complete(task)
  File "C:\Python313\Lib\asyncio\base_events.py", line 707, in run_until_complete
    self.run_forever()
  File "C:\Python313\Lib\asyncio\base_events.py", line 678, in run_forever
    self._run_once()
  File "C:\Python313\Lib\asyncio\base_events.py", line 2033, in _run_once
    handle._run()
  File "C:\Python313\Lib\asyncio\events.py", line 89, in _run
    self._context.run(self._callback, *self._args)

  File "C:\Users\mikeb\work\sifu2\run_agents.py", line 857, in main
    await agent.run()

  File "C:\Users\mikeb\work\sifu2\run_agents.py", line 691, in run
    result = await getattr(self, task.tool)(**task.args)

  File "C:\Users\mikeb\work\sifu2\run_agents.py", line 344, in _synthesize_knowledge
    knowledge = await self.knowledge_system.process_source(content)

  File "C:\Users\mikeb\work\sifu2\scripts\knowledge_acquisition.py", line 466, in process_source
    relationships = await self._extract_relationships(content)

> File "C:\Users\mikeb\work\sifu2\scripts\knowledge_acquisition.py", line 650, in _extract_relationships
    converted_relationships.append(Relationship(**rel))

  File "C:\Python313\Lib\site-packages\pydantic\main.py", line 214, in __init__
    validated_self = self.__pydantic_validator__.validate_python(data, self_instance=self)

pydantic_core._pydantic_core.ValidationError: 1 validation error for Relationship
relation
  Input should be 'is_a', 'has_part' or 'related_to' [type=literal_error, input_value='precedes', input_type=str]
    For further information visit https://errors.pydantic.dev/2.10/v/literal_error
2025-02-09 14:57:26.480 | 40372:34912 | ERROR    | scripts.knowledge_acquisition:_extract_relationships:652 | Failed to convert relationship: {'source': 'Model Training', 'relation': 'uses', 'target': 'Training Data'}: 1 validation error for Relationship
relation
  Input should be 'is_a', 'has_part' or 'related_to' [type=literal_error, input_value='uses', input_type=str]
    For further information visit https://errors.pydantic.dev/2.10/v/literal_error
Traceback (most recent call last):

  File "C:\Users\mikeb\work\sifu2\run_agents.py", line 868, in <module>
    asyncio.run(main())

  File "C:\Python313\Lib\asyncio\runners.py", line 194, in run
    return runner.run(main)
  File "C:\Python313\Lib\asyncio\runners.py", line 118, in run
    return self._loop.run_until_complete(task)
  File "C:\Python313\Lib\asyncio\base_events.py", line 707, in run_until_complete
    self.run_forever()
  File "C:\Python313\Lib\asyncio\base_events.py", line 678, in run_forever
    self._run_once()
  File "C:\Python313\Lib\asyncio\base_events.py", line 2033, in _run_once
    handle._run()
  File "C:\Python313\Lib\asyncio\events.py", line 89, in _run
    self._context.run(self._callback, *self._args)

  File "C:\Users\mikeb\work\sifu2\run_agents.py", line 857, in main
    await agent.run()

  File "C:\Users\mikeb\work\sifu2\run_agents.py", line 691, in run
    result = await getattr(self, task.tool)(**task.args)

  File "C:\Users\mikeb\work\sifu2\run_agents.py", line 344, in _synthesize_knowledge
    knowledge = await self.knowledge_system.process_source(content)

  File "C:\Users\mikeb\work\sifu2\scripts\knowledge_acquisition.py", line 466, in process_source
    relationships = await self._extract_relationships(content)

> File "C:\Users\mikeb\work\sifu2\scripts\knowledge_acquisition.py", line 650, in _extract_relationships
    converted_relationships.append(Relationship(**rel))

  File "C:\Python313\Lib\site-packages\pydantic\main.py", line 214, in __init__
    validated_self = self.__pydantic_validator__.validate_python(data, self_instance=self)

pydantic_core._pydantic_core.ValidationError: 1 validation error for Relationship
relation
  Input should be 'is_a', 'has_part' or 'related_to' [type=literal_error, input_value='uses', input_type=str]
    For further information visit https://errors.pydantic.dev/2.10/v/literal_error
2025-02-09 14:57:26.510 | 40372:34912 | ERROR    | scripts.knowledge_acquisition:_extract_relationships:652 | Failed to convert relationship: {'source': 'Model Training', 'relation': 'output_of', 'target': 'Trained Model'}: 1 validation error for Relationship
relation
  Input should be 'is_a', 'has_part' or 'related_to' [type=literal_error, input_value='output_of', input_type=str]
    For further information visit https://errors.pydantic.dev/2.10/v/literal_error
Traceback (most recent call last):

  File "C:\Users\mikeb\work\sifu2\run_agents.py", line 868, in <module>
    asyncio.run(main())

  File "C:\Python313\Lib\asyncio\runners.py", line 194, in run
    return runner.run(main)
  File "C:\Python313\Lib\asyncio\runners.py", line 118, in run
    return self._loop.run_until_complete(task)
  File "C:\Python313\Lib\asyncio\base_events.py", line 707, in run_until_complete
    self.run_forever()
  File "C:\Python313\Lib\asyncio\base_events.py", line 678, in run_forever
    self._run_once()
  File "C:\Python313\Lib\asyncio\base_events.py", line 2033, in _run_once
    handle._run()
  File "C:\Python313\Lib\asyncio\events.py", line 89, in _run
    self._context.run(self._callback, *self._args)

  File "C:\Users\mikeb\work\sifu2\run_agents.py", line 857, in main
    await agent.run()

  File "C:\Users\mikeb\work\sifu2\run_agents.py", line 691, in run
    result = await getattr(self, task.tool)(**task.args)

  File "C:\Users\mikeb\work\sifu2\run_agents.py", line 344, in _synthesize_knowledge
    knowledge = await self.knowledge_system.process_source(content)

  File "C:\Users\mikeb\work\sifu2\scripts\knowledge_acquisition.py", line 466, in process_source
    relationships = await self._extract_relationships(content)

> File "C:\Users\mikeb\work\sifu2\scripts\knowledge_acquisition.py", line 650, in _extract_relationships
    converted_relationships.append(Relationship(**rel))

  File "C:\Python313\Lib\site-packages\pydantic\main.py", line 214, in __init__
    validated_self = self.__pydantic_validator__.validate_python(data, self_instance=self)

pydantic_core._pydantic_core.ValidationError: 1 validation error for Relationship
relation
  Input should be 'is_a', 'has_part' or 'related_to' [type=literal_error, input_value='output_of', input_type=str]
    For further information visit https://errors.pydantic.dev/2.10/v/literal_error
2025-02-09 14:57:26.538 | 40372:34912 | ERROR    | scripts.knowledge_acquisition:_extract_relationships:652 | Failed to convert relationship: {'source': 'Trained Model', 'relation': 'input_to', 'target': 'Model Evaluation'}: 1 validation error for Relationship
relation
  Input should be 'is_a', 'has_part' or 'related_to' [type=literal_error, input_value='input_to', input_type=str]
    For further information visit https://errors.pydantic.dev/2.10/v/literal_error
Traceback (most recent call last):

  File "C:\Users\mikeb\work\sifu2\run_agents.py", line 868, in <module>
    asyncio.run(main())

  File "C:\Python313\Lib\asyncio\runners.py", line 194, in run
    return runner.run(main)
  File "C:\Python313\Lib\asyncio\runners.py", line 118, in run
    return self._loop.run_until_complete(task)
  File "C:\Python313\Lib\asyncio\base_events.py", line 707, in run_until_complete
    self.run_forever()
  File "C:\Python313\Lib\asyncio\base_events.py", line 678, in run_forever
    self._run_once()
  File "C:\Python313\Lib\asyncio\base_events.py", line 2033, in _run_once
    handle._run()
  File "C:\Python313\Lib\asyncio\events.py", line 89, in _run
    self._context.run(self._callback, *self._args)

  File "C:\Users\mikeb\work\sifu2\run_agents.py", line 857, in main
    await agent.run()

  File "C:\Users\mikeb\work\sifu2\run_agents.py", line 691, in run
    result = await getattr(self, task.tool)(**task.args)

  File "C:\Users\mikeb\work\sifu2\run_agents.py", line 344, in _synthesize_knowledge
    knowledge = await self.knowledge_system.process_source(content)

  File "C:\Users\mikeb\work\sifu2\scripts\knowledge_acquisition.py", line 466, in process_source
    relationships = await self._extract_relationships(content)

> File "C:\Users\mikeb\work\sifu2\scripts\knowledge_acquisition.py", line 650, in _extract_relationships
    converted_relationships.append(Relationship(**rel))

  File "C:\Python313\Lib\site-packages\pydantic\main.py", line 214, in __init__
    validated_self = self.__pydantic_validator__.validate_python(data, self_instance=self)

pydantic_core._pydantic_core.ValidationError: 1 validation error for Relationship
relation
  Input should be 'is_a', 'has_part' or 'related_to' [type=literal_error, input_value='input_to', input_type=str]
    For further information visit https://errors.pydantic.dev/2.10/v/literal_error
2025-02-09 14:57:26.566 | 40372:34912 | ERROR    | scripts.knowledge_acquisition:_extract_relationships:652 | Failed to convert relationship: {'source': 'Model Evaluation', 'relation': 'uses', 'target': 'Evaluation Metrics'}: 1 validation error for Relationship
relation
  Input should be 'is_a', 'has_part' or 'related_to' [type=literal_error, input_value='uses', input_type=str]
    For further information visit https://errors.pydantic.dev/2.10/v/literal_error
Traceback (most recent call last):

  File "C:\Users\mikeb\work\sifu2\run_agents.py", line 868, in <module>
    asyncio.run(main())

  File "C:\Python313\Lib\asyncio\runners.py", line 194, in run
    return runner.run(main)
  File "C:\Python313\Lib\asyncio\runners.py", line 118, in run
    return self._loop.run_until_complete(task)
  File "C:\Python313\Lib\asyncio\base_events.py", line 707, in run_until_complete
    self.run_forever()
  File "C:\Python313\Lib\asyncio\base_events.py", line 678, in run_forever
    self._run_once()
  File "C:\Python313\Lib\asyncio\base_events.py", line 2033, in _run_once
    handle._run()
  File "C:\Python313\Lib\asyncio\events.py", line 89, in _run
    self._context.run(self._callback, *self._args)

  File "C:\Users\mikeb\work\sifu2\run_agents.py", line 857, in main
    await agent.run()

  File "C:\Users\mikeb\work\sifu2\run_agents.py", line 691, in run
    result = await getattr(self, task.tool)(**task.args)

  File "C:\Users\mikeb\work\sifu2\run_agents.py", line 344, in _synthesize_knowledge
    knowledge = await self.knowledge_system.process_source(content)

  File "C:\Users\mikeb\work\sifu2\scripts\knowledge_acquisition.py", line 466, in process_source
    relationships = await self._extract_relationships(content)

> File "C:\Users\mikeb\work\sifu2\scripts\knowledge_acquisition.py", line 650, in _extract_relationships
    converted_relationships.append(Relationship(**rel))

  File "C:\Python313\Lib\site-packages\pydantic\main.py", line 214, in __init__
    validated_self = self.__pydantic_validator__.validate_python(data, self_instance=self)

pydantic_core._pydantic_core.ValidationError: 1 validation error for Relationship
relation
  Input should be 'is_a', 'has_part' or 'related_to' [type=literal_error, input_value='uses', input_type=str]
    For further information visit https://errors.pydantic.dev/2.10/v/literal_error
2025-02-09 14:57:26.599 | 40372:34912 | ERROR    | scripts.knowledge_acquisition:_extract_relationships:652 | Failed to convert relationship: {'source': 'CNNs', 'relation': 'applied_to', 'target': 'Image Recognition'}: 1 validation error for Relationship
relation
  Input should be 'is_a', 'has_part' or 'related_to' [type=literal_error, input_value='applied_to', input_type=str]
    For further information visit https://errors.pydantic.dev/2.10/v/literal_error
Traceback (most recent call last):

  File "C:\Users\mikeb\work\sifu2\run_agents.py", line 868, in <module>
    asyncio.run(main())

  File "C:\Python313\Lib\asyncio\runners.py", line 194, in run
    return runner.run(main)
  File "C:\Python313\Lib\asyncio\runners.py", line 118, in run
    return self._loop.run_until_complete(task)
  File "C:\Python313\Lib\asyncio\base_events.py", line 707, in run_until_complete
    self.run_forever()
  File "C:\Python313\Lib\asyncio\base_events.py", line 678, in run_forever
    self._run_once()
  File "C:\Python313\Lib\asyncio\base_events.py", line 2033, in _run_once
    handle._run()
  File "C:\Python313\Lib\asyncio\events.py", line 89, in _run
    self._context.run(self._callback, *self._args)

  File "C:\Users\mikeb\work\sifu2\run_agents.py", line 857, in main
    await agent.run()

  File "C:\Users\mikeb\work\sifu2\run_agents.py", line 691, in run
    result = await getattr(self, task.tool)(**task.args)

  File "C:\Users\mikeb\work\sifu2\run_agents.py", line 344, in _synthesize_knowledge
    knowledge = await self.knowledge_system.process_source(content)

  File "C:\Users\mikeb\work\sifu2\scripts\knowledge_acquisition.py", line 466, in process_source
    relationships = await self._extract_relationships(content)

> File "C:\Users\mikeb\work\sifu2\scripts\knowledge_acquisition.py", line 650, in _extract_relationships
    converted_relationships.append(Relationship(**rel))

  File "C:\Python313\Lib\site-packages\pydantic\main.py", line 214, in __init__
    validated_self = self.__pydantic_validator__.validate_python(data, self_instance=self)

pydantic_core._pydantic_core.ValidationError: 1 validation error for Relationship
relation
  Input should be 'is_a', 'has_part' or 'related_to' [type=literal_error, input_value='applied_to', input_type=str]
    For further information visit https://errors.pydantic.dev/2.10/v/literal_error
2025-02-09 14:57:26.627 | 40372:34912 | ERROR    | scripts.knowledge_acquisition:_extract_relationships:652 | Failed to convert relationship: {'source': 'RNNs', 'relation': 'applied_to', 'target': 'Natural Language Processing'}: 1 validation error for Relationship
relation
  Input should be 'is_a', 'has_part' or 'related_to' [type=literal_error, input_value='applied_to', input_type=str]
    For further information visit https://errors.pydantic.dev/2.10/v/literal_error
Traceback (most recent call last):

  File "C:\Users\mikeb\work\sifu2\run_agents.py", line 868, in <module>
    asyncio.run(main())

  File "C:\Python313\Lib\asyncio\runners.py", line 194, in run
    return runner.run(main)
  File "C:\Python313\Lib\asyncio\runners.py", line 118, in run
    return self._loop.run_until_complete(task)
  File "C:\Python313\Lib\asyncio\base_events.py", line 707, in run_until_complete
    self.run_forever()
  File "C:\Python313\Lib\asyncio\base_events.py", line 678, in run_forever
    self._run_once()
  File "C:\Python313\Lib\asyncio\base_events.py", line 2033, in _run_once
    handle._run()
  File "C:\Python313\Lib\asyncio\events.py", line 89, in _run
    self._context.run(self._callback, *self._args)

  File "C:\Users\mikeb\work\sifu2\run_agents.py", line 857, in main
    await agent.run()

  File "C:\Users\mikeb\work\sifu2\run_agents.py", line 691, in run
    result = await getattr(self, task.tool)(**task.args)

  File "C:\Users\mikeb\work\sifu2\run_agents.py", line 344, in _synthesize_knowledge
    knowledge = await self.knowledge_system.process_source(content)

  File "C:\Users\mikeb\work\sifu2\scripts\knowledge_acquisition.py", line 466, in process_source
    relationships = await self._extract_relationships(content)

> File "C:\Users\mikeb\work\sifu2\scripts\knowledge_acquisition.py", line 650, in _extract_relationships
    converted_relationships.append(Relationship(**rel))

  File "C:\Python313\Lib\site-packages\pydantic\main.py", line 214, in __init__
    validated_self = self.__pydantic_validator__.validate_python(data, self_instance=self)

pydantic_core._pydantic_core.ValidationError: 1 validation error for Relationship
relation
  Input should be 'is_a', 'has_part' or 'related_to' [type=literal_error, input_value='applied_to', input_type=str]
    For further information visit https://errors.pydantic.dev/2.10/v/literal_error
2025-02-09 14:57:26.651 | 40372:34912 | INFO     | scripts.knowledge_acquisition:process_source:478 | KnowledgeAcquisition: Extracted 3 relationships
2025-02-09 14:57:26.652 | 40372:34912 | INFO     | scripts.knowledge_acquisition:process_source:482 | KnowledgeAcquisition: Relationship: Convolutional Neural Networks (CNNs) -> is_a -> Neural Networks
2025-02-09 14:57:26.654 | 40372:34912 | INFO     | scripts.knowledge_acquisition:process_source:482 | KnowledgeAcquisition: Relationship: Recurrent Neural Networks (RNNs) -> is_a -> Neural Networks
2025-02-09 14:57:26.656 | 40372:34912 | INFO     | scripts.knowledge_acquisition:process_source:482 | KnowledgeAcquisition: Relationship: Neural Networks -> is_a -> Machine Learning Models
2025-02-09 14:57:26.657 | 40372:34912 | INFO     | scripts.knowledge_acquisition:process_source:488 | KnowledgeAcquisition: Generating metadata...
2025-02-09 14:57:27.743 | 40372:34912 | INFO     | scripts.knowledge_acquisition:process_source:495 | KnowledgeAcquisition: Generated metadata: {'source_type': 'text', 'confidence_score': 0.9, 'domain_relevance': 0.8, 'timestamp': '2024-02-09T12:00:00.000Z', 'validation_status': 'processed', 'domain': 'machine_learning'}
2025-02-09 14:57:27.745 | 40372:34912 | INFO     | scripts.knowledge_acquisition:process_source:501 | KnowledgeAcquisition: Evaluating confidence...
2025-02-09 14:57:29.047 | 40372:34912 | INFO     | scripts.knowledge_acquisition:process_source:511 | KnowledgeAcquisition: Confidence score: 0.8
2025-02-09 14:57:29.058 | 40372:34912 | INFO     | __main__:_synthesize_knowledge:325 | Knowledge Synthesis: Processing source: Domain Rating Checker 【Free tool, No Login, Super Fast】 (source_3.txt)
2025-02-09 14:57:29.060 | 40372:34912 | INFO     | __main__:_synthesize_knowledge:329 | Knowledge Synthesis: Content preview:
![AI Writer for SEO? Domain Rating (DR) is a metric developed to estimate the relative strength of a website's backlink profile compared to all other sites on the internet on a scale from 0 to 100. The higher the DR score, the stronger and more authoritative the website is considered to be. This metric is crucial for understanding how likely a website is to rank in The calculation of DR takes into account the quantity and quality of external backlinks, denoting websites that have robust backlink...
2025-02-09 14:57:29.061 | 40372:34912 | INFO     | scripts.knowledge_acquisition:process_source:444 | KnowledgeAcquisition: Starting source processing with content length: 4993
2025-02-09 14:57:29.062 | 40372:34912 | INFO     | scripts.knowledge_acquisition:process_source:448 | KnowledgeAcquisition: Content preview:
![AI Writer for SEO? Domain Rating (DR) is a metric developed to estimate the relative strength of a website's backlink profile compared to all other sites on the internet on a scale from 0 to 100. Th...
2025-02-09 14:57:29.064 | 40372:34912 | INFO     | scripts.knowledge_acquisition:process_source:451 | KnowledgeAcquisition: Extracting entities...
2025-02-09 14:57:29.974 | 40372:34912 | INFO     | scripts.knowledge_acquisition:process_source:458 | KnowledgeAcquisition: Extracted 10 entities: ['Machine Learning', 'Deep Learning', 'Neural Networks', 'TensorFlow', 'Python', 'Keras', 'Computer Vision', 'Natural Language Processing', 'Data Science', 'Artificial Intelligence']
2025-02-09 14:57:29.976 | 40372:34912 | INFO     | scripts.knowledge_acquisition:process_source:464 | KnowledgeAcquisition: Extracting relationships...
2025-02-09 14:57:33.003 | 40372:34912 | ERROR    | scripts.knowledge_acquisition:_extract_relationships:652 | Failed to convert relationship: {'source': 'Data Preprocessing', 'relation': 'precedes', 'target': 'Model Training'}: 1 validation error for Relationship
relation
  Input should be 'is_a', 'has_part' or 'related_to' [type=literal_error, input_value='precedes', input_type=str]
    For further information visit https://errors.pydantic.dev/2.10/v/literal_error
Traceback (most recent call last):

  File "C:\Users\mikeb\work\sifu2\run_agents.py", line 868, in <module>
    asyncio.run(main())

  File "C:\Python313\Lib\asyncio\runners.py", line 194, in run
    return runner.run(main)
  File "C:\Python313\Lib\asyncio\runners.py", line 118, in run
    return self._loop.run_until_complete(task)
  File "C:\Python313\Lib\asyncio\base_events.py", line 707, in run_until_complete
    self.run_forever()
  File "C:\Python313\Lib\asyncio\base_events.py", line 678, in run_forever
    self._run_once()
  File "C:\Python313\Lib\asyncio\base_events.py", line 2033, in _run_once
    handle._run()
  File "C:\Python313\Lib\asyncio\events.py", line 89, in _run
    self._context.run(self._callback, *self._args)

  File "C:\Users\mikeb\work\sifu2\run_agents.py", line 857, in main
    await agent.run()

  File "C:\Users\mikeb\work\sifu2\run_agents.py", line 691, in run
    result = await getattr(self, task.tool)(**task.args)

  File "C:\Users\mikeb\work\sifu2\run_agents.py", line 344, in _synthesize_knowledge
    knowledge = await self.knowledge_system.process_source(content)

  File "C:\Users\mikeb\work\sifu2\scripts\knowledge_acquisition.py", line 466, in process_source
    relationships = await self._extract_relationships(content)

> File "C:\Users\mikeb\work\sifu2\scripts\knowledge_acquisition.py", line 650, in _extract_relationships
    converted_relationships.append(Relationship(**rel))

  File "C:\Python313\Lib\site-packages\pydantic\main.py", line 214, in __init__
    validated_self = self.__pydantic_validator__.validate_python(data, self_instance=self)

pydantic_core._pydantic_core.ValidationError: 1 validation error for Relationship
relation
  Input should be 'is_a', 'has_part' or 'related_to' [type=literal_error, input_value='precedes', input_type=str]
    For further information visit https://errors.pydantic.dev/2.10/v/literal_error
2025-02-09 14:57:33.026 | 40372:34912 | ERROR    | scripts.knowledge_acquisition:_extract_relationships:652 | Failed to convert relationship: {'source': 'Model Training', 'relation': 'uses', 'target': 'Training Data'}: 1 validation error for Relationship
relation
  Input should be 'is_a', 'has_part' or 'related_to' [type=literal_error, input_value='uses', input_type=str]
    For further information visit https://errors.pydantic.dev/2.10/v/literal_error
Traceback (most recent call last):

  File "C:\Users\mikeb\work\sifu2\run_agents.py", line 868, in <module>
    asyncio.run(main())

  File "C:\Python313\Lib\asyncio\runners.py", line 194, in run
    return runner.run(main)
  File "C:\Python313\Lib\asyncio\runners.py", line 118, in run
    return self._loop.run_until_complete(task)
  File "C:\Python313\Lib\asyncio\base_events.py", line 707, in run_until_complete
    self.run_forever()
  File "C:\Python313\Lib\asyncio\base_events.py", line 678, in run_forever
    self._run_once()
  File "C:\Python313\Lib\asyncio\base_events.py", line 2033, in _run_once
    handle._run()
  File "C:\Python313\Lib\asyncio\events.py", line 89, in _run
    self._context.run(self._callback, *self._args)

  File "C:\Users\mikeb\work\sifu2\run_agents.py", line 857, in main
    await agent.run()

  File "C:\Users\mikeb\work\sifu2\run_agents.py", line 691, in run
    result = await getattr(self, task.tool)(**task.args)

  File "C:\Users\mikeb\work\sifu2\run_agents.py", line 344, in _synthesize_knowledge
    knowledge = await self.knowledge_system.process_source(content)

  File "C:\Users\mikeb\work\sifu2\scripts\knowledge_acquisition.py", line 466, in process_source
    relationships = await self._extract_relationships(content)

> File "C:\Users\mikeb\work\sifu2\scripts\knowledge_acquisition.py", line 650, in _extract_relationships
    converted_relationships.append(Relationship(**rel))

  File "C:\Python313\Lib\site-packages\pydantic\main.py", line 214, in __init__
    validated_self = self.__pydantic_validator__.validate_python(data, self_instance=self)

pydantic_core._pydantic_core.ValidationError: 1 validation error for Relationship
relation
  Input should be 'is_a', 'has_part' or 'related_to' [type=literal_error, input_value='uses', input_type=str]
    For further information visit https://errors.pydantic.dev/2.10/v/literal_error
2025-02-09 14:57:33.049 | 40372:34912 | ERROR    | scripts.knowledge_acquisition:_extract_relationships:652 | Failed to convert relationship: {'source': 'Model Training', 'relation': 'produces', 'target': 'Trained Model'}: 1 validation error for Relationship
relation
  Input should be 'is_a', 'has_part' or 'related_to' [type=literal_error, input_value='produces', input_type=str]
    For further information visit https://errors.pydantic.dev/2.10/v/literal_error
Traceback (most recent call last):

  File "C:\Users\mikeb\work\sifu2\run_agents.py", line 868, in <module>
    asyncio.run(main())

  File "C:\Python313\Lib\asyncio\runners.py", line 194, in run
    return runner.run(main)
  File "C:\Python313\Lib\asyncio\runners.py", line 118, in run
    return self._loop.run_until_complete(task)
  File "C:\Python313\Lib\asyncio\base_events.py", line 707, in run_until_complete
    self.run_forever()
  File "C:\Python313\Lib\asyncio\base_events.py", line 678, in run_forever
    self._run_once()
  File "C:\Python313\Lib\asyncio\base_events.py", line 2033, in _run_once
    handle._run()
  File "C:\Python313\Lib\asyncio\events.py", line 89, in _run
    self._context.run(self._callback, *self._args)

  File "C:\Users\mikeb\work\sifu2\run_agents.py", line 857, in main
    await agent.run()

  File "C:\Users\mikeb\work\sifu2\run_agents.py", line 691, in run
    result = await getattr(self, task.tool)(**task.args)

  File "C:\Users\mikeb\work\sifu2\run_agents.py", line 344, in _synthesize_knowledge
    knowledge = await self.knowledge_system.process_source(content)

  File "C:\Users\mikeb\work\sifu2\scripts\knowledge_acquisition.py", line 466, in process_source
    relationships = await self._extract_relationships(content)

> File "C:\Users\mikeb\work\sifu2\scripts\knowledge_acquisition.py", line 650, in _extract_relationships
    converted_relationships.append(Relationship(**rel))

  File "C:\Python313\Lib\site-packages\pydantic\main.py", line 214, in __init__
    validated_self = self.__pydantic_validator__.validate_python(data, self_instance=self)

pydantic_core._pydantic_core.ValidationError: 1 validation error for Relationship
relation
  Input should be 'is_a', 'has_part' or 'related_to' [type=literal_error, input_value='produces', input_type=str]
    For further information visit https://errors.pydantic.dev/2.10/v/literal_error
2025-02-09 14:57:33.073 | 40372:34912 | ERROR    | scripts.knowledge_acquisition:_extract_relationships:652 | Failed to convert relationship: {'source': 'Trained Model', 'relation': 'used_by', 'target': 'Model Evaluation'}: 1 validation error for Relationship
relation
  Input should be 'is_a', 'has_part' or 'related_to' [type=literal_error, input_value='used_by', input_type=str]
    For further information visit https://errors.pydantic.dev/2.10/v/literal_error
Traceback (most recent call last):

  File "C:\Users\mikeb\work\sifu2\run_agents.py", line 868, in <module>
    asyncio.run(main())

  File "C:\Python313\Lib\asyncio\runners.py", line 194, in run
    return runner.run(main)
  File "C:\Python313\Lib\asyncio\runners.py", line 118, in run
    return self._loop.run_until_complete(task)
  File "C:\Python313\Lib\asyncio\base_events.py", line 707, in run_until_complete
    self.run_forever()
  File "C:\Python313\Lib\asyncio\base_events.py", line 678, in run_forever
    self._run_once()
  File "C:\Python313\Lib\asyncio\base_events.py", line 2033, in _run_once
    handle._run()
  File "C:\Python313\Lib\asyncio\events.py", line 89, in _run
    self._context.run(self._callback, *self._args)

  File "C:\Users\mikeb\work\sifu2\run_agents.py", line 857, in main
    await agent.run()

  File "C:\Users\mikeb\work\sifu2\run_agents.py", line 691, in run
    result = await getattr(self, task.tool)(**task.args)

  File "C:\Users\mikeb\work\sifu2\run_agents.py", line 344, in _synthesize_knowledge
    knowledge = await self.knowledge_system.process_source(content)

  File "C:\Users\mikeb\work\sifu2\scripts\knowledge_acquisition.py", line 466, in process_source
    relationships = await self._extract_relationships(content)

> File "C:\Users\mikeb\work\sifu2\scripts\knowledge_acquisition.py", line 650, in _extract_relationships
    converted_relationships.append(Relationship(**rel))

  File "C:\Python313\Lib\site-packages\pydantic\main.py", line 214, in __init__
    validated_self = self.__pydantic_validator__.validate_python(data, self_instance=self)

pydantic_core._pydantic_core.ValidationError: 1 validation error for Relationship
relation
  Input should be 'is_a', 'has_part' or 'related_to' [type=literal_error, input_value='used_by', input_type=str]
    For further information visit https://errors.pydantic.dev/2.10/v/literal_error
2025-02-09 14:57:33.098 | 40372:34912 | ERROR    | scripts.knowledge_acquisition:_extract_relationships:652 | Failed to convert relationship: {'source': 'Model Evaluation', 'relation': 'produces', 'target': 'Evaluation Metrics'}: 1 validation error for Relationship
relation
  Input should be 'is_a', 'has_part' or 'related_to' [type=literal_error, input_value='produces', input_type=str]
    For further information visit https://errors.pydantic.dev/2.10/v/literal_error
Traceback (most recent call last):

  File "C:\Users\mikeb\work\sifu2\run_agents.py", line 868, in <module>
    asyncio.run(main())

  File "C:\Python313\Lib\asyncio\runners.py", line 194, in run
    return runner.run(main)
  File "C:\Python313\Lib\asyncio\runners.py", line 118, in run
    return self._loop.run_until_complete(task)
  File "C:\Python313\Lib\asyncio\base_events.py", line 707, in run_until_complete
    self.run_forever()
  File "C:\Python313\Lib\asyncio\base_events.py", line 678, in run_forever
    self._run_once()
  File "C:\Python313\Lib\asyncio\base_events.py", line 2033, in _run_once
    handle._run()
  File "C:\Python313\Lib\asyncio\events.py", line 89, in _run
    self._context.run(self._callback, *self._args)

  File "C:\Users\mikeb\work\sifu2\run_agents.py", line 857, in main
    await agent.run()

  File "C:\Users\mikeb\work\sifu2\run_agents.py", line 691, in run
    result = await getattr(self, task.tool)(**task.args)

  File "C:\Users\mikeb\work\sifu2\run_agents.py", line 344, in _synthesize_knowledge
    knowledge = await self.knowledge_system.process_source(content)

  File "C:\Users\mikeb\work\sifu2\scripts\knowledge_acquisition.py", line 466, in process_source
    relationships = await self._extract_relationships(content)

> File "C:\Users\mikeb\work\sifu2\scripts\knowledge_acquisition.py", line 650, in _extract_relationships
    converted_relationships.append(Relationship(**rel))

  File "C:\Python313\Lib\site-packages\pydantic\main.py", line 214, in __init__
    validated_self = self.__pydantic_validator__.validate_python(data, self_instance=self)

pydantic_core._pydantic_core.ValidationError: 1 validation error for Relationship
relation
  Input should be 'is_a', 'has_part' or 'related_to' [type=literal_error, input_value='produces', input_type=str]
    For further information visit https://errors.pydantic.dev/2.10/v/literal_error
2025-02-09 14:57:33.125 | 40372:34912 | ERROR    | scripts.knowledge_acquisition:_extract_relationships:652 | Failed to convert relationship: {'source': 'CNNs', 'relation': 'applied_to', 'target': 'Image Recognition'}: 1 validation error for Relationship
relation
  Input should be 'is_a', 'has_part' or 'related_to' [type=literal_error, input_value='applied_to', input_type=str]
    For further information visit https://errors.pydantic.dev/2.10/v/literal_error
Traceback (most recent call last):

  File "C:\Users\mikeb\work\sifu2\run_agents.py", line 868, in <module>
    asyncio.run(main())

  File "C:\Python313\Lib\asyncio\runners.py", line 194, in run
    return runner.run(main)
  File "C:\Python313\Lib\asyncio\runners.py", line 118, in run
    return self._loop.run_until_complete(task)
  File "C:\Python313\Lib\asyncio\base_events.py", line 707, in run_until_complete
    self.run_forever()
  File "C:\Python313\Lib\asyncio\base_events.py", line 678, in run_forever
    self._run_once()
  File "C:\Python313\Lib\asyncio\base_events.py", line 2033, in _run_once
    handle._run()
  File "C:\Python313\Lib\asyncio\events.py", line 89, in _run
    self._context.run(self._callback, *self._args)

  File "C:\Users\mikeb\work\sifu2\run_agents.py", line 857, in main
    await agent.run()

  File "C:\Users\mikeb\work\sifu2\run_agents.py", line 691, in run
    result = await getattr(self, task.tool)(**task.args)

  File "C:\Users\mikeb\work\sifu2\run_agents.py", line 344, in _synthesize_knowledge
    knowledge = await self.knowledge_system.process_source(content)

  File "C:\Users\mikeb\work\sifu2\scripts\knowledge_acquisition.py", line 466, in process_source
    relationships = await self._extract_relationships(content)

> File "C:\Users\mikeb\work\sifu2\scripts\knowledge_acquisition.py", line 650, in _extract_relationships
    converted_relationships.append(Relationship(**rel))

  File "C:\Python313\Lib\site-packages\pydantic\main.py", line 214, in __init__
    validated_self = self.__pydantic_validator__.validate_python(data, self_instance=self)

pydantic_core._pydantic_core.ValidationError: 1 validation error for Relationship
relation
  Input should be 'is_a', 'has_part' or 'related_to' [type=literal_error, input_value='applied_to', input_type=str]
    For further information visit https://errors.pydantic.dev/2.10/v/literal_error
2025-02-09 14:57:33.147 | 40372:34912 | ERROR    | scripts.knowledge_acquisition:_extract_relationships:652 | Failed to convert relationship: {'source': 'RNNs', 'relation': 'applied_to', 'target': 'Natural Language Processing'}: 1 validation error for Relationship
relation
  Input should be 'is_a', 'has_part' or 'related_to' [type=literal_error, input_value='applied_to', input_type=str]
    For further information visit https://errors.pydantic.dev/2.10/v/literal_error
Traceback (most recent call last):

  File "C:\Users\mikeb\work\sifu2\run_agents.py", line 868, in <module>
    asyncio.run(main())

  File "C:\Python313\Lib\asyncio\runners.py", line 194, in run
    return runner.run(main)
  File "C:\Python313\Lib\asyncio\runners.py", line 118, in run
    return self._loop.run_until_complete(task)
  File "C:\Python313\Lib\asyncio\base_events.py", line 707, in run_until_complete
    self.run_forever()
  File "C:\Python313\Lib\asyncio\base_events.py", line 678, in run_forever
    self._run_once()
  File "C:\Python313\Lib\asyncio\base_events.py", line 2033, in _run_once
    handle._run()
  File "C:\Python313\Lib\asyncio\events.py", line 89, in _run
    self._context.run(self._callback, *self._args)

  File "C:\Users\mikeb\work\sifu2\run_agents.py", line 857, in main
    await agent.run()

  File "C:\Users\mikeb\work\sifu2\run_agents.py", line 691, in run
    result = await getattr(self, task.tool)(**task.args)

  File "C:\Users\mikeb\work\sifu2\run_agents.py", line 344, in _synthesize_knowledge
    knowledge = await self.knowledge_system.process_source(content)

  File "C:\Users\mikeb\work\sifu2\scripts\knowledge_acquisition.py", line 466, in process_source
    relationships = await self._extract_relationships(content)

> File "C:\Users\mikeb\work\sifu2\scripts\knowledge_acquisition.py", line 650, in _extract_relationships
    converted_relationships.append(Relationship(**rel))

  File "C:\Python313\Lib\site-packages\pydantic\main.py", line 214, in __init__
    validated_self = self.__pydantic_validator__.validate_python(data, self_instance=self)

pydantic_core._pydantic_core.ValidationError: 1 validation error for Relationship
relation
  Input should be 'is_a', 'has_part' or 'related_to' [type=literal_error, input_value='applied_to', input_type=str]
    For further information visit https://errors.pydantic.dev/2.10/v/literal_error
2025-02-09 14:57:33.170 | 40372:34912 | INFO     | scripts.knowledge_acquisition:process_source:478 | KnowledgeAcquisition: Extracted 3 relationships
2025-02-09 14:57:33.172 | 40372:34912 | INFO     | scripts.knowledge_acquisition:process_source:482 | KnowledgeAcquisition: Relationship: Convolutional Neural Networks (CNNs) -> is_a -> Neural Networks
2025-02-09 14:57:33.174 | 40372:34912 | INFO     | scripts.knowledge_acquisition:process_source:482 | KnowledgeAcquisition: Relationship: Recurrent Neural Networks (RNNs) -> is_a -> Neural Networks
2025-02-09 14:57:33.175 | 40372:34912 | INFO     | scripts.knowledge_acquisition:process_source:482 | KnowledgeAcquisition: Relationship: Neural Networks -> is_a -> Machine Learning Models
2025-02-09 14:57:33.176 | 40372:34912 | INFO     | scripts.knowledge_acquisition:process_source:488 | KnowledgeAcquisition: Generating metadata...
2025-02-09 14:57:34.313 | 40372:34912 | INFO     | scripts.knowledge_acquisition:process_source:495 | KnowledgeAcquisition: Generated metadata: {'source_type': 'text', 'confidence_score': 0.85, 'domain_relevance': 0.9, 'timestamp': '2024-02-09T11:42:32.000Z', 'validation_status': 'processed', 'domain': 'machine_learning'}
2025-02-09 14:57:34.314 | 40372:34912 | INFO     | scripts.knowledge_acquisition:process_source:501 | KnowledgeAcquisition: Evaluating confidence...
2025-02-09 14:57:35.588 | 40372:34912 | INFO     | scripts.knowledge_acquisition:process_source:511 | KnowledgeAcquisition: Confidence score: 0.8
2025-02-09 14:57:35.597 | 40372:34912 | INFO     | __main__:_synthesize_knowledge:325 | Knowledge Synthesis: Processing source: Check Domain Authority Score【No Login, Super Fast, FREE】 (source_5.txt)
2025-02-09 14:57:35.598 | 40372:34912 | INFO     | __main__:_synthesize_knowledge:329 | Knowledge Synthesis: Content preview:
![AI Writer for SEO Domain Authority (DA) is a metric that predicts how well a website is likely to rank on DA is determined by analyzing multiple factors, including the number of linking root domains and the total count of links, culminating in a single DA score. This score is commonly used for comparing the ranking potential of different websites or monitoring a website's strength over time. It's important to understand that Domain Authority is not utilized by Google in its ## Examples of doma...
2025-02-09 14:57:35.599 | 40372:34912 | INFO     | scripts.knowledge_acquisition:process_source:444 | KnowledgeAcquisition: Starting source processing with content length: 5785
2025-02-09 14:57:35.601 | 40372:34912 | INFO     | scripts.knowledge_acquisition:process_source:448 | KnowledgeAcquisition: Content preview:
![AI Writer for SEO Domain Authority (DA) is a metric that predicts how well a website is likely to rank on DA is determined by analyzing multiple factors, including the number of linking root domains...
2025-02-09 14:57:35.602 | 40372:34912 | INFO     | scripts.knowledge_acquisition:process_source:451 | KnowledgeAcquisition: Extracting entities...
2025-02-09 14:57:36.487 | 40372:34912 | INFO     | scripts.knowledge_acquisition:process_source:458 | KnowledgeAcquisition: Extracted 10 entities: ['Machine Learning', 'Deep Learning', 'Neural Networks', 'TensorFlow', 'Python', 'Keras', 'Computer Vision', 'Natural Language Processing', 'Data Science', 'Artificial Intelligence']
2025-02-09 14:57:36.488 | 40372:34912 | INFO     | scripts.knowledge_acquisition:process_source:464 | KnowledgeAcquisition: Extracting relationships...
2025-02-09 14:57:36.958 | 40372:34912 | INFO     | scripts.knowledge_acquisition:process_source:478 | KnowledgeAcquisition: Extracted 1 relationships
2025-02-09 14:57:36.960 | 40372:34912 | INFO     | scripts.knowledge_acquisition:process_source:482 | KnowledgeAcquisition: Relationship: Machine Learning -> related_to -> Deep Learning
2025-02-09 14:57:36.961 | 40372:34912 | INFO     | scripts.knowledge_acquisition:process_source:488 | KnowledgeAcquisition: Generating metadata...
2025-02-09 14:57:38.016 | 40372:34912 | INFO     | scripts.knowledge_acquisition:process_source:495 | KnowledgeAcquisition: Generated metadata: {'source_type': 'text', 'confidence_score': 0.85, 'domain_relevance': 0.9, 'timestamp': '2024-02-09T11:42:32.000Z', 'validation_status': 'processed', 'domain': 'machine_learning'}
2025-02-09 14:57:38.018 | 40372:34912 | INFO     | scripts.knowledge_acquisition:process_source:501 | KnowledgeAcquisition: Evaluating confidence...
2025-02-09 14:57:39.588 | 40372:34912 | INFO     | scripts.knowledge_acquisition:process_source:511 | KnowledgeAcquisition: Confidence score: 0.8
2025-02-09 14:57:39.596 | 40372:34912 | INFO     | __main__:_synthesize_knowledge:325 | Knowledge Synthesis: Processing source: Free Website Authority Checker (& How to Improve Yours) (source_7.txt)
2025-02-09 14:57:39.597 | 40372:34912 | INFO     | __main__:_synthesize_knowledge:329 | Knowledge Synthesis: Content preview:
!grid-line !( Keri Engel January 10, 2025 Our free website authority checker lets you check domain authority for any website on the internet. To get your analysis, just enter a domain name and hit enter. The website authority report is split into six sections. First, you’ll see an overview of domain metrics, like your authority score. This indicates the level of trust that !undefined:** Combines factors like link quality, organic traffic, and spam presence to create an accurate measure, aiming t...
2025-02-09 14:57:39.599 | 40372:34912 | INFO     | scripts.knowledge_acquisition:process_source:444 | KnowledgeAcquisition: Starting source processing with content length: 1060
2025-02-09 14:57:39.600 | 40372:34912 | INFO     | scripts.knowledge_acquisition:process_source:448 | KnowledgeAcquisition: Content preview:
!grid-line !( Keri Engel January 10, 2025 Our free website authority checker lets you check domain authority for any website on the internet. To get your analysis, just enter a domain name and hit ent...
2025-02-09 14:57:39.602 | 40372:34912 | INFO     | scripts.knowledge_acquisition:process_source:451 | KnowledgeAcquisition: Extracting entities...
2025-02-09 14:57:40.509 | 40372:34912 | INFO     | scripts.knowledge_acquisition:process_source:458 | KnowledgeAcquisition: Extracted 10 entities: ['Machine Learning', 'Deep Learning', 'Neural Networks', 'TensorFlow', 'Python', 'Data Science', 'Artificial Intelligence', 'Big Data', 'Cloud Computing', 'Natural Language Processing']
2025-02-09 14:57:40.511 | 40372:34912 | INFO     | scripts.knowledge_acquisition:process_source:464 | KnowledgeAcquisition: Extracting relationships...
2025-02-09 14:57:43.764 | 40372:34912 | ERROR    | scripts.knowledge_acquisition:_extract_relationships:652 | Failed to convert relationship: {'source': 'Data Preprocessing', 'relation': 'precedes', 'target': 'Model Training'}: 1 validation error for Relationship
relation
  Input should be 'is_a', 'has_part' or 'related_to' [type=literal_error, input_value='precedes', input_type=str]
    For further information visit https://errors.pydantic.dev/2.10/v/literal_error
Traceback (most recent call last):

  File "C:\Users\mikeb\work\sifu2\run_agents.py", line 868, in <module>
    asyncio.run(main())

  File "C:\Python313\Lib\asyncio\runners.py", line 194, in run
    return runner.run(main)
  File "C:\Python313\Lib\asyncio\runners.py", line 118, in run
    return self._loop.run_until_complete(task)
  File "C:\Python313\Lib\asyncio\base_events.py", line 707, in run_until_complete
    self.run_forever()
  File "C:\Python313\Lib\asyncio\base_events.py", line 678, in run_forever
    self._run_once()
  File "C:\Python313\Lib\asyncio\base_events.py", line 2033, in _run_once
    handle._run()
  File "C:\Python313\Lib\asyncio\events.py", line 89, in _run
    self._context.run(self._callback, *self._args)

  File "C:\Users\mikeb\work\sifu2\run_agents.py", line 857, in main
    await agent.run()

  File "C:\Users\mikeb\work\sifu2\run_agents.py", line 691, in run
    result = await getattr(self, task.tool)(**task.args)

  File "C:\Users\mikeb\work\sifu2\run_agents.py", line 344, in _synthesize_knowledge
    knowledge = await self.knowledge_system.process_source(content)

  File "C:\Users\mikeb\work\sifu2\scripts\knowledge_acquisition.py", line 466, in process_source
    relationships = await self._extract_relationships(content)

> File "C:\Users\mikeb\work\sifu2\scripts\knowledge_acquisition.py", line 650, in _extract_relationships
    converted_relationships.append(Relationship(**rel))

  File "C:\Python313\Lib\site-packages\pydantic\main.py", line 214, in __init__
    validated_self = self.__pydantic_validator__.validate_python(data, self_instance=self)

pydantic_core._pydantic_core.ValidationError: 1 validation error for Relationship
relation
  Input should be 'is_a', 'has_part' or 'related_to' [type=literal_error, input_value='precedes', input_type=str]
    For further information visit https://errors.pydantic.dev/2.10/v/literal_error
2025-02-09 14:57:43.789 | 40372:34912 | ERROR    | scripts.knowledge_acquisition:_extract_relationships:652 | Failed to convert relationship: {'source': 'Model Training', 'relation': 'uses', 'target': 'Training Data'}: 1 validation error for Relationship
relation
  Input should be 'is_a', 'has_part' or 'related_to' [type=literal_error, input_value='uses', input_type=str]
    For further information visit https://errors.pydantic.dev/2.10/v/literal_error
Traceback (most recent call last):

  File "C:\Users\mikeb\work\sifu2\run_agents.py", line 868, in <module>
    asyncio.run(main())

  File "C:\Python313\Lib\asyncio\runners.py", line 194, in run
    return runner.run(main)
  File "C:\Python313\Lib\asyncio\runners.py", line 118, in run
    return self._loop.run_until_complete(task)
  File "C:\Python313\Lib\asyncio\base_events.py", line 707, in run_until_complete
    self.run_forever()
  File "C:\Python313\Lib\asyncio\base_events.py", line 678, in run_forever
    self._run_once()
  File "C:\Python313\Lib\asyncio\base_events.py", line 2033, in _run_once
    handle._run()
  File "C:\Python313\Lib\asyncio\events.py", line 89, in _run
    self._context.run(self._callback, *self._args)

  File "C:\Users\mikeb\work\sifu2\run_agents.py", line 857, in main
    await agent.run()

  File "C:\Users\mikeb\work\sifu2\run_agents.py", line 691, in run
    result = await getattr(self, task.tool)(**task.args)

  File "C:\Users\mikeb\work\sifu2\run_agents.py", line 344, in _synthesize_knowledge
    knowledge = await self.knowledge_system.process_source(content)

  File "C:\Users\mikeb\work\sifu2\scripts\knowledge_acquisition.py", line 466, in process_source
    relationships = await self._extract_relationships(content)

> File "C:\Users\mikeb\work\sifu2\scripts\knowledge_acquisition.py", line 650, in _extract_relationships
    converted_relationships.append(Relationship(**rel))

  File "C:\Python313\Lib\site-packages\pydantic\main.py", line 214, in __init__
    validated_self = self.__pydantic_validator__.validate_python(data, self_instance=self)

pydantic_core._pydantic_core.ValidationError: 1 validation error for Relationship
relation
  Input should be 'is_a', 'has_part' or 'related_to' [type=literal_error, input_value='uses', input_type=str]
    For further information visit https://errors.pydantic.dev/2.10/v/literal_error
2025-02-09 14:57:43.813 | 40372:34912 | ERROR    | scripts.knowledge_acquisition:_extract_relationships:652 | Failed to convert relationship: {'source': 'Model Training', 'relation': 'output_of', 'target': 'Trained Model'}: 1 validation error for Relationship
relation
  Input should be 'is_a', 'has_part' or 'related_to' [type=literal_error, input_value='output_of', input_type=str]
    For further information visit https://errors.pydantic.dev/2.10/v/literal_error
Traceback (most recent call last):

  File "C:\Users\mikeb\work\sifu2\run_agents.py", line 868, in <module>
    asyncio.run(main())

  File "C:\Python313\Lib\asyncio\runners.py", line 194, in run
    return runner.run(main)
  File "C:\Python313\Lib\asyncio\runners.py", line 118, in run
    return self._loop.run_until_complete(task)
  File "C:\Python313\Lib\asyncio\base_events.py", line 707, in run_until_complete
    self.run_forever()
  File "C:\Python313\Lib\asyncio\base_events.py", line 678, in run_forever
    self._run_once()
  File "C:\Python313\Lib\asyncio\base_events.py", line 2033, in _run_once
    handle._run()
  File "C:\Python313\Lib\asyncio\events.py", line 89, in _run
    self._context.run(self._callback, *self._args)

  File "C:\Users\mikeb\work\sifu2\run_agents.py", line 857, in main
    await agent.run()

  File "C:\Users\mikeb\work\sifu2\run_agents.py", line 691, in run
    result = await getattr(self, task.tool)(**task.args)

  File "C:\Users\mikeb\work\sifu2\run_agents.py", line 344, in _synthesize_knowledge
    knowledge = await self.knowledge_system.process_source(content)

  File "C:\Users\mikeb\work\sifu2\scripts\knowledge_acquisition.py", line 466, in process_source
    relationships = await self._extract_relationships(content)

> File "C:\Users\mikeb\work\sifu2\scripts\knowledge_acquisition.py", line 650, in _extract_relationships
    converted_relationships.append(Relationship(**rel))

  File "C:\Python313\Lib\site-packages\pydantic\main.py", line 214, in __init__
    validated_self = self.__pydantic_validator__.validate_python(data, self_instance=self)

pydantic_core._pydantic_core.ValidationError: 1 validation error for Relationship
relation
  Input should be 'is_a', 'has_part' or 'related_to' [type=literal_error, input_value='output_of', input_type=str]
    For further information visit https://errors.pydantic.dev/2.10/v/literal_error
2025-02-09 14:57:43.838 | 40372:34912 | ERROR    | scripts.knowledge_acquisition:_extract_relationships:652 | Failed to convert relationship: {'source': 'Trained Model', 'relation': 'input_to', 'target': 'Model Evaluation'}: 1 validation error for Relationship
relation
  Input should be 'is_a', 'has_part' or 'related_to' [type=literal_error, input_value='input_to', input_type=str]
    For further information visit https://errors.pydantic.dev/2.10/v/literal_error
Traceback (most recent call last):

  File "C:\Users\mikeb\work\sifu2\run_agents.py", line 868, in <module>
    asyncio.run(main())

  File "C:\Python313\Lib\asyncio\runners.py", line 194, in run
    return runner.run(main)
  File "C:\Python313\Lib\asyncio\runners.py", line 118, in run
    return self._loop.run_until_complete(task)
  File "C:\Python313\Lib\asyncio\base_events.py", line 707, in run_until_complete
    self.run_forever()
  File "C:\Python313\Lib\asyncio\base_events.py", line 678, in run_forever
    self._run_once()
  File "C:\Python313\Lib\asyncio\base_events.py", line 2033, in _run_once
    handle._run()
  File "C:\Python313\Lib\asyncio\events.py", line 89, in _run
    self._context.run(self._callback, *self._args)

  File "C:\Users\mikeb\work\sifu2\run_agents.py", line 857, in main
    await agent.run()

  File "C:\Users\mikeb\work\sifu2\run_agents.py", line 691, in run
    result = await getattr(self, task.tool)(**task.args)

  File "C:\Users\mikeb\work\sifu2\run_agents.py", line 344, in _synthesize_knowledge
    knowledge = await self.knowledge_system.process_source(content)

  File "C:\Users\mikeb\work\sifu2\scripts\knowledge_acquisition.py", line 466, in process_source
    relationships = await self._extract_relationships(content)

> File "C:\Users\mikeb\work\sifu2\scripts\knowledge_acquisition.py", line 650, in _extract_relationships
    converted_relationships.append(Relationship(**rel))

  File "C:\Python313\Lib\site-packages\pydantic\main.py", line 214, in __init__
    validated_self = self.__pydantic_validator__.validate_python(data, self_instance=self)

pydantic_core._pydantic_core.ValidationError: 1 validation error for Relationship
relation
  Input should be 'is_a', 'has_part' or 'related_to' [type=literal_error, input_value='input_to', input_type=str]
    For further information visit https://errors.pydantic.dev/2.10/v/literal_error
2025-02-09 14:57:43.862 | 40372:34912 | ERROR    | scripts.knowledge_acquisition:_extract_relationships:652 | Failed to convert relationship: {'source': 'Model Evaluation', 'relation': 'uses', 'target': 'Test Data'}: 1 validation error for Relationship
relation
  Input should be 'is_a', 'has_part' or 'related_to' [type=literal_error, input_value='uses', input_type=str]
    For further information visit https://errors.pydantic.dev/2.10/v/literal_error
Traceback (most recent call last):

  File "C:\Users\mikeb\work\sifu2\run_agents.py", line 868, in <module>
    asyncio.run(main())

  File "C:\Python313\Lib\asyncio\runners.py", line 194, in run
    return runner.run(main)
  File "C:\Python313\Lib\asyncio\runners.py", line 118, in run
    return self._loop.run_until_complete(task)
  File "C:\Python313\Lib\asyncio\base_events.py", line 707, in run_until_complete
    self.run_forever()
  File "C:\Python313\Lib\asyncio\base_events.py", line 678, in run_forever
    self._run_once()
  File "C:\Python313\Lib\asyncio\base_events.py", line 2033, in _run_once
    handle._run()
  File "C:\Python313\Lib\asyncio\events.py", line 89, in _run
    self._context.run(self._callback, *self._args)

  File "C:\Users\mikeb\work\sifu2\run_agents.py", line 857, in main
    await agent.run()

  File "C:\Users\mikeb\work\sifu2\run_agents.py", line 691, in run
    result = await getattr(self, task.tool)(**task.args)

  File "C:\Users\mikeb\work\sifu2\run_agents.py", line 344, in _synthesize_knowledge
    knowledge = await self.knowledge_system.process_source(content)

  File "C:\Users\mikeb\work\sifu2\scripts\knowledge_acquisition.py", line 466, in process_source
    relationships = await self._extract_relationships(content)

> File "C:\Users\mikeb\work\sifu2\scripts\knowledge_acquisition.py", line 650, in _extract_relationships
    converted_relationships.append(Relationship(**rel))

  File "C:\Python313\Lib\site-packages\pydantic\main.py", line 214, in __init__
    validated_self = self.__pydantic_validator__.validate_python(data, self_instance=self)

pydantic_core._pydantic_core.ValidationError: 1 validation error for Relationship
relation
  Input should be 'is_a', 'has_part' or 'related_to' [type=literal_error, input_value='uses', input_type=str]
    For further information visit https://errors.pydantic.dev/2.10/v/literal_error
2025-02-09 14:57:43.886 | 40372:34912 | ERROR    | scripts.knowledge_acquisition:_extract_relationships:652 | Failed to convert relationship: {'source': 'Model Evaluation', 'relation': 'output_of', 'target': 'Evaluation Metrics'}: 1 validation error for Relationship
relation
  Input should be 'is_a', 'has_part' or 'related_to' [type=literal_error, input_value='output_of', input_type=str]
    For further information visit https://errors.pydantic.dev/2.10/v/literal_error
Traceback (most recent call last):

  File "C:\Users\mikeb\work\sifu2\run_agents.py", line 868, in <module>
    asyncio.run(main())

  File "C:\Python313\Lib\asyncio\runners.py", line 194, in run
    return runner.run(main)
  File "C:\Python313\Lib\asyncio\runners.py", line 118, in run
    return self._loop.run_until_complete(task)
  File "C:\Python313\Lib\asyncio\base_events.py", line 707, in run_until_complete
    self.run_forever()
  File "C:\Python313\Lib\asyncio\base_events.py", line 678, in run_forever
    self._run_once()
  File "C:\Python313\Lib\asyncio\base_events.py", line 2033, in _run_once
    handle._run()
  File "C:\Python313\Lib\asyncio\events.py", line 89, in _run
    self._context.run(self._callback, *self._args)

  File "C:\Users\mikeb\work\sifu2\run_agents.py", line 857, in main
    await agent.run()

  File "C:\Users\mikeb\work\sifu2\run_agents.py", line 691, in run
    result = await getattr(self, task.tool)(**task.args)

  File "C:\Users\mikeb\work\sifu2\run_agents.py", line 344, in _synthesize_knowledge
    knowledge = await self.knowledge_system.process_source(content)

  File "C:\Users\mikeb\work\sifu2\scripts\knowledge_acquisition.py", line 466, in process_source
    relationships = await self._extract_relationships(content)

> File "C:\Users\mikeb\work\sifu2\scripts\knowledge_acquisition.py", line 650, in _extract_relationships
    converted_relationships.append(Relationship(**rel))

  File "C:\Python313\Lib\site-packages\pydantic\main.py", line 214, in __init__
    validated_self = self.__pydantic_validator__.validate_python(data, self_instance=self)

pydantic_core._pydantic_core.ValidationError: 1 validation error for Relationship
relation
  Input should be 'is_a', 'has_part' or 'related_to' [type=literal_error, input_value='output_of', input_type=str]
    For further information visit https://errors.pydantic.dev/2.10/v/literal_error
2025-02-09 14:57:43.908 | 40372:34912 | ERROR    | scripts.knowledge_acquisition:_extract_relationships:652 | Failed to convert relationship: {'source': 'CNNs', 'relation': 'applied_to', 'target': 'Image Recognition'}: 1 validation error for Relationship
relation
  Input should be 'is_a', 'has_part' or 'related_to' [type=literal_error, input_value='applied_to', input_type=str]
    For further information visit https://errors.pydantic.dev/2.10/v/literal_error
Traceback (most recent call last):

  File "C:\Users\mikeb\work\sifu2\run_agents.py", line 868, in <module>
    asyncio.run(main())

  File "C:\Python313\Lib\asyncio\runners.py", line 194, in run
    return runner.run(main)
  File "C:\Python313\Lib\asyncio\runners.py", line 118, in run
    return self._loop.run_until_complete(task)
  File "C:\Python313\Lib\asyncio\base_events.py", line 707, in run_until_complete
    self.run_forever()
  File "C:\Python313\Lib\asyncio\base_events.py", line 678, in run_forever
    self._run_once()
  File "C:\Python313\Lib\asyncio\base_events.py", line 2033, in _run_once
    handle._run()
  File "C:\Python313\Lib\asyncio\events.py", line 89, in _run
    self._context.run(self._callback, *self._args)

  File "C:\Users\mikeb\work\sifu2\run_agents.py", line 857, in main
    await agent.run()

  File "C:\Users\mikeb\work\sifu2\run_agents.py", line 691, in run
    result = await getattr(self, task.tool)(**task.args)

  File "C:\Users\mikeb\work\sifu2\run_agents.py", line 344, in _synthesize_knowledge
    knowledge = await self.knowledge_system.process_source(content)

  File "C:\Users\mikeb\work\sifu2\scripts\knowledge_acquisition.py", line 466, in process_source
    relationships = await self._extract_relationships(content)

> File "C:\Users\mikeb\work\sifu2\scripts\knowledge_acquisition.py", line 650, in _extract_relationships
    converted_relationships.append(Relationship(**rel))

  File "C:\Python313\Lib\site-packages\pydantic\main.py", line 214, in __init__
    validated_self = self.__pydantic_validator__.validate_python(data, self_instance=self)

pydantic_core._pydantic_core.ValidationError: 1 validation error for Relationship
relation
  Input should be 'is_a', 'has_part' or 'related_to' [type=literal_error, input_value='applied_to', input_type=str]
    For further information visit https://errors.pydantic.dev/2.10/v/literal_error
2025-02-09 14:57:43.932 | 40372:34912 | ERROR    | scripts.knowledge_acquisition:_extract_relationships:652 | Failed to convert relationship: {'source': 'RNNs', 'relation': 'applied_to', 'target': 'Natural Language Processing'}: 1 validation error for Relationship
relation
  Input should be 'is_a', 'has_part' or 'related_to' [type=literal_error, input_value='applied_to', input_type=str]
    For further information visit https://errors.pydantic.dev/2.10/v/literal_error
Traceback (most recent call last):

  File "C:\Users\mikeb\work\sifu2\run_agents.py", line 868, in <module>
    asyncio.run(main())

  File "C:\Python313\Lib\asyncio\runners.py", line 194, in run
    return runner.run(main)
  File "C:\Python313\Lib\asyncio\runners.py", line 118, in run
    return self._loop.run_until_complete(task)
  File "C:\Python313\Lib\asyncio\base_events.py", line 707, in run_until_complete
    self.run_forever()
  File "C:\Python313\Lib\asyncio\base_events.py", line 678, in run_forever
    self._run_once()
  File "C:\Python313\Lib\asyncio\base_events.py", line 2033, in _run_once
    handle._run()
  File "C:\Python313\Lib\asyncio\events.py", line 89, in _run
    self._context.run(self._callback, *self._args)

  File "C:\Users\mikeb\work\sifu2\run_agents.py", line 857, in main
    await agent.run()

  File "C:\Users\mikeb\work\sifu2\run_agents.py", line 691, in run
    result = await getattr(self, task.tool)(**task.args)

  File "C:\Users\mikeb\work\sifu2\run_agents.py", line 344, in _synthesize_knowledge
    knowledge = await self.knowledge_system.process_source(content)

  File "C:\Users\mikeb\work\sifu2\scripts\knowledge_acquisition.py", line 466, in process_source
    relationships = await self._extract_relationships(content)

> File "C:\Users\mikeb\work\sifu2\scripts\knowledge_acquisition.py", line 650, in _extract_relationships
    converted_relationships.append(Relationship(**rel))

  File "C:\Python313\Lib\site-packages\pydantic\main.py", line 214, in __init__
    validated_self = self.__pydantic_validator__.validate_python(data, self_instance=self)

pydantic_core._pydantic_core.ValidationError: 1 validation error for Relationship
relation
  Input should be 'is_a', 'has_part' or 'related_to' [type=literal_error, input_value='applied_to', input_type=str]
    For further information visit https://errors.pydantic.dev/2.10/v/literal_error
2025-02-09 14:57:43.957 | 40372:34912 | INFO     | scripts.knowledge_acquisition:process_source:478 | KnowledgeAcquisition: Extracted 3 relationships
2025-02-09 14:57:43.959 | 40372:34912 | INFO     | scripts.knowledge_acquisition:process_source:482 | KnowledgeAcquisition: Relationship: Convolutional Neural Networks (CNNs) -> is_a -> Neural Networks
2025-02-09 14:57:43.960 | 40372:34912 | INFO     | scripts.knowledge_acquisition:process_source:482 | KnowledgeAcquisition: Relationship: Recurrent Neural Networks (RNNs) -> is_a -> Neural Networks
2025-02-09 14:57:43.961 | 40372:34912 | INFO     | scripts.knowledge_acquisition:process_source:482 | KnowledgeAcquisition: Relationship: Neural Networks -> is_a -> Machine Learning Model
2025-02-09 14:57:43.963 | 40372:34912 | INFO     | scripts.knowledge_acquisition:process_source:488 | KnowledgeAcquisition: Generating metadata...
2025-02-09 14:57:45.214 | 40372:34912 | INFO     | scripts.knowledge_acquisition:process_source:495 | KnowledgeAcquisition: Generated metadata: {'source_type': 'text', 'confidence_score': 0.9, 'domain_relevance': 0.85, 'timestamp': '2024-02-09T12:45:00.000Z', 'validation_status': 'processed', 'domain': 'machine_learning'}
2025-02-09 14:57:45.216 | 40372:34912 | INFO     | scripts.knowledge_acquisition:process_source:501 | KnowledgeAcquisition: Evaluating confidence...
2025-02-09 14:57:46.789 | 40372:34912 | INFO     | scripts.knowledge_acquisition:process_source:511 | KnowledgeAcquisition: Confidence score: 0.85
2025-02-09 14:57:46.797 | 40372:34912 | INFO     | __main__:_synthesize_knowledge:325 | Knowledge Synthesis: Processing source: CHECK DOMAIN OVERVIEW - SmallSEOTools.com (source_9.txt)
2025-02-09 14:57:46.798 | 40372:34912 | INFO     | __main__:_synthesize_knowledge:329 | Knowledge Synthesis: Content preview:
![Image of website logo( Login( * ![PRO Pricing( * Plagiarism Checker( * Free Grammar Checker( * Reverse Image * [Paraphrasing Tool( * Login( × !image of languages( EN English - EN( русский - RU( 日本語 - JA( Italiano - IT( Français - FR( Português - PT( Español - ES( Deutsche - DE( 中文 - ZH( !Report Bug( # CHECK DOMAIN OVERVIEW Use website checker to get a domain overview and have a better insight into the online presence of a website. Just enter the domain or URL below and click the big blue "Chec...
2025-02-09 14:57:46.800 | 40372:34912 | INFO     | scripts.knowledge_acquisition:process_source:444 | KnowledgeAcquisition: Starting source processing with content length: 7208
2025-02-09 14:57:46.801 | 40372:34912 | INFO     | scripts.knowledge_acquisition:process_source:448 | KnowledgeAcquisition: Content preview:
![Image of website logo( Login( * ![PRO Pricing( * Plagiarism Checker( * Free Grammar Checker( * Reverse Image * [Paraphrasing Tool( * Login( × !image of languages( EN English - EN( русский - RU( 日本語 ...
2025-02-09 14:57:46.803 | 40372:34912 | INFO     | scripts.knowledge_acquisition:process_source:451 | KnowledgeAcquisition: Extracting entities...
2025-02-09 14:57:47.806 | 40372:34912 | INFO     | scripts.knowledge_acquisition:process_source:458 | KnowledgeAcquisition: Extracted 10 entities: ['Machine Learning', 'Deep Learning', 'Neural Networks', 'TensorFlow', 'Python', 'Natural Language Processing', 'Computer Vision', 'Data Science', 'Artificial Intelligence', 'Big Data']
2025-02-09 14:57:47.808 | 40372:34912 | INFO     | scripts.knowledge_acquisition:process_source:464 | KnowledgeAcquisition: Extracting relationships...
2025-02-09 14:57:51.067 | 40372:34912 | ERROR    | scripts.knowledge_acquisition:_extract_relationships:652 | Failed to convert relationship: {'source': 'Data Preprocessing', 'relation': 'precedes', 'target': 'Model Training'}: 1 validation error for Relationship
relation
  Input should be 'is_a', 'has_part' or 'related_to' [type=literal_error, input_value='precedes', input_type=str]
    For further information visit https://errors.pydantic.dev/2.10/v/literal_error
Traceback (most recent call last):

  File "C:\Users\mikeb\work\sifu2\run_agents.py", line 868, in <module>
    asyncio.run(main())

  File "C:\Python313\Lib\asyncio\runners.py", line 194, in run
    return runner.run(main)
  File "C:\Python313\Lib\asyncio\runners.py", line 118, in run
    return self._loop.run_until_complete(task)
  File "C:\Python313\Lib\asyncio\base_events.py", line 707, in run_until_complete
    self.run_forever()
  File "C:\Python313\Lib\asyncio\base_events.py", line 678, in run_forever
    self._run_once()
  File "C:\Python313\Lib\asyncio\base_events.py", line 2033, in _run_once
    handle._run()
  File "C:\Python313\Lib\asyncio\events.py", line 89, in _run
    self._context.run(self._callback, *self._args)

  File "C:\Users\mikeb\work\sifu2\run_agents.py", line 857, in main
    await agent.run()

  File "C:\Users\mikeb\work\sifu2\run_agents.py", line 691, in run
    result = await getattr(self, task.tool)(**task.args)

  File "C:\Users\mikeb\work\sifu2\run_agents.py", line 344, in _synthesize_knowledge
    knowledge = await self.knowledge_system.process_source(content)

  File "C:\Users\mikeb\work\sifu2\scripts\knowledge_acquisition.py", line 466, in process_source
    relationships = await self._extract_relationships(content)

> File "C:\Users\mikeb\work\sifu2\scripts\knowledge_acquisition.py", line 650, in _extract_relationships
    converted_relationships.append(Relationship(**rel))

  File "C:\Python313\Lib\site-packages\pydantic\main.py", line 214, in __init__
    validated_self = self.__pydantic_validator__.validate_python(data, self_instance=self)

pydantic_core._pydantic_core.ValidationError: 1 validation error for Relationship
relation
  Input should be 'is_a', 'has_part' or 'related_to' [type=literal_error, input_value='precedes', input_type=str]
    For further information visit https://errors.pydantic.dev/2.10/v/literal_error
2025-02-09 14:57:51.091 | 40372:34912 | ERROR    | scripts.knowledge_acquisition:_extract_relationships:652 | Failed to convert relationship: {'source': 'Model Training', 'relation': 'uses', 'target': 'Training Data'}: 1 validation error for Relationship
relation
  Input should be 'is_a', 'has_part' or 'related_to' [type=literal_error, input_value='uses', input_type=str]
    For further information visit https://errors.pydantic.dev/2.10/v/literal_error
Traceback (most recent call last):

  File "C:\Users\mikeb\work\sifu2\run_agents.py", line 868, in <module>
    asyncio.run(main())

  File "C:\Python313\Lib\asyncio\runners.py", line 194, in run
    return runner.run(main)
  File "C:\Python313\Lib\asyncio\runners.py", line 118, in run
    return self._loop.run_until_complete(task)
  File "C:\Python313\Lib\asyncio\base_events.py", line 707, in run_until_complete
    self.run_forever()
  File "C:\Python313\Lib\asyncio\base_events.py", line 678, in run_forever
    self._run_once()
  File "C:\Python313\Lib\asyncio\base_events.py", line 2033, in _run_once
    handle._run()
  File "C:\Python313\Lib\asyncio\events.py", line 89, in _run
    self._context.run(self._callback, *self._args)

  File "C:\Users\mikeb\work\sifu2\run_agents.py", line 857, in main
    await agent.run()

  File "C:\Users\mikeb\work\sifu2\run_agents.py", line 691, in run
    result = await getattr(self, task.tool)(**task.args)

  File "C:\Users\mikeb\work\sifu2\run_agents.py", line 344, in _synthesize_knowledge
    knowledge = await self.knowledge_system.process_source(content)

  File "C:\Users\mikeb\work\sifu2\scripts\knowledge_acquisition.py", line 466, in process_source
    relationships = await self._extract_relationships(content)

> File "C:\Users\mikeb\work\sifu2\scripts\knowledge_acquisition.py", line 650, in _extract_relationships
    converted_relationships.append(Relationship(**rel))

  File "C:\Python313\Lib\site-packages\pydantic\main.py", line 214, in __init__
    validated_self = self.__pydantic_validator__.validate_python(data, self_instance=self)

pydantic_core._pydantic_core.ValidationError: 1 validation error for Relationship
relation
  Input should be 'is_a', 'has_part' or 'related_to' [type=literal_error, input_value='uses', input_type=str]
    For further information visit https://errors.pydantic.dev/2.10/v/literal_error
2025-02-09 14:57:51.117 | 40372:34912 | ERROR    | scripts.knowledge_acquisition:_extract_relationships:652 | Failed to convert relationship: {'source': 'Model Training', 'relation': 'produces', 'target': 'Trained Model'}: 1 validation error for Relationship
relation
  Input should be 'is_a', 'has_part' or 'related_to' [type=literal_error, input_value='produces', input_type=str]
    For further information visit https://errors.pydantic.dev/2.10/v/literal_error
Traceback (most recent call last):

  File "C:\Users\mikeb\work\sifu2\run_agents.py", line 868, in <module>
    asyncio.run(main())

  File "C:\Python313\Lib\asyncio\runners.py", line 194, in run
    return runner.run(main)
  File "C:\Python313\Lib\asyncio\runners.py", line 118, in run
    return self._loop.run_until_complete(task)
  File "C:\Python313\Lib\asyncio\base_events.py", line 707, in run_until_complete
    self.run_forever()
  File "C:\Python313\Lib\asyncio\base_events.py", line 678, in run_forever
    self._run_once()
  File "C:\Python313\Lib\asyncio\base_events.py", line 2033, in _run_once
    handle._run()
  File "C:\Python313\Lib\asyncio\events.py", line 89, in _run
    self._context.run(self._callback, *self._args)

  File "C:\Users\mikeb\work\sifu2\run_agents.py", line 857, in main
    await agent.run()

  File "C:\Users\mikeb\work\sifu2\run_agents.py", line 691, in run
    result = await getattr(self, task.tool)(**task.args)

  File "C:\Users\mikeb\work\sifu2\run_agents.py", line 344, in _synthesize_knowledge
    knowledge = await self.knowledge_system.process_source(content)

  File "C:\Users\mikeb\work\sifu2\scripts\knowledge_acquisition.py", line 466, in process_source
    relationships = await self._extract_relationships(content)

> File "C:\Users\mikeb\work\sifu2\scripts\knowledge_acquisition.py", line 650, in _extract_relationships
    converted_relationships.append(Relationship(**rel))

  File "C:\Python313\Lib\site-packages\pydantic\main.py", line 214, in __init__
    validated_self = self.__pydantic_validator__.validate_python(data, self_instance=self)

pydantic_core._pydantic_core.ValidationError: 1 validation error for Relationship
relation
  Input should be 'is_a', 'has_part' or 'related_to' [type=literal_error, input_value='produces', input_type=str]
    For further information visit https://errors.pydantic.dev/2.10/v/literal_error
2025-02-09 14:57:51.140 | 40372:34912 | ERROR    | scripts.knowledge_acquisition:_extract_relationships:652 | Failed to convert relationship: {'source': 'Trained Model', 'relation': 'used_by', 'target': 'Model Evaluation'}: 1 validation error for Relationship
relation
  Input should be 'is_a', 'has_part' or 'related_to' [type=literal_error, input_value='used_by', input_type=str]
    For further information visit https://errors.pydantic.dev/2.10/v/literal_error
Traceback (most recent call last):

  File "C:\Users\mikeb\work\sifu2\run_agents.py", line 868, in <module>
    asyncio.run(main())

  File "C:\Python313\Lib\asyncio\runners.py", line 194, in run
    return runner.run(main)
  File "C:\Python313\Lib\asyncio\runners.py", line 118, in run
    return self._loop.run_until_complete(task)
  File "C:\Python313\Lib\asyncio\base_events.py", line 707, in run_until_complete
    self.run_forever()
  File "C:\Python313\Lib\asyncio\base_events.py", line 678, in run_forever
    self._run_once()
  File "C:\Python313\Lib\asyncio\base_events.py", line 2033, in _run_once
    handle._run()
  File "C:\Python313\Lib\asyncio\events.py", line 89, in _run
    self._context.run(self._callback, *self._args)

  File "C:\Users\mikeb\work\sifu2\run_agents.py", line 857, in main
    await agent.run()

  File "C:\Users\mikeb\work\sifu2\run_agents.py", line 691, in run
    result = await getattr(self, task.tool)(**task.args)

  File "C:\Users\mikeb\work\sifu2\run_agents.py", line 344, in _synthesize_knowledge
    knowledge = await self.knowledge_system.process_source(content)

  File "C:\Users\mikeb\work\sifu2\scripts\knowledge_acquisition.py", line 466, in process_source
    relationships = await self._extract_relationships(content)

> File "C:\Users\mikeb\work\sifu2\scripts\knowledge_acquisition.py", line 650, in _extract_relationships
    converted_relationships.append(Relationship(**rel))

  File "C:\Python313\Lib\site-packages\pydantic\main.py", line 214, in __init__
    validated_self = self.__pydantic_validator__.validate_python(data, self_instance=self)

pydantic_core._pydantic_core.ValidationError: 1 validation error for Relationship
relation
  Input should be 'is_a', 'has_part' or 'related_to' [type=literal_error, input_value='used_by', input_type=str]
    For further information visit https://errors.pydantic.dev/2.10/v/literal_error
2025-02-09 14:57:51.164 | 40372:34912 | ERROR    | scripts.knowledge_acquisition:_extract_relationships:652 | Failed to convert relationship: {'source': 'Model Evaluation', 'relation': 'uses', 'target': 'Test Data'}: 1 validation error for Relationship
relation
  Input should be 'is_a', 'has_part' or 'related_to' [type=literal_error, input_value='uses', input_type=str]
    For further information visit https://errors.pydantic.dev/2.10/v/literal_error
Traceback (most recent call last):

  File "C:\Users\mikeb\work\sifu2\run_agents.py", line 868, in <module>
    asyncio.run(main())

  File "C:\Python313\Lib\asyncio\runners.py", line 194, in run
    return runner.run(main)
  File "C:\Python313\Lib\asyncio\runners.py", line 118, in run
    return self._loop.run_until_complete(task)
  File "C:\Python313\Lib\asyncio\base_events.py", line 707, in run_until_complete
    self.run_forever()
  File "C:\Python313\Lib\asyncio\base_events.py", line 678, in run_forever
    self._run_once()
  File "C:\Python313\Lib\asyncio\base_events.py", line 2033, in _run_once
    handle._run()
  File "C:\Python313\Lib\asyncio\events.py", line 89, in _run
    self._context.run(self._callback, *self._args)

  File "C:\Users\mikeb\work\sifu2\run_agents.py", line 857, in main
    await agent.run()

  File "C:\Users\mikeb\work\sifu2\run_agents.py", line 691, in run
    result = await getattr(self, task.tool)(**task.args)

  File "C:\Users\mikeb\work\sifu2\run_agents.py", line 344, in _synthesize_knowledge
    knowledge = await self.knowledge_system.process_source(content)

  File "C:\Users\mikeb\work\sifu2\scripts\knowledge_acquisition.py", line 466, in process_source
    relationships = await self._extract_relationships(content)

> File "C:\Users\mikeb\work\sifu2\scripts\knowledge_acquisition.py", line 650, in _extract_relationships
    converted_relationships.append(Relationship(**rel))

  File "C:\Python313\Lib\site-packages\pydantic\main.py", line 214, in __init__
    validated_self = self.__pydantic_validator__.validate_python(data, self_instance=self)

pydantic_core._pydantic_core.ValidationError: 1 validation error for Relationship
relation
  Input should be 'is_a', 'has_part' or 'related_to' [type=literal_error, input_value='uses', input_type=str]
    For further information visit https://errors.pydantic.dev/2.10/v/literal_error
2025-02-09 14:57:51.188 | 40372:34912 | ERROR    | scripts.knowledge_acquisition:_extract_relationships:652 | Failed to convert relationship: {'source': 'Model Evaluation', 'relation': 'produces', 'target': 'Evaluation Metrics'}: 1 validation error for Relationship
relation
  Input should be 'is_a', 'has_part' or 'related_to' [type=literal_error, input_value='produces', input_type=str]
    For further information visit https://errors.pydantic.dev/2.10/v/literal_error
Traceback (most recent call last):

  File "C:\Users\mikeb\work\sifu2\run_agents.py", line 868, in <module>
    asyncio.run(main())

  File "C:\Python313\Lib\asyncio\runners.py", line 194, in run
    return runner.run(main)
  File "C:\Python313\Lib\asyncio\runners.py", line 118, in run
    return self._loop.run_until_complete(task)
  File "C:\Python313\Lib\asyncio\base_events.py", line 707, in run_until_complete
    self.run_forever()
  File "C:\Python313\Lib\asyncio\base_events.py", line 678, in run_forever
    self._run_once()
  File "C:\Python313\Lib\asyncio\base_events.py", line 2033, in _run_once
    handle._run()
  File "C:\Python313\Lib\asyncio\events.py", line 89, in _run
    self._context.run(self._callback, *self._args)

  File "C:\Users\mikeb\work\sifu2\run_agents.py", line 857, in main
    await agent.run()

  File "C:\Users\mikeb\work\sifu2\run_agents.py", line 691, in run
    result = await getattr(self, task.tool)(**task.args)

  File "C:\Users\mikeb\work\sifu2\run_agents.py", line 344, in _synthesize_knowledge
    knowledge = await self.knowledge_system.process_source(content)

  File "C:\Users\mikeb\work\sifu2\scripts\knowledge_acquisition.py", line 466, in process_source
    relationships = await self._extract_relationships(content)

> File "C:\Users\mikeb\work\sifu2\scripts\knowledge_acquisition.py", line 650, in _extract_relationships
    converted_relationships.append(Relationship(**rel))

  File "C:\Python313\Lib\site-packages\pydantic\main.py", line 214, in __init__
    validated_self = self.__pydantic_validator__.validate_python(data, self_instance=self)

pydantic_core._pydantic_core.ValidationError: 1 validation error for Relationship
relation
  Input should be 'is_a', 'has_part' or 'related_to' [type=literal_error, input_value='produces', input_type=str]
    For further information visit https://errors.pydantic.dev/2.10/v/literal_error
2025-02-09 14:57:51.212 | 40372:34912 | ERROR    | scripts.knowledge_acquisition:_extract_relationships:652 | Failed to convert relationship: {'source': 'CNNs', 'relation': 'applied_to', 'target': 'Image Recognition'}: 1 validation error for Relationship
relation
  Input should be 'is_a', 'has_part' or 'related_to' [type=literal_error, input_value='applied_to', input_type=str]
    For further information visit https://errors.pydantic.dev/2.10/v/literal_error
Traceback (most recent call last):

  File "C:\Users\mikeb\work\sifu2\run_agents.py", line 868, in <module>
    asyncio.run(main())

  File "C:\Python313\Lib\asyncio\runners.py", line 194, in run
    return runner.run(main)
  File "C:\Python313\Lib\asyncio\runners.py", line 118, in run
    return self._loop.run_until_complete(task)
  File "C:\Python313\Lib\asyncio\base_events.py", line 707, in run_until_complete
    self.run_forever()
  File "C:\Python313\Lib\asyncio\base_events.py", line 678, in run_forever
    self._run_once()
  File "C:\Python313\Lib\asyncio\base_events.py", line 2033, in _run_once
    handle._run()
  File "C:\Python313\Lib\asyncio\events.py", line 89, in _run
    self._context.run(self._callback, *self._args)

  File "C:\Users\mikeb\work\sifu2\run_agents.py", line 857, in main
    await agent.run()

  File "C:\Users\mikeb\work\sifu2\run_agents.py", line 691, in run
    result = await getattr(self, task.tool)(**task.args)

  File "C:\Users\mikeb\work\sifu2\run_agents.py", line 344, in _synthesize_knowledge
    knowledge = await self.knowledge_system.process_source(content)

  File "C:\Users\mikeb\work\sifu2\scripts\knowledge_acquisition.py", line 466, in process_source
    relationships = await self._extract_relationships(content)

> File "C:\Users\mikeb\work\sifu2\scripts\knowledge_acquisition.py", line 650, in _extract_relationships
    converted_relationships.append(Relationship(**rel))

  File "C:\Python313\Lib\site-packages\pydantic\main.py", line 214, in __init__
    validated_self = self.__pydantic_validator__.validate_python(data, self_instance=self)

pydantic_core._pydantic_core.ValidationError: 1 validation error for Relationship
relation
  Input should be 'is_a', 'has_part' or 'related_to' [type=literal_error, input_value='applied_to', input_type=str]
    For further information visit https://errors.pydantic.dev/2.10/v/literal_error
2025-02-09 14:57:51.236 | 40372:34912 | ERROR    | scripts.knowledge_acquisition:_extract_relationships:652 | Failed to convert relationship: {'source': 'RNNs', 'relation': 'applied_to', 'target': 'Natural Language Processing'}: 1 validation error for Relationship
relation
  Input should be 'is_a', 'has_part' or 'related_to' [type=literal_error, input_value='applied_to', input_type=str]
    For further information visit https://errors.pydantic.dev/2.10/v/literal_error
Traceback (most recent call last):

  File "C:\Users\mikeb\work\sifu2\run_agents.py", line 868, in <module>
    asyncio.run(main())

  File "C:\Python313\Lib\asyncio\runners.py", line 194, in run
    return runner.run(main)
  File "C:\Python313\Lib\asyncio\runners.py", line 118, in run
    return self._loop.run_until_complete(task)
  File "C:\Python313\Lib\asyncio\base_events.py", line 707, in run_until_complete
    self.run_forever()
  File "C:\Python313\Lib\asyncio\base_events.py", line 678, in run_forever
    self._run_once()
  File "C:\Python313\Lib\asyncio\base_events.py", line 2033, in _run_once
    handle._run()
  File "C:\Python313\Lib\asyncio\events.py", line 89, in _run
    self._context.run(self._callback, *self._args)

  File "C:\Users\mikeb\work\sifu2\run_agents.py", line 857, in main
    await agent.run()

  File "C:\Users\mikeb\work\sifu2\run_agents.py", line 691, in run
    result = await getattr(self, task.tool)(**task.args)

  File "C:\Users\mikeb\work\sifu2\run_agents.py", line 344, in _synthesize_knowledge
    knowledge = await self.knowledge_system.process_source(content)

  File "C:\Users\mikeb\work\sifu2\scripts\knowledge_acquisition.py", line 466, in process_source
    relationships = await self._extract_relationships(content)

> File "C:\Users\mikeb\work\sifu2\scripts\knowledge_acquisition.py", line 650, in _extract_relationships
    converted_relationships.append(Relationship(**rel))

  File "C:\Python313\Lib\site-packages\pydantic\main.py", line 214, in __init__
    validated_self = self.__pydantic_validator__.validate_python(data, self_instance=self)

pydantic_core._pydantic_core.ValidationError: 1 validation error for Relationship
relation
  Input should be 'is_a', 'has_part' or 'related_to' [type=literal_error, input_value='applied_to', input_type=str]
    For further information visit https://errors.pydantic.dev/2.10/v/literal_error
2025-02-09 14:57:51.260 | 40372:34912 | INFO     | scripts.knowledge_acquisition:process_source:478 | KnowledgeAcquisition: Extracted 3 relationships
2025-02-09 14:57:51.262 | 40372:34912 | INFO     | scripts.knowledge_acquisition:process_source:482 | KnowledgeAcquisition: Relationship: Convolutional Neural Networks (CNNs) -> is_a -> Neural Networks
2025-02-09 14:57:51.263 | 40372:34912 | INFO     | scripts.knowledge_acquisition:process_source:482 | KnowledgeAcquisition: Relationship: Recurrent Neural Networks (RNNs) -> is_a -> Neural Networks
2025-02-09 14:57:51.265 | 40372:34912 | INFO     | scripts.knowledge_acquisition:process_source:482 | KnowledgeAcquisition: Relationship: Neural Networks -> is_a -> Machine Learning Models
2025-02-09 14:57:51.267 | 40372:34912 | INFO     | scripts.knowledge_acquisition:process_source:488 | KnowledgeAcquisition: Generating metadata...
2025-02-09 14:57:52.295 | 40372:34912 | INFO     | scripts.knowledge_acquisition:process_source:495 | KnowledgeAcquisition: Generated metadata: {'source_type': 'text', 'confidence_score': 0.9, 'domain_relevance': 0.8, 'timestamp': '2024-02-09T12:45:00.000Z', 'validation_status': 'processed', 'domain': 'machine_learning'}
2025-02-09 14:57:52.297 | 40372:34912 | INFO     | scripts.knowledge_acquisition:process_source:501 | KnowledgeAcquisition: Evaluating confidence...
2025-02-09 14:57:53.630 | 40372:34912 | INFO     | scripts.knowledge_acquisition:process_source:511 | KnowledgeAcquisition: Confidence score: 0.8
2025-02-09 14:57:53.640 | 40372:34912 | INFO     | __main__:run:657 | Execution: Executing task 2: _generate_examples
2025-02-09 14:57:53.641 | 40372:34912 | INFO     | __main__:run:678 | Execution: Found 10 knowledge entries for example generation
2025-02-09 14:58:44.834 | 40372:34912 | INFO     | __main__:run:657 | Execution: Executing task 3: _train_model
2025-02-09 14:58:44.835 | 40372:34912 | INFO     | __main__:run:688 | Execution: Found 69 examples for training
2025-02-09 14:58:44.838 | 40372:34912 | INFO     | __main__:run:722 | Decision: Making join decision
2025-02-09 14:58:44.839 | 40372:34912 | INFO     | scripts.llm_compiler:make_join_decision:412 | Decision: Making join decision
2025-02-09 14:58:45.923 | 40372:34912 | INFO     | __main__:run:733 | Compiler: Generating final result
2025-02-09 14:58:45.924 | 40372:34912 | INFO     | scripts.llm_compiler:_generate_final_result:560 | Compiler: Generating final result
2025-02-09 14:58:45.925 | 40372:34912 | INFO     | scripts.llm_compiler:_generate_final_result:570 | Compiler: Generated final result
2025-02-09 14:58:45.926 | 40372:34912 | INFO     | __main__:run:737 | Research: Research workflow completed successfully
