2025-02-09 15:02:39.917 | 29884:30460 | INFO     | __main__:main:853 | Main: Initializing research agent
2025-02-09 15:02:39.934 | 29884:30460 | INFO     | scripts.llm_compiler:__init__:77 | Compiler: Initialized LLM compiler
2025-02-09 15:02:40.687 | 29884:30460 | INFO     | scripts.llm_compiler:__init__:77 | Compiler: Initialized LLM compiler
2025-02-09 15:02:41.337 | 29884:30460 | INFO     | scripts.knowledge_acquisition:__init__:278 | KnowledgeAcquisition: Knowledge acquisition system initialized
2025-02-09 15:02:41.339 | 29884:30460 | INFO     | scripts.knowledge_acquisition:__init__:278 | 
Local Variables:
  self = <scripts.knowledge_acquisition.KnowledgeAcquisitionSystem object at 0x000002BAC26B27B0>
  config = domains=[DomainConfig(name='medical', description='Medical domain knowledge including diseases, treatments, and healthcare concepts', classes=[OntologyClass(name='Disease', description='A medical cond...
  api_key = AIzaSyA_5-fcCihRyNZvfl6S5wm420SnuvijQT0
  llm = temperature=0.7 api_key=SecretStr('**********') pydantic_schema=<class 'prompts.knowledge_acquisition.entity_extraction.EntityResponse'>
  __class__ = <class 'scripts.knowledge_acquisition.KnowledgeAcquisitionSystem'>

2025-02-09 15:02:41.341 | 29884:30460 | INFO     | scripts.llm_compiler:__init__:77 | Compiler: Initialized LLM compiler
2025-02-09 15:02:41.343 | 29884:30460 | INFO     | scripts.llm_compiler:__init__:77 | Compiler: Initialized LLM compiler
2025-02-09 15:02:41.347 | 29884:30460 | INFO     | scripts.llm_compiler:register_tool:87 | Compiler: Registered tool: _research_topics
2025-02-09 15:02:41.348 | 29884:30460 | INFO     | scripts.llm_compiler:register_tool:87 | Compiler: Registered tool: _synthesize_knowledge
2025-02-09 15:02:41.350 | 29884:30460 | INFO     | scripts.llm_compiler:register_tool:87 | Compiler: Registered tool: _generate_examples
2025-02-09 15:02:41.351 | 29884:30460 | INFO     | scripts.llm_compiler:register_tool:87 | Compiler: Registered tool: _train_model
2025-02-09 15:02:41.352 | 29884:30460 | INFO     | __main__:__init__:206 | Research: Research agent initialized
2025-02-09 15:02:41.354 | 29884:30460 | INFO     | __main__:main:856 | Main: Starting research agent
2025-02-09 15:02:41.355 | 29884:30460 | INFO     | __main__:run:608 | Research: Starting research workflow for domain: test_domain
2025-02-09 15:02:41.356 | 29884:30460 | INFO     | __main__:run:643 | Execution: Starting execution of 4 tasks
2025-02-09 15:02:41.357 | 29884:30460 | INFO     | __main__:run:657 | Execution: Executing task 0: _research_topics
2025-02-09 15:02:41.358 | 29884:30460 | INFO     | __main__:_research_topics:229 | Research: Starting topic research for domain: test_domain
2025-02-09 15:02:41.360 | 29884:30460 | INFO     | scripts.knowledge_acquisition:initialize:287 | KnowledgeAcquisition: Starting system initialization
2025-02-09 15:02:41.809 | 29884:30460 | INFO     | scripts.knowledge_acquisition:initialize:296 | KnowledgeAcquisition: Embeddings initialized
2025-02-09 15:02:41.965 | 29884:30460 | INFO     | scripts.knowledge_acquisition:initialize:309 | KnowledgeAcquisition: Vector store initialized
2025-02-09 15:02:41.997 | 29884:30460 | INFO     | scripts.knowledge_acquisition:initialize:322 | KnowledgeAcquisition: Graph database initialized
2025-02-09 15:02:41.998 | 29884:30460 | INFO     | __main__:_research_topics:247 | Search: Searching for: test_domain overview
2025-02-09 15:02:50.508 | 29884:30460 | INFO     | __main__:_research_topics:247 | Search: Searching for: test_domain key concepts
2025-02-09 15:02:55.449 | 29884:30460 | INFO     | __main__:_research_topics:247 | Search: Searching for: test_domain latest developments
2025-02-09 15:03:01.255 | 29884:30460 | INFO     | __main__:_research_topics:247 | Search: Searching for: test_domain research papers
2025-02-09 15:03:09.673 | 29884:30460 | INFO     | __main__:run:657 | Execution: Executing task 1: _synthesize_knowledge
2025-02-09 15:03:09.674 | 29884:30460 | INFO     | __main__:run:668 | Execution: Found 10 sources for synthesis
2025-02-09 15:03:09.676 | 29884:30460 | INFO     | __main__:_synthesize_knowledge:325 | Knowledge Synthesis: Processing source: Free Website Authority Checker (Enter Any Domain or URL) (source_1.txt)
2025-02-09 15:03:09.678 | 29884:30460 | INFO     | __main__:_synthesize_knowledge:329 | Knowledge Synthesis: Content preview:
* ArticlesArticles + Popular + SEO Fundamentals + Content Marketing + Link Building + Marketing + What Is SEO?For people that are new to + SEO ChecklistCovers technical SEO, On-page SEO, and keyword re + [SEO Audit Checklist18-step guide to get higher Google rankings.Step-by-step guide to building a website in 2024.( * ToolsTools + Free Tools + Tool Guides + Tool Reviews + Keyword Re + Backlink CheckerDiscover who’s linking to you and your competitors.Step-by-step guide to building a website in ...
2025-02-09 15:03:09.680 | 29884:30460 | INFO     | scripts.knowledge_acquisition:process_source:444 | KnowledgeAcquisition: Starting source processing with content length: 12294
2025-02-09 15:03:09.681 | 29884:30460 | INFO     | scripts.knowledge_acquisition:process_source:448 | KnowledgeAcquisition: Content preview:
* ArticlesArticles + Popular + SEO Fundamentals + Content Marketing + Link Building + Marketing + What Is SEO?For people that are new to + SEO ChecklistCovers technical SEO, On-page SEO, and keyword r...
2025-02-09 15:03:09.682 | 29884:30460 | INFO     | scripts.knowledge_acquisition:process_source:451 | KnowledgeAcquisition: Extracting entities...
2025-02-09 15:03:10.363 | 29884:30460 | INFO     | scripts.knowledge_acquisition:process_source:458 | KnowledgeAcquisition: Extracted 10 entities: ['Machine Learning', 'Deep Learning', 'Neural Networks', 'TensorFlow', 'Python', 'Keras', 'Computer Vision', 'Natural Language Processing', 'Data Science', 'Artificial Intelligence']
2025-02-09 15:03:10.365 | 29884:30460 | INFO     | scripts.knowledge_acquisition:process_source:464 | KnowledgeAcquisition: Extracting relationships...
2025-02-09 15:03:12.639 | 29884:30460 | ERROR    | scripts.knowledge_acquisition:_extract_relationships:652 | Failed to convert relationship: {'source': 'CNNs', 'relation': 'used_in', 'target': 'Image Recognition'}: 1 validation error for Relationship
relation
  Input should be 'uses', 'applies', 'implements', 'improves', 'outperforms', 'achieves', 'contains', 'consists_of', 'part_of', 'better_than', 'similar_to', 'different_from', 'leads_to', 'causes', 'affects', 'precedes', 'follows', 'concurrent_with', 'is_a', 'has_part' or 'related_to' [type=literal_error, input_value='used_in', input_type=str]
    For further information visit https://errors.pydantic.dev/2.10/v/literal_error
Traceback (most recent call last):

  File "C:\Users\mikeb\work\sifu2\run_agents.py", line 868, in <module>
    asyncio.run(main())

  File "C:\Python313\Lib\asyncio\runners.py", line 194, in run
    return runner.run(main)
  File "C:\Python313\Lib\asyncio\runners.py", line 118, in run
    return self._loop.run_until_complete(task)
  File "C:\Python313\Lib\asyncio\base_events.py", line 707, in run_until_complete
    self.run_forever()
  File "C:\Python313\Lib\asyncio\base_events.py", line 678, in run_forever
    self._run_once()
  File "C:\Python313\Lib\asyncio\base_events.py", line 2033, in _run_once
    handle._run()
  File "C:\Python313\Lib\asyncio\events.py", line 89, in _run
    self._context.run(self._callback, *self._args)

  File "C:\Users\mikeb\work\sifu2\run_agents.py", line 857, in main
    await agent.run()

  File "C:\Users\mikeb\work\sifu2\run_agents.py", line 691, in run
    result = await getattr(self, task.tool)(**task.args)

  File "C:\Users\mikeb\work\sifu2\run_agents.py", line 344, in _synthesize_knowledge
    knowledge = await self.knowledge_system.process_source(content)

  File "C:\Users\mikeb\work\sifu2\scripts\knowledge_acquisition.py", line 466, in process_source
    relationships = await self._extract_relationships(content)

> File "C:\Users\mikeb\work\sifu2\scripts\knowledge_acquisition.py", line 650, in _extract_relationships
    converted_relationships.append(Relationship(**rel))

  File "C:\Python313\Lib\site-packages\pydantic\main.py", line 214, in __init__
    validated_self = self.__pydantic_validator__.validate_python(data, self_instance=self)

pydantic_core._pydantic_core.ValidationError: 1 validation error for Relationship
relation
  Input should be 'uses', 'applies', 'implements', 'improves', 'outperforms', 'achieves', 'contains', 'consists_of', 'part_of', 'better_than', 'similar_to', 'different_from', 'leads_to', 'causes', 'affects', 'precedes', 'follows', 'concurrent_with', 'is_a', 'has_part' or 'related_to' [type=literal_error, input_value='used_in', input_type=str]
    For further information visit https://errors.pydantic.dev/2.10/v/literal_error
2025-02-09 15:03:12.680 | 29884:30460 | ERROR    | scripts.knowledge_acquisition:_extract_relationships:652 | Failed to convert relationship: {'source': 'RNNs', 'relation': 'used_in', 'target': 'Natural Language Processing'}: 1 validation error for Relationship
relation
  Input should be 'uses', 'applies', 'implements', 'improves', 'outperforms', 'achieves', 'contains', 'consists_of', 'part_of', 'better_than', 'similar_to', 'different_from', 'leads_to', 'causes', 'affects', 'precedes', 'follows', 'concurrent_with', 'is_a', 'has_part' or 'related_to' [type=literal_error, input_value='used_in', input_type=str]
    For further information visit https://errors.pydantic.dev/2.10/v/literal_error
Traceback (most recent call last):

  File "C:\Users\mikeb\work\sifu2\run_agents.py", line 868, in <module>
    asyncio.run(main())

  File "C:\Python313\Lib\asyncio\runners.py", line 194, in run
    return runner.run(main)
  File "C:\Python313\Lib\asyncio\runners.py", line 118, in run
    return self._loop.run_until_complete(task)
  File "C:\Python313\Lib\asyncio\base_events.py", line 707, in run_until_complete
    self.run_forever()
  File "C:\Python313\Lib\asyncio\base_events.py", line 678, in run_forever
    self._run_once()
  File "C:\Python313\Lib\asyncio\base_events.py", line 2033, in _run_once
    handle._run()
  File "C:\Python313\Lib\asyncio\events.py", line 89, in _run
    self._context.run(self._callback, *self._args)

  File "C:\Users\mikeb\work\sifu2\run_agents.py", line 857, in main
    await agent.run()

  File "C:\Users\mikeb\work\sifu2\run_agents.py", line 691, in run
    result = await getattr(self, task.tool)(**task.args)

  File "C:\Users\mikeb\work\sifu2\run_agents.py", line 344, in _synthesize_knowledge
    knowledge = await self.knowledge_system.process_source(content)

  File "C:\Users\mikeb\work\sifu2\scripts\knowledge_acquisition.py", line 466, in process_source
    relationships = await self._extract_relationships(content)

> File "C:\Users\mikeb\work\sifu2\scripts\knowledge_acquisition.py", line 650, in _extract_relationships
    converted_relationships.append(Relationship(**rel))

  File "C:\Python313\Lib\site-packages\pydantic\main.py", line 214, in __init__
    validated_self = self.__pydantic_validator__.validate_python(data, self_instance=self)

pydantic_core._pydantic_core.ValidationError: 1 validation error for Relationship
relation
  Input should be 'uses', 'applies', 'implements', 'improves', 'outperforms', 'achieves', 'contains', 'consists_of', 'part_of', 'better_than', 'similar_to', 'different_from', 'leads_to', 'causes', 'affects', 'precedes', 'follows', 'concurrent_with', 'is_a', 'has_part' or 'related_to' [type=literal_error, input_value='used_in', input_type=str]
    For further information visit https://errors.pydantic.dev/2.10/v/literal_error
2025-02-09 15:03:12.703 | 29884:30460 | ERROR    | scripts.knowledge_acquisition:_extract_relationships:652 | Failed to convert relationship: {'source': 'Backpropagation', 'relation': 'used_in', 'target': 'Training Neural Networks'}: 1 validation error for Relationship
relation
  Input should be 'uses', 'applies', 'implements', 'improves', 'outperforms', 'achieves', 'contains', 'consists_of', 'part_of', 'better_than', 'similar_to', 'different_from', 'leads_to', 'causes', 'affects', 'precedes', 'follows', 'concurrent_with', 'is_a', 'has_part' or 'related_to' [type=literal_error, input_value='used_in', input_type=str]
    For further information visit https://errors.pydantic.dev/2.10/v/literal_error
Traceback (most recent call last):

  File "C:\Users\mikeb\work\sifu2\run_agents.py", line 868, in <module>
    asyncio.run(main())

  File "C:\Python313\Lib\asyncio\runners.py", line 194, in run
    return runner.run(main)
  File "C:\Python313\Lib\asyncio\runners.py", line 118, in run
    return self._loop.run_until_complete(task)
  File "C:\Python313\Lib\asyncio\base_events.py", line 707, in run_until_complete
    self.run_forever()
  File "C:\Python313\Lib\asyncio\base_events.py", line 678, in run_forever
    self._run_once()
  File "C:\Python313\Lib\asyncio\base_events.py", line 2033, in _run_once
    handle._run()
  File "C:\Python313\Lib\asyncio\events.py", line 89, in _run
    self._context.run(self._callback, *self._args)

  File "C:\Users\mikeb\work\sifu2\run_agents.py", line 857, in main
    await agent.run()

  File "C:\Users\mikeb\work\sifu2\run_agents.py", line 691, in run
    result = await getattr(self, task.tool)(**task.args)

  File "C:\Users\mikeb\work\sifu2\run_agents.py", line 344, in _synthesize_knowledge
    knowledge = await self.knowledge_system.process_source(content)

  File "C:\Users\mikeb\work\sifu2\scripts\knowledge_acquisition.py", line 466, in process_source
    relationships = await self._extract_relationships(content)

> File "C:\Users\mikeb\work\sifu2\scripts\knowledge_acquisition.py", line 650, in _extract_relationships
    converted_relationships.append(Relationship(**rel))

  File "C:\Python313\Lib\site-packages\pydantic\main.py", line 214, in __init__
    validated_self = self.__pydantic_validator__.validate_python(data, self_instance=self)

pydantic_core._pydantic_core.ValidationError: 1 validation error for Relationship
relation
  Input should be 'uses', 'applies', 'implements', 'improves', 'outperforms', 'achieves', 'contains', 'consists_of', 'part_of', 'better_than', 'similar_to', 'different_from', 'leads_to', 'causes', 'affects', 'precedes', 'follows', 'concurrent_with', 'is_a', 'has_part' or 'related_to' [type=literal_error, input_value='used_in', input_type=str]
    For further information visit https://errors.pydantic.dev/2.10/v/literal_error
2025-02-09 15:03:12.724 | 29884:30460 | ERROR    | scripts.knowledge_acquisition:_extract_relationships:652 | Failed to convert relationship: {'source': 'Deep Learning', 'relation': 'subset_of', 'target': 'Machine Learning'}: 1 validation error for Relationship
relation
  Input should be 'uses', 'applies', 'implements', 'improves', 'outperforms', 'achieves', 'contains', 'consists_of', 'part_of', 'better_than', 'similar_to', 'different_from', 'leads_to', 'causes', 'affects', 'precedes', 'follows', 'concurrent_with', 'is_a', 'has_part' or 'related_to' [type=literal_error, input_value='subset_of', input_type=str]
    For further information visit https://errors.pydantic.dev/2.10/v/literal_error
Traceback (most recent call last):

  File "C:\Users\mikeb\work\sifu2\run_agents.py", line 868, in <module>
    asyncio.run(main())

  File "C:\Python313\Lib\asyncio\runners.py", line 194, in run
    return runner.run(main)
  File "C:\Python313\Lib\asyncio\runners.py", line 118, in run
    return self._loop.run_until_complete(task)
  File "C:\Python313\Lib\asyncio\base_events.py", line 707, in run_until_complete
    self.run_forever()
  File "C:\Python313\Lib\asyncio\base_events.py", line 678, in run_forever
    self._run_once()
  File "C:\Python313\Lib\asyncio\base_events.py", line 2033, in _run_once
    handle._run()
  File "C:\Python313\Lib\asyncio\events.py", line 89, in _run
    self._context.run(self._callback, *self._args)

  File "C:\Users\mikeb\work\sifu2\run_agents.py", line 857, in main
    await agent.run()

  File "C:\Users\mikeb\work\sifu2\run_agents.py", line 691, in run
    result = await getattr(self, task.tool)(**task.args)

  File "C:\Users\mikeb\work\sifu2\run_agents.py", line 344, in _synthesize_knowledge
    knowledge = await self.knowledge_system.process_source(content)

  File "C:\Users\mikeb\work\sifu2\scripts\knowledge_acquisition.py", line 466, in process_source
    relationships = await self._extract_relationships(content)

> File "C:\Users\mikeb\work\sifu2\scripts\knowledge_acquisition.py", line 650, in _extract_relationships
    converted_relationships.append(Relationship(**rel))

  File "C:\Python313\Lib\site-packages\pydantic\main.py", line 214, in __init__
    validated_self = self.__pydantic_validator__.validate_python(data, self_instance=self)

pydantic_core._pydantic_core.ValidationError: 1 validation error for Relationship
relation
  Input should be 'uses', 'applies', 'implements', 'improves', 'outperforms', 'achieves', 'contains', 'consists_of', 'part_of', 'better_than', 'similar_to', 'different_from', 'leads_to', 'causes', 'affects', 'precedes', 'follows', 'concurrent_with', 'is_a', 'has_part' or 'related_to' [type=literal_error, input_value='subset_of', input_type=str]
    For further information visit https://errors.pydantic.dev/2.10/v/literal_error
2025-02-09 15:03:12.745 | 29884:30460 | INFO     | scripts.knowledge_acquisition:process_source:478 | KnowledgeAcquisition: Extracted 3 relationships
2025-02-09 15:03:12.747 | 29884:30460 | INFO     | scripts.knowledge_acquisition:process_source:482 | KnowledgeAcquisition: Relationship: Convolutional Neural Networks (CNNs) -> is_a -> Neural Networks
2025-02-09 15:03:12.748 | 29884:30460 | INFO     | scripts.knowledge_acquisition:process_source:482 | KnowledgeAcquisition: Relationship: Recurrent Neural Networks (RNNs) -> is_a -> Neural Networks
2025-02-09 15:03:12.750 | 29884:30460 | INFO     | scripts.knowledge_acquisition:process_source:482 | KnowledgeAcquisition: Relationship: Neural Networks -> part_of -> Deep Learning
2025-02-09 15:03:12.751 | 29884:30460 | INFO     | scripts.knowledge_acquisition:process_source:488 | KnowledgeAcquisition: Generating metadata...
2025-02-09 15:03:13.804 | 29884:30460 | INFO     | scripts.knowledge_acquisition:process_source:495 | KnowledgeAcquisition: Generated metadata: {'source_type': 'text', 'confidence_score': 0.9, 'domain_relevance': 0.85, 'timestamp': '2024-02-09T12:45:00.000Z', 'validation_status': 'processed', 'domain': 'machine_learning'}
2025-02-09 15:03:13.806 | 29884:30460 | INFO     | scripts.knowledge_acquisition:process_source:501 | KnowledgeAcquisition: Evaluating confidence...
2025-02-09 15:03:15.149 | 29884:30460 | INFO     | scripts.knowledge_acquisition:process_source:511 | KnowledgeAcquisition: Confidence score: 0.8
2025-02-09 15:03:15.159 | 29884:30460 | INFO     | __main__:_synthesize_knowledge:325 | Knowledge Synthesis: Processing source: Website Authority Checker | Check Authority Score of Any ... (source_11.txt)
2025-02-09 15:03:15.160 | 29884:30460 | INFO     | __main__:_synthesize_knowledge:329 | Knowledge Synthesis: Content preview:
Skip to content * Features * Svenska * Tiếng Việt * Türkçe * 中文 * 日本語 * 한국어 Log In is a measurement used to evaluate a domain’s overall quality and SEO performance. For example, Semrush’s Authority Score is a compound metric that’s calculated based on the website’s referring domains, backlinks, organic traffic, and other factors. This value is expressed on a scale from 0 to 100. The higher the number, the stronger and more authoritative the website is. And the likelier it is to rank well in Goog...
2025-02-09 15:03:15.162 | 29884:30460 | INFO     | scripts.knowledge_acquisition:process_source:444 | KnowledgeAcquisition: Starting source processing with content length: 1691
2025-02-09 15:03:15.163 | 29884:30460 | INFO     | scripts.knowledge_acquisition:process_source:448 | KnowledgeAcquisition: Content preview:
Skip to content * Features * Svenska * Tiếng Việt * Türkçe * 中文 * 日本語 * 한국어 Log In is a measurement used to evaluate a domain’s overall quality and SEO performance. For example, Semrush’s Authority Sc...
2025-02-09 15:03:15.165 | 29884:30460 | INFO     | scripts.knowledge_acquisition:process_source:451 | KnowledgeAcquisition: Extracting entities...
2025-02-09 15:03:16.055 | 29884:30460 | INFO     | scripts.knowledge_acquisition:process_source:458 | KnowledgeAcquisition: Extracted 10 entities: ['Machine Learning', 'Deep Learning', 'Neural Networks', 'TensorFlow', 'Python', 'Data Science', 'Artificial Intelligence', 'Big Data', 'Cloud Computing', 'Natural Language Processing']
2025-02-09 15:03:16.057 | 29884:30460 | INFO     | scripts.knowledge_acquisition:process_source:464 | KnowledgeAcquisition: Extracting relationships...
2025-02-09 15:03:16.463 | 29884:30460 | INFO     | scripts.knowledge_acquisition:process_source:478 | KnowledgeAcquisition: Extracted 1 relationships
2025-02-09 15:03:16.464 | 29884:30460 | INFO     | scripts.knowledge_acquisition:process_source:482 | KnowledgeAcquisition: Relationship: Machine Learning -> related_to -> Deep Learning
2025-02-09 15:03:16.466 | 29884:30460 | INFO     | scripts.knowledge_acquisition:process_source:488 | KnowledgeAcquisition: Generating metadata...
2025-02-09 15:03:17.515 | 29884:30460 | INFO     | scripts.knowledge_acquisition:process_source:495 | KnowledgeAcquisition: Generated metadata: {'source_type': 'text', 'confidence_score': 0.9, 'domain_relevance': 0.8, 'timestamp': '2024-02-09T12:45:00.000Z', 'validation_status': 'processed', 'domain': 'machine_learning'}
2025-02-09 15:03:17.516 | 29884:30460 | INFO     | scripts.knowledge_acquisition:process_source:501 | KnowledgeAcquisition: Evaluating confidence...
2025-02-09 15:03:18.931 | 29884:30460 | INFO     | scripts.knowledge_acquisition:process_source:511 | KnowledgeAcquisition: Confidence score: 0.8
2025-02-09 15:03:18.939 | 29884:30460 | INFO     | __main__:_synthesize_knowledge:325 | Knowledge Synthesis: Processing source: Domains Overview : Support - Solutions (source_13.txt)
2025-02-09 15:03:18.941 | 29884:30460 | INFO     | __main__:_synthesize_knowledge:329 | Knowledge Synthesis: Content preview:
![Logo Solution home. At least one Domain must be set up within a Test Data Project to generate test data. Some examples of Domains for Projects are shown below: !( ## **In This Article** * Training Video * When Should Domains Be Used? * How Do Domains Work? * Can a Domain Reference Another Domain's Attributes? * Can the Domain loopCount Value be passed at Runtime? * How to View and Manage Domains * How do I create Domains? * Domains Example - Modeling a Database * Learn More About Domains ## **...
2025-02-09 15:03:18.942 | 29884:30460 | INFO     | scripts.knowledge_acquisition:process_source:444 | KnowledgeAcquisition: Starting source processing with content length: 3582
2025-02-09 15:03:18.943 | 29884:30460 | INFO     | scripts.knowledge_acquisition:process_source:448 | KnowledgeAcquisition: Content preview:
![Logo Solution home. At least one Domain must be set up within a Test Data Project to generate test data. Some examples of Domains for Projects are shown below: !( ## **In This Article** * Training V...
2025-02-09 15:03:18.945 | 29884:30460 | INFO     | scripts.knowledge_acquisition:process_source:451 | KnowledgeAcquisition: Extracting entities...
2025-02-09 15:03:19.805 | 29884:30460 | INFO     | scripts.knowledge_acquisition:process_source:458 | KnowledgeAcquisition: Extracted 10 entities: ['Machine Learning', 'Deep Learning', 'Neural Networks', 'TensorFlow', 'Python', 'Keras', 'Computer Vision', 'Natural Language Processing', 'Data Science', 'Artificial Intelligence']
2025-02-09 15:03:19.807 | 29884:30460 | INFO     | scripts.knowledge_acquisition:process_source:464 | KnowledgeAcquisition: Extracting relationships...
2025-02-09 15:03:22.981 | 29884:30460 | ERROR    | scripts.knowledge_acquisition:_extract_relationships:652 | Failed to convert relationship: {'source': 'Gradient Descent', 'relation': 'optimizes', 'target': 'Model Parameters'}: 1 validation error for Relationship
relation
  Input should be 'uses', 'applies', 'implements', 'improves', 'outperforms', 'achieves', 'contains', 'consists_of', 'part_of', 'better_than', 'similar_to', 'different_from', 'leads_to', 'causes', 'affects', 'precedes', 'follows', 'concurrent_with', 'is_a', 'has_part' or 'related_to' [type=literal_error, input_value='optimizes', input_type=str]
    For further information visit https://errors.pydantic.dev/2.10/v/literal_error
Traceback (most recent call last):

  File "C:\Users\mikeb\work\sifu2\run_agents.py", line 868, in <module>
    asyncio.run(main())

  File "C:\Python313\Lib\asyncio\runners.py", line 194, in run
    return runner.run(main)
  File "C:\Python313\Lib\asyncio\runners.py", line 118, in run
    return self._loop.run_until_complete(task)
  File "C:\Python313\Lib\asyncio\base_events.py", line 707, in run_until_complete
    self.run_forever()
  File "C:\Python313\Lib\asyncio\base_events.py", line 678, in run_forever
    self._run_once()
  File "C:\Python313\Lib\asyncio\base_events.py", line 2033, in _run_once
    handle._run()
  File "C:\Python313\Lib\asyncio\events.py", line 89, in _run
    self._context.run(self._callback, *self._args)

  File "C:\Users\mikeb\work\sifu2\run_agents.py", line 857, in main
    await agent.run()

  File "C:\Users\mikeb\work\sifu2\run_agents.py", line 691, in run
    result = await getattr(self, task.tool)(**task.args)

  File "C:\Users\mikeb\work\sifu2\run_agents.py", line 344, in _synthesize_knowledge
    knowledge = await self.knowledge_system.process_source(content)

  File "C:\Users\mikeb\work\sifu2\scripts\knowledge_acquisition.py", line 466, in process_source
    relationships = await self._extract_relationships(content)

> File "C:\Users\mikeb\work\sifu2\scripts\knowledge_acquisition.py", line 650, in _extract_relationships
    converted_relationships.append(Relationship(**rel))

  File "C:\Python313\Lib\site-packages\pydantic\main.py", line 214, in __init__
    validated_self = self.__pydantic_validator__.validate_python(data, self_instance=self)

pydantic_core._pydantic_core.ValidationError: 1 validation error for Relationship
relation
  Input should be 'uses', 'applies', 'implements', 'improves', 'outperforms', 'achieves', 'contains', 'consists_of', 'part_of', 'better_than', 'similar_to', 'different_from', 'leads_to', 'causes', 'affects', 'precedes', 'follows', 'concurrent_with', 'is_a', 'has_part' or 'related_to' [type=literal_error, input_value='optimizes', input_type=str]
    For further information visit https://errors.pydantic.dev/2.10/v/literal_error
2025-02-09 15:03:23.002 | 29884:30460 | INFO     | scripts.knowledge_acquisition:process_source:478 | KnowledgeAcquisition: Extracted 9 relationships
2025-02-09 15:03:23.003 | 29884:30460 | INFO     | scripts.knowledge_acquisition:process_source:482 | KnowledgeAcquisition: Relationship: Convolutional Neural Networks (CNNs) -> is_a -> Deep Learning Model
2025-02-09 15:03:23.004 | 29884:30460 | INFO     | scripts.knowledge_acquisition:process_source:482 | KnowledgeAcquisition: Relationship: Recurrent Neural Networks (RNNs) -> is_a -> Deep Learning Model
2025-02-09 15:03:23.006 | 29884:30460 | INFO     | scripts.knowledge_acquisition:process_source:482 | KnowledgeAcquisition: Relationship: Deep Learning Models -> is_a -> Machine Learning Models
2025-02-09 15:03:23.007 | 29884:30460 | INFO     | scripts.knowledge_acquisition:process_source:482 | KnowledgeAcquisition: Relationship: Data Augmentation -> improves -> Model Accuracy
2025-02-09 15:03:23.008 | 29884:30460 | INFO     | scripts.knowledge_acquisition:process_source:482 | KnowledgeAcquisition: Relationship: Regularization Techniques -> improves -> Model Generalization
2025-02-09 15:03:23.010 | 29884:30460 | INFO     | scripts.knowledge_acquisition:process_source:482 | KnowledgeAcquisition: Relationship: Transfer Learning -> improves -> Model Training Efficiency
2025-02-09 15:03:23.011 | 29884:30460 | INFO     | scripts.knowledge_acquisition:process_source:482 | KnowledgeAcquisition: Relationship: Backpropagation -> uses -> Gradient Descent
2025-02-09 15:03:23.012 | 29884:30460 | INFO     | scripts.knowledge_acquisition:process_source:482 | KnowledgeAcquisition: Relationship: Large Datasets -> improves -> Model Performance
2025-02-09 15:03:23.014 | 29884:30460 | INFO     | scripts.knowledge_acquisition:process_source:482 | KnowledgeAcquisition: Relationship: Hyperparameter Tuning -> improves -> Model Performance
2025-02-09 15:03:23.015 | 29884:30460 | INFO     | scripts.knowledge_acquisition:process_source:488 | KnowledgeAcquisition: Generating metadata...
2025-02-09 15:03:24.138 | 29884:30460 | INFO     | scripts.knowledge_acquisition:process_source:495 | KnowledgeAcquisition: Generated metadata: {'source_type': 'text', 'confidence_score': 0.85, 'domain_relevance': 0.9, 'timestamp': '2024-02-09T11:42:32.000Z', 'validation_status': 'processed', 'domain': 'machine_learning'}
2025-02-09 15:03:24.140 | 29884:30460 | INFO     | scripts.knowledge_acquisition:process_source:501 | KnowledgeAcquisition: Evaluating confidence...
2025-02-09 15:03:25.891 | 29884:30460 | INFO     | scripts.knowledge_acquisition:process_source:511 | KnowledgeAcquisition: Confidence score: 0.8
2025-02-09 15:03:25.900 | 29884:30460 | INFO     | __main__:_synthesize_knowledge:325 | Knowledge Synthesis: Processing source: Domain Testing - Introduction, Testing Strategy & conclusion (source_15.txt)
2025-02-09 15:03:25.902 | 29884:30460 | INFO     | __main__:_synthesize_knowledge:329 | Knowledge Synthesis: Content preview:
![QACraft for ease of testing. In other words, Domain testing is a **software testing TAGS : domain testing ## 24 Nov ![Automated Front-End Testing ## 31 Jul ![write script in katalon ## Recent Posts * Regression testing comes under which type of testing?( * Why is Regression Testing In Agile?( * Difference Between Selenium and Automation Testing( * Is Integration Testing White box Testing?( * How Many Types of Integration Testing Are There?( ## Categories * Agile Testing( * Agile Testing( * And...
2025-02-09 15:03:25.903 | 29884:30460 | INFO     | scripts.knowledge_acquisition:process_source:444 | KnowledgeAcquisition: Starting source processing with content length: 2375
2025-02-09 15:03:25.905 | 29884:30460 | INFO     | scripts.knowledge_acquisition:process_source:448 | KnowledgeAcquisition: Content preview:
![QACraft for ease of testing. In other words, Domain testing is a **software testing TAGS : domain testing ## 24 Nov ![Automated Front-End Testing ## 31 Jul ![write script in katalon ## Recent Posts ...
2025-02-09 15:03:25.907 | 29884:30460 | INFO     | scripts.knowledge_acquisition:process_source:451 | KnowledgeAcquisition: Extracting entities...
2025-02-09 15:03:26.763 | 29884:30460 | INFO     | scripts.knowledge_acquisition:process_source:458 | KnowledgeAcquisition: Extracted 10 entities: ['Machine Learning', 'Deep Learning', 'Neural Networks', 'TensorFlow', 'Python', 'Keras', 'Computer Vision', 'Natural Language Processing', 'Data Science', 'Artificial Intelligence']
2025-02-09 15:03:26.765 | 29884:30460 | INFO     | scripts.knowledge_acquisition:process_source:464 | KnowledgeAcquisition: Extracting relationships...
2025-02-09 15:03:27.121 | 29884:30460 | INFO     | scripts.knowledge_acquisition:process_source:478 | KnowledgeAcquisition: Extracted 1 relationships
2025-02-09 15:03:27.123 | 29884:30460 | INFO     | scripts.knowledge_acquisition:process_source:482 | KnowledgeAcquisition: Relationship: Machine Learning -> related_to -> Deep Learning
2025-02-09 15:03:27.124 | 29884:30460 | INFO     | scripts.knowledge_acquisition:process_source:488 | KnowledgeAcquisition: Generating metadata...
2025-02-09 15:03:28.183 | 29884:30460 | INFO     | scripts.knowledge_acquisition:process_source:495 | KnowledgeAcquisition: Generated metadata: {'source_type': 'text', 'confidence_score': 0.9, 'domain_relevance': 0.8, 'timestamp': '2024-02-09T12:42:32.000Z', 'validation_status': 'processed', 'domain': 'machine_learning'}
2025-02-09 15:03:28.185 | 29884:30460 | INFO     | scripts.knowledge_acquisition:process_source:501 | KnowledgeAcquisition: Evaluating confidence...
2025-02-09 15:03:29.697 | 29884:30460 | INFO     | scripts.knowledge_acquisition:process_source:511 | KnowledgeAcquisition: Confidence score: 0.8
2025-02-09 15:03:29.705 | 29884:30460 | INFO     | __main__:_synthesize_knowledge:325 | Knowledge Synthesis: Processing source: CHECK DOMAIN OVERVIEW - SmallSEOTools.com (source_17.txt)
2025-02-09 15:03:29.706 | 29884:30460 | INFO     | __main__:_synthesize_knowledge:329 | Knowledge Synthesis: Content preview:
![Image of website logo( Login( * ![PRO Pricing( * Plagiarism Checker( * Free Grammar Checker( * Reverse Image * [Paraphrasing Tool( * Login( × !image of languages( EN English - EN( русский - RU( 日本語 - JA( Italiano - IT( Français - FR( Português - PT( Español - ES( Deutsche - DE( 中文 - ZH( !Report Bug( # CHECK DOMAIN OVERVIEW Use website checker to get a domain overview and have a better insight into the online presence of a website. Just enter the domain or URL below and click the big blue "Chec...
2025-02-09 15:03:29.708 | 29884:30460 | INFO     | scripts.knowledge_acquisition:process_source:444 | KnowledgeAcquisition: Starting source processing with content length: 7208
2025-02-09 15:03:29.710 | 29884:30460 | INFO     | scripts.knowledge_acquisition:process_source:448 | KnowledgeAcquisition: Content preview:
![Image of website logo( Login( * ![PRO Pricing( * Plagiarism Checker( * Free Grammar Checker( * Reverse Image * [Paraphrasing Tool( * Login( × !image of languages( EN English - EN( русский - RU( 日本語 ...
2025-02-09 15:03:29.711 | 29884:30460 | INFO     | scripts.knowledge_acquisition:process_source:451 | KnowledgeAcquisition: Extracting entities...
2025-02-09 15:03:30.670 | 29884:30460 | INFO     | scripts.knowledge_acquisition:process_source:458 | KnowledgeAcquisition: Extracted 10 entities: ['Machine Learning', 'Neural Networks', 'TensorFlow', 'Deep Learning', 'Python', 'Data Science', 'Artificial Intelligence', 'Big Data', 'Cloud Computing', 'Natural Language Processing']
2025-02-09 15:03:30.671 | 29884:30460 | INFO     | scripts.knowledge_acquisition:process_source:464 | KnowledgeAcquisition: Extracting relationships...
2025-02-09 15:03:31.050 | 29884:30460 | INFO     | scripts.knowledge_acquisition:process_source:478 | KnowledgeAcquisition: Extracted 1 relationships
2025-02-09 15:03:31.052 | 29884:30460 | INFO     | scripts.knowledge_acquisition:process_source:482 | KnowledgeAcquisition: Relationship: Machine Learning -> related_to -> Neural Networks
2025-02-09 15:03:31.054 | 29884:30460 | INFO     | scripts.knowledge_acquisition:process_source:488 | KnowledgeAcquisition: Generating metadata...
2025-02-09 15:03:32.200 | 29884:30460 | INFO     | scripts.knowledge_acquisition:process_source:495 | KnowledgeAcquisition: Generated metadata: {'source_type': 'text', 'confidence_score': 0.85, 'domain_relevance': 0.9, 'timestamp': '2024-02-09T11:42:32.000Z', 'validation_status': 'processed', 'domain': 'machine_learning'}
2025-02-09 15:03:32.202 | 29884:30460 | INFO     | scripts.knowledge_acquisition:process_source:501 | KnowledgeAcquisition: Evaluating confidence...
2025-02-09 15:03:33.571 | 29884:30460 | INFO     | scripts.knowledge_acquisition:process_source:511 | KnowledgeAcquisition: Confidence score: 0.8
2025-02-09 15:03:33.580 | 29884:30460 | INFO     | __main__:_synthesize_knowledge:325 | Knowledge Synthesis: Processing source: NIH News in Health | A monthly newsletter from the National ... (source_19.txt)
2025-02-09 15:03:33.582 | 29884:30460 | INFO     | __main__:_synthesize_knowledge:329 | Knowledge Synthesis: Content preview:
Skip to main content ![NIH News in Health A monthly newsletter from the National Institutes of Health, part of the U.S. Department of Health and Human Services ## ## Site * Home ### Beyond Basic Blood Tests The Power of Pets Rough Up Your Diet Caring for Concussions Do Social Ties Affect Our Health?( NIH Office of Communications and Public Liaison Building 31, Room 5B52 Bethesda, MD 20892-2094 nihnewsinhealth@od.nih.gov Tel: 301-451-8224 **Editor:** Harrison Wein, Ph.D. **Managing Editor:** Tian...
2025-02-09 15:03:33.584 | 29884:30460 | INFO     | scripts.knowledge_acquisition:process_source:444 | KnowledgeAcquisition: Starting source processing with content length: 1195
2025-02-09 15:03:33.585 | 29884:30460 | INFO     | scripts.knowledge_acquisition:process_source:448 | KnowledgeAcquisition: Content preview:
Skip to main content ![NIH News in Health A monthly newsletter from the National Institutes of Health, part of the U.S. Department of Health and Human Services ## ## Site * Home ### Beyond Basic Blood...
2025-02-09 15:03:33.586 | 29884:30460 | INFO     | scripts.knowledge_acquisition:process_source:451 | KnowledgeAcquisition: Extracting entities...
2025-02-09 15:03:34.491 | 29884:30460 | INFO     | scripts.knowledge_acquisition:process_source:458 | KnowledgeAcquisition: Extracted 10 entities: ['Machine Learning', 'Deep Learning', 'Neural Networks', 'TensorFlow', 'Python', 'Keras', 'Computer Vision', 'Natural Language Processing', 'Data Science', 'Artificial Intelligence']
2025-02-09 15:03:34.493 | 29884:30460 | INFO     | scripts.knowledge_acquisition:process_source:464 | KnowledgeAcquisition: Extracting relationships...
2025-02-09 15:03:34.925 | 29884:30460 | INFO     | scripts.knowledge_acquisition:process_source:478 | KnowledgeAcquisition: Extracted 1 relationships
2025-02-09 15:03:34.926 | 29884:30460 | INFO     | scripts.knowledge_acquisition:process_source:482 | KnowledgeAcquisition: Relationship: Machine Learning -> related_to -> Deep Learning
2025-02-09 15:03:34.927 | 29884:30460 | INFO     | scripts.knowledge_acquisition:process_source:488 | KnowledgeAcquisition: Generating metadata...
2025-02-09 15:03:36.039 | 29884:30460 | INFO     | scripts.knowledge_acquisition:process_source:495 | KnowledgeAcquisition: Generated metadata: {'source_type': 'text', 'confidence_score': 0.9, 'domain_relevance': 0.8, 'timestamp': '2024-02-09T12:00:00.000Z', 'validation_status': 'processed', 'domain': 'machine_learning'}
2025-02-09 15:03:36.041 | 29884:30460 | INFO     | scripts.knowledge_acquisition:process_source:501 | KnowledgeAcquisition: Evaluating confidence...
2025-02-09 15:03:37.442 | 29884:30460 | INFO     | scripts.knowledge_acquisition:process_source:511 | KnowledgeAcquisition: Confidence score: 0.8
2025-02-09 15:03:37.450 | 29884:30460 | INFO     | __main__:_synthesize_knowledge:325 | Knowledge Synthesis: Processing source: Domain Rating Checker 【Free tool, No Login, Super Fast】 (source_3.txt)
2025-02-09 15:03:37.451 | 29884:30460 | INFO     | __main__:_synthesize_knowledge:329 | Knowledge Synthesis: Content preview:
![AI Writer for SEO? Domain Rating (DR) is a metric developed to estimate the relative strength of a website's backlink profile compared to all other sites on the internet on a scale from 0 to 100. The higher the DR score, the stronger and more authoritative the website is considered to be. This metric is crucial for understanding how likely a website is to rank in The calculation of DR takes into account the quantity and quality of external backlinks, denoting websites that have robust backlink...
2025-02-09 15:03:37.452 | 29884:30460 | INFO     | scripts.knowledge_acquisition:process_source:444 | KnowledgeAcquisition: Starting source processing with content length: 4993
2025-02-09 15:03:37.453 | 29884:30460 | INFO     | scripts.knowledge_acquisition:process_source:448 | KnowledgeAcquisition: Content preview:
![AI Writer for SEO? Domain Rating (DR) is a metric developed to estimate the relative strength of a website's backlink profile compared to all other sites on the internet on a scale from 0 to 100. Th...
2025-02-09 15:03:37.455 | 29884:30460 | INFO     | scripts.knowledge_acquisition:process_source:451 | KnowledgeAcquisition: Extracting entities...
2025-02-09 15:03:38.271 | 29884:30460 | INFO     | scripts.knowledge_acquisition:process_source:458 | KnowledgeAcquisition: Extracted 10 entities: ['Machine Learning', 'Neural Networks', 'TensorFlow', 'Deep Learning', 'Python', 'Data Science', 'Artificial Intelligence', 'Big Data', 'Cloud Computing', 'GPU']
2025-02-09 15:03:38.272 | 29884:30460 | INFO     | scripts.knowledge_acquisition:process_source:464 | KnowledgeAcquisition: Extracting relationships...
2025-02-09 15:03:41.387 | 29884:30460 | ERROR    | scripts.knowledge_acquisition:_extract_relationships:652 | Failed to convert relationship: {'source': 'CNNs', 'relation': 'used_in', 'target': 'Image Recognition'}: 1 validation error for Relationship
relation
  Input should be 'uses', 'applies', 'implements', 'improves', 'outperforms', 'achieves', 'contains', 'consists_of', 'part_of', 'better_than', 'similar_to', 'different_from', 'leads_to', 'causes', 'affects', 'precedes', 'follows', 'concurrent_with', 'is_a', 'has_part' or 'related_to' [type=literal_error, input_value='used_in', input_type=str]
    For further information visit https://errors.pydantic.dev/2.10/v/literal_error
Traceback (most recent call last):

  File "C:\Users\mikeb\work\sifu2\run_agents.py", line 868, in <module>
    asyncio.run(main())

  File "C:\Python313\Lib\asyncio\runners.py", line 194, in run
    return runner.run(main)
  File "C:\Python313\Lib\asyncio\runners.py", line 118, in run
    return self._loop.run_until_complete(task)
  File "C:\Python313\Lib\asyncio\base_events.py", line 707, in run_until_complete
    self.run_forever()
  File "C:\Python313\Lib\asyncio\base_events.py", line 678, in run_forever
    self._run_once()
  File "C:\Python313\Lib\asyncio\base_events.py", line 2033, in _run_once
    handle._run()
  File "C:\Python313\Lib\asyncio\events.py", line 89, in _run
    self._context.run(self._callback, *self._args)

  File "C:\Users\mikeb\work\sifu2\run_agents.py", line 857, in main
    await agent.run()

  File "C:\Users\mikeb\work\sifu2\run_agents.py", line 691, in run
    result = await getattr(self, task.tool)(**task.args)

  File "C:\Users\mikeb\work\sifu2\run_agents.py", line 344, in _synthesize_knowledge
    knowledge = await self.knowledge_system.process_source(content)

  File "C:\Users\mikeb\work\sifu2\scripts\knowledge_acquisition.py", line 466, in process_source
    relationships = await self._extract_relationships(content)

> File "C:\Users\mikeb\work\sifu2\scripts\knowledge_acquisition.py", line 650, in _extract_relationships
    converted_relationships.append(Relationship(**rel))

  File "C:\Python313\Lib\site-packages\pydantic\main.py", line 214, in __init__
    validated_self = self.__pydantic_validator__.validate_python(data, self_instance=self)

pydantic_core._pydantic_core.ValidationError: 1 validation error for Relationship
relation
  Input should be 'uses', 'applies', 'implements', 'improves', 'outperforms', 'achieves', 'contains', 'consists_of', 'part_of', 'better_than', 'similar_to', 'different_from', 'leads_to', 'causes', 'affects', 'precedes', 'follows', 'concurrent_with', 'is_a', 'has_part' or 'related_to' [type=literal_error, input_value='used_in', input_type=str]
    For further information visit https://errors.pydantic.dev/2.10/v/literal_error
2025-02-09 15:03:41.411 | 29884:30460 | ERROR    | scripts.knowledge_acquisition:_extract_relationships:652 | Failed to convert relationship: {'source': 'RNNs', 'relation': 'used_in', 'target': 'Natural Language Processing'}: 1 validation error for Relationship
relation
  Input should be 'uses', 'applies', 'implements', 'improves', 'outperforms', 'achieves', 'contains', 'consists_of', 'part_of', 'better_than', 'similar_to', 'different_from', 'leads_to', 'causes', 'affects', 'precedes', 'follows', 'concurrent_with', 'is_a', 'has_part' or 'related_to' [type=literal_error, input_value='used_in', input_type=str]
    For further information visit https://errors.pydantic.dev/2.10/v/literal_error
Traceback (most recent call last):

  File "C:\Users\mikeb\work\sifu2\run_agents.py", line 868, in <module>
    asyncio.run(main())

  File "C:\Python313\Lib\asyncio\runners.py", line 194, in run
    return runner.run(main)
  File "C:\Python313\Lib\asyncio\runners.py", line 118, in run
    return self._loop.run_until_complete(task)
  File "C:\Python313\Lib\asyncio\base_events.py", line 707, in run_until_complete
    self.run_forever()
  File "C:\Python313\Lib\asyncio\base_events.py", line 678, in run_forever
    self._run_once()
  File "C:\Python313\Lib\asyncio\base_events.py", line 2033, in _run_once
    handle._run()
  File "C:\Python313\Lib\asyncio\events.py", line 89, in _run
    self._context.run(self._callback, *self._args)

  File "C:\Users\mikeb\work\sifu2\run_agents.py", line 857, in main
    await agent.run()

  File "C:\Users\mikeb\work\sifu2\run_agents.py", line 691, in run
    result = await getattr(self, task.tool)(**task.args)

  File "C:\Users\mikeb\work\sifu2\run_agents.py", line 344, in _synthesize_knowledge
    knowledge = await self.knowledge_system.process_source(content)

  File "C:\Users\mikeb\work\sifu2\scripts\knowledge_acquisition.py", line 466, in process_source
    relationships = await self._extract_relationships(content)

> File "C:\Users\mikeb\work\sifu2\scripts\knowledge_acquisition.py", line 650, in _extract_relationships
    converted_relationships.append(Relationship(**rel))

  File "C:\Python313\Lib\site-packages\pydantic\main.py", line 214, in __init__
    validated_self = self.__pydantic_validator__.validate_python(data, self_instance=self)

pydantic_core._pydantic_core.ValidationError: 1 validation error for Relationship
relation
  Input should be 'uses', 'applies', 'implements', 'improves', 'outperforms', 'achieves', 'contains', 'consists_of', 'part_of', 'better_than', 'similar_to', 'different_from', 'leads_to', 'causes', 'affects', 'precedes', 'follows', 'concurrent_with', 'is_a', 'has_part' or 'related_to' [type=literal_error, input_value='used_in', input_type=str]
    For further information visit https://errors.pydantic.dev/2.10/v/literal_error
2025-02-09 15:03:41.433 | 29884:30460 | ERROR    | scripts.knowledge_acquisition:_extract_relationships:652 | Failed to convert relationship: {'source': 'Backpropagation', 'relation': 'used_in', 'target': 'Training Neural Networks'}: 1 validation error for Relationship
relation
  Input should be 'uses', 'applies', 'implements', 'improves', 'outperforms', 'achieves', 'contains', 'consists_of', 'part_of', 'better_than', 'similar_to', 'different_from', 'leads_to', 'causes', 'affects', 'precedes', 'follows', 'concurrent_with', 'is_a', 'has_part' or 'related_to' [type=literal_error, input_value='used_in', input_type=str]
    For further information visit https://errors.pydantic.dev/2.10/v/literal_error
Traceback (most recent call last):

  File "C:\Users\mikeb\work\sifu2\run_agents.py", line 868, in <module>
    asyncio.run(main())

  File "C:\Python313\Lib\asyncio\runners.py", line 194, in run
    return runner.run(main)
  File "C:\Python313\Lib\asyncio\runners.py", line 118, in run
    return self._loop.run_until_complete(task)
  File "C:\Python313\Lib\asyncio\base_events.py", line 707, in run_until_complete
    self.run_forever()
  File "C:\Python313\Lib\asyncio\base_events.py", line 678, in run_forever
    self._run_once()
  File "C:\Python313\Lib\asyncio\base_events.py", line 2033, in _run_once
    handle._run()
  File "C:\Python313\Lib\asyncio\events.py", line 89, in _run
    self._context.run(self._callback, *self._args)

  File "C:\Users\mikeb\work\sifu2\run_agents.py", line 857, in main
    await agent.run()

  File "C:\Users\mikeb\work\sifu2\run_agents.py", line 691, in run
    result = await getattr(self, task.tool)(**task.args)

  File "C:\Users\mikeb\work\sifu2\run_agents.py", line 344, in _synthesize_knowledge
    knowledge = await self.knowledge_system.process_source(content)

  File "C:\Users\mikeb\work\sifu2\scripts\knowledge_acquisition.py", line 466, in process_source
    relationships = await self._extract_relationships(content)

> File "C:\Users\mikeb\work\sifu2\scripts\knowledge_acquisition.py", line 650, in _extract_relationships
    converted_relationships.append(Relationship(**rel))

  File "C:\Python313\Lib\site-packages\pydantic\main.py", line 214, in __init__
    validated_self = self.__pydantic_validator__.validate_python(data, self_instance=self)

pydantic_core._pydantic_core.ValidationError: 1 validation error for Relationship
relation
  Input should be 'uses', 'applies', 'implements', 'improves', 'outperforms', 'achieves', 'contains', 'consists_of', 'part_of', 'better_than', 'similar_to', 'different_from', 'leads_to', 'causes', 'affects', 'precedes', 'follows', 'concurrent_with', 'is_a', 'has_part' or 'related_to' [type=literal_error, input_value='used_in', input_type=str]
    For further information visit https://errors.pydantic.dev/2.10/v/literal_error
2025-02-09 15:03:41.459 | 29884:30460 | ERROR    | scripts.knowledge_acquisition:_extract_relationships:652 | Failed to convert relationship: {'source': 'SGD', 'relation': 'used_in', 'target': 'Training Neural Networks'}: 1 validation error for Relationship
relation
  Input should be 'uses', 'applies', 'implements', 'improves', 'outperforms', 'achieves', 'contains', 'consists_of', 'part_of', 'better_than', 'similar_to', 'different_from', 'leads_to', 'causes', 'affects', 'precedes', 'follows', 'concurrent_with', 'is_a', 'has_part' or 'related_to' [type=literal_error, input_value='used_in', input_type=str]
    For further information visit https://errors.pydantic.dev/2.10/v/literal_error
Traceback (most recent call last):

  File "C:\Users\mikeb\work\sifu2\run_agents.py", line 868, in <module>
    asyncio.run(main())

  File "C:\Python313\Lib\asyncio\runners.py", line 194, in run
    return runner.run(main)
  File "C:\Python313\Lib\asyncio\runners.py", line 118, in run
    return self._loop.run_until_complete(task)
  File "C:\Python313\Lib\asyncio\base_events.py", line 707, in run_until_complete
    self.run_forever()
  File "C:\Python313\Lib\asyncio\base_events.py", line 678, in run_forever
    self._run_once()
  File "C:\Python313\Lib\asyncio\base_events.py", line 2033, in _run_once
    handle._run()
  File "C:\Python313\Lib\asyncio\events.py", line 89, in _run
    self._context.run(self._callback, *self._args)

  File "C:\Users\mikeb\work\sifu2\run_agents.py", line 857, in main
    await agent.run()

  File "C:\Users\mikeb\work\sifu2\run_agents.py", line 691, in run
    result = await getattr(self, task.tool)(**task.args)

  File "C:\Users\mikeb\work\sifu2\run_agents.py", line 344, in _synthesize_knowledge
    knowledge = await self.knowledge_system.process_source(content)

  File "C:\Users\mikeb\work\sifu2\scripts\knowledge_acquisition.py", line 466, in process_source
    relationships = await self._extract_relationships(content)

> File "C:\Users\mikeb\work\sifu2\scripts\knowledge_acquisition.py", line 650, in _extract_relationships
    converted_relationships.append(Relationship(**rel))

  File "C:\Python313\Lib\site-packages\pydantic\main.py", line 214, in __init__
    validated_self = self.__pydantic_validator__.validate_python(data, self_instance=self)

pydantic_core._pydantic_core.ValidationError: 1 validation error for Relationship
relation
  Input should be 'uses', 'applies', 'implements', 'improves', 'outperforms', 'achieves', 'contains', 'consists_of', 'part_of', 'better_than', 'similar_to', 'different_from', 'leads_to', 'causes', 'affects', 'precedes', 'follows', 'concurrent_with', 'is_a', 'has_part' or 'related_to' [type=literal_error, input_value='used_in', input_type=str]
    For further information visit https://errors.pydantic.dev/2.10/v/literal_error
2025-02-09 15:03:41.483 | 29884:30460 | ERROR    | scripts.knowledge_acquisition:_extract_relationships:652 | Failed to convert relationship: {'source': 'Regularization', 'relation': 'prevents', 'target': 'Overfitting'}: 1 validation error for Relationship
relation
  Input should be 'uses', 'applies', 'implements', 'improves', 'outperforms', 'achieves', 'contains', 'consists_of', 'part_of', 'better_than', 'similar_to', 'different_from', 'leads_to', 'causes', 'affects', 'precedes', 'follows', 'concurrent_with', 'is_a', 'has_part' or 'related_to' [type=literal_error, input_value='prevents', input_type=str]
    For further information visit https://errors.pydantic.dev/2.10/v/literal_error
Traceback (most recent call last):

  File "C:\Users\mikeb\work\sifu2\run_agents.py", line 868, in <module>
    asyncio.run(main())

  File "C:\Python313\Lib\asyncio\runners.py", line 194, in run
    return runner.run(main)
  File "C:\Python313\Lib\asyncio\runners.py", line 118, in run
    return self._loop.run_until_complete(task)
  File "C:\Python313\Lib\asyncio\base_events.py", line 707, in run_until_complete
    self.run_forever()
  File "C:\Python313\Lib\asyncio\base_events.py", line 678, in run_forever
    self._run_once()
  File "C:\Python313\Lib\asyncio\base_events.py", line 2033, in _run_once
    handle._run()
  File "C:\Python313\Lib\asyncio\events.py", line 89, in _run
    self._context.run(self._callback, *self._args)

  File "C:\Users\mikeb\work\sifu2\run_agents.py", line 857, in main
    await agent.run()

  File "C:\Users\mikeb\work\sifu2\run_agents.py", line 691, in run
    result = await getattr(self, task.tool)(**task.args)

  File "C:\Users\mikeb\work\sifu2\run_agents.py", line 344, in _synthesize_knowledge
    knowledge = await self.knowledge_system.process_source(content)

  File "C:\Users\mikeb\work\sifu2\scripts\knowledge_acquisition.py", line 466, in process_source
    relationships = await self._extract_relationships(content)

> File "C:\Users\mikeb\work\sifu2\scripts\knowledge_acquisition.py", line 650, in _extract_relationships
    converted_relationships.append(Relationship(**rel))

  File "C:\Python313\Lib\site-packages\pydantic\main.py", line 214, in __init__
    validated_self = self.__pydantic_validator__.validate_python(data, self_instance=self)

pydantic_core._pydantic_core.ValidationError: 1 validation error for Relationship
relation
  Input should be 'uses', 'applies', 'implements', 'improves', 'outperforms', 'achieves', 'contains', 'consists_of', 'part_of', 'better_than', 'similar_to', 'different_from', 'leads_to', 'causes', 'affects', 'precedes', 'follows', 'concurrent_with', 'is_a', 'has_part' or 'related_to' [type=literal_error, input_value='prevents', input_type=str]
    For further information visit https://errors.pydantic.dev/2.10/v/literal_error
2025-02-09 15:03:41.504 | 29884:30460 | INFO     | scripts.knowledge_acquisition:process_source:478 | KnowledgeAcquisition: Extracted 5 relationships
2025-02-09 15:03:41.506 | 29884:30460 | INFO     | scripts.knowledge_acquisition:process_source:482 | KnowledgeAcquisition: Relationship: Convolutional Neural Networks (CNNs) -> is_a -> Neural Networks
2025-02-09 15:03:41.508 | 29884:30460 | INFO     | scripts.knowledge_acquisition:process_source:482 | KnowledgeAcquisition: Relationship: Recurrent Neural Networks (RNNs) -> is_a -> Neural Networks
2025-02-09 15:03:41.509 | 29884:30460 | INFO     | scripts.knowledge_acquisition:process_source:482 | KnowledgeAcquisition: Relationship: Stochastic Gradient Descent (SGD) -> is_a -> Optimization Algorithm
2025-02-09 15:03:41.510 | 29884:30460 | INFO     | scripts.knowledge_acquisition:process_source:482 | KnowledgeAcquisition: Relationship: Data Augmentation -> improves -> Model Accuracy
2025-02-09 15:03:41.512 | 29884:30460 | INFO     | scripts.knowledge_acquisition:process_source:482 | KnowledgeAcquisition: Relationship: Transfer Learning -> improves -> Model Performance
2025-02-09 15:03:41.513 | 29884:30460 | INFO     | scripts.knowledge_acquisition:process_source:488 | KnowledgeAcquisition: Generating metadata...
2025-02-09 15:03:42.568 | 29884:30460 | INFO     | scripts.knowledge_acquisition:process_source:495 | KnowledgeAcquisition: Generated metadata: {'source_type': 'text', 'confidence_score': 0.85, 'domain_relevance': 0.9, 'timestamp': '2024-02-09T11:42:32.000Z', 'validation_status': 'processed', 'domain': 'machine_learning'}
2025-02-09 15:03:42.570 | 29884:30460 | INFO     | scripts.knowledge_acquisition:process_source:501 | KnowledgeAcquisition: Evaluating confidence...
2025-02-09 15:03:44.094 | 29884:30460 | INFO     | scripts.knowledge_acquisition:process_source:511 | KnowledgeAcquisition: Confidence score: 0.85
2025-02-09 15:03:44.104 | 29884:30460 | INFO     | __main__:_synthesize_knowledge:325 | Knowledge Synthesis: Processing source: Free Website Authority Checker (& How to Improve Yours) (source_5.txt)
2025-02-09 15:03:44.106 | 29884:30460 | INFO     | __main__:_synthesize_knowledge:329 | Knowledge Synthesis: Content preview:
!grid-line !( Keri Engel January 10, 2025 Our free website authority checker lets you check domain authority for any website on the internet. To get your analysis, just enter a domain name and hit enter. The website authority report is split into six sections. First, you’ll see an overview of domain metrics, like your authority score. This indicates the level of trust that !undefined:** Combines factors like link quality, organic traffic, and spam presence to create an accurate measure, aiming t...
2025-02-09 15:03:44.107 | 29884:30460 | INFO     | scripts.knowledge_acquisition:process_source:444 | KnowledgeAcquisition: Starting source processing with content length: 1060
2025-02-09 15:03:44.108 | 29884:30460 | INFO     | scripts.knowledge_acquisition:process_source:448 | KnowledgeAcquisition: Content preview:
!grid-line !( Keri Engel January 10, 2025 Our free website authority checker lets you check domain authority for any website on the internet. To get your analysis, just enter a domain name and hit ent...
2025-02-09 15:03:44.110 | 29884:30460 | INFO     | scripts.knowledge_acquisition:process_source:451 | KnowledgeAcquisition: Extracting entities...
2025-02-09 15:03:47.267 | 29884:30460 | INFO     | scripts.knowledge_acquisition:process_source:458 | KnowledgeAcquisition: Extracted 56 entities: ['Machine Learning', 'Deep Learning', 'Neural Networks', 'TensorFlow', 'Python', 'Keras', 'Computer Vision', 'Image Classification', 'Object Detection', 'Natural Language Processing', 'Sentiment Analysis', 'Recurrent Neural Networks', 'Convolutional Neural Networks', 'Backpropagation', 'Gradient Descent', 'Regularization', 'Overfitting', 'Underfitting', 'Data Augmentation', 'Transfer Learning', 'Hyperparameter Tuning', 'Model Evaluation', 'Accuracy', 'Precision', 'Recall', 'F1-Score', 'AUC', 'ROC Curve', 'Confusion Matrix', 'Cross-validation', 'Data Preprocessing', 'Feature Engineering', 'Dimensionality Reduction', 'Principal Component Analysis', 'Clustering', 'K-means', 'Hierarchical Clustering', 'DBSCAN', 'Classification', 'Regression', 'Clustering', 'Time Series Analysis', 'Reinforcement Learning', 'Generative Adversarial Networks', 'Autoencoders', 'Recurrent Neural Networks', 'Long Short-Term Memory Networks', 'Gated Recurrent Units', 'Transformers', 'Attention Mechanisms', 'BERT', 'GPT', 'Word Embeddings', 'Word2Vec', 'GloVe', 'FastText']
2025-02-09 15:03:47.269 | 29884:30460 | INFO     | scripts.knowledge_acquisition:process_source:464 | KnowledgeAcquisition: Extracting relationships...
2025-02-09 15:03:50.375 | 29884:30460 | ERROR    | scripts.knowledge_acquisition:_extract_relationships:652 | Failed to convert relationship: {'source': 'CNNs', 'relation': 'used_for', 'target': 'Image Recognition'}: 1 validation error for Relationship
relation
  Input should be 'uses', 'applies', 'implements', 'improves', 'outperforms', 'achieves', 'contains', 'consists_of', 'part_of', 'better_than', 'similar_to', 'different_from', 'leads_to', 'causes', 'affects', 'precedes', 'follows', 'concurrent_with', 'is_a', 'has_part' or 'related_to' [type=literal_error, input_value='used_for', input_type=str]
    For further information visit https://errors.pydantic.dev/2.10/v/literal_error
Traceback (most recent call last):

  File "C:\Users\mikeb\work\sifu2\run_agents.py", line 868, in <module>
    asyncio.run(main())

  File "C:\Python313\Lib\asyncio\runners.py", line 194, in run
    return runner.run(main)
  File "C:\Python313\Lib\asyncio\runners.py", line 118, in run
    return self._loop.run_until_complete(task)
  File "C:\Python313\Lib\asyncio\base_events.py", line 707, in run_until_complete
    self.run_forever()
  File "C:\Python313\Lib\asyncio\base_events.py", line 678, in run_forever
    self._run_once()
  File "C:\Python313\Lib\asyncio\base_events.py", line 2033, in _run_once
    handle._run()
  File "C:\Python313\Lib\asyncio\events.py", line 89, in _run
    self._context.run(self._callback, *self._args)

  File "C:\Users\mikeb\work\sifu2\run_agents.py", line 857, in main
    await agent.run()

  File "C:\Users\mikeb\work\sifu2\run_agents.py", line 691, in run
    result = await getattr(self, task.tool)(**task.args)

  File "C:\Users\mikeb\work\sifu2\run_agents.py", line 344, in _synthesize_knowledge
    knowledge = await self.knowledge_system.process_source(content)

  File "C:\Users\mikeb\work\sifu2\scripts\knowledge_acquisition.py", line 466, in process_source
    relationships = await self._extract_relationships(content)

> File "C:\Users\mikeb\work\sifu2\scripts\knowledge_acquisition.py", line 650, in _extract_relationships
    converted_relationships.append(Relationship(**rel))

  File "C:\Python313\Lib\site-packages\pydantic\main.py", line 214, in __init__
    validated_self = self.__pydantic_validator__.validate_python(data, self_instance=self)

pydantic_core._pydantic_core.ValidationError: 1 validation error for Relationship
relation
  Input should be 'uses', 'applies', 'implements', 'improves', 'outperforms', 'achieves', 'contains', 'consists_of', 'part_of', 'better_than', 'similar_to', 'different_from', 'leads_to', 'causes', 'affects', 'precedes', 'follows', 'concurrent_with', 'is_a', 'has_part' or 'related_to' [type=literal_error, input_value='used_for', input_type=str]
    For further information visit https://errors.pydantic.dev/2.10/v/literal_error
2025-02-09 15:03:50.397 | 29884:30460 | ERROR    | scripts.knowledge_acquisition:_extract_relationships:652 | Failed to convert relationship: {'source': 'RNNs', 'relation': 'used_for', 'target': 'Natural Language Processing'}: 1 validation error for Relationship
relation
  Input should be 'uses', 'applies', 'implements', 'improves', 'outperforms', 'achieves', 'contains', 'consists_of', 'part_of', 'better_than', 'similar_to', 'different_from', 'leads_to', 'causes', 'affects', 'precedes', 'follows', 'concurrent_with', 'is_a', 'has_part' or 'related_to' [type=literal_error, input_value='used_for', input_type=str]
    For further information visit https://errors.pydantic.dev/2.10/v/literal_error
Traceback (most recent call last):

  File "C:\Users\mikeb\work\sifu2\run_agents.py", line 868, in <module>
    asyncio.run(main())

  File "C:\Python313\Lib\asyncio\runners.py", line 194, in run
    return runner.run(main)
  File "C:\Python313\Lib\asyncio\runners.py", line 118, in run
    return self._loop.run_until_complete(task)
  File "C:\Python313\Lib\asyncio\base_events.py", line 707, in run_until_complete
    self.run_forever()
  File "C:\Python313\Lib\asyncio\base_events.py", line 678, in run_forever
    self._run_once()
  File "C:\Python313\Lib\asyncio\base_events.py", line 2033, in _run_once
    handle._run()
  File "C:\Python313\Lib\asyncio\events.py", line 89, in _run
    self._context.run(self._callback, *self._args)

  File "C:\Users\mikeb\work\sifu2\run_agents.py", line 857, in main
    await agent.run()

  File "C:\Users\mikeb\work\sifu2\run_agents.py", line 691, in run
    result = await getattr(self, task.tool)(**task.args)

  File "C:\Users\mikeb\work\sifu2\run_agents.py", line 344, in _synthesize_knowledge
    knowledge = await self.knowledge_system.process_source(content)

  File "C:\Users\mikeb\work\sifu2\scripts\knowledge_acquisition.py", line 466, in process_source
    relationships = await self._extract_relationships(content)

> File "C:\Users\mikeb\work\sifu2\scripts\knowledge_acquisition.py", line 650, in _extract_relationships
    converted_relationships.append(Relationship(**rel))

  File "C:\Python313\Lib\site-packages\pydantic\main.py", line 214, in __init__
    validated_self = self.__pydantic_validator__.validate_python(data, self_instance=self)

pydantic_core._pydantic_core.ValidationError: 1 validation error for Relationship
relation
  Input should be 'uses', 'applies', 'implements', 'improves', 'outperforms', 'achieves', 'contains', 'consists_of', 'part_of', 'better_than', 'similar_to', 'different_from', 'leads_to', 'causes', 'affects', 'precedes', 'follows', 'concurrent_with', 'is_a', 'has_part' or 'related_to' [type=literal_error, input_value='used_for', input_type=str]
    For further information visit https://errors.pydantic.dev/2.10/v/literal_error
2025-02-09 15:03:50.418 | 29884:30460 | ERROR    | scripts.knowledge_acquisition:_extract_relationships:652 | Failed to convert relationship: {'source': 'Backpropagation', 'relation': 'used_in', 'target': 'Training Neural Networks'}: 1 validation error for Relationship
relation
  Input should be 'uses', 'applies', 'implements', 'improves', 'outperforms', 'achieves', 'contains', 'consists_of', 'part_of', 'better_than', 'similar_to', 'different_from', 'leads_to', 'causes', 'affects', 'precedes', 'follows', 'concurrent_with', 'is_a', 'has_part' or 'related_to' [type=literal_error, input_value='used_in', input_type=str]
    For further information visit https://errors.pydantic.dev/2.10/v/literal_error
Traceback (most recent call last):

  File "C:\Users\mikeb\work\sifu2\run_agents.py", line 868, in <module>
    asyncio.run(main())

  File "C:\Python313\Lib\asyncio\runners.py", line 194, in run
    return runner.run(main)
  File "C:\Python313\Lib\asyncio\runners.py", line 118, in run
    return self._loop.run_until_complete(task)
  File "C:\Python313\Lib\asyncio\base_events.py", line 707, in run_until_complete
    self.run_forever()
  File "C:\Python313\Lib\asyncio\base_events.py", line 678, in run_forever
    self._run_once()
  File "C:\Python313\Lib\asyncio\base_events.py", line 2033, in _run_once
    handle._run()
  File "C:\Python313\Lib\asyncio\events.py", line 89, in _run
    self._context.run(self._callback, *self._args)

  File "C:\Users\mikeb\work\sifu2\run_agents.py", line 857, in main
    await agent.run()

  File "C:\Users\mikeb\work\sifu2\run_agents.py", line 691, in run
    result = await getattr(self, task.tool)(**task.args)

  File "C:\Users\mikeb\work\sifu2\run_agents.py", line 344, in _synthesize_knowledge
    knowledge = await self.knowledge_system.process_source(content)

  File "C:\Users\mikeb\work\sifu2\scripts\knowledge_acquisition.py", line 466, in process_source
    relationships = await self._extract_relationships(content)

> File "C:\Users\mikeb\work\sifu2\scripts\knowledge_acquisition.py", line 650, in _extract_relationships
    converted_relationships.append(Relationship(**rel))

  File "C:\Python313\Lib\site-packages\pydantic\main.py", line 214, in __init__
    validated_self = self.__pydantic_validator__.validate_python(data, self_instance=self)

pydantic_core._pydantic_core.ValidationError: 1 validation error for Relationship
relation
  Input should be 'uses', 'applies', 'implements', 'improves', 'outperforms', 'achieves', 'contains', 'consists_of', 'part_of', 'better_than', 'similar_to', 'different_from', 'leads_to', 'causes', 'affects', 'precedes', 'follows', 'concurrent_with', 'is_a', 'has_part' or 'related_to' [type=literal_error, input_value='used_in', input_type=str]
    For further information visit https://errors.pydantic.dev/2.10/v/literal_error
2025-02-09 15:03:50.440 | 29884:30460 | ERROR    | scripts.knowledge_acquisition:_extract_relationships:652 | Failed to convert relationship: {'source': 'Gradient Descent', 'relation': 'algorithm_for', 'target': 'Optimizing Neural Networks'}: 1 validation error for Relationship
relation
  Input should be 'uses', 'applies', 'implements', 'improves', 'outperforms', 'achieves', 'contains', 'consists_of', 'part_of', 'better_than', 'similar_to', 'different_from', 'leads_to', 'causes', 'affects', 'precedes', 'follows', 'concurrent_with', 'is_a', 'has_part' or 'related_to' [type=literal_error, input_value='algorithm_for', input_type=str]
    For further information visit https://errors.pydantic.dev/2.10/v/literal_error
Traceback (most recent call last):

  File "C:\Users\mikeb\work\sifu2\run_agents.py", line 868, in <module>
    asyncio.run(main())

  File "C:\Python313\Lib\asyncio\runners.py", line 194, in run
    return runner.run(main)
  File "C:\Python313\Lib\asyncio\runners.py", line 118, in run
    return self._loop.run_until_complete(task)
  File "C:\Python313\Lib\asyncio\base_events.py", line 707, in run_until_complete
    self.run_forever()
  File "C:\Python313\Lib\asyncio\base_events.py", line 678, in run_forever
    self._run_once()
  File "C:\Python313\Lib\asyncio\base_events.py", line 2033, in _run_once
    handle._run()
  File "C:\Python313\Lib\asyncio\events.py", line 89, in _run
    self._context.run(self._callback, *self._args)

  File "C:\Users\mikeb\work\sifu2\run_agents.py", line 857, in main
    await agent.run()

  File "C:\Users\mikeb\work\sifu2\run_agents.py", line 691, in run
    result = await getattr(self, task.tool)(**task.args)

  File "C:\Users\mikeb\work\sifu2\run_agents.py", line 344, in _synthesize_knowledge
    knowledge = await self.knowledge_system.process_source(content)

  File "C:\Users\mikeb\work\sifu2\scripts\knowledge_acquisition.py", line 466, in process_source
    relationships = await self._extract_relationships(content)

> File "C:\Users\mikeb\work\sifu2\scripts\knowledge_acquisition.py", line 650, in _extract_relationships
    converted_relationships.append(Relationship(**rel))

  File "C:\Python313\Lib\site-packages\pydantic\main.py", line 214, in __init__
    validated_self = self.__pydantic_validator__.validate_python(data, self_instance=self)

pydantic_core._pydantic_core.ValidationError: 1 validation error for Relationship
relation
  Input should be 'uses', 'applies', 'implements', 'improves', 'outperforms', 'achieves', 'contains', 'consists_of', 'part_of', 'better_than', 'similar_to', 'different_from', 'leads_to', 'causes', 'affects', 'precedes', 'follows', 'concurrent_with', 'is_a', 'has_part' or 'related_to' [type=literal_error, input_value='algorithm_for', input_type=str]
    For further information visit https://errors.pydantic.dev/2.10/v/literal_error
2025-02-09 15:03:50.460 | 29884:30460 | ERROR    | scripts.knowledge_acquisition:_extract_relationships:652 | Failed to convert relationship: {'source': 'Regularization Techniques', 'relation': 'used_to', 'target': 'Prevent Overfitting'}: 1 validation error for Relationship
relation
  Input should be 'uses', 'applies', 'implements', 'improves', 'outperforms', 'achieves', 'contains', 'consists_of', 'part_of', 'better_than', 'similar_to', 'different_from', 'leads_to', 'causes', 'affects', 'precedes', 'follows', 'concurrent_with', 'is_a', 'has_part' or 'related_to' [type=literal_error, input_value='used_to', input_type=str]
    For further information visit https://errors.pydantic.dev/2.10/v/literal_error
Traceback (most recent call last):

  File "C:\Users\mikeb\work\sifu2\run_agents.py", line 868, in <module>
    asyncio.run(main())

  File "C:\Python313\Lib\asyncio\runners.py", line 194, in run
    return runner.run(main)
  File "C:\Python313\Lib\asyncio\runners.py", line 118, in run
    return self._loop.run_until_complete(task)
  File "C:\Python313\Lib\asyncio\base_events.py", line 707, in run_until_complete
    self.run_forever()
  File "C:\Python313\Lib\asyncio\base_events.py", line 678, in run_forever
    self._run_once()
  File "C:\Python313\Lib\asyncio\base_events.py", line 2033, in _run_once
    handle._run()
  File "C:\Python313\Lib\asyncio\events.py", line 89, in _run
    self._context.run(self._callback, *self._args)

  File "C:\Users\mikeb\work\sifu2\run_agents.py", line 857, in main
    await agent.run()

  File "C:\Users\mikeb\work\sifu2\run_agents.py", line 691, in run
    result = await getattr(self, task.tool)(**task.args)

  File "C:\Users\mikeb\work\sifu2\run_agents.py", line 344, in _synthesize_knowledge
    knowledge = await self.knowledge_system.process_source(content)

  File "C:\Users\mikeb\work\sifu2\scripts\knowledge_acquisition.py", line 466, in process_source
    relationships = await self._extract_relationships(content)

> File "C:\Users\mikeb\work\sifu2\scripts\knowledge_acquisition.py", line 650, in _extract_relationships
    converted_relationships.append(Relationship(**rel))

  File "C:\Python313\Lib\site-packages\pydantic\main.py", line 214, in __init__
    validated_self = self.__pydantic_validator__.validate_python(data, self_instance=self)

pydantic_core._pydantic_core.ValidationError: 1 validation error for Relationship
relation
  Input should be 'uses', 'applies', 'implements', 'improves', 'outperforms', 'achieves', 'contains', 'consists_of', 'part_of', 'better_than', 'similar_to', 'different_from', 'leads_to', 'causes', 'affects', 'precedes', 'follows', 'concurrent_with', 'is_a', 'has_part' or 'related_to' [type=literal_error, input_value='used_to', input_type=str]
    For further information visit https://errors.pydantic.dev/2.10/v/literal_error
2025-02-09 15:03:50.481 | 29884:30460 | ERROR    | scripts.knowledge_acquisition:_extract_relationships:652 | Failed to convert relationship: {'source': 'Overfitting', 'relation': 'problem_in', 'target': 'Machine Learning'}: 1 validation error for Relationship
relation
  Input should be 'uses', 'applies', 'implements', 'improves', 'outperforms', 'achieves', 'contains', 'consists_of', 'part_of', 'better_than', 'similar_to', 'different_from', 'leads_to', 'causes', 'affects', 'precedes', 'follows', 'concurrent_with', 'is_a', 'has_part' or 'related_to' [type=literal_error, input_value='problem_in', input_type=str]
    For further information visit https://errors.pydantic.dev/2.10/v/literal_error
Traceback (most recent call last):

  File "C:\Users\mikeb\work\sifu2\run_agents.py", line 868, in <module>
    asyncio.run(main())

  File "C:\Python313\Lib\asyncio\runners.py", line 194, in run
    return runner.run(main)
  File "C:\Python313\Lib\asyncio\runners.py", line 118, in run
    return self._loop.run_until_complete(task)
  File "C:\Python313\Lib\asyncio\base_events.py", line 707, in run_until_complete
    self.run_forever()
  File "C:\Python313\Lib\asyncio\base_events.py", line 678, in run_forever
    self._run_once()
  File "C:\Python313\Lib\asyncio\base_events.py", line 2033, in _run_once
    handle._run()
  File "C:\Python313\Lib\asyncio\events.py", line 89, in _run
    self._context.run(self._callback, *self._args)

  File "C:\Users\mikeb\work\sifu2\run_agents.py", line 857, in main
    await agent.run()

  File "C:\Users\mikeb\work\sifu2\run_agents.py", line 691, in run
    result = await getattr(self, task.tool)(**task.args)

  File "C:\Users\mikeb\work\sifu2\run_agents.py", line 344, in _synthesize_knowledge
    knowledge = await self.knowledge_system.process_source(content)

  File "C:\Users\mikeb\work\sifu2\scripts\knowledge_acquisition.py", line 466, in process_source
    relationships = await self._extract_relationships(content)

> File "C:\Users\mikeb\work\sifu2\scripts\knowledge_acquisition.py", line 650, in _extract_relationships
    converted_relationships.append(Relationship(**rel))

  File "C:\Python313\Lib\site-packages\pydantic\main.py", line 214, in __init__
    validated_self = self.__pydantic_validator__.validate_python(data, self_instance=self)

pydantic_core._pydantic_core.ValidationError: 1 validation error for Relationship
relation
  Input should be 'uses', 'applies', 'implements', 'improves', 'outperforms', 'achieves', 'contains', 'consists_of', 'part_of', 'better_than', 'similar_to', 'different_from', 'leads_to', 'causes', 'affects', 'precedes', 'follows', 'concurrent_with', 'is_a', 'has_part' or 'related_to' [type=literal_error, input_value='problem_in', input_type=str]
    For further information visit https://errors.pydantic.dev/2.10/v/literal_error
2025-02-09 15:03:50.501 | 29884:30460 | ERROR    | scripts.knowledge_acquisition:_extract_relationships:652 | Failed to convert relationship: {'source': 'Transfer Learning', 'relation': 'technique_for', 'target': 'Improving Model Performance'}: 1 validation error for Relationship
relation
  Input should be 'uses', 'applies', 'implements', 'improves', 'outperforms', 'achieves', 'contains', 'consists_of', 'part_of', 'better_than', 'similar_to', 'different_from', 'leads_to', 'causes', 'affects', 'precedes', 'follows', 'concurrent_with', 'is_a', 'has_part' or 'related_to' [type=literal_error, input_value='technique_for', input_type=str]
    For further information visit https://errors.pydantic.dev/2.10/v/literal_error
Traceback (most recent call last):

  File "C:\Users\mikeb\work\sifu2\run_agents.py", line 868, in <module>
    asyncio.run(main())

  File "C:\Python313\Lib\asyncio\runners.py", line 194, in run
    return runner.run(main)
  File "C:\Python313\Lib\asyncio\runners.py", line 118, in run
    return self._loop.run_until_complete(task)
  File "C:\Python313\Lib\asyncio\base_events.py", line 707, in run_until_complete
    self.run_forever()
  File "C:\Python313\Lib\asyncio\base_events.py", line 678, in run_forever
    self._run_once()
  File "C:\Python313\Lib\asyncio\base_events.py", line 2033, in _run_once
    handle._run()
  File "C:\Python313\Lib\asyncio\events.py", line 89, in _run
    self._context.run(self._callback, *self._args)

  File "C:\Users\mikeb\work\sifu2\run_agents.py", line 857, in main
    await agent.run()

  File "C:\Users\mikeb\work\sifu2\run_agents.py", line 691, in run
    result = await getattr(self, task.tool)(**task.args)

  File "C:\Users\mikeb\work\sifu2\run_agents.py", line 344, in _synthesize_knowledge
    knowledge = await self.knowledge_system.process_source(content)

  File "C:\Users\mikeb\work\sifu2\scripts\knowledge_acquisition.py", line 466, in process_source
    relationships = await self._extract_relationships(content)

> File "C:\Users\mikeb\work\sifu2\scripts\knowledge_acquisition.py", line 650, in _extract_relationships
    converted_relationships.append(Relationship(**rel))

  File "C:\Python313\Lib\site-packages\pydantic\main.py", line 214, in __init__
    validated_self = self.__pydantic_validator__.validate_python(data, self_instance=self)

pydantic_core._pydantic_core.ValidationError: 1 validation error for Relationship
relation
  Input should be 'uses', 'applies', 'implements', 'improves', 'outperforms', 'achieves', 'contains', 'consists_of', 'part_of', 'better_than', 'similar_to', 'different_from', 'leads_to', 'causes', 'affects', 'precedes', 'follows', 'concurrent_with', 'is_a', 'has_part' or 'related_to' [type=literal_error, input_value='technique_for', input_type=str]
    For further information visit https://errors.pydantic.dev/2.10/v/literal_error
2025-02-09 15:03:50.523 | 29884:30460 | INFO     | scripts.knowledge_acquisition:process_source:478 | KnowledgeAcquisition: Extracted 3 relationships
2025-02-09 15:03:50.524 | 29884:30460 | INFO     | scripts.knowledge_acquisition:process_source:482 | KnowledgeAcquisition: Relationship: Convolutional Neural Networks (CNNs) -> is_a -> Neural Network
2025-02-09 15:03:50.526 | 29884:30460 | INFO     | scripts.knowledge_acquisition:process_source:482 | KnowledgeAcquisition: Relationship: Recurrent Neural Networks (RNNs) -> is_a -> Neural Network
2025-02-09 15:03:50.527 | 29884:30460 | INFO     | scripts.knowledge_acquisition:process_source:482 | KnowledgeAcquisition: Relationship: Activation Functions -> part_of -> Neural Networks
2025-02-09 15:03:50.529 | 29884:30460 | INFO     | scripts.knowledge_acquisition:process_source:488 | KnowledgeAcquisition: Generating metadata...
2025-02-09 15:03:51.607 | 29884:30460 | INFO     | scripts.knowledge_acquisition:process_source:495 | KnowledgeAcquisition: Generated metadata: {'source_type': 'text', 'confidence_score': 0.9, 'domain_relevance': 0.8, 'timestamp': '2024-02-09T12:45:00.000Z', 'validation_status': 'processed', 'domain': 'machine_learning'}
2025-02-09 15:03:51.609 | 29884:30460 | INFO     | scripts.knowledge_acquisition:process_source:501 | KnowledgeAcquisition: Evaluating confidence...
2025-02-09 15:03:52.852 | 29884:30460 | INFO     | scripts.knowledge_acquisition:process_source:511 | KnowledgeAcquisition: Confidence score: 0.8
2025-02-09 15:03:52.864 | 29884:30460 | INFO     | __main__:_synthesize_knowledge:325 | Knowledge Synthesis: Processing source: Get a Test Domain using Unstoppable Website Faucet Guide (source_7.txt)
2025-02-09 15:03:52.865 | 29884:30460 | INFO     | __main__:_synthesize_knowledge:329 | Knowledge Synthesis: Content preview:
![UD Developer Docs Logo are not supported. ## Get a free domain from Unstoppable Website * Go to the Unstoppable WebsiteNext to **Polygon Faucet Guide**( * Terms of Use( * Privacy Notice( Community * Twitter( * Facebook( Resources * Medium( * Podcast( * Youtube( * Github( Copyright © 2024 Unstoppable Domains Inc. All rights reserved....
2025-02-09 15:03:52.867 | 29884:30460 | INFO     | scripts.knowledge_acquisition:process_source:444 | KnowledgeAcquisition: Starting source processing with content length: 336
2025-02-09 15:03:52.868 | 29884:30460 | INFO     | scripts.knowledge_acquisition:process_source:448 | KnowledgeAcquisition: Content preview:
![UD Developer Docs Logo are not supported. ## Get a free domain from Unstoppable Website * Go to the Unstoppable WebsiteNext to **Polygon Faucet Guide**( * Terms of Use( * Privacy Notice( Community *...
2025-02-09 15:03:52.870 | 29884:30460 | INFO     | scripts.knowledge_acquisition:process_source:451 | KnowledgeAcquisition: Extracting entities...
2025-02-09 15:03:53.649 | 29884:30460 | INFO     | scripts.knowledge_acquisition:process_source:458 | KnowledgeAcquisition: Extracted 10 entities: ['Machine Learning', 'Deep Learning', 'Neural Networks', 'TensorFlow', 'Python', 'Keras', 'Computer Vision', 'Natural Language Processing', 'Data Science', 'Artificial Intelligence']
2025-02-09 15:03:53.651 | 29884:30460 | INFO     | scripts.knowledge_acquisition:process_source:464 | KnowledgeAcquisition: Extracting relationships...
2025-02-09 15:03:56.327 | 29884:30460 | ERROR    | scripts.knowledge_acquisition:_extract_relationships:652 | Failed to convert relationship: {'source': 'CNNs', 'relation': 'used_in', 'target': 'Image Recognition'}: 1 validation error for Relationship
relation
  Input should be 'uses', 'applies', 'implements', 'improves', 'outperforms', 'achieves', 'contains', 'consists_of', 'part_of', 'better_than', 'similar_to', 'different_from', 'leads_to', 'causes', 'affects', 'precedes', 'follows', 'concurrent_with', 'is_a', 'has_part' or 'related_to' [type=literal_error, input_value='used_in', input_type=str]
    For further information visit https://errors.pydantic.dev/2.10/v/literal_error
Traceback (most recent call last):

  File "C:\Users\mikeb\work\sifu2\run_agents.py", line 868, in <module>
    asyncio.run(main())

  File "C:\Python313\Lib\asyncio\runners.py", line 194, in run
    return runner.run(main)
  File "C:\Python313\Lib\asyncio\runners.py", line 118, in run
    return self._loop.run_until_complete(task)
  File "C:\Python313\Lib\asyncio\base_events.py", line 707, in run_until_complete
    self.run_forever()
  File "C:\Python313\Lib\asyncio\base_events.py", line 678, in run_forever
    self._run_once()
  File "C:\Python313\Lib\asyncio\base_events.py", line 2033, in _run_once
    handle._run()
  File "C:\Python313\Lib\asyncio\events.py", line 89, in _run
    self._context.run(self._callback, *self._args)

  File "C:\Users\mikeb\work\sifu2\run_agents.py", line 857, in main
    await agent.run()

  File "C:\Users\mikeb\work\sifu2\run_agents.py", line 691, in run
    result = await getattr(self, task.tool)(**task.args)

  File "C:\Users\mikeb\work\sifu2\run_agents.py", line 344, in _synthesize_knowledge
    knowledge = await self.knowledge_system.process_source(content)

  File "C:\Users\mikeb\work\sifu2\scripts\knowledge_acquisition.py", line 466, in process_source
    relationships = await self._extract_relationships(content)

> File "C:\Users\mikeb\work\sifu2\scripts\knowledge_acquisition.py", line 650, in _extract_relationships
    converted_relationships.append(Relationship(**rel))

  File "C:\Python313\Lib\site-packages\pydantic\main.py", line 214, in __init__
    validated_self = self.__pydantic_validator__.validate_python(data, self_instance=self)

pydantic_core._pydantic_core.ValidationError: 1 validation error for Relationship
relation
  Input should be 'uses', 'applies', 'implements', 'improves', 'outperforms', 'achieves', 'contains', 'consists_of', 'part_of', 'better_than', 'similar_to', 'different_from', 'leads_to', 'causes', 'affects', 'precedes', 'follows', 'concurrent_with', 'is_a', 'has_part' or 'related_to' [type=literal_error, input_value='used_in', input_type=str]
    For further information visit https://errors.pydantic.dev/2.10/v/literal_error
2025-02-09 15:03:56.348 | 29884:30460 | ERROR    | scripts.knowledge_acquisition:_extract_relationships:652 | Failed to convert relationship: {'source': 'RNNs', 'relation': 'used_in', 'target': 'Natural Language Processing'}: 1 validation error for Relationship
relation
  Input should be 'uses', 'applies', 'implements', 'improves', 'outperforms', 'achieves', 'contains', 'consists_of', 'part_of', 'better_than', 'similar_to', 'different_from', 'leads_to', 'causes', 'affects', 'precedes', 'follows', 'concurrent_with', 'is_a', 'has_part' or 'related_to' [type=literal_error, input_value='used_in', input_type=str]
    For further information visit https://errors.pydantic.dev/2.10/v/literal_error
Traceback (most recent call last):

  File "C:\Users\mikeb\work\sifu2\run_agents.py", line 868, in <module>
    asyncio.run(main())

  File "C:\Python313\Lib\asyncio\runners.py", line 194, in run
    return runner.run(main)
  File "C:\Python313\Lib\asyncio\runners.py", line 118, in run
    return self._loop.run_until_complete(task)
  File "C:\Python313\Lib\asyncio\base_events.py", line 707, in run_until_complete
    self.run_forever()
  File "C:\Python313\Lib\asyncio\base_events.py", line 678, in run_forever
    self._run_once()
  File "C:\Python313\Lib\asyncio\base_events.py", line 2033, in _run_once
    handle._run()
  File "C:\Python313\Lib\asyncio\events.py", line 89, in _run
    self._context.run(self._callback, *self._args)

  File "C:\Users\mikeb\work\sifu2\run_agents.py", line 857, in main
    await agent.run()

  File "C:\Users\mikeb\work\sifu2\run_agents.py", line 691, in run
    result = await getattr(self, task.tool)(**task.args)

  File "C:\Users\mikeb\work\sifu2\run_agents.py", line 344, in _synthesize_knowledge
    knowledge = await self.knowledge_system.process_source(content)

  File "C:\Users\mikeb\work\sifu2\scripts\knowledge_acquisition.py", line 466, in process_source
    relationships = await self._extract_relationships(content)

> File "C:\Users\mikeb\work\sifu2\scripts\knowledge_acquisition.py", line 650, in _extract_relationships
    converted_relationships.append(Relationship(**rel))

  File "C:\Python313\Lib\site-packages\pydantic\main.py", line 214, in __init__
    validated_self = self.__pydantic_validator__.validate_python(data, self_instance=self)

pydantic_core._pydantic_core.ValidationError: 1 validation error for Relationship
relation
  Input should be 'uses', 'applies', 'implements', 'improves', 'outperforms', 'achieves', 'contains', 'consists_of', 'part_of', 'better_than', 'similar_to', 'different_from', 'leads_to', 'causes', 'affects', 'precedes', 'follows', 'concurrent_with', 'is_a', 'has_part' or 'related_to' [type=literal_error, input_value='used_in', input_type=str]
    For further information visit https://errors.pydantic.dev/2.10/v/literal_error
2025-02-09 15:03:56.367 | 29884:30460 | ERROR    | scripts.knowledge_acquisition:_extract_relationships:652 | Failed to convert relationship: {'source': 'Backpropagation', 'relation': 'used_in', 'target': 'Training Neural Networks'}: 1 validation error for Relationship
relation
  Input should be 'uses', 'applies', 'implements', 'improves', 'outperforms', 'achieves', 'contains', 'consists_of', 'part_of', 'better_than', 'similar_to', 'different_from', 'leads_to', 'causes', 'affects', 'precedes', 'follows', 'concurrent_with', 'is_a', 'has_part' or 'related_to' [type=literal_error, input_value='used_in', input_type=str]
    For further information visit https://errors.pydantic.dev/2.10/v/literal_error
Traceback (most recent call last):

  File "C:\Users\mikeb\work\sifu2\run_agents.py", line 868, in <module>
    asyncio.run(main())

  File "C:\Python313\Lib\asyncio\runners.py", line 194, in run
    return runner.run(main)
  File "C:\Python313\Lib\asyncio\runners.py", line 118, in run
    return self._loop.run_until_complete(task)
  File "C:\Python313\Lib\asyncio\base_events.py", line 707, in run_until_complete
    self.run_forever()
  File "C:\Python313\Lib\asyncio\base_events.py", line 678, in run_forever
    self._run_once()
  File "C:\Python313\Lib\asyncio\base_events.py", line 2033, in _run_once
    handle._run()
  File "C:\Python313\Lib\asyncio\events.py", line 89, in _run
    self._context.run(self._callback, *self._args)

  File "C:\Users\mikeb\work\sifu2\run_agents.py", line 857, in main
    await agent.run()

  File "C:\Users\mikeb\work\sifu2\run_agents.py", line 691, in run
    result = await getattr(self, task.tool)(**task.args)

  File "C:\Users\mikeb\work\sifu2\run_agents.py", line 344, in _synthesize_knowledge
    knowledge = await self.knowledge_system.process_source(content)

  File "C:\Users\mikeb\work\sifu2\scripts\knowledge_acquisition.py", line 466, in process_source
    relationships = await self._extract_relationships(content)

> File "C:\Users\mikeb\work\sifu2\scripts\knowledge_acquisition.py", line 650, in _extract_relationships
    converted_relationships.append(Relationship(**rel))

  File "C:\Python313\Lib\site-packages\pydantic\main.py", line 214, in __init__
    validated_self = self.__pydantic_validator__.validate_python(data, self_instance=self)

pydantic_core._pydantic_core.ValidationError: 1 validation error for Relationship
relation
  Input should be 'uses', 'applies', 'implements', 'improves', 'outperforms', 'achieves', 'contains', 'consists_of', 'part_of', 'better_than', 'similar_to', 'different_from', 'leads_to', 'causes', 'affects', 'precedes', 'follows', 'concurrent_with', 'is_a', 'has_part' or 'related_to' [type=literal_error, input_value='used_in', input_type=str]
    For further information visit https://errors.pydantic.dev/2.10/v/literal_error
2025-02-09 15:03:56.387 | 29884:30460 | ERROR    | scripts.knowledge_acquisition:_extract_relationships:652 | Failed to convert relationship: {'source': 'Gradient Descent', 'relation': 'used_in', 'target': 'Training Neural Networks'}: 1 validation error for Relationship
relation
  Input should be 'uses', 'applies', 'implements', 'improves', 'outperforms', 'achieves', 'contains', 'consists_of', 'part_of', 'better_than', 'similar_to', 'different_from', 'leads_to', 'causes', 'affects', 'precedes', 'follows', 'concurrent_with', 'is_a', 'has_part' or 'related_to' [type=literal_error, input_value='used_in', input_type=str]
    For further information visit https://errors.pydantic.dev/2.10/v/literal_error
Traceback (most recent call last):

  File "C:\Users\mikeb\work\sifu2\run_agents.py", line 868, in <module>
    asyncio.run(main())

  File "C:\Python313\Lib\asyncio\runners.py", line 194, in run
    return runner.run(main)
  File "C:\Python313\Lib\asyncio\runners.py", line 118, in run
    return self._loop.run_until_complete(task)
  File "C:\Python313\Lib\asyncio\base_events.py", line 707, in run_until_complete
    self.run_forever()
  File "C:\Python313\Lib\asyncio\base_events.py", line 678, in run_forever
    self._run_once()
  File "C:\Python313\Lib\asyncio\base_events.py", line 2033, in _run_once
    handle._run()
  File "C:\Python313\Lib\asyncio\events.py", line 89, in _run
    self._context.run(self._callback, *self._args)

  File "C:\Users\mikeb\work\sifu2\run_agents.py", line 857, in main
    await agent.run()

  File "C:\Users\mikeb\work\sifu2\run_agents.py", line 691, in run
    result = await getattr(self, task.tool)(**task.args)

  File "C:\Users\mikeb\work\sifu2\run_agents.py", line 344, in _synthesize_knowledge
    knowledge = await self.knowledge_system.process_source(content)

  File "C:\Users\mikeb\work\sifu2\scripts\knowledge_acquisition.py", line 466, in process_source
    relationships = await self._extract_relationships(content)

> File "C:\Users\mikeb\work\sifu2\scripts\knowledge_acquisition.py", line 650, in _extract_relationships
    converted_relationships.append(Relationship(**rel))

  File "C:\Python313\Lib\site-packages\pydantic\main.py", line 214, in __init__
    validated_self = self.__pydantic_validator__.validate_python(data, self_instance=self)

pydantic_core._pydantic_core.ValidationError: 1 validation error for Relationship
relation
  Input should be 'uses', 'applies', 'implements', 'improves', 'outperforms', 'achieves', 'contains', 'consists_of', 'part_of', 'better_than', 'similar_to', 'different_from', 'leads_to', 'causes', 'affects', 'precedes', 'follows', 'concurrent_with', 'is_a', 'has_part' or 'related_to' [type=literal_error, input_value='used_in', input_type=str]
    For further information visit https://errors.pydantic.dev/2.10/v/literal_error
2025-02-09 15:03:56.408 | 29884:30460 | INFO     | scripts.knowledge_acquisition:process_source:478 | KnowledgeAcquisition: Extracted 6 relationships
2025-02-09 15:03:56.410 | 29884:30460 | INFO     | scripts.knowledge_acquisition:process_source:482 | KnowledgeAcquisition: Relationship: Convolutional Neural Networks (CNNs) -> is_a -> Neural Networks
2025-02-09 15:03:56.411 | 29884:30460 | INFO     | scripts.knowledge_acquisition:process_source:482 | KnowledgeAcquisition: Relationship: Recurrent Neural Networks (RNNs) -> is_a -> Neural Networks
2025-02-09 15:03:56.413 | 29884:30460 | INFO     | scripts.knowledge_acquisition:process_source:482 | KnowledgeAcquisition: Relationship: Gradient Descent -> is_a -> Optimization Algorithm
2025-02-09 15:03:56.414 | 29884:30460 | INFO     | scripts.knowledge_acquisition:process_source:482 | KnowledgeAcquisition: Relationship: Activation Functions -> part_of -> Neural Networks
2025-02-09 15:03:56.415 | 29884:30460 | INFO     | scripts.knowledge_acquisition:process_source:482 | KnowledgeAcquisition: Relationship: Data Augmentation -> improves -> Model Accuracy
2025-02-09 15:03:56.417 | 29884:30460 | INFO     | scripts.knowledge_acquisition:process_source:482 | KnowledgeAcquisition: Relationship: Regularization Techniques -> improves -> Model Generalization
2025-02-09 15:03:56.418 | 29884:30460 | INFO     | scripts.knowledge_acquisition:process_source:488 | KnowledgeAcquisition: Generating metadata...
2025-02-09 15:03:57.387 | 29884:30460 | INFO     | scripts.knowledge_acquisition:process_source:495 | KnowledgeAcquisition: Generated metadata: {'source_type': 'text', 'confidence_score': 0.9, 'domain_relevance': 0.8, 'timestamp': '2024-02-09T12:45:00.000Z', 'validation_status': 'processed', 'domain': 'machine_learning'}
2025-02-09 15:03:57.388 | 29884:30460 | INFO     | scripts.knowledge_acquisition:process_source:501 | KnowledgeAcquisition: Evaluating confidence...
2025-02-09 15:03:58.706 | 29884:30460 | INFO     | scripts.knowledge_acquisition:process_source:511 | KnowledgeAcquisition: Confidence score: 0.8
2025-02-09 15:03:58.715 | 29884:30460 | INFO     | __main__:_synthesize_knowledge:325 | Knowledge Synthesis: Processing source: Check Domain Authority Score【No Login, Super Fast, FREE】 (source_9.txt)
2025-02-09 15:03:58.716 | 29884:30460 | INFO     | __main__:_synthesize_knowledge:329 | Knowledge Synthesis: Content preview:
![AI Writer for SEO Domain Authority (DA) is a metric that predicts how well a website is likely to rank on DA is determined by analyzing multiple factors, including the number of linking root domains and the total count of links, culminating in a single DA score. This score is commonly used for comparing the ranking potential of different websites or monitoring a website's strength over time. It's important to understand that Domain Authority is not utilized by Google in its ## Examples of doma...
2025-02-09 15:03:58.718 | 29884:30460 | INFO     | scripts.knowledge_acquisition:process_source:444 | KnowledgeAcquisition: Starting source processing with content length: 5785
2025-02-09 15:03:58.719 | 29884:30460 | INFO     | scripts.knowledge_acquisition:process_source:448 | KnowledgeAcquisition: Content preview:
![AI Writer for SEO Domain Authority (DA) is a metric that predicts how well a website is likely to rank on DA is determined by analyzing multiple factors, including the number of linking root domains...
2025-02-09 15:03:58.720 | 29884:30460 | INFO     | scripts.knowledge_acquisition:process_source:451 | KnowledgeAcquisition: Extracting entities...
2025-02-09 15:03:59.277 | 29884:30460 | INFO     | scripts.knowledge_acquisition:process_source:458 | KnowledgeAcquisition: Extracted 10 entities: ['Machine Learning', 'Deep Learning', 'Neural Networks', 'TensorFlow', 'Python', 'Keras', 'Computer Vision', 'Natural Language Processing', 'Data Science', 'Artificial Intelligence']
2025-02-09 15:03:59.279 | 29884:30460 | INFO     | scripts.knowledge_acquisition:process_source:464 | KnowledgeAcquisition: Extracting relationships...
2025-02-09 15:04:01.295 | 29884:30460 | ERROR    | scripts.knowledge_acquisition:_extract_relationships:652 | Failed to convert relationship: {'source': 'CNNs', 'relation': 'used_for', 'target': 'Image Recognition'}: 1 validation error for Relationship
relation
  Input should be 'uses', 'applies', 'implements', 'improves', 'outperforms', 'achieves', 'contains', 'consists_of', 'part_of', 'better_than', 'similar_to', 'different_from', 'leads_to', 'causes', 'affects', 'precedes', 'follows', 'concurrent_with', 'is_a', 'has_part' or 'related_to' [type=literal_error, input_value='used_for', input_type=str]
    For further information visit https://errors.pydantic.dev/2.10/v/literal_error
Traceback (most recent call last):

  File "C:\Users\mikeb\work\sifu2\run_agents.py", line 868, in <module>
    asyncio.run(main())

  File "C:\Python313\Lib\asyncio\runners.py", line 194, in run
    return runner.run(main)
  File "C:\Python313\Lib\asyncio\runners.py", line 118, in run
    return self._loop.run_until_complete(task)
  File "C:\Python313\Lib\asyncio\base_events.py", line 707, in run_until_complete
    self.run_forever()
  File "C:\Python313\Lib\asyncio\base_events.py", line 678, in run_forever
    self._run_once()
  File "C:\Python313\Lib\asyncio\base_events.py", line 2033, in _run_once
    handle._run()
  File "C:\Python313\Lib\asyncio\events.py", line 89, in _run
    self._context.run(self._callback, *self._args)

  File "C:\Users\mikeb\work\sifu2\run_agents.py", line 857, in main
    await agent.run()

  File "C:\Users\mikeb\work\sifu2\run_agents.py", line 691, in run
    result = await getattr(self, task.tool)(**task.args)

  File "C:\Users\mikeb\work\sifu2\run_agents.py", line 344, in _synthesize_knowledge
    knowledge = await self.knowledge_system.process_source(content)

  File "C:\Users\mikeb\work\sifu2\scripts\knowledge_acquisition.py", line 466, in process_source
    relationships = await self._extract_relationships(content)

> File "C:\Users\mikeb\work\sifu2\scripts\knowledge_acquisition.py", line 650, in _extract_relationships
    converted_relationships.append(Relationship(**rel))

  File "C:\Python313\Lib\site-packages\pydantic\main.py", line 214, in __init__
    validated_self = self.__pydantic_validator__.validate_python(data, self_instance=self)

pydantic_core._pydantic_core.ValidationError: 1 validation error for Relationship
relation
  Input should be 'uses', 'applies', 'implements', 'improves', 'outperforms', 'achieves', 'contains', 'consists_of', 'part_of', 'better_than', 'similar_to', 'different_from', 'leads_to', 'causes', 'affects', 'precedes', 'follows', 'concurrent_with', 'is_a', 'has_part' or 'related_to' [type=literal_error, input_value='used_for', input_type=str]
    For further information visit https://errors.pydantic.dev/2.10/v/literal_error
2025-02-09 15:04:01.317 | 29884:30460 | ERROR    | scripts.knowledge_acquisition:_extract_relationships:652 | Failed to convert relationship: {'source': 'RNNs', 'relation': 'used_for', 'target': 'Natural Language Processing'}: 1 validation error for Relationship
relation
  Input should be 'uses', 'applies', 'implements', 'improves', 'outperforms', 'achieves', 'contains', 'consists_of', 'part_of', 'better_than', 'similar_to', 'different_from', 'leads_to', 'causes', 'affects', 'precedes', 'follows', 'concurrent_with', 'is_a', 'has_part' or 'related_to' [type=literal_error, input_value='used_for', input_type=str]
    For further information visit https://errors.pydantic.dev/2.10/v/literal_error
Traceback (most recent call last):

  File "C:\Users\mikeb\work\sifu2\run_agents.py", line 868, in <module>
    asyncio.run(main())

  File "C:\Python313\Lib\asyncio\runners.py", line 194, in run
    return runner.run(main)
  File "C:\Python313\Lib\asyncio\runners.py", line 118, in run
    return self._loop.run_until_complete(task)
  File "C:\Python313\Lib\asyncio\base_events.py", line 707, in run_until_complete
    self.run_forever()
  File "C:\Python313\Lib\asyncio\base_events.py", line 678, in run_forever
    self._run_once()
  File "C:\Python313\Lib\asyncio\base_events.py", line 2033, in _run_once
    handle._run()
  File "C:\Python313\Lib\asyncio\events.py", line 89, in _run
    self._context.run(self._callback, *self._args)

  File "C:\Users\mikeb\work\sifu2\run_agents.py", line 857, in main
    await agent.run()

  File "C:\Users\mikeb\work\sifu2\run_agents.py", line 691, in run
    result = await getattr(self, task.tool)(**task.args)

  File "C:\Users\mikeb\work\sifu2\run_agents.py", line 344, in _synthesize_knowledge
    knowledge = await self.knowledge_system.process_source(content)

  File "C:\Users\mikeb\work\sifu2\scripts\knowledge_acquisition.py", line 466, in process_source
    relationships = await self._extract_relationships(content)

> File "C:\Users\mikeb\work\sifu2\scripts\knowledge_acquisition.py", line 650, in _extract_relationships
    converted_relationships.append(Relationship(**rel))

  File "C:\Python313\Lib\site-packages\pydantic\main.py", line 214, in __init__
    validated_self = self.__pydantic_validator__.validate_python(data, self_instance=self)

pydantic_core._pydantic_core.ValidationError: 1 validation error for Relationship
relation
  Input should be 'uses', 'applies', 'implements', 'improves', 'outperforms', 'achieves', 'contains', 'consists_of', 'part_of', 'better_than', 'similar_to', 'different_from', 'leads_to', 'causes', 'affects', 'precedes', 'follows', 'concurrent_with', 'is_a', 'has_part' or 'related_to' [type=literal_error, input_value='used_for', input_type=str]
    For further information visit https://errors.pydantic.dev/2.10/v/literal_error
2025-02-09 15:04:01.338 | 29884:30460 | INFO     | scripts.knowledge_acquisition:process_source:478 | KnowledgeAcquisition: Extracted 5 relationships
2025-02-09 15:04:01.339 | 29884:30460 | INFO     | scripts.knowledge_acquisition:process_source:482 | KnowledgeAcquisition: Relationship: Convolutional Neural Networks (CNNs) -> is_a -> Neural Networks
2025-02-09 15:04:01.341 | 29884:30460 | INFO     | scripts.knowledge_acquisition:process_source:482 | KnowledgeAcquisition: Relationship: Recurrent Neural Networks (RNNs) -> is_a -> Neural Networks
2025-02-09 15:04:01.342 | 29884:30460 | INFO     | scripts.knowledge_acquisition:process_source:482 | KnowledgeAcquisition: Relationship: Neural Networks -> is_a -> Machine Learning Model
2025-02-09 15:04:01.344 | 29884:30460 | INFO     | scripts.knowledge_acquisition:process_source:482 | KnowledgeAcquisition: Relationship: Data Preprocessing -> precedes -> Model Training
2025-02-09 15:04:01.345 | 29884:30460 | INFO     | scripts.knowledge_acquisition:process_source:482 | KnowledgeAcquisition: Relationship: Model Training -> leads_to -> Model Evaluation
2025-02-09 15:04:01.346 | 29884:30460 | INFO     | scripts.knowledge_acquisition:process_source:488 | KnowledgeAcquisition: Generating metadata...
2025-02-09 15:04:02.300 | 29884:30460 | INFO     | scripts.knowledge_acquisition:process_source:495 | KnowledgeAcquisition: Generated metadata: {'source_type': 'text', 'confidence_score': 0.85, 'domain_relevance': 0.9, 'timestamp': '2024-02-09T11:42:32.000Z', 'validation_status': 'processed', 'domain': 'machine_learning'}
2025-02-09 15:04:02.302 | 29884:30460 | INFO     | scripts.knowledge_acquisition:process_source:501 | KnowledgeAcquisition: Evaluating confidence...
2025-02-09 15:04:03.531 | 29884:30460 | INFO     | scripts.knowledge_acquisition:process_source:511 | KnowledgeAcquisition: Confidence score: 0.8
2025-02-09 15:04:03.540 | 29884:30460 | INFO     | __main__:run:657 | Execution: Executing task 2: _generate_examples
2025-02-09 15:04:03.541 | 29884:30460 | INFO     | __main__:run:678 | Execution: Found 10 knowledge entries for example generation
2025-02-09 15:04:50.747 | 29884:30460 | INFO     | __main__:run:657 | Execution: Executing task 3: _train_model
2025-02-09 15:04:50.749 | 29884:30460 | INFO     | __main__:run:688 | Execution: Found 67 examples for training
2025-02-09 15:04:50.755 | 29884:30460 | INFO     | __main__:run:722 | Decision: Making join decision
2025-02-09 15:04:50.758 | 29884:30460 | INFO     | scripts.llm_compiler:make_join_decision:412 | Decision: Making join decision
2025-02-09 15:04:51.613 | 29884:30460 | INFO     | __main__:run:733 | Compiler: Generating final result
2025-02-09 15:04:51.614 | 29884:30460 | INFO     | scripts.llm_compiler:_generate_final_result:560 | Compiler: Generating final result
2025-02-09 15:04:51.616 | 29884:30460 | INFO     | scripts.llm_compiler:_generate_final_result:570 | Compiler: Generated final result
2025-02-09 15:04:51.617 | 29884:30460 | INFO     | __main__:run:737 | Research: Research workflow completed successfully
