2025-02-09 14:56:53.963 | 40372:34912 | ERROR    | scripts.knowledge_acquisition:_extract_relationships:652 | Failed to convert relationship: {'source': 'Machine Learning Models', 'relation': 'used_in', 'target': 'Artificial Intelligence'}: 1 validation error for Relationship
relation
  Input should be 'is_a', 'has_part' or 'related_to' [type=literal_error, input_value='used_in', input_type=str]
    For further information visit https://errors.pydantic.dev/2.10/v/literal_error
Traceback (most recent call last):

  File "C:\Users\mikeb\work\sifu2\run_agents.py", line 868, in <module>
    asyncio.run(main())

  File "C:\Python313\Lib\asyncio\runners.py", line 194, in run
    return runner.run(main)
  File "C:\Python313\Lib\asyncio\runners.py", line 118, in run
    return self._loop.run_until_complete(task)
  File "C:\Python313\Lib\asyncio\base_events.py", line 707, in run_until_complete
    self.run_forever()
  File "C:\Python313\Lib\asyncio\base_events.py", line 678, in run_forever
    self._run_once()
  File "C:\Python313\Lib\asyncio\base_events.py", line 2033, in _run_once
    handle._run()
  File "C:\Python313\Lib\asyncio\events.py", line 89, in _run
    self._context.run(self._callback, *self._args)

  File "C:\Users\mikeb\work\sifu2\run_agents.py", line 857, in main
    await agent.run()

  File "C:\Users\mikeb\work\sifu2\run_agents.py", line 691, in run
    result = await getattr(self, task.tool)(**task.args)

  File "C:\Users\mikeb\work\sifu2\run_agents.py", line 344, in _synthesize_knowledge
    knowledge = await self.knowledge_system.process_source(content)

  File "C:\Users\mikeb\work\sifu2\scripts\knowledge_acquisition.py", line 466, in process_source
    relationships = await self._extract_relationships(content)

> File "C:\Users\mikeb\work\sifu2\scripts\knowledge_acquisition.py", line 650, in _extract_relationships
    converted_relationships.append(Relationship(**rel))

  File "C:\Python313\Lib\site-packages\pydantic\main.py", line 214, in __init__
    validated_self = self.__pydantic_validator__.validate_python(data, self_instance=self)

pydantic_core._pydantic_core.ValidationError: 1 validation error for Relationship
relation
  Input should be 'is_a', 'has_part' or 'related_to' [type=literal_error, input_value='used_in', input_type=str]
    For further information visit https://errors.pydantic.dev/2.10/v/literal_error
2025-02-09 14:56:54.007 | 40372:34912 | ERROR    | scripts.knowledge_acquisition:_extract_relationships:652 | Failed to convert relationship: {'source': 'Data Preprocessing', 'relation': 'precedes', 'target': 'Model Training'}: 1 validation error for Relationship
relation
  Input should be 'is_a', 'has_part' or 'related_to' [type=literal_error, input_value='precedes', input_type=str]
    For further information visit https://errors.pydantic.dev/2.10/v/literal_error
Traceback (most recent call last):

  File "C:\Users\mikeb\work\sifu2\run_agents.py", line 868, in <module>
    asyncio.run(main())

  File "C:\Python313\Lib\asyncio\runners.py", line 194, in run
    return runner.run(main)
  File "C:\Python313\Lib\asyncio\runners.py", line 118, in run
    return self._loop.run_until_complete(task)
  File "C:\Python313\Lib\asyncio\base_events.py", line 707, in run_until_complete
    self.run_forever()
  File "C:\Python313\Lib\asyncio\base_events.py", line 678, in run_forever
    self._run_once()
  File "C:\Python313\Lib\asyncio\base_events.py", line 2033, in _run_once
    handle._run()
  File "C:\Python313\Lib\asyncio\events.py", line 89, in _run
    self._context.run(self._callback, *self._args)

  File "C:\Users\mikeb\work\sifu2\run_agents.py", line 857, in main
    await agent.run()

  File "C:\Users\mikeb\work\sifu2\run_agents.py", line 691, in run
    result = await getattr(self, task.tool)(**task.args)

  File "C:\Users\mikeb\work\sifu2\run_agents.py", line 344, in _synthesize_knowledge
    knowledge = await self.knowledge_system.process_source(content)

  File "C:\Users\mikeb\work\sifu2\scripts\knowledge_acquisition.py", line 466, in process_source
    relationships = await self._extract_relationships(content)

> File "C:\Users\mikeb\work\sifu2\scripts\knowledge_acquisition.py", line 650, in _extract_relationships
    converted_relationships.append(Relationship(**rel))

  File "C:\Python313\Lib\site-packages\pydantic\main.py", line 214, in __init__
    validated_self = self.__pydantic_validator__.validate_python(data, self_instance=self)

pydantic_core._pydantic_core.ValidationError: 1 validation error for Relationship
relation
  Input should be 'is_a', 'has_part' or 'related_to' [type=literal_error, input_value='precedes', input_type=str]
    For further information visit https://errors.pydantic.dev/2.10/v/literal_error
2025-02-09 14:56:54.032 | 40372:34912 | ERROR    | scripts.knowledge_acquisition:_extract_relationships:652 | Failed to convert relationship: {'source': 'Model Training', 'relation': 'uses', 'target': 'Training Data'}: 1 validation error for Relationship
relation
  Input should be 'is_a', 'has_part' or 'related_to' [type=literal_error, input_value='uses', input_type=str]
    For further information visit https://errors.pydantic.dev/2.10/v/literal_error
Traceback (most recent call last):

  File "C:\Users\mikeb\work\sifu2\run_agents.py", line 868, in <module>
    asyncio.run(main())

  File "C:\Python313\Lib\asyncio\runners.py", line 194, in run
    return runner.run(main)
  File "C:\Python313\Lib\asyncio\runners.py", line 118, in run
    return self._loop.run_until_complete(task)
  File "C:\Python313\Lib\asyncio\base_events.py", line 707, in run_until_complete
    self.run_forever()
  File "C:\Python313\Lib\asyncio\base_events.py", line 678, in run_forever
    self._run_once()
  File "C:\Python313\Lib\asyncio\base_events.py", line 2033, in _run_once
    handle._run()
  File "C:\Python313\Lib\asyncio\events.py", line 89, in _run
    self._context.run(self._callback, *self._args)

  File "C:\Users\mikeb\work\sifu2\run_agents.py", line 857, in main
    await agent.run()

  File "C:\Users\mikeb\work\sifu2\run_agents.py", line 691, in run
    result = await getattr(self, task.tool)(**task.args)

  File "C:\Users\mikeb\work\sifu2\run_agents.py", line 344, in _synthesize_knowledge
    knowledge = await self.knowledge_system.process_source(content)

  File "C:\Users\mikeb\work\sifu2\scripts\knowledge_acquisition.py", line 466, in process_source
    relationships = await self._extract_relationships(content)

> File "C:\Users\mikeb\work\sifu2\scripts\knowledge_acquisition.py", line 650, in _extract_relationships
    converted_relationships.append(Relationship(**rel))

  File "C:\Python313\Lib\site-packages\pydantic\main.py", line 214, in __init__
    validated_self = self.__pydantic_validator__.validate_python(data, self_instance=self)

pydantic_core._pydantic_core.ValidationError: 1 validation error for Relationship
relation
  Input should be 'is_a', 'has_part' or 'related_to' [type=literal_error, input_value='uses', input_type=str]
    For further information visit https://errors.pydantic.dev/2.10/v/literal_error
2025-02-09 14:56:54.057 | 40372:34912 | ERROR    | scripts.knowledge_acquisition:_extract_relationships:652 | Failed to convert relationship: {'source': 'Model Training', 'relation': 'precedes', 'target': 'Model Evaluation'}: 1 validation error for Relationship
relation
  Input should be 'is_a', 'has_part' or 'related_to' [type=literal_error, input_value='precedes', input_type=str]
    For further information visit https://errors.pydantic.dev/2.10/v/literal_error
Traceback (most recent call last):

  File "C:\Users\mikeb\work\sifu2\run_agents.py", line 868, in <module>
    asyncio.run(main())

  File "C:\Python313\Lib\asyncio\runners.py", line 194, in run
    return runner.run(main)
  File "C:\Python313\Lib\asyncio\runners.py", line 118, in run
    return self._loop.run_until_complete(task)
  File "C:\Python313\Lib\asyncio\base_events.py", line 707, in run_until_complete
    self.run_forever()
  File "C:\Python313\Lib\asyncio\base_events.py", line 678, in run_forever
    self._run_once()
  File "C:\Python313\Lib\asyncio\base_events.py", line 2033, in _run_once
    handle._run()
  File "C:\Python313\Lib\asyncio\events.py", line 89, in _run
    self._context.run(self._callback, *self._args)

  File "C:\Users\mikeb\work\sifu2\run_agents.py", line 857, in main
    await agent.run()

  File "C:\Users\mikeb\work\sifu2\run_agents.py", line 691, in run
    result = await getattr(self, task.tool)(**task.args)

  File "C:\Users\mikeb\work\sifu2\run_agents.py", line 344, in _synthesize_knowledge
    knowledge = await self.knowledge_system.process_source(content)

  File "C:\Users\mikeb\work\sifu2\scripts\knowledge_acquisition.py", line 466, in process_source
    relationships = await self._extract_relationships(content)

> File "C:\Users\mikeb\work\sifu2\scripts\knowledge_acquisition.py", line 650, in _extract_relationships
    converted_relationships.append(Relationship(**rel))

  File "C:\Python313\Lib\site-packages\pydantic\main.py", line 214, in __init__
    validated_self = self.__pydantic_validator__.validate_python(data, self_instance=self)

pydantic_core._pydantic_core.ValidationError: 1 validation error for Relationship
relation
  Input should be 'is_a', 'has_part' or 'related_to' [type=literal_error, input_value='precedes', input_type=str]
    For further information visit https://errors.pydantic.dev/2.10/v/literal_error
2025-02-09 14:56:54.081 | 40372:34912 | ERROR    | scripts.knowledge_acquisition:_extract_relationships:652 | Failed to convert relationship: {'source': 'Model Evaluation', 'relation': 'uses', 'target': 'Validation Data'}: 1 validation error for Relationship
relation
  Input should be 'is_a', 'has_part' or 'related_to' [type=literal_error, input_value='uses', input_type=str]
    For further information visit https://errors.pydantic.dev/2.10/v/literal_error
Traceback (most recent call last):

  File "C:\Users\mikeb\work\sifu2\run_agents.py", line 868, in <module>
    asyncio.run(main())

  File "C:\Python313\Lib\asyncio\runners.py", line 194, in run
    return runner.run(main)
  File "C:\Python313\Lib\asyncio\runners.py", line 118, in run
    return self._loop.run_until_complete(task)
  File "C:\Python313\Lib\asyncio\base_events.py", line 707, in run_until_complete
    self.run_forever()
  File "C:\Python313\Lib\asyncio\base_events.py", line 678, in run_forever
    self._run_once()
  File "C:\Python313\Lib\asyncio\base_events.py", line 2033, in _run_once
    handle._run()
  File "C:\Python313\Lib\asyncio\events.py", line 89, in _run
    self._context.run(self._callback, *self._args)

  File "C:\Users\mikeb\work\sifu2\run_agents.py", line 857, in main
    await agent.run()

  File "C:\Users\mikeb\work\sifu2\run_agents.py", line 691, in run
    result = await getattr(self, task.tool)(**task.args)

  File "C:\Users\mikeb\work\sifu2\run_agents.py", line 344, in _synthesize_knowledge
    knowledge = await self.knowledge_system.process_source(content)

  File "C:\Users\mikeb\work\sifu2\scripts\knowledge_acquisition.py", line 466, in process_source
    relationships = await self._extract_relationships(content)

> File "C:\Users\mikeb\work\sifu2\scripts\knowledge_acquisition.py", line 650, in _extract_relationships
    converted_relationships.append(Relationship(**rel))

  File "C:\Python313\Lib\site-packages\pydantic\main.py", line 214, in __init__
    validated_self = self.__pydantic_validator__.validate_python(data, self_instance=self)

pydantic_core._pydantic_core.ValidationError: 1 validation error for Relationship
relation
  Input should be 'is_a', 'has_part' or 'related_to' [type=literal_error, input_value='uses', input_type=str]
    For further information visit https://errors.pydantic.dev/2.10/v/literal_error
2025-02-09 14:56:54.105 | 40372:34912 | ERROR    | scripts.knowledge_acquisition:_extract_relationships:652 | Failed to convert relationship: {'source': 'CNNs', 'relation': 'applied_to', 'target': 'Image Recognition'}: 1 validation error for Relationship
relation
  Input should be 'is_a', 'has_part' or 'related_to' [type=literal_error, input_value='applied_to', input_type=str]
    For further information visit https://errors.pydantic.dev/2.10/v/literal_error
Traceback (most recent call last):

  File "C:\Users\mikeb\work\sifu2\run_agents.py", line 868, in <module>
    asyncio.run(main())

  File "C:\Python313\Lib\asyncio\runners.py", line 194, in run
    return runner.run(main)
  File "C:\Python313\Lib\asyncio\runners.py", line 118, in run
    return self._loop.run_until_complete(task)
  File "C:\Python313\Lib\asyncio\base_events.py", line 707, in run_until_complete
    self.run_forever()
  File "C:\Python313\Lib\asyncio\base_events.py", line 678, in run_forever
    self._run_once()
  File "C:\Python313\Lib\asyncio\base_events.py", line 2033, in _run_once
    handle._run()
  File "C:\Python313\Lib\asyncio\events.py", line 89, in _run
    self._context.run(self._callback, *self._args)

  File "C:\Users\mikeb\work\sifu2\run_agents.py", line 857, in main
    await agent.run()

  File "C:\Users\mikeb\work\sifu2\run_agents.py", line 691, in run
    result = await getattr(self, task.tool)(**task.args)

  File "C:\Users\mikeb\work\sifu2\run_agents.py", line 344, in _synthesize_knowledge
    knowledge = await self.knowledge_system.process_source(content)

  File "C:\Users\mikeb\work\sifu2\scripts\knowledge_acquisition.py", line 466, in process_source
    relationships = await self._extract_relationships(content)

> File "C:\Users\mikeb\work\sifu2\scripts\knowledge_acquisition.py", line 650, in _extract_relationships
    converted_relationships.append(Relationship(**rel))

  File "C:\Python313\Lib\site-packages\pydantic\main.py", line 214, in __init__
    validated_self = self.__pydantic_validator__.validate_python(data, self_instance=self)

pydantic_core._pydantic_core.ValidationError: 1 validation error for Relationship
relation
  Input should be 'is_a', 'has_part' or 'related_to' [type=literal_error, input_value='applied_to', input_type=str]
    For further information visit https://errors.pydantic.dev/2.10/v/literal_error
2025-02-09 14:56:54.128 | 40372:34912 | ERROR    | scripts.knowledge_acquisition:_extract_relationships:652 | Failed to convert relationship: {'source': 'RNNs', 'relation': 'applied_to', 'target': 'Natural Language Processing'}: 1 validation error for Relationship
relation
  Input should be 'is_a', 'has_part' or 'related_to' [type=literal_error, input_value='applied_to', input_type=str]
    For further information visit https://errors.pydantic.dev/2.10/v/literal_error
Traceback (most recent call last):

  File "C:\Users\mikeb\work\sifu2\run_agents.py", line 868, in <module>
    asyncio.run(main())

  File "C:\Python313\Lib\asyncio\runners.py", line 194, in run
    return runner.run(main)
  File "C:\Python313\Lib\asyncio\runners.py", line 118, in run
    return self._loop.run_until_complete(task)
  File "C:\Python313\Lib\asyncio\base_events.py", line 707, in run_until_complete
    self.run_forever()
  File "C:\Python313\Lib\asyncio\base_events.py", line 678, in run_forever
    self._run_once()
  File "C:\Python313\Lib\asyncio\base_events.py", line 2033, in _run_once
    handle._run()
  File "C:\Python313\Lib\asyncio\events.py", line 89, in _run
    self._context.run(self._callback, *self._args)

  File "C:\Users\mikeb\work\sifu2\run_agents.py", line 857, in main
    await agent.run()

  File "C:\Users\mikeb\work\sifu2\run_agents.py", line 691, in run
    result = await getattr(self, task.tool)(**task.args)

  File "C:\Users\mikeb\work\sifu2\run_agents.py", line 344, in _synthesize_knowledge
    knowledge = await self.knowledge_system.process_source(content)

  File "C:\Users\mikeb\work\sifu2\scripts\knowledge_acquisition.py", line 466, in process_source
    relationships = await self._extract_relationships(content)

> File "C:\Users\mikeb\work\sifu2\scripts\knowledge_acquisition.py", line 650, in _extract_relationships
    converted_relationships.append(Relationship(**rel))

  File "C:\Python313\Lib\site-packages\pydantic\main.py", line 214, in __init__
    validated_self = self.__pydantic_validator__.validate_python(data, self_instance=self)

pydantic_core._pydantic_core.ValidationError: 1 validation error for Relationship
relation
  Input should be 'is_a', 'has_part' or 'related_to' [type=literal_error, input_value='applied_to', input_type=str]
    For further information visit https://errors.pydantic.dev/2.10/v/literal_error
2025-02-09 14:57:00.529 | 40372:34912 | ERROR    | scripts.knowledge_acquisition:_extract_relationships:652 | Failed to convert relationship: {'source': 'Data Preprocessing', 'relation': 'precedes', 'target': 'Model Training'}: 1 validation error for Relationship
relation
  Input should be 'is_a', 'has_part' or 'related_to' [type=literal_error, input_value='precedes', input_type=str]
    For further information visit https://errors.pydantic.dev/2.10/v/literal_error
Traceback (most recent call last):

  File "C:\Users\mikeb\work\sifu2\run_agents.py", line 868, in <module>
    asyncio.run(main())

  File "C:\Python313\Lib\asyncio\runners.py", line 194, in run
    return runner.run(main)
  File "C:\Python313\Lib\asyncio\runners.py", line 118, in run
    return self._loop.run_until_complete(task)
  File "C:\Python313\Lib\asyncio\base_events.py", line 707, in run_until_complete
    self.run_forever()
  File "C:\Python313\Lib\asyncio\base_events.py", line 678, in run_forever
    self._run_once()
  File "C:\Python313\Lib\asyncio\base_events.py", line 2033, in _run_once
    handle._run()
  File "C:\Python313\Lib\asyncio\events.py", line 89, in _run
    self._context.run(self._callback, *self._args)

  File "C:\Users\mikeb\work\sifu2\run_agents.py", line 857, in main
    await agent.run()

  File "C:\Users\mikeb\work\sifu2\run_agents.py", line 691, in run
    result = await getattr(self, task.tool)(**task.args)

  File "C:\Users\mikeb\work\sifu2\run_agents.py", line 344, in _synthesize_knowledge
    knowledge = await self.knowledge_system.process_source(content)

  File "C:\Users\mikeb\work\sifu2\scripts\knowledge_acquisition.py", line 466, in process_source
    relationships = await self._extract_relationships(content)

> File "C:\Users\mikeb\work\sifu2\scripts\knowledge_acquisition.py", line 650, in _extract_relationships
    converted_relationships.append(Relationship(**rel))

  File "C:\Python313\Lib\site-packages\pydantic\main.py", line 214, in __init__
    validated_self = self.__pydantic_validator__.validate_python(data, self_instance=self)

pydantic_core._pydantic_core.ValidationError: 1 validation error for Relationship
relation
  Input should be 'is_a', 'has_part' or 'related_to' [type=literal_error, input_value='precedes', input_type=str]
    For further information visit https://errors.pydantic.dev/2.10/v/literal_error
2025-02-09 14:57:00.555 | 40372:34912 | ERROR    | scripts.knowledge_acquisition:_extract_relationships:652 | Failed to convert relationship: {'source': 'Model Training', 'relation': 'uses', 'target': 'Training Data'}: 1 validation error for Relationship
relation
  Input should be 'is_a', 'has_part' or 'related_to' [type=literal_error, input_value='uses', input_type=str]
    For further information visit https://errors.pydantic.dev/2.10/v/literal_error
Traceback (most recent call last):

  File "C:\Users\mikeb\work\sifu2\run_agents.py", line 868, in <module>
    asyncio.run(main())

  File "C:\Python313\Lib\asyncio\runners.py", line 194, in run
    return runner.run(main)
  File "C:\Python313\Lib\asyncio\runners.py", line 118, in run
    return self._loop.run_until_complete(task)
  File "C:\Python313\Lib\asyncio\base_events.py", line 707, in run_until_complete
    self.run_forever()
  File "C:\Python313\Lib\asyncio\base_events.py", line 678, in run_forever
    self._run_once()
  File "C:\Python313\Lib\asyncio\base_events.py", line 2033, in _run_once
    handle._run()
  File "C:\Python313\Lib\asyncio\events.py", line 89, in _run
    self._context.run(self._callback, *self._args)

  File "C:\Users\mikeb\work\sifu2\run_agents.py", line 857, in main
    await agent.run()

  File "C:\Users\mikeb\work\sifu2\run_agents.py", line 691, in run
    result = await getattr(self, task.tool)(**task.args)

  File "C:\Users\mikeb\work\sifu2\run_agents.py", line 344, in _synthesize_knowledge
    knowledge = await self.knowledge_system.process_source(content)

  File "C:\Users\mikeb\work\sifu2\scripts\knowledge_acquisition.py", line 466, in process_source
    relationships = await self._extract_relationships(content)

> File "C:\Users\mikeb\work\sifu2\scripts\knowledge_acquisition.py", line 650, in _extract_relationships
    converted_relationships.append(Relationship(**rel))

  File "C:\Python313\Lib\site-packages\pydantic\main.py", line 214, in __init__
    validated_self = self.__pydantic_validator__.validate_python(data, self_instance=self)

pydantic_core._pydantic_core.ValidationError: 1 validation error for Relationship
relation
  Input should be 'is_a', 'has_part' or 'related_to' [type=literal_error, input_value='uses', input_type=str]
    For further information visit https://errors.pydantic.dev/2.10/v/literal_error
2025-02-09 14:57:00.578 | 40372:34912 | ERROR    | scripts.knowledge_acquisition:_extract_relationships:652 | Failed to convert relationship: {'source': 'Model Training', 'relation': 'produces', 'target': 'Trained Model'}: 1 validation error for Relationship
relation
  Input should be 'is_a', 'has_part' or 'related_to' [type=literal_error, input_value='produces', input_type=str]
    For further information visit https://errors.pydantic.dev/2.10/v/literal_error
Traceback (most recent call last):

  File "C:\Users\mikeb\work\sifu2\run_agents.py", line 868, in <module>
    asyncio.run(main())

  File "C:\Python313\Lib\asyncio\runners.py", line 194, in run
    return runner.run(main)
  File "C:\Python313\Lib\asyncio\runners.py", line 118, in run
    return self._loop.run_until_complete(task)
  File "C:\Python313\Lib\asyncio\base_events.py", line 707, in run_until_complete
    self.run_forever()
  File "C:\Python313\Lib\asyncio\base_events.py", line 678, in run_forever
    self._run_once()
  File "C:\Python313\Lib\asyncio\base_events.py", line 2033, in _run_once
    handle._run()
  File "C:\Python313\Lib\asyncio\events.py", line 89, in _run
    self._context.run(self._callback, *self._args)

  File "C:\Users\mikeb\work\sifu2\run_agents.py", line 857, in main
    await agent.run()

  File "C:\Users\mikeb\work\sifu2\run_agents.py", line 691, in run
    result = await getattr(self, task.tool)(**task.args)

  File "C:\Users\mikeb\work\sifu2\run_agents.py", line 344, in _synthesize_knowledge
    knowledge = await self.knowledge_system.process_source(content)

  File "C:\Users\mikeb\work\sifu2\scripts\knowledge_acquisition.py", line 466, in process_source
    relationships = await self._extract_relationships(content)

> File "C:\Users\mikeb\work\sifu2\scripts\knowledge_acquisition.py", line 650, in _extract_relationships
    converted_relationships.append(Relationship(**rel))

  File "C:\Python313\Lib\site-packages\pydantic\main.py", line 214, in __init__
    validated_self = self.__pydantic_validator__.validate_python(data, self_instance=self)

pydantic_core._pydantic_core.ValidationError: 1 validation error for Relationship
relation
  Input should be 'is_a', 'has_part' or 'related_to' [type=literal_error, input_value='produces', input_type=str]
    For further information visit https://errors.pydantic.dev/2.10/v/literal_error
2025-02-09 14:57:00.600 | 40372:34912 | ERROR    | scripts.knowledge_acquisition:_extract_relationships:652 | Failed to convert relationship: {'source': 'Trained Model', 'relation': 'used_in', 'target': 'Model Evaluation'}: 1 validation error for Relationship
relation
  Input should be 'is_a', 'has_part' or 'related_to' [type=literal_error, input_value='used_in', input_type=str]
    For further information visit https://errors.pydantic.dev/2.10/v/literal_error
Traceback (most recent call last):

  File "C:\Users\mikeb\work\sifu2\run_agents.py", line 868, in <module>
    asyncio.run(main())

  File "C:\Python313\Lib\asyncio\runners.py", line 194, in run
    return runner.run(main)
  File "C:\Python313\Lib\asyncio\runners.py", line 118, in run
    return self._loop.run_until_complete(task)
  File "C:\Python313\Lib\asyncio\base_events.py", line 707, in run_until_complete
    self.run_forever()
  File "C:\Python313\Lib\asyncio\base_events.py", line 678, in run_forever
    self._run_once()
  File "C:\Python313\Lib\asyncio\base_events.py", line 2033, in _run_once
    handle._run()
  File "C:\Python313\Lib\asyncio\events.py", line 89, in _run
    self._context.run(self._callback, *self._args)

  File "C:\Users\mikeb\work\sifu2\run_agents.py", line 857, in main
    await agent.run()

  File "C:\Users\mikeb\work\sifu2\run_agents.py", line 691, in run
    result = await getattr(self, task.tool)(**task.args)

  File "C:\Users\mikeb\work\sifu2\run_agents.py", line 344, in _synthesize_knowledge
    knowledge = await self.knowledge_system.process_source(content)

  File "C:\Users\mikeb\work\sifu2\scripts\knowledge_acquisition.py", line 466, in process_source
    relationships = await self._extract_relationships(content)

> File "C:\Users\mikeb\work\sifu2\scripts\knowledge_acquisition.py", line 650, in _extract_relationships
    converted_relationships.append(Relationship(**rel))

  File "C:\Python313\Lib\site-packages\pydantic\main.py", line 214, in __init__
    validated_self = self.__pydantic_validator__.validate_python(data, self_instance=self)

pydantic_core._pydantic_core.ValidationError: 1 validation error for Relationship
relation
  Input should be 'is_a', 'has_part' or 'related_to' [type=literal_error, input_value='used_in', input_type=str]
    For further information visit https://errors.pydantic.dev/2.10/v/literal_error
2025-02-09 14:57:00.625 | 40372:34912 | ERROR    | scripts.knowledge_acquisition:_extract_relationships:652 | Failed to convert relationship: {'source': 'Model Evaluation', 'relation': 'uses', 'target': 'Evaluation Metrics'}: 1 validation error for Relationship
relation
  Input should be 'is_a', 'has_part' or 'related_to' [type=literal_error, input_value='uses', input_type=str]
    For further information visit https://errors.pydantic.dev/2.10/v/literal_error
Traceback (most recent call last):

  File "C:\Users\mikeb\work\sifu2\run_agents.py", line 868, in <module>
    asyncio.run(main())

  File "C:\Python313\Lib\asyncio\runners.py", line 194, in run
    return runner.run(main)
  File "C:\Python313\Lib\asyncio\runners.py", line 118, in run
    return self._loop.run_until_complete(task)
  File "C:\Python313\Lib\asyncio\base_events.py", line 707, in run_until_complete
    self.run_forever()
  File "C:\Python313\Lib\asyncio\base_events.py", line 678, in run_forever
    self._run_once()
  File "C:\Python313\Lib\asyncio\base_events.py", line 2033, in _run_once
    handle._run()
  File "C:\Python313\Lib\asyncio\events.py", line 89, in _run
    self._context.run(self._callback, *self._args)

  File "C:\Users\mikeb\work\sifu2\run_agents.py", line 857, in main
    await agent.run()

  File "C:\Users\mikeb\work\sifu2\run_agents.py", line 691, in run
    result = await getattr(self, task.tool)(**task.args)

  File "C:\Users\mikeb\work\sifu2\run_agents.py", line 344, in _synthesize_knowledge
    knowledge = await self.knowledge_system.process_source(content)

  File "C:\Users\mikeb\work\sifu2\scripts\knowledge_acquisition.py", line 466, in process_source
    relationships = await self._extract_relationships(content)

> File "C:\Users\mikeb\work\sifu2\scripts\knowledge_acquisition.py", line 650, in _extract_relationships
    converted_relationships.append(Relationship(**rel))

  File "C:\Python313\Lib\site-packages\pydantic\main.py", line 214, in __init__
    validated_self = self.__pydantic_validator__.validate_python(data, self_instance=self)

pydantic_core._pydantic_core.ValidationError: 1 validation error for Relationship
relation
  Input should be 'is_a', 'has_part' or 'related_to' [type=literal_error, input_value='uses', input_type=str]
    For further information visit https://errors.pydantic.dev/2.10/v/literal_error
2025-02-09 14:57:00.649 | 40372:34912 | ERROR    | scripts.knowledge_acquisition:_extract_relationships:652 | Failed to convert relationship: {'source': 'CNNs', 'relation': 'applied_to', 'target': 'Image Recognition'}: 1 validation error for Relationship
relation
  Input should be 'is_a', 'has_part' or 'related_to' [type=literal_error, input_value='applied_to', input_type=str]
    For further information visit https://errors.pydantic.dev/2.10/v/literal_error
Traceback (most recent call last):

  File "C:\Users\mikeb\work\sifu2\run_agents.py", line 868, in <module>
    asyncio.run(main())

  File "C:\Python313\Lib\asyncio\runners.py", line 194, in run
    return runner.run(main)
  File "C:\Python313\Lib\asyncio\runners.py", line 118, in run
    return self._loop.run_until_complete(task)
  File "C:\Python313\Lib\asyncio\base_events.py", line 707, in run_until_complete
    self.run_forever()
  File "C:\Python313\Lib\asyncio\base_events.py", line 678, in run_forever
    self._run_once()
  File "C:\Python313\Lib\asyncio\base_events.py", line 2033, in _run_once
    handle._run()
  File "C:\Python313\Lib\asyncio\events.py", line 89, in _run
    self._context.run(self._callback, *self._args)

  File "C:\Users\mikeb\work\sifu2\run_agents.py", line 857, in main
    await agent.run()

  File "C:\Users\mikeb\work\sifu2\run_agents.py", line 691, in run
    result = await getattr(self, task.tool)(**task.args)

  File "C:\Users\mikeb\work\sifu2\run_agents.py", line 344, in _synthesize_knowledge
    knowledge = await self.knowledge_system.process_source(content)

  File "C:\Users\mikeb\work\sifu2\scripts\knowledge_acquisition.py", line 466, in process_source
    relationships = await self._extract_relationships(content)

> File "C:\Users\mikeb\work\sifu2\scripts\knowledge_acquisition.py", line 650, in _extract_relationships
    converted_relationships.append(Relationship(**rel))

  File "C:\Python313\Lib\site-packages\pydantic\main.py", line 214, in __init__
    validated_self = self.__pydantic_validator__.validate_python(data, self_instance=self)

pydantic_core._pydantic_core.ValidationError: 1 validation error for Relationship
relation
  Input should be 'is_a', 'has_part' or 'related_to' [type=literal_error, input_value='applied_to', input_type=str]
    For further information visit https://errors.pydantic.dev/2.10/v/literal_error
2025-02-09 14:57:00.674 | 40372:34912 | ERROR    | scripts.knowledge_acquisition:_extract_relationships:652 | Failed to convert relationship: {'source': 'RNNs', 'relation': 'applied_to', 'target': 'Natural Language Processing'}: 1 validation error for Relationship
relation
  Input should be 'is_a', 'has_part' or 'related_to' [type=literal_error, input_value='applied_to', input_type=str]
    For further information visit https://errors.pydantic.dev/2.10/v/literal_error
Traceback (most recent call last):

  File "C:\Users\mikeb\work\sifu2\run_agents.py", line 868, in <module>
    asyncio.run(main())

  File "C:\Python313\Lib\asyncio\runners.py", line 194, in run
    return runner.run(main)
  File "C:\Python313\Lib\asyncio\runners.py", line 118, in run
    return self._loop.run_until_complete(task)
  File "C:\Python313\Lib\asyncio\base_events.py", line 707, in run_until_complete
    self.run_forever()
  File "C:\Python313\Lib\asyncio\base_events.py", line 678, in run_forever
    self._run_once()
  File "C:\Python313\Lib\asyncio\base_events.py", line 2033, in _run_once
    handle._run()
  File "C:\Python313\Lib\asyncio\events.py", line 89, in _run
    self._context.run(self._callback, *self._args)

  File "C:\Users\mikeb\work\sifu2\run_agents.py", line 857, in main
    await agent.run()

  File "C:\Users\mikeb\work\sifu2\run_agents.py", line 691, in run
    result = await getattr(self, task.tool)(**task.args)

  File "C:\Users\mikeb\work\sifu2\run_agents.py", line 344, in _synthesize_knowledge
    knowledge = await self.knowledge_system.process_source(content)

  File "C:\Users\mikeb\work\sifu2\scripts\knowledge_acquisition.py", line 466, in process_source
    relationships = await self._extract_relationships(content)

> File "C:\Users\mikeb\work\sifu2\scripts\knowledge_acquisition.py", line 650, in _extract_relationships
    converted_relationships.append(Relationship(**rel))

  File "C:\Python313\Lib\site-packages\pydantic\main.py", line 214, in __init__
    validated_self = self.__pydantic_validator__.validate_python(data, self_instance=self)

pydantic_core._pydantic_core.ValidationError: 1 validation error for Relationship
relation
  Input should be 'is_a', 'has_part' or 'related_to' [type=literal_error, input_value='applied_to', input_type=str]
    For further information visit https://errors.pydantic.dev/2.10/v/literal_error
2025-02-09 14:57:07.370 | 40372:34912 | ERROR    | scripts.knowledge_acquisition:_extract_relationships:652 | Failed to convert relationship: {'source': 'Data Preprocessing', 'relation': 'precedes', 'target': 'Model Training'}: 1 validation error for Relationship
relation
  Input should be 'is_a', 'has_part' or 'related_to' [type=literal_error, input_value='precedes', input_type=str]
    For further information visit https://errors.pydantic.dev/2.10/v/literal_error
Traceback (most recent call last):

  File "C:\Users\mikeb\work\sifu2\run_agents.py", line 868, in <module>
    asyncio.run(main())

  File "C:\Python313\Lib\asyncio\runners.py", line 194, in run
    return runner.run(main)
  File "C:\Python313\Lib\asyncio\runners.py", line 118, in run
    return self._loop.run_until_complete(task)
  File "C:\Python313\Lib\asyncio\base_events.py", line 707, in run_until_complete
    self.run_forever()
  File "C:\Python313\Lib\asyncio\base_events.py", line 678, in run_forever
    self._run_once()
  File "C:\Python313\Lib\asyncio\base_events.py", line 2033, in _run_once
    handle._run()
  File "C:\Python313\Lib\asyncio\events.py", line 89, in _run
    self._context.run(self._callback, *self._args)

  File "C:\Users\mikeb\work\sifu2\run_agents.py", line 857, in main
    await agent.run()

  File "C:\Users\mikeb\work\sifu2\run_agents.py", line 691, in run
    result = await getattr(self, task.tool)(**task.args)

  File "C:\Users\mikeb\work\sifu2\run_agents.py", line 344, in _synthesize_knowledge
    knowledge = await self.knowledge_system.process_source(content)

  File "C:\Users\mikeb\work\sifu2\scripts\knowledge_acquisition.py", line 466, in process_source
    relationships = await self._extract_relationships(content)

> File "C:\Users\mikeb\work\sifu2\scripts\knowledge_acquisition.py", line 650, in _extract_relationships
    converted_relationships.append(Relationship(**rel))

  File "C:\Python313\Lib\site-packages\pydantic\main.py", line 214, in __init__
    validated_self = self.__pydantic_validator__.validate_python(data, self_instance=self)

pydantic_core._pydantic_core.ValidationError: 1 validation error for Relationship
relation
  Input should be 'is_a', 'has_part' or 'related_to' [type=literal_error, input_value='precedes', input_type=str]
    For further information visit https://errors.pydantic.dev/2.10/v/literal_error
2025-02-09 14:57:07.391 | 40372:34912 | ERROR    | scripts.knowledge_acquisition:_extract_relationships:652 | Failed to convert relationship: {'source': 'Model Training', 'relation': 'uses', 'target': 'Training Data'}: 1 validation error for Relationship
relation
  Input should be 'is_a', 'has_part' or 'related_to' [type=literal_error, input_value='uses', input_type=str]
    For further information visit https://errors.pydantic.dev/2.10/v/literal_error
Traceback (most recent call last):

  File "C:\Users\mikeb\work\sifu2\run_agents.py", line 868, in <module>
    asyncio.run(main())

  File "C:\Python313\Lib\asyncio\runners.py", line 194, in run
    return runner.run(main)
  File "C:\Python313\Lib\asyncio\runners.py", line 118, in run
    return self._loop.run_until_complete(task)
  File "C:\Python313\Lib\asyncio\base_events.py", line 707, in run_until_complete
    self.run_forever()
  File "C:\Python313\Lib\asyncio\base_events.py", line 678, in run_forever
    self._run_once()
  File "C:\Python313\Lib\asyncio\base_events.py", line 2033, in _run_once
    handle._run()
  File "C:\Python313\Lib\asyncio\events.py", line 89, in _run
    self._context.run(self._callback, *self._args)

  File "C:\Users\mikeb\work\sifu2\run_agents.py", line 857, in main
    await agent.run()

  File "C:\Users\mikeb\work\sifu2\run_agents.py", line 691, in run
    result = await getattr(self, task.tool)(**task.args)

  File "C:\Users\mikeb\work\sifu2\run_agents.py", line 344, in _synthesize_knowledge
    knowledge = await self.knowledge_system.process_source(content)

  File "C:\Users\mikeb\work\sifu2\scripts\knowledge_acquisition.py", line 466, in process_source
    relationships = await self._extract_relationships(content)

> File "C:\Users\mikeb\work\sifu2\scripts\knowledge_acquisition.py", line 650, in _extract_relationships
    converted_relationships.append(Relationship(**rel))

  File "C:\Python313\Lib\site-packages\pydantic\main.py", line 214, in __init__
    validated_self = self.__pydantic_validator__.validate_python(data, self_instance=self)

pydantic_core._pydantic_core.ValidationError: 1 validation error for Relationship
relation
  Input should be 'is_a', 'has_part' or 'related_to' [type=literal_error, input_value='uses', input_type=str]
    For further information visit https://errors.pydantic.dev/2.10/v/literal_error
2025-02-09 14:57:07.413 | 40372:34912 | ERROR    | scripts.knowledge_acquisition:_extract_relationships:652 | Failed to convert relationship: {'source': 'Model Training', 'relation': 'output_of', 'target': 'Trained Model'}: 1 validation error for Relationship
relation
  Input should be 'is_a', 'has_part' or 'related_to' [type=literal_error, input_value='output_of', input_type=str]
    For further information visit https://errors.pydantic.dev/2.10/v/literal_error
Traceback (most recent call last):

  File "C:\Users\mikeb\work\sifu2\run_agents.py", line 868, in <module>
    asyncio.run(main())

  File "C:\Python313\Lib\asyncio\runners.py", line 194, in run
    return runner.run(main)
  File "C:\Python313\Lib\asyncio\runners.py", line 118, in run
    return self._loop.run_until_complete(task)
  File "C:\Python313\Lib\asyncio\base_events.py", line 707, in run_until_complete
    self.run_forever()
  File "C:\Python313\Lib\asyncio\base_events.py", line 678, in run_forever
    self._run_once()
  File "C:\Python313\Lib\asyncio\base_events.py", line 2033, in _run_once
    handle._run()
  File "C:\Python313\Lib\asyncio\events.py", line 89, in _run
    self._context.run(self._callback, *self._args)

  File "C:\Users\mikeb\work\sifu2\run_agents.py", line 857, in main
    await agent.run()

  File "C:\Users\mikeb\work\sifu2\run_agents.py", line 691, in run
    result = await getattr(self, task.tool)(**task.args)

  File "C:\Users\mikeb\work\sifu2\run_agents.py", line 344, in _synthesize_knowledge
    knowledge = await self.knowledge_system.process_source(content)

  File "C:\Users\mikeb\work\sifu2\scripts\knowledge_acquisition.py", line 466, in process_source
    relationships = await self._extract_relationships(content)

> File "C:\Users\mikeb\work\sifu2\scripts\knowledge_acquisition.py", line 650, in _extract_relationships
    converted_relationships.append(Relationship(**rel))

  File "C:\Python313\Lib\site-packages\pydantic\main.py", line 214, in __init__
    validated_self = self.__pydantic_validator__.validate_python(data, self_instance=self)

pydantic_core._pydantic_core.ValidationError: 1 validation error for Relationship
relation
  Input should be 'is_a', 'has_part' or 'related_to' [type=literal_error, input_value='output_of', input_type=str]
    For further information visit https://errors.pydantic.dev/2.10/v/literal_error
2025-02-09 14:57:07.437 | 40372:34912 | ERROR    | scripts.knowledge_acquisition:_extract_relationships:652 | Failed to convert relationship: {'source': 'Trained Model', 'relation': 'input_to', 'target': 'Model Evaluation'}: 1 validation error for Relationship
relation
  Input should be 'is_a', 'has_part' or 'related_to' [type=literal_error, input_value='input_to', input_type=str]
    For further information visit https://errors.pydantic.dev/2.10/v/literal_error
Traceback (most recent call last):

  File "C:\Users\mikeb\work\sifu2\run_agents.py", line 868, in <module>
    asyncio.run(main())

  File "C:\Python313\Lib\asyncio\runners.py", line 194, in run
    return runner.run(main)
  File "C:\Python313\Lib\asyncio\runners.py", line 118, in run
    return self._loop.run_until_complete(task)
  File "C:\Python313\Lib\asyncio\base_events.py", line 707, in run_until_complete
    self.run_forever()
  File "C:\Python313\Lib\asyncio\base_events.py", line 678, in run_forever
    self._run_once()
  File "C:\Python313\Lib\asyncio\base_events.py", line 2033, in _run_once
    handle._run()
  File "C:\Python313\Lib\asyncio\events.py", line 89, in _run
    self._context.run(self._callback, *self._args)

  File "C:\Users\mikeb\work\sifu2\run_agents.py", line 857, in main
    await agent.run()

  File "C:\Users\mikeb\work\sifu2\run_agents.py", line 691, in run
    result = await getattr(self, task.tool)(**task.args)

  File "C:\Users\mikeb\work\sifu2\run_agents.py", line 344, in _synthesize_knowledge
    knowledge = await self.knowledge_system.process_source(content)

  File "C:\Users\mikeb\work\sifu2\scripts\knowledge_acquisition.py", line 466, in process_source
    relationships = await self._extract_relationships(content)

> File "C:\Users\mikeb\work\sifu2\scripts\knowledge_acquisition.py", line 650, in _extract_relationships
    converted_relationships.append(Relationship(**rel))

  File "C:\Python313\Lib\site-packages\pydantic\main.py", line 214, in __init__
    validated_self = self.__pydantic_validator__.validate_python(data, self_instance=self)

pydantic_core._pydantic_core.ValidationError: 1 validation error for Relationship
relation
  Input should be 'is_a', 'has_part' or 'related_to' [type=literal_error, input_value='input_to', input_type=str]
    For further information visit https://errors.pydantic.dev/2.10/v/literal_error
2025-02-09 14:57:07.460 | 40372:34912 | ERROR    | scripts.knowledge_acquisition:_extract_relationships:652 | Failed to convert relationship: {'source': 'Model Evaluation', 'relation': 'uses', 'target': 'Evaluation Metrics'}: 1 validation error for Relationship
relation
  Input should be 'is_a', 'has_part' or 'related_to' [type=literal_error, input_value='uses', input_type=str]
    For further information visit https://errors.pydantic.dev/2.10/v/literal_error
Traceback (most recent call last):

  File "C:\Users\mikeb\work\sifu2\run_agents.py", line 868, in <module>
    asyncio.run(main())

  File "C:\Python313\Lib\asyncio\runners.py", line 194, in run
    return runner.run(main)
  File "C:\Python313\Lib\asyncio\runners.py", line 118, in run
    return self._loop.run_until_complete(task)
  File "C:\Python313\Lib\asyncio\base_events.py", line 707, in run_until_complete
    self.run_forever()
  File "C:\Python313\Lib\asyncio\base_events.py", line 678, in run_forever
    self._run_once()
  File "C:\Python313\Lib\asyncio\base_events.py", line 2033, in _run_once
    handle._run()
  File "C:\Python313\Lib\asyncio\events.py", line 89, in _run
    self._context.run(self._callback, *self._args)

  File "C:\Users\mikeb\work\sifu2\run_agents.py", line 857, in main
    await agent.run()

  File "C:\Users\mikeb\work\sifu2\run_agents.py", line 691, in run
    result = await getattr(self, task.tool)(**task.args)

  File "C:\Users\mikeb\work\sifu2\run_agents.py", line 344, in _synthesize_knowledge
    knowledge = await self.knowledge_system.process_source(content)

  File "C:\Users\mikeb\work\sifu2\scripts\knowledge_acquisition.py", line 466, in process_source
    relationships = await self._extract_relationships(content)

> File "C:\Users\mikeb\work\sifu2\scripts\knowledge_acquisition.py", line 650, in _extract_relationships
    converted_relationships.append(Relationship(**rel))

  File "C:\Python313\Lib\site-packages\pydantic\main.py", line 214, in __init__
    validated_self = self.__pydantic_validator__.validate_python(data, self_instance=self)

pydantic_core._pydantic_core.ValidationError: 1 validation error for Relationship
relation
  Input should be 'is_a', 'has_part' or 'related_to' [type=literal_error, input_value='uses', input_type=str]
    For further information visit https://errors.pydantic.dev/2.10/v/literal_error
2025-02-09 14:57:07.482 | 40372:34912 | ERROR    | scripts.knowledge_acquisition:_extract_relationships:652 | Failed to convert relationship: {'source': 'CNNs', 'relation': 'applied_to', 'target': 'Image Recognition'}: 1 validation error for Relationship
relation
  Input should be 'is_a', 'has_part' or 'related_to' [type=literal_error, input_value='applied_to', input_type=str]
    For further information visit https://errors.pydantic.dev/2.10/v/literal_error
Traceback (most recent call last):

  File "C:\Users\mikeb\work\sifu2\run_agents.py", line 868, in <module>
    asyncio.run(main())

  File "C:\Python313\Lib\asyncio\runners.py", line 194, in run
    return runner.run(main)
  File "C:\Python313\Lib\asyncio\runners.py", line 118, in run
    return self._loop.run_until_complete(task)
  File "C:\Python313\Lib\asyncio\base_events.py", line 707, in run_until_complete
    self.run_forever()
  File "C:\Python313\Lib\asyncio\base_events.py", line 678, in run_forever
    self._run_once()
  File "C:\Python313\Lib\asyncio\base_events.py", line 2033, in _run_once
    handle._run()
  File "C:\Python313\Lib\asyncio\events.py", line 89, in _run
    self._context.run(self._callback, *self._args)

  File "C:\Users\mikeb\work\sifu2\run_agents.py", line 857, in main
    await agent.run()

  File "C:\Users\mikeb\work\sifu2\run_agents.py", line 691, in run
    result = await getattr(self, task.tool)(**task.args)

  File "C:\Users\mikeb\work\sifu2\run_agents.py", line 344, in _synthesize_knowledge
    knowledge = await self.knowledge_system.process_source(content)

  File "C:\Users\mikeb\work\sifu2\scripts\knowledge_acquisition.py", line 466, in process_source
    relationships = await self._extract_relationships(content)

> File "C:\Users\mikeb\work\sifu2\scripts\knowledge_acquisition.py", line 650, in _extract_relationships
    converted_relationships.append(Relationship(**rel))

  File "C:\Python313\Lib\site-packages\pydantic\main.py", line 214, in __init__
    validated_self = self.__pydantic_validator__.validate_python(data, self_instance=self)

pydantic_core._pydantic_core.ValidationError: 1 validation error for Relationship
relation
  Input should be 'is_a', 'has_part' or 'related_to' [type=literal_error, input_value='applied_to', input_type=str]
    For further information visit https://errors.pydantic.dev/2.10/v/literal_error
2025-02-09 14:57:07.504 | 40372:34912 | ERROR    | scripts.knowledge_acquisition:_extract_relationships:652 | Failed to convert relationship: {'source': 'RNNs', 'relation': 'applied_to', 'target': 'Natural Language Processing'}: 1 validation error for Relationship
relation
  Input should be 'is_a', 'has_part' or 'related_to' [type=literal_error, input_value='applied_to', input_type=str]
    For further information visit https://errors.pydantic.dev/2.10/v/literal_error
Traceback (most recent call last):

  File "C:\Users\mikeb\work\sifu2\run_agents.py", line 868, in <module>
    asyncio.run(main())

  File "C:\Python313\Lib\asyncio\runners.py", line 194, in run
    return runner.run(main)
  File "C:\Python313\Lib\asyncio\runners.py", line 118, in run
    return self._loop.run_until_complete(task)
  File "C:\Python313\Lib\asyncio\base_events.py", line 707, in run_until_complete
    self.run_forever()
  File "C:\Python313\Lib\asyncio\base_events.py", line 678, in run_forever
    self._run_once()
  File "C:\Python313\Lib\asyncio\base_events.py", line 2033, in _run_once
    handle._run()
  File "C:\Python313\Lib\asyncio\events.py", line 89, in _run
    self._context.run(self._callback, *self._args)

  File "C:\Users\mikeb\work\sifu2\run_agents.py", line 857, in main
    await agent.run()

  File "C:\Users\mikeb\work\sifu2\run_agents.py", line 691, in run
    result = await getattr(self, task.tool)(**task.args)

  File "C:\Users\mikeb\work\sifu2\run_agents.py", line 344, in _synthesize_knowledge
    knowledge = await self.knowledge_system.process_source(content)

  File "C:\Users\mikeb\work\sifu2\scripts\knowledge_acquisition.py", line 466, in process_source
    relationships = await self._extract_relationships(content)

> File "C:\Users\mikeb\work\sifu2\scripts\knowledge_acquisition.py", line 650, in _extract_relationships
    converted_relationships.append(Relationship(**rel))

  File "C:\Python313\Lib\site-packages\pydantic\main.py", line 214, in __init__
    validated_self = self.__pydantic_validator__.validate_python(data, self_instance=self)

pydantic_core._pydantic_core.ValidationError: 1 validation error for Relationship
relation
  Input should be 'is_a', 'has_part' or 'related_to' [type=literal_error, input_value='applied_to', input_type=str]
    For further information visit https://errors.pydantic.dev/2.10/v/literal_error
2025-02-09 14:57:14.252 | 40372:34912 | ERROR    | scripts.knowledge_acquisition:_extract_relationships:652 | Failed to convert relationship: {'source': 'CNNs', 'relation': 'used_for', 'target': 'Image Recognition'}: 1 validation error for Relationship
relation
  Input should be 'is_a', 'has_part' or 'related_to' [type=literal_error, input_value='used_for', input_type=str]
    For further information visit https://errors.pydantic.dev/2.10/v/literal_error
Traceback (most recent call last):

  File "C:\Users\mikeb\work\sifu2\run_agents.py", line 868, in <module>
    asyncio.run(main())

  File "C:\Python313\Lib\asyncio\runners.py", line 194, in run
    return runner.run(main)
  File "C:\Python313\Lib\asyncio\runners.py", line 118, in run
    return self._loop.run_until_complete(task)
  File "C:\Python313\Lib\asyncio\base_events.py", line 707, in run_until_complete
    self.run_forever()
  File "C:\Python313\Lib\asyncio\base_events.py", line 678, in run_forever
    self._run_once()
  File "C:\Python313\Lib\asyncio\base_events.py", line 2033, in _run_once
    handle._run()
  File "C:\Python313\Lib\asyncio\events.py", line 89, in _run
    self._context.run(self._callback, *self._args)

  File "C:\Users\mikeb\work\sifu2\run_agents.py", line 857, in main
    await agent.run()

  File "C:\Users\mikeb\work\sifu2\run_agents.py", line 691, in run
    result = await getattr(self, task.tool)(**task.args)

  File "C:\Users\mikeb\work\sifu2\run_agents.py", line 344, in _synthesize_knowledge
    knowledge = await self.knowledge_system.process_source(content)

  File "C:\Users\mikeb\work\sifu2\scripts\knowledge_acquisition.py", line 466, in process_source
    relationships = await self._extract_relationships(content)

> File "C:\Users\mikeb\work\sifu2\scripts\knowledge_acquisition.py", line 650, in _extract_relationships
    converted_relationships.append(Relationship(**rel))

  File "C:\Python313\Lib\site-packages\pydantic\main.py", line 214, in __init__
    validated_self = self.__pydantic_validator__.validate_python(data, self_instance=self)

pydantic_core._pydantic_core.ValidationError: 1 validation error for Relationship
relation
  Input should be 'is_a', 'has_part' or 'related_to' [type=literal_error, input_value='used_for', input_type=str]
    For further information visit https://errors.pydantic.dev/2.10/v/literal_error
2025-02-09 14:57:14.280 | 40372:34912 | ERROR    | scripts.knowledge_acquisition:_extract_relationships:652 | Failed to convert relationship: {'source': 'RNNs', 'relation': 'used_for', 'target': 'Natural Language Processing'}: 1 validation error for Relationship
relation
  Input should be 'is_a', 'has_part' or 'related_to' [type=literal_error, input_value='used_for', input_type=str]
    For further information visit https://errors.pydantic.dev/2.10/v/literal_error
Traceback (most recent call last):

  File "C:\Users\mikeb\work\sifu2\run_agents.py", line 868, in <module>
    asyncio.run(main())

  File "C:\Python313\Lib\asyncio\runners.py", line 194, in run
    return runner.run(main)
  File "C:\Python313\Lib\asyncio\runners.py", line 118, in run
    return self._loop.run_until_complete(task)
  File "C:\Python313\Lib\asyncio\base_events.py", line 707, in run_until_complete
    self.run_forever()
  File "C:\Python313\Lib\asyncio\base_events.py", line 678, in run_forever
    self._run_once()
  File "C:\Python313\Lib\asyncio\base_events.py", line 2033, in _run_once
    handle._run()
  File "C:\Python313\Lib\asyncio\events.py", line 89, in _run
    self._context.run(self._callback, *self._args)

  File "C:\Users\mikeb\work\sifu2\run_agents.py", line 857, in main
    await agent.run()

  File "C:\Users\mikeb\work\sifu2\run_agents.py", line 691, in run
    result = await getattr(self, task.tool)(**task.args)

  File "C:\Users\mikeb\work\sifu2\run_agents.py", line 344, in _synthesize_knowledge
    knowledge = await self.knowledge_system.process_source(content)

  File "C:\Users\mikeb\work\sifu2\scripts\knowledge_acquisition.py", line 466, in process_source
    relationships = await self._extract_relationships(content)

> File "C:\Users\mikeb\work\sifu2\scripts\knowledge_acquisition.py", line 650, in _extract_relationships
    converted_relationships.append(Relationship(**rel))

  File "C:\Python313\Lib\site-packages\pydantic\main.py", line 214, in __init__
    validated_self = self.__pydantic_validator__.validate_python(data, self_instance=self)

pydantic_core._pydantic_core.ValidationError: 1 validation error for Relationship
relation
  Input should be 'is_a', 'has_part' or 'related_to' [type=literal_error, input_value='used_for', input_type=str]
    For further information visit https://errors.pydantic.dev/2.10/v/literal_error
2025-02-09 14:57:14.312 | 40372:34912 | ERROR    | scripts.knowledge_acquisition:_extract_relationships:652 | Failed to convert relationship: {'source': 'Data Preprocessing', 'relation': 'precedes', 'target': 'Model Training'}: 1 validation error for Relationship
relation
  Input should be 'is_a', 'has_part' or 'related_to' [type=literal_error, input_value='precedes', input_type=str]
    For further information visit https://errors.pydantic.dev/2.10/v/literal_error
Traceback (most recent call last):

  File "C:\Users\mikeb\work\sifu2\run_agents.py", line 868, in <module>
    asyncio.run(main())

  File "C:\Python313\Lib\asyncio\runners.py", line 194, in run
    return runner.run(main)
  File "C:\Python313\Lib\asyncio\runners.py", line 118, in run
    return self._loop.run_until_complete(task)
  File "C:\Python313\Lib\asyncio\base_events.py", line 707, in run_until_complete
    self.run_forever()
  File "C:\Python313\Lib\asyncio\base_events.py", line 678, in run_forever
    self._run_once()
  File "C:\Python313\Lib\asyncio\base_events.py", line 2033, in _run_once
    handle._run()
  File "C:\Python313\Lib\asyncio\events.py", line 89, in _run
    self._context.run(self._callback, *self._args)

  File "C:\Users\mikeb\work\sifu2\run_agents.py", line 857, in main
    await agent.run()

  File "C:\Users\mikeb\work\sifu2\run_agents.py", line 691, in run
    result = await getattr(self, task.tool)(**task.args)

  File "C:\Users\mikeb\work\sifu2\run_agents.py", line 344, in _synthesize_knowledge
    knowledge = await self.knowledge_system.process_source(content)

  File "C:\Users\mikeb\work\sifu2\scripts\knowledge_acquisition.py", line 466, in process_source
    relationships = await self._extract_relationships(content)

> File "C:\Users\mikeb\work\sifu2\scripts\knowledge_acquisition.py", line 650, in _extract_relationships
    converted_relationships.append(Relationship(**rel))

  File "C:\Python313\Lib\site-packages\pydantic\main.py", line 214, in __init__
    validated_self = self.__pydantic_validator__.validate_python(data, self_instance=self)

pydantic_core._pydantic_core.ValidationError: 1 validation error for Relationship
relation
  Input should be 'is_a', 'has_part' or 'related_to' [type=literal_error, input_value='precedes', input_type=str]
    For further information visit https://errors.pydantic.dev/2.10/v/literal_error
2025-02-09 14:57:14.358 | 40372:34912 | ERROR    | scripts.knowledge_acquisition:_extract_relationships:652 | Failed to convert relationship: {'source': 'Model Training', 'relation': 'uses', 'target': 'Training Data'}: 1 validation error for Relationship
relation
  Input should be 'is_a', 'has_part' or 'related_to' [type=literal_error, input_value='uses', input_type=str]
    For further information visit https://errors.pydantic.dev/2.10/v/literal_error
Traceback (most recent call last):

  File "C:\Users\mikeb\work\sifu2\run_agents.py", line 868, in <module>
    asyncio.run(main())

  File "C:\Python313\Lib\asyncio\runners.py", line 194, in run
    return runner.run(main)
  File "C:\Python313\Lib\asyncio\runners.py", line 118, in run
    return self._loop.run_until_complete(task)
  File "C:\Python313\Lib\asyncio\base_events.py", line 707, in run_until_complete
    self.run_forever()
  File "C:\Python313\Lib\asyncio\base_events.py", line 678, in run_forever
    self._run_once()
  File "C:\Python313\Lib\asyncio\base_events.py", line 2033, in _run_once
    handle._run()
  File "C:\Python313\Lib\asyncio\events.py", line 89, in _run
    self._context.run(self._callback, *self._args)

  File "C:\Users\mikeb\work\sifu2\run_agents.py", line 857, in main
    await agent.run()

  File "C:\Users\mikeb\work\sifu2\run_agents.py", line 691, in run
    result = await getattr(self, task.tool)(**task.args)

  File "C:\Users\mikeb\work\sifu2\run_agents.py", line 344, in _synthesize_knowledge
    knowledge = await self.knowledge_system.process_source(content)

  File "C:\Users\mikeb\work\sifu2\scripts\knowledge_acquisition.py", line 466, in process_source
    relationships = await self._extract_relationships(content)

> File "C:\Users\mikeb\work\sifu2\scripts\knowledge_acquisition.py", line 650, in _extract_relationships
    converted_relationships.append(Relationship(**rel))

  File "C:\Python313\Lib\site-packages\pydantic\main.py", line 214, in __init__
    validated_self = self.__pydantic_validator__.validate_python(data, self_instance=self)

pydantic_core._pydantic_core.ValidationError: 1 validation error for Relationship
relation
  Input should be 'is_a', 'has_part' or 'related_to' [type=literal_error, input_value='uses', input_type=str]
    For further information visit https://errors.pydantic.dev/2.10/v/literal_error
2025-02-09 14:57:14.392 | 40372:34912 | ERROR    | scripts.knowledge_acquisition:_extract_relationships:652 | Failed to convert relationship: {'source': 'Model Evaluation', 'relation': 'follows', 'target': 'Model Training'}: 1 validation error for Relationship
relation
  Input should be 'is_a', 'has_part' or 'related_to' [type=literal_error, input_value='follows', input_type=str]
    For further information visit https://errors.pydantic.dev/2.10/v/literal_error
Traceback (most recent call last):

  File "C:\Users\mikeb\work\sifu2\run_agents.py", line 868, in <module>
    asyncio.run(main())

  File "C:\Python313\Lib\asyncio\runners.py", line 194, in run
    return runner.run(main)
  File "C:\Python313\Lib\asyncio\runners.py", line 118, in run
    return self._loop.run_until_complete(task)
  File "C:\Python313\Lib\asyncio\base_events.py", line 707, in run_until_complete
    self.run_forever()
  File "C:\Python313\Lib\asyncio\base_events.py", line 678, in run_forever
    self._run_once()
  File "C:\Python313\Lib\asyncio\base_events.py", line 2033, in _run_once
    handle._run()
  File "C:\Python313\Lib\asyncio\events.py", line 89, in _run
    self._context.run(self._callback, *self._args)

  File "C:\Users\mikeb\work\sifu2\run_agents.py", line 857, in main
    await agent.run()

  File "C:\Users\mikeb\work\sifu2\run_agents.py", line 691, in run
    result = await getattr(self, task.tool)(**task.args)

  File "C:\Users\mikeb\work\sifu2\run_agents.py", line 344, in _synthesize_knowledge
    knowledge = await self.knowledge_system.process_source(content)

  File "C:\Users\mikeb\work\sifu2\scripts\knowledge_acquisition.py", line 466, in process_source
    relationships = await self._extract_relationships(content)

> File "C:\Users\mikeb\work\sifu2\scripts\knowledge_acquisition.py", line 650, in _extract_relationships
    converted_relationships.append(Relationship(**rel))

  File "C:\Python313\Lib\site-packages\pydantic\main.py", line 214, in __init__
    validated_self = self.__pydantic_validator__.validate_python(data, self_instance=self)

pydantic_core._pydantic_core.ValidationError: 1 validation error for Relationship
relation
  Input should be 'is_a', 'has_part' or 'related_to' [type=literal_error, input_value='follows', input_type=str]
    For further information visit https://errors.pydantic.dev/2.10/v/literal_error
2025-02-09 14:57:14.418 | 40372:34912 | ERROR    | scripts.knowledge_acquisition:_extract_relationships:652 | Failed to convert relationship: {'source': 'Model Evaluation', 'relation': 'uses', 'target': 'Test Data'}: 1 validation error for Relationship
relation
  Input should be 'is_a', 'has_part' or 'related_to' [type=literal_error, input_value='uses', input_type=str]
    For further information visit https://errors.pydantic.dev/2.10/v/literal_error
Traceback (most recent call last):

  File "C:\Users\mikeb\work\sifu2\run_agents.py", line 868, in <module>
    asyncio.run(main())

  File "C:\Python313\Lib\asyncio\runners.py", line 194, in run
    return runner.run(main)
  File "C:\Python313\Lib\asyncio\runners.py", line 118, in run
    return self._loop.run_until_complete(task)
  File "C:\Python313\Lib\asyncio\base_events.py", line 707, in run_until_complete
    self.run_forever()
  File "C:\Python313\Lib\asyncio\base_events.py", line 678, in run_forever
    self._run_once()
  File "C:\Python313\Lib\asyncio\base_events.py", line 2033, in _run_once
    handle._run()
  File "C:\Python313\Lib\asyncio\events.py", line 89, in _run
    self._context.run(self._callback, *self._args)

  File "C:\Users\mikeb\work\sifu2\run_agents.py", line 857, in main
    await agent.run()

  File "C:\Users\mikeb\work\sifu2\run_agents.py", line 691, in run
    result = await getattr(self, task.tool)(**task.args)

  File "C:\Users\mikeb\work\sifu2\run_agents.py", line 344, in _synthesize_knowledge
    knowledge = await self.knowledge_system.process_source(content)

  File "C:\Users\mikeb\work\sifu2\scripts\knowledge_acquisition.py", line 466, in process_source
    relationships = await self._extract_relationships(content)

> File "C:\Users\mikeb\work\sifu2\scripts\knowledge_acquisition.py", line 650, in _extract_relationships
    converted_relationships.append(Relationship(**rel))

  File "C:\Python313\Lib\site-packages\pydantic\main.py", line 214, in __init__
    validated_self = self.__pydantic_validator__.validate_python(data, self_instance=self)

pydantic_core._pydantic_core.ValidationError: 1 validation error for Relationship
relation
  Input should be 'is_a', 'has_part' or 'related_to' [type=literal_error, input_value='uses', input_type=str]
    For further information visit https://errors.pydantic.dev/2.10/v/literal_error
2025-02-09 14:57:14.446 | 40372:34912 | ERROR    | scripts.knowledge_acquisition:_extract_relationships:652 | Failed to convert relationship: {'source': 'Hyperparameter Tuning', 'relation': 'improves', 'target': 'Model Performance'}: 1 validation error for Relationship
relation
  Input should be 'is_a', 'has_part' or 'related_to' [type=literal_error, input_value='improves', input_type=str]
    For further information visit https://errors.pydantic.dev/2.10/v/literal_error
Traceback (most recent call last):

  File "C:\Users\mikeb\work\sifu2\run_agents.py", line 868, in <module>
    asyncio.run(main())

  File "C:\Python313\Lib\asyncio\runners.py", line 194, in run
    return runner.run(main)
  File "C:\Python313\Lib\asyncio\runners.py", line 118, in run
    return self._loop.run_until_complete(task)
  File "C:\Python313\Lib\asyncio\base_events.py", line 707, in run_until_complete
    self.run_forever()
  File "C:\Python313\Lib\asyncio\base_events.py", line 678, in run_forever
    self._run_once()
  File "C:\Python313\Lib\asyncio\base_events.py", line 2033, in _run_once
    handle._run()
  File "C:\Python313\Lib\asyncio\events.py", line 89, in _run
    self._context.run(self._callback, *self._args)

  File "C:\Users\mikeb\work\sifu2\run_agents.py", line 857, in main
    await agent.run()

  File "C:\Users\mikeb\work\sifu2\run_agents.py", line 691, in run
    result = await getattr(self, task.tool)(**task.args)

  File "C:\Users\mikeb\work\sifu2\run_agents.py", line 344, in _synthesize_knowledge
    knowledge = await self.knowledge_system.process_source(content)

  File "C:\Users\mikeb\work\sifu2\scripts\knowledge_acquisition.py", line 466, in process_source
    relationships = await self._extract_relationships(content)

> File "C:\Users\mikeb\work\sifu2\scripts\knowledge_acquisition.py", line 650, in _extract_relationships
    converted_relationships.append(Relationship(**rel))

  File "C:\Python313\Lib\site-packages\pydantic\main.py", line 214, in __init__
    validated_self = self.__pydantic_validator__.validate_python(data, self_instance=self)

pydantic_core._pydantic_core.ValidationError: 1 validation error for Relationship
relation
  Input should be 'is_a', 'has_part' or 'related_to' [type=literal_error, input_value='improves', input_type=str]
    For further information visit https://errors.pydantic.dev/2.10/v/literal_error
2025-02-09 14:57:26.452 | 40372:34912 | ERROR    | scripts.knowledge_acquisition:_extract_relationships:652 | Failed to convert relationship: {'source': 'Data Preprocessing', 'relation': 'precedes', 'target': 'Model Training'}: 1 validation error for Relationship
relation
  Input should be 'is_a', 'has_part' or 'related_to' [type=literal_error, input_value='precedes', input_type=str]
    For further information visit https://errors.pydantic.dev/2.10/v/literal_error
Traceback (most recent call last):

  File "C:\Users\mikeb\work\sifu2\run_agents.py", line 868, in <module>
    asyncio.run(main())

  File "C:\Python313\Lib\asyncio\runners.py", line 194, in run
    return runner.run(main)
  File "C:\Python313\Lib\asyncio\runners.py", line 118, in run
    return self._loop.run_until_complete(task)
  File "C:\Python313\Lib\asyncio\base_events.py", line 707, in run_until_complete
    self.run_forever()
  File "C:\Python313\Lib\asyncio\base_events.py", line 678, in run_forever
    self._run_once()
  File "C:\Python313\Lib\asyncio\base_events.py", line 2033, in _run_once
    handle._run()
  File "C:\Python313\Lib\asyncio\events.py", line 89, in _run
    self._context.run(self._callback, *self._args)

  File "C:\Users\mikeb\work\sifu2\run_agents.py", line 857, in main
    await agent.run()

  File "C:\Users\mikeb\work\sifu2\run_agents.py", line 691, in run
    result = await getattr(self, task.tool)(**task.args)

  File "C:\Users\mikeb\work\sifu2\run_agents.py", line 344, in _synthesize_knowledge
    knowledge = await self.knowledge_system.process_source(content)

  File "C:\Users\mikeb\work\sifu2\scripts\knowledge_acquisition.py", line 466, in process_source
    relationships = await self._extract_relationships(content)

> File "C:\Users\mikeb\work\sifu2\scripts\knowledge_acquisition.py", line 650, in _extract_relationships
    converted_relationships.append(Relationship(**rel))

  File "C:\Python313\Lib\site-packages\pydantic\main.py", line 214, in __init__
    validated_self = self.__pydantic_validator__.validate_python(data, self_instance=self)

pydantic_core._pydantic_core.ValidationError: 1 validation error for Relationship
relation
  Input should be 'is_a', 'has_part' or 'related_to' [type=literal_error, input_value='precedes', input_type=str]
    For further information visit https://errors.pydantic.dev/2.10/v/literal_error
2025-02-09 14:57:26.480 | 40372:34912 | ERROR    | scripts.knowledge_acquisition:_extract_relationships:652 | Failed to convert relationship: {'source': 'Model Training', 'relation': 'uses', 'target': 'Training Data'}: 1 validation error for Relationship
relation
  Input should be 'is_a', 'has_part' or 'related_to' [type=literal_error, input_value='uses', input_type=str]
    For further information visit https://errors.pydantic.dev/2.10/v/literal_error
Traceback (most recent call last):

  File "C:\Users\mikeb\work\sifu2\run_agents.py", line 868, in <module>
    asyncio.run(main())

  File "C:\Python313\Lib\asyncio\runners.py", line 194, in run
    return runner.run(main)
  File "C:\Python313\Lib\asyncio\runners.py", line 118, in run
    return self._loop.run_until_complete(task)
  File "C:\Python313\Lib\asyncio\base_events.py", line 707, in run_until_complete
    self.run_forever()
  File "C:\Python313\Lib\asyncio\base_events.py", line 678, in run_forever
    self._run_once()
  File "C:\Python313\Lib\asyncio\base_events.py", line 2033, in _run_once
    handle._run()
  File "C:\Python313\Lib\asyncio\events.py", line 89, in _run
    self._context.run(self._callback, *self._args)

  File "C:\Users\mikeb\work\sifu2\run_agents.py", line 857, in main
    await agent.run()

  File "C:\Users\mikeb\work\sifu2\run_agents.py", line 691, in run
    result = await getattr(self, task.tool)(**task.args)

  File "C:\Users\mikeb\work\sifu2\run_agents.py", line 344, in _synthesize_knowledge
    knowledge = await self.knowledge_system.process_source(content)

  File "C:\Users\mikeb\work\sifu2\scripts\knowledge_acquisition.py", line 466, in process_source
    relationships = await self._extract_relationships(content)

> File "C:\Users\mikeb\work\sifu2\scripts\knowledge_acquisition.py", line 650, in _extract_relationships
    converted_relationships.append(Relationship(**rel))

  File "C:\Python313\Lib\site-packages\pydantic\main.py", line 214, in __init__
    validated_self = self.__pydantic_validator__.validate_python(data, self_instance=self)

pydantic_core._pydantic_core.ValidationError: 1 validation error for Relationship
relation
  Input should be 'is_a', 'has_part' or 'related_to' [type=literal_error, input_value='uses', input_type=str]
    For further information visit https://errors.pydantic.dev/2.10/v/literal_error
2025-02-09 14:57:26.510 | 40372:34912 | ERROR    | scripts.knowledge_acquisition:_extract_relationships:652 | Failed to convert relationship: {'source': 'Model Training', 'relation': 'output_of', 'target': 'Trained Model'}: 1 validation error for Relationship
relation
  Input should be 'is_a', 'has_part' or 'related_to' [type=literal_error, input_value='output_of', input_type=str]
    For further information visit https://errors.pydantic.dev/2.10/v/literal_error
Traceback (most recent call last):

  File "C:\Users\mikeb\work\sifu2\run_agents.py", line 868, in <module>
    asyncio.run(main())

  File "C:\Python313\Lib\asyncio\runners.py", line 194, in run
    return runner.run(main)
  File "C:\Python313\Lib\asyncio\runners.py", line 118, in run
    return self._loop.run_until_complete(task)
  File "C:\Python313\Lib\asyncio\base_events.py", line 707, in run_until_complete
    self.run_forever()
  File "C:\Python313\Lib\asyncio\base_events.py", line 678, in run_forever
    self._run_once()
  File "C:\Python313\Lib\asyncio\base_events.py", line 2033, in _run_once
    handle._run()
  File "C:\Python313\Lib\asyncio\events.py", line 89, in _run
    self._context.run(self._callback, *self._args)

  File "C:\Users\mikeb\work\sifu2\run_agents.py", line 857, in main
    await agent.run()

  File "C:\Users\mikeb\work\sifu2\run_agents.py", line 691, in run
    result = await getattr(self, task.tool)(**task.args)

  File "C:\Users\mikeb\work\sifu2\run_agents.py", line 344, in _synthesize_knowledge
    knowledge = await self.knowledge_system.process_source(content)

  File "C:\Users\mikeb\work\sifu2\scripts\knowledge_acquisition.py", line 466, in process_source
    relationships = await self._extract_relationships(content)

> File "C:\Users\mikeb\work\sifu2\scripts\knowledge_acquisition.py", line 650, in _extract_relationships
    converted_relationships.append(Relationship(**rel))

  File "C:\Python313\Lib\site-packages\pydantic\main.py", line 214, in __init__
    validated_self = self.__pydantic_validator__.validate_python(data, self_instance=self)

pydantic_core._pydantic_core.ValidationError: 1 validation error for Relationship
relation
  Input should be 'is_a', 'has_part' or 'related_to' [type=literal_error, input_value='output_of', input_type=str]
    For further information visit https://errors.pydantic.dev/2.10/v/literal_error
2025-02-09 14:57:26.538 | 40372:34912 | ERROR    | scripts.knowledge_acquisition:_extract_relationships:652 | Failed to convert relationship: {'source': 'Trained Model', 'relation': 'input_to', 'target': 'Model Evaluation'}: 1 validation error for Relationship
relation
  Input should be 'is_a', 'has_part' or 'related_to' [type=literal_error, input_value='input_to', input_type=str]
    For further information visit https://errors.pydantic.dev/2.10/v/literal_error
Traceback (most recent call last):

  File "C:\Users\mikeb\work\sifu2\run_agents.py", line 868, in <module>
    asyncio.run(main())

  File "C:\Python313\Lib\asyncio\runners.py", line 194, in run
    return runner.run(main)
  File "C:\Python313\Lib\asyncio\runners.py", line 118, in run
    return self._loop.run_until_complete(task)
  File "C:\Python313\Lib\asyncio\base_events.py", line 707, in run_until_complete
    self.run_forever()
  File "C:\Python313\Lib\asyncio\base_events.py", line 678, in run_forever
    self._run_once()
  File "C:\Python313\Lib\asyncio\base_events.py", line 2033, in _run_once
    handle._run()
  File "C:\Python313\Lib\asyncio\events.py", line 89, in _run
    self._context.run(self._callback, *self._args)

  File "C:\Users\mikeb\work\sifu2\run_agents.py", line 857, in main
    await agent.run()

  File "C:\Users\mikeb\work\sifu2\run_agents.py", line 691, in run
    result = await getattr(self, task.tool)(**task.args)

  File "C:\Users\mikeb\work\sifu2\run_agents.py", line 344, in _synthesize_knowledge
    knowledge = await self.knowledge_system.process_source(content)

  File "C:\Users\mikeb\work\sifu2\scripts\knowledge_acquisition.py", line 466, in process_source
    relationships = await self._extract_relationships(content)

> File "C:\Users\mikeb\work\sifu2\scripts\knowledge_acquisition.py", line 650, in _extract_relationships
    converted_relationships.append(Relationship(**rel))

  File "C:\Python313\Lib\site-packages\pydantic\main.py", line 214, in __init__
    validated_self = self.__pydantic_validator__.validate_python(data, self_instance=self)

pydantic_core._pydantic_core.ValidationError: 1 validation error for Relationship
relation
  Input should be 'is_a', 'has_part' or 'related_to' [type=literal_error, input_value='input_to', input_type=str]
    For further information visit https://errors.pydantic.dev/2.10/v/literal_error
2025-02-09 14:57:26.566 | 40372:34912 | ERROR    | scripts.knowledge_acquisition:_extract_relationships:652 | Failed to convert relationship: {'source': 'Model Evaluation', 'relation': 'uses', 'target': 'Evaluation Metrics'}: 1 validation error for Relationship
relation
  Input should be 'is_a', 'has_part' or 'related_to' [type=literal_error, input_value='uses', input_type=str]
    For further information visit https://errors.pydantic.dev/2.10/v/literal_error
Traceback (most recent call last):

  File "C:\Users\mikeb\work\sifu2\run_agents.py", line 868, in <module>
    asyncio.run(main())

  File "C:\Python313\Lib\asyncio\runners.py", line 194, in run
    return runner.run(main)
  File "C:\Python313\Lib\asyncio\runners.py", line 118, in run
    return self._loop.run_until_complete(task)
  File "C:\Python313\Lib\asyncio\base_events.py", line 707, in run_until_complete
    self.run_forever()
  File "C:\Python313\Lib\asyncio\base_events.py", line 678, in run_forever
    self._run_once()
  File "C:\Python313\Lib\asyncio\base_events.py", line 2033, in _run_once
    handle._run()
  File "C:\Python313\Lib\asyncio\events.py", line 89, in _run
    self._context.run(self._callback, *self._args)

  File "C:\Users\mikeb\work\sifu2\run_agents.py", line 857, in main
    await agent.run()

  File "C:\Users\mikeb\work\sifu2\run_agents.py", line 691, in run
    result = await getattr(self, task.tool)(**task.args)

  File "C:\Users\mikeb\work\sifu2\run_agents.py", line 344, in _synthesize_knowledge
    knowledge = await self.knowledge_system.process_source(content)

  File "C:\Users\mikeb\work\sifu2\scripts\knowledge_acquisition.py", line 466, in process_source
    relationships = await self._extract_relationships(content)

> File "C:\Users\mikeb\work\sifu2\scripts\knowledge_acquisition.py", line 650, in _extract_relationships
    converted_relationships.append(Relationship(**rel))

  File "C:\Python313\Lib\site-packages\pydantic\main.py", line 214, in __init__
    validated_self = self.__pydantic_validator__.validate_python(data, self_instance=self)

pydantic_core._pydantic_core.ValidationError: 1 validation error for Relationship
relation
  Input should be 'is_a', 'has_part' or 'related_to' [type=literal_error, input_value='uses', input_type=str]
    For further information visit https://errors.pydantic.dev/2.10/v/literal_error
2025-02-09 14:57:26.599 | 40372:34912 | ERROR    | scripts.knowledge_acquisition:_extract_relationships:652 | Failed to convert relationship: {'source': 'CNNs', 'relation': 'applied_to', 'target': 'Image Recognition'}: 1 validation error for Relationship
relation
  Input should be 'is_a', 'has_part' or 'related_to' [type=literal_error, input_value='applied_to', input_type=str]
    For further information visit https://errors.pydantic.dev/2.10/v/literal_error
Traceback (most recent call last):

  File "C:\Users\mikeb\work\sifu2\run_agents.py", line 868, in <module>
    asyncio.run(main())

  File "C:\Python313\Lib\asyncio\runners.py", line 194, in run
    return runner.run(main)
  File "C:\Python313\Lib\asyncio\runners.py", line 118, in run
    return self._loop.run_until_complete(task)
  File "C:\Python313\Lib\asyncio\base_events.py", line 707, in run_until_complete
    self.run_forever()
  File "C:\Python313\Lib\asyncio\base_events.py", line 678, in run_forever
    self._run_once()
  File "C:\Python313\Lib\asyncio\base_events.py", line 2033, in _run_once
    handle._run()
  File "C:\Python313\Lib\asyncio\events.py", line 89, in _run
    self._context.run(self._callback, *self._args)

  File "C:\Users\mikeb\work\sifu2\run_agents.py", line 857, in main
    await agent.run()

  File "C:\Users\mikeb\work\sifu2\run_agents.py", line 691, in run
    result = await getattr(self, task.tool)(**task.args)

  File "C:\Users\mikeb\work\sifu2\run_agents.py", line 344, in _synthesize_knowledge
    knowledge = await self.knowledge_system.process_source(content)

  File "C:\Users\mikeb\work\sifu2\scripts\knowledge_acquisition.py", line 466, in process_source
    relationships = await self._extract_relationships(content)

> File "C:\Users\mikeb\work\sifu2\scripts\knowledge_acquisition.py", line 650, in _extract_relationships
    converted_relationships.append(Relationship(**rel))

  File "C:\Python313\Lib\site-packages\pydantic\main.py", line 214, in __init__
    validated_self = self.__pydantic_validator__.validate_python(data, self_instance=self)

pydantic_core._pydantic_core.ValidationError: 1 validation error for Relationship
relation
  Input should be 'is_a', 'has_part' or 'related_to' [type=literal_error, input_value='applied_to', input_type=str]
    For further information visit https://errors.pydantic.dev/2.10/v/literal_error
2025-02-09 14:57:26.627 | 40372:34912 | ERROR    | scripts.knowledge_acquisition:_extract_relationships:652 | Failed to convert relationship: {'source': 'RNNs', 'relation': 'applied_to', 'target': 'Natural Language Processing'}: 1 validation error for Relationship
relation
  Input should be 'is_a', 'has_part' or 'related_to' [type=literal_error, input_value='applied_to', input_type=str]
    For further information visit https://errors.pydantic.dev/2.10/v/literal_error
Traceback (most recent call last):

  File "C:\Users\mikeb\work\sifu2\run_agents.py", line 868, in <module>
    asyncio.run(main())

  File "C:\Python313\Lib\asyncio\runners.py", line 194, in run
    return runner.run(main)
  File "C:\Python313\Lib\asyncio\runners.py", line 118, in run
    return self._loop.run_until_complete(task)
  File "C:\Python313\Lib\asyncio\base_events.py", line 707, in run_until_complete
    self.run_forever()
  File "C:\Python313\Lib\asyncio\base_events.py", line 678, in run_forever
    self._run_once()
  File "C:\Python313\Lib\asyncio\base_events.py", line 2033, in _run_once
    handle._run()
  File "C:\Python313\Lib\asyncio\events.py", line 89, in _run
    self._context.run(self._callback, *self._args)

  File "C:\Users\mikeb\work\sifu2\run_agents.py", line 857, in main
    await agent.run()

  File "C:\Users\mikeb\work\sifu2\run_agents.py", line 691, in run
    result = await getattr(self, task.tool)(**task.args)

  File "C:\Users\mikeb\work\sifu2\run_agents.py", line 344, in _synthesize_knowledge
    knowledge = await self.knowledge_system.process_source(content)

  File "C:\Users\mikeb\work\sifu2\scripts\knowledge_acquisition.py", line 466, in process_source
    relationships = await self._extract_relationships(content)

> File "C:\Users\mikeb\work\sifu2\scripts\knowledge_acquisition.py", line 650, in _extract_relationships
    converted_relationships.append(Relationship(**rel))

  File "C:\Python313\Lib\site-packages\pydantic\main.py", line 214, in __init__
    validated_self = self.__pydantic_validator__.validate_python(data, self_instance=self)

pydantic_core._pydantic_core.ValidationError: 1 validation error for Relationship
relation
  Input should be 'is_a', 'has_part' or 'related_to' [type=literal_error, input_value='applied_to', input_type=str]
    For further information visit https://errors.pydantic.dev/2.10/v/literal_error
2025-02-09 14:57:33.003 | 40372:34912 | ERROR    | scripts.knowledge_acquisition:_extract_relationships:652 | Failed to convert relationship: {'source': 'Data Preprocessing', 'relation': 'precedes', 'target': 'Model Training'}: 1 validation error for Relationship
relation
  Input should be 'is_a', 'has_part' or 'related_to' [type=literal_error, input_value='precedes', input_type=str]
    For further information visit https://errors.pydantic.dev/2.10/v/literal_error
Traceback (most recent call last):

  File "C:\Users\mikeb\work\sifu2\run_agents.py", line 868, in <module>
    asyncio.run(main())

  File "C:\Python313\Lib\asyncio\runners.py", line 194, in run
    return runner.run(main)
  File "C:\Python313\Lib\asyncio\runners.py", line 118, in run
    return self._loop.run_until_complete(task)
  File "C:\Python313\Lib\asyncio\base_events.py", line 707, in run_until_complete
    self.run_forever()
  File "C:\Python313\Lib\asyncio\base_events.py", line 678, in run_forever
    self._run_once()
  File "C:\Python313\Lib\asyncio\base_events.py", line 2033, in _run_once
    handle._run()
  File "C:\Python313\Lib\asyncio\events.py", line 89, in _run
    self._context.run(self._callback, *self._args)

  File "C:\Users\mikeb\work\sifu2\run_agents.py", line 857, in main
    await agent.run()

  File "C:\Users\mikeb\work\sifu2\run_agents.py", line 691, in run
    result = await getattr(self, task.tool)(**task.args)

  File "C:\Users\mikeb\work\sifu2\run_agents.py", line 344, in _synthesize_knowledge
    knowledge = await self.knowledge_system.process_source(content)

  File "C:\Users\mikeb\work\sifu2\scripts\knowledge_acquisition.py", line 466, in process_source
    relationships = await self._extract_relationships(content)

> File "C:\Users\mikeb\work\sifu2\scripts\knowledge_acquisition.py", line 650, in _extract_relationships
    converted_relationships.append(Relationship(**rel))

  File "C:\Python313\Lib\site-packages\pydantic\main.py", line 214, in __init__
    validated_self = self.__pydantic_validator__.validate_python(data, self_instance=self)

pydantic_core._pydantic_core.ValidationError: 1 validation error for Relationship
relation
  Input should be 'is_a', 'has_part' or 'related_to' [type=literal_error, input_value='precedes', input_type=str]
    For further information visit https://errors.pydantic.dev/2.10/v/literal_error
2025-02-09 14:57:33.026 | 40372:34912 | ERROR    | scripts.knowledge_acquisition:_extract_relationships:652 | Failed to convert relationship: {'source': 'Model Training', 'relation': 'uses', 'target': 'Training Data'}: 1 validation error for Relationship
relation
  Input should be 'is_a', 'has_part' or 'related_to' [type=literal_error, input_value='uses', input_type=str]
    For further information visit https://errors.pydantic.dev/2.10/v/literal_error
Traceback (most recent call last):

  File "C:\Users\mikeb\work\sifu2\run_agents.py", line 868, in <module>
    asyncio.run(main())

  File "C:\Python313\Lib\asyncio\runners.py", line 194, in run
    return runner.run(main)
  File "C:\Python313\Lib\asyncio\runners.py", line 118, in run
    return self._loop.run_until_complete(task)
  File "C:\Python313\Lib\asyncio\base_events.py", line 707, in run_until_complete
    self.run_forever()
  File "C:\Python313\Lib\asyncio\base_events.py", line 678, in run_forever
    self._run_once()
  File "C:\Python313\Lib\asyncio\base_events.py", line 2033, in _run_once
    handle._run()
  File "C:\Python313\Lib\asyncio\events.py", line 89, in _run
    self._context.run(self._callback, *self._args)

  File "C:\Users\mikeb\work\sifu2\run_agents.py", line 857, in main
    await agent.run()

  File "C:\Users\mikeb\work\sifu2\run_agents.py", line 691, in run
    result = await getattr(self, task.tool)(**task.args)

  File "C:\Users\mikeb\work\sifu2\run_agents.py", line 344, in _synthesize_knowledge
    knowledge = await self.knowledge_system.process_source(content)

  File "C:\Users\mikeb\work\sifu2\scripts\knowledge_acquisition.py", line 466, in process_source
    relationships = await self._extract_relationships(content)

> File "C:\Users\mikeb\work\sifu2\scripts\knowledge_acquisition.py", line 650, in _extract_relationships
    converted_relationships.append(Relationship(**rel))

  File "C:\Python313\Lib\site-packages\pydantic\main.py", line 214, in __init__
    validated_self = self.__pydantic_validator__.validate_python(data, self_instance=self)

pydantic_core._pydantic_core.ValidationError: 1 validation error for Relationship
relation
  Input should be 'is_a', 'has_part' or 'related_to' [type=literal_error, input_value='uses', input_type=str]
    For further information visit https://errors.pydantic.dev/2.10/v/literal_error
2025-02-09 14:57:33.049 | 40372:34912 | ERROR    | scripts.knowledge_acquisition:_extract_relationships:652 | Failed to convert relationship: {'source': 'Model Training', 'relation': 'produces', 'target': 'Trained Model'}: 1 validation error for Relationship
relation
  Input should be 'is_a', 'has_part' or 'related_to' [type=literal_error, input_value='produces', input_type=str]
    For further information visit https://errors.pydantic.dev/2.10/v/literal_error
Traceback (most recent call last):

  File "C:\Users\mikeb\work\sifu2\run_agents.py", line 868, in <module>
    asyncio.run(main())

  File "C:\Python313\Lib\asyncio\runners.py", line 194, in run
    return runner.run(main)
  File "C:\Python313\Lib\asyncio\runners.py", line 118, in run
    return self._loop.run_until_complete(task)
  File "C:\Python313\Lib\asyncio\base_events.py", line 707, in run_until_complete
    self.run_forever()
  File "C:\Python313\Lib\asyncio\base_events.py", line 678, in run_forever
    self._run_once()
  File "C:\Python313\Lib\asyncio\base_events.py", line 2033, in _run_once
    handle._run()
  File "C:\Python313\Lib\asyncio\events.py", line 89, in _run
    self._context.run(self._callback, *self._args)

  File "C:\Users\mikeb\work\sifu2\run_agents.py", line 857, in main
    await agent.run()

  File "C:\Users\mikeb\work\sifu2\run_agents.py", line 691, in run
    result = await getattr(self, task.tool)(**task.args)

  File "C:\Users\mikeb\work\sifu2\run_agents.py", line 344, in _synthesize_knowledge
    knowledge = await self.knowledge_system.process_source(content)

  File "C:\Users\mikeb\work\sifu2\scripts\knowledge_acquisition.py", line 466, in process_source
    relationships = await self._extract_relationships(content)

> File "C:\Users\mikeb\work\sifu2\scripts\knowledge_acquisition.py", line 650, in _extract_relationships
    converted_relationships.append(Relationship(**rel))

  File "C:\Python313\Lib\site-packages\pydantic\main.py", line 214, in __init__
    validated_self = self.__pydantic_validator__.validate_python(data, self_instance=self)

pydantic_core._pydantic_core.ValidationError: 1 validation error for Relationship
relation
  Input should be 'is_a', 'has_part' or 'related_to' [type=literal_error, input_value='produces', input_type=str]
    For further information visit https://errors.pydantic.dev/2.10/v/literal_error
2025-02-09 14:57:33.073 | 40372:34912 | ERROR    | scripts.knowledge_acquisition:_extract_relationships:652 | Failed to convert relationship: {'source': 'Trained Model', 'relation': 'used_by', 'target': 'Model Evaluation'}: 1 validation error for Relationship
relation
  Input should be 'is_a', 'has_part' or 'related_to' [type=literal_error, input_value='used_by', input_type=str]
    For further information visit https://errors.pydantic.dev/2.10/v/literal_error
Traceback (most recent call last):

  File "C:\Users\mikeb\work\sifu2\run_agents.py", line 868, in <module>
    asyncio.run(main())

  File "C:\Python313\Lib\asyncio\runners.py", line 194, in run
    return runner.run(main)
  File "C:\Python313\Lib\asyncio\runners.py", line 118, in run
    return self._loop.run_until_complete(task)
  File "C:\Python313\Lib\asyncio\base_events.py", line 707, in run_until_complete
    self.run_forever()
  File "C:\Python313\Lib\asyncio\base_events.py", line 678, in run_forever
    self._run_once()
  File "C:\Python313\Lib\asyncio\base_events.py", line 2033, in _run_once
    handle._run()
  File "C:\Python313\Lib\asyncio\events.py", line 89, in _run
    self._context.run(self._callback, *self._args)

  File "C:\Users\mikeb\work\sifu2\run_agents.py", line 857, in main
    await agent.run()

  File "C:\Users\mikeb\work\sifu2\run_agents.py", line 691, in run
    result = await getattr(self, task.tool)(**task.args)

  File "C:\Users\mikeb\work\sifu2\run_agents.py", line 344, in _synthesize_knowledge
    knowledge = await self.knowledge_system.process_source(content)

  File "C:\Users\mikeb\work\sifu2\scripts\knowledge_acquisition.py", line 466, in process_source
    relationships = await self._extract_relationships(content)

> File "C:\Users\mikeb\work\sifu2\scripts\knowledge_acquisition.py", line 650, in _extract_relationships
    converted_relationships.append(Relationship(**rel))

  File "C:\Python313\Lib\site-packages\pydantic\main.py", line 214, in __init__
    validated_self = self.__pydantic_validator__.validate_python(data, self_instance=self)

pydantic_core._pydantic_core.ValidationError: 1 validation error for Relationship
relation
  Input should be 'is_a', 'has_part' or 'related_to' [type=literal_error, input_value='used_by', input_type=str]
    For further information visit https://errors.pydantic.dev/2.10/v/literal_error
2025-02-09 14:57:33.098 | 40372:34912 | ERROR    | scripts.knowledge_acquisition:_extract_relationships:652 | Failed to convert relationship: {'source': 'Model Evaluation', 'relation': 'produces', 'target': 'Evaluation Metrics'}: 1 validation error for Relationship
relation
  Input should be 'is_a', 'has_part' or 'related_to' [type=literal_error, input_value='produces', input_type=str]
    For further information visit https://errors.pydantic.dev/2.10/v/literal_error
Traceback (most recent call last):

  File "C:\Users\mikeb\work\sifu2\run_agents.py", line 868, in <module>
    asyncio.run(main())

  File "C:\Python313\Lib\asyncio\runners.py", line 194, in run
    return runner.run(main)
  File "C:\Python313\Lib\asyncio\runners.py", line 118, in run
    return self._loop.run_until_complete(task)
  File "C:\Python313\Lib\asyncio\base_events.py", line 707, in run_until_complete
    self.run_forever()
  File "C:\Python313\Lib\asyncio\base_events.py", line 678, in run_forever
    self._run_once()
  File "C:\Python313\Lib\asyncio\base_events.py", line 2033, in _run_once
    handle._run()
  File "C:\Python313\Lib\asyncio\events.py", line 89, in _run
    self._context.run(self._callback, *self._args)

  File "C:\Users\mikeb\work\sifu2\run_agents.py", line 857, in main
    await agent.run()

  File "C:\Users\mikeb\work\sifu2\run_agents.py", line 691, in run
    result = await getattr(self, task.tool)(**task.args)

  File "C:\Users\mikeb\work\sifu2\run_agents.py", line 344, in _synthesize_knowledge
    knowledge = await self.knowledge_system.process_source(content)

  File "C:\Users\mikeb\work\sifu2\scripts\knowledge_acquisition.py", line 466, in process_source
    relationships = await self._extract_relationships(content)

> File "C:\Users\mikeb\work\sifu2\scripts\knowledge_acquisition.py", line 650, in _extract_relationships
    converted_relationships.append(Relationship(**rel))

  File "C:\Python313\Lib\site-packages\pydantic\main.py", line 214, in __init__
    validated_self = self.__pydantic_validator__.validate_python(data, self_instance=self)

pydantic_core._pydantic_core.ValidationError: 1 validation error for Relationship
relation
  Input should be 'is_a', 'has_part' or 'related_to' [type=literal_error, input_value='produces', input_type=str]
    For further information visit https://errors.pydantic.dev/2.10/v/literal_error
2025-02-09 14:57:33.125 | 40372:34912 | ERROR    | scripts.knowledge_acquisition:_extract_relationships:652 | Failed to convert relationship: {'source': 'CNNs', 'relation': 'applied_to', 'target': 'Image Recognition'}: 1 validation error for Relationship
relation
  Input should be 'is_a', 'has_part' or 'related_to' [type=literal_error, input_value='applied_to', input_type=str]
    For further information visit https://errors.pydantic.dev/2.10/v/literal_error
Traceback (most recent call last):

  File "C:\Users\mikeb\work\sifu2\run_agents.py", line 868, in <module>
    asyncio.run(main())

  File "C:\Python313\Lib\asyncio\runners.py", line 194, in run
    return runner.run(main)
  File "C:\Python313\Lib\asyncio\runners.py", line 118, in run
    return self._loop.run_until_complete(task)
  File "C:\Python313\Lib\asyncio\base_events.py", line 707, in run_until_complete
    self.run_forever()
  File "C:\Python313\Lib\asyncio\base_events.py", line 678, in run_forever
    self._run_once()
  File "C:\Python313\Lib\asyncio\base_events.py", line 2033, in _run_once
    handle._run()
  File "C:\Python313\Lib\asyncio\events.py", line 89, in _run
    self._context.run(self._callback, *self._args)

  File "C:\Users\mikeb\work\sifu2\run_agents.py", line 857, in main
    await agent.run()

  File "C:\Users\mikeb\work\sifu2\run_agents.py", line 691, in run
    result = await getattr(self, task.tool)(**task.args)

  File "C:\Users\mikeb\work\sifu2\run_agents.py", line 344, in _synthesize_knowledge
    knowledge = await self.knowledge_system.process_source(content)

  File "C:\Users\mikeb\work\sifu2\scripts\knowledge_acquisition.py", line 466, in process_source
    relationships = await self._extract_relationships(content)

> File "C:\Users\mikeb\work\sifu2\scripts\knowledge_acquisition.py", line 650, in _extract_relationships
    converted_relationships.append(Relationship(**rel))

  File "C:\Python313\Lib\site-packages\pydantic\main.py", line 214, in __init__
    validated_self = self.__pydantic_validator__.validate_python(data, self_instance=self)

pydantic_core._pydantic_core.ValidationError: 1 validation error for Relationship
relation
  Input should be 'is_a', 'has_part' or 'related_to' [type=literal_error, input_value='applied_to', input_type=str]
    For further information visit https://errors.pydantic.dev/2.10/v/literal_error
2025-02-09 14:57:33.147 | 40372:34912 | ERROR    | scripts.knowledge_acquisition:_extract_relationships:652 | Failed to convert relationship: {'source': 'RNNs', 'relation': 'applied_to', 'target': 'Natural Language Processing'}: 1 validation error for Relationship
relation
  Input should be 'is_a', 'has_part' or 'related_to' [type=literal_error, input_value='applied_to', input_type=str]
    For further information visit https://errors.pydantic.dev/2.10/v/literal_error
Traceback (most recent call last):

  File "C:\Users\mikeb\work\sifu2\run_agents.py", line 868, in <module>
    asyncio.run(main())

  File "C:\Python313\Lib\asyncio\runners.py", line 194, in run
    return runner.run(main)
  File "C:\Python313\Lib\asyncio\runners.py", line 118, in run
    return self._loop.run_until_complete(task)
  File "C:\Python313\Lib\asyncio\base_events.py", line 707, in run_until_complete
    self.run_forever()
  File "C:\Python313\Lib\asyncio\base_events.py", line 678, in run_forever
    self._run_once()
  File "C:\Python313\Lib\asyncio\base_events.py", line 2033, in _run_once
    handle._run()
  File "C:\Python313\Lib\asyncio\events.py", line 89, in _run
    self._context.run(self._callback, *self._args)

  File "C:\Users\mikeb\work\sifu2\run_agents.py", line 857, in main
    await agent.run()

  File "C:\Users\mikeb\work\sifu2\run_agents.py", line 691, in run
    result = await getattr(self, task.tool)(**task.args)

  File "C:\Users\mikeb\work\sifu2\run_agents.py", line 344, in _synthesize_knowledge
    knowledge = await self.knowledge_system.process_source(content)

  File "C:\Users\mikeb\work\sifu2\scripts\knowledge_acquisition.py", line 466, in process_source
    relationships = await self._extract_relationships(content)

> File "C:\Users\mikeb\work\sifu2\scripts\knowledge_acquisition.py", line 650, in _extract_relationships
    converted_relationships.append(Relationship(**rel))

  File "C:\Python313\Lib\site-packages\pydantic\main.py", line 214, in __init__
    validated_self = self.__pydantic_validator__.validate_python(data, self_instance=self)

pydantic_core._pydantic_core.ValidationError: 1 validation error for Relationship
relation
  Input should be 'is_a', 'has_part' or 'related_to' [type=literal_error, input_value='applied_to', input_type=str]
    For further information visit https://errors.pydantic.dev/2.10/v/literal_error
2025-02-09 14:57:43.764 | 40372:34912 | ERROR    | scripts.knowledge_acquisition:_extract_relationships:652 | Failed to convert relationship: {'source': 'Data Preprocessing', 'relation': 'precedes', 'target': 'Model Training'}: 1 validation error for Relationship
relation
  Input should be 'is_a', 'has_part' or 'related_to' [type=literal_error, input_value='precedes', input_type=str]
    For further information visit https://errors.pydantic.dev/2.10/v/literal_error
Traceback (most recent call last):

  File "C:\Users\mikeb\work\sifu2\run_agents.py", line 868, in <module>
    asyncio.run(main())

  File "C:\Python313\Lib\asyncio\runners.py", line 194, in run
    return runner.run(main)
  File "C:\Python313\Lib\asyncio\runners.py", line 118, in run
    return self._loop.run_until_complete(task)
  File "C:\Python313\Lib\asyncio\base_events.py", line 707, in run_until_complete
    self.run_forever()
  File "C:\Python313\Lib\asyncio\base_events.py", line 678, in run_forever
    self._run_once()
  File "C:\Python313\Lib\asyncio\base_events.py", line 2033, in _run_once
    handle._run()
  File "C:\Python313\Lib\asyncio\events.py", line 89, in _run
    self._context.run(self._callback, *self._args)

  File "C:\Users\mikeb\work\sifu2\run_agents.py", line 857, in main
    await agent.run()

  File "C:\Users\mikeb\work\sifu2\run_agents.py", line 691, in run
    result = await getattr(self, task.tool)(**task.args)

  File "C:\Users\mikeb\work\sifu2\run_agents.py", line 344, in _synthesize_knowledge
    knowledge = await self.knowledge_system.process_source(content)

  File "C:\Users\mikeb\work\sifu2\scripts\knowledge_acquisition.py", line 466, in process_source
    relationships = await self._extract_relationships(content)

> File "C:\Users\mikeb\work\sifu2\scripts\knowledge_acquisition.py", line 650, in _extract_relationships
    converted_relationships.append(Relationship(**rel))

  File "C:\Python313\Lib\site-packages\pydantic\main.py", line 214, in __init__
    validated_self = self.__pydantic_validator__.validate_python(data, self_instance=self)

pydantic_core._pydantic_core.ValidationError: 1 validation error for Relationship
relation
  Input should be 'is_a', 'has_part' or 'related_to' [type=literal_error, input_value='precedes', input_type=str]
    For further information visit https://errors.pydantic.dev/2.10/v/literal_error
2025-02-09 14:57:43.789 | 40372:34912 | ERROR    | scripts.knowledge_acquisition:_extract_relationships:652 | Failed to convert relationship: {'source': 'Model Training', 'relation': 'uses', 'target': 'Training Data'}: 1 validation error for Relationship
relation
  Input should be 'is_a', 'has_part' or 'related_to' [type=literal_error, input_value='uses', input_type=str]
    For further information visit https://errors.pydantic.dev/2.10/v/literal_error
Traceback (most recent call last):

  File "C:\Users\mikeb\work\sifu2\run_agents.py", line 868, in <module>
    asyncio.run(main())

  File "C:\Python313\Lib\asyncio\runners.py", line 194, in run
    return runner.run(main)
  File "C:\Python313\Lib\asyncio\runners.py", line 118, in run
    return self._loop.run_until_complete(task)
  File "C:\Python313\Lib\asyncio\base_events.py", line 707, in run_until_complete
    self.run_forever()
  File "C:\Python313\Lib\asyncio\base_events.py", line 678, in run_forever
    self._run_once()
  File "C:\Python313\Lib\asyncio\base_events.py", line 2033, in _run_once
    handle._run()
  File "C:\Python313\Lib\asyncio\events.py", line 89, in _run
    self._context.run(self._callback, *self._args)

  File "C:\Users\mikeb\work\sifu2\run_agents.py", line 857, in main
    await agent.run()

  File "C:\Users\mikeb\work\sifu2\run_agents.py", line 691, in run
    result = await getattr(self, task.tool)(**task.args)

  File "C:\Users\mikeb\work\sifu2\run_agents.py", line 344, in _synthesize_knowledge
    knowledge = await self.knowledge_system.process_source(content)

  File "C:\Users\mikeb\work\sifu2\scripts\knowledge_acquisition.py", line 466, in process_source
    relationships = await self._extract_relationships(content)

> File "C:\Users\mikeb\work\sifu2\scripts\knowledge_acquisition.py", line 650, in _extract_relationships
    converted_relationships.append(Relationship(**rel))

  File "C:\Python313\Lib\site-packages\pydantic\main.py", line 214, in __init__
    validated_self = self.__pydantic_validator__.validate_python(data, self_instance=self)

pydantic_core._pydantic_core.ValidationError: 1 validation error for Relationship
relation
  Input should be 'is_a', 'has_part' or 'related_to' [type=literal_error, input_value='uses', input_type=str]
    For further information visit https://errors.pydantic.dev/2.10/v/literal_error
2025-02-09 14:57:43.813 | 40372:34912 | ERROR    | scripts.knowledge_acquisition:_extract_relationships:652 | Failed to convert relationship: {'source': 'Model Training', 'relation': 'output_of', 'target': 'Trained Model'}: 1 validation error for Relationship
relation
  Input should be 'is_a', 'has_part' or 'related_to' [type=literal_error, input_value='output_of', input_type=str]
    For further information visit https://errors.pydantic.dev/2.10/v/literal_error
Traceback (most recent call last):

  File "C:\Users\mikeb\work\sifu2\run_agents.py", line 868, in <module>
    asyncio.run(main())

  File "C:\Python313\Lib\asyncio\runners.py", line 194, in run
    return runner.run(main)
  File "C:\Python313\Lib\asyncio\runners.py", line 118, in run
    return self._loop.run_until_complete(task)
  File "C:\Python313\Lib\asyncio\base_events.py", line 707, in run_until_complete
    self.run_forever()
  File "C:\Python313\Lib\asyncio\base_events.py", line 678, in run_forever
    self._run_once()
  File "C:\Python313\Lib\asyncio\base_events.py", line 2033, in _run_once
    handle._run()
  File "C:\Python313\Lib\asyncio\events.py", line 89, in _run
    self._context.run(self._callback, *self._args)

  File "C:\Users\mikeb\work\sifu2\run_agents.py", line 857, in main
    await agent.run()

  File "C:\Users\mikeb\work\sifu2\run_agents.py", line 691, in run
    result = await getattr(self, task.tool)(**task.args)

  File "C:\Users\mikeb\work\sifu2\run_agents.py", line 344, in _synthesize_knowledge
    knowledge = await self.knowledge_system.process_source(content)

  File "C:\Users\mikeb\work\sifu2\scripts\knowledge_acquisition.py", line 466, in process_source
    relationships = await self._extract_relationships(content)

> File "C:\Users\mikeb\work\sifu2\scripts\knowledge_acquisition.py", line 650, in _extract_relationships
    converted_relationships.append(Relationship(**rel))

  File "C:\Python313\Lib\site-packages\pydantic\main.py", line 214, in __init__
    validated_self = self.__pydantic_validator__.validate_python(data, self_instance=self)

pydantic_core._pydantic_core.ValidationError: 1 validation error for Relationship
relation
  Input should be 'is_a', 'has_part' or 'related_to' [type=literal_error, input_value='output_of', input_type=str]
    For further information visit https://errors.pydantic.dev/2.10/v/literal_error
2025-02-09 14:57:43.838 | 40372:34912 | ERROR    | scripts.knowledge_acquisition:_extract_relationships:652 | Failed to convert relationship: {'source': 'Trained Model', 'relation': 'input_to', 'target': 'Model Evaluation'}: 1 validation error for Relationship
relation
  Input should be 'is_a', 'has_part' or 'related_to' [type=literal_error, input_value='input_to', input_type=str]
    For further information visit https://errors.pydantic.dev/2.10/v/literal_error
Traceback (most recent call last):

  File "C:\Users\mikeb\work\sifu2\run_agents.py", line 868, in <module>
    asyncio.run(main())

  File "C:\Python313\Lib\asyncio\runners.py", line 194, in run
    return runner.run(main)
  File "C:\Python313\Lib\asyncio\runners.py", line 118, in run
    return self._loop.run_until_complete(task)
  File "C:\Python313\Lib\asyncio\base_events.py", line 707, in run_until_complete
    self.run_forever()
  File "C:\Python313\Lib\asyncio\base_events.py", line 678, in run_forever
    self._run_once()
  File "C:\Python313\Lib\asyncio\base_events.py", line 2033, in _run_once
    handle._run()
  File "C:\Python313\Lib\asyncio\events.py", line 89, in _run
    self._context.run(self._callback, *self._args)

  File "C:\Users\mikeb\work\sifu2\run_agents.py", line 857, in main
    await agent.run()

  File "C:\Users\mikeb\work\sifu2\run_agents.py", line 691, in run
    result = await getattr(self, task.tool)(**task.args)

  File "C:\Users\mikeb\work\sifu2\run_agents.py", line 344, in _synthesize_knowledge
    knowledge = await self.knowledge_system.process_source(content)

  File "C:\Users\mikeb\work\sifu2\scripts\knowledge_acquisition.py", line 466, in process_source
    relationships = await self._extract_relationships(content)

> File "C:\Users\mikeb\work\sifu2\scripts\knowledge_acquisition.py", line 650, in _extract_relationships
    converted_relationships.append(Relationship(**rel))

  File "C:\Python313\Lib\site-packages\pydantic\main.py", line 214, in __init__
    validated_self = self.__pydantic_validator__.validate_python(data, self_instance=self)

pydantic_core._pydantic_core.ValidationError: 1 validation error for Relationship
relation
  Input should be 'is_a', 'has_part' or 'related_to' [type=literal_error, input_value='input_to', input_type=str]
    For further information visit https://errors.pydantic.dev/2.10/v/literal_error
2025-02-09 14:57:43.862 | 40372:34912 | ERROR    | scripts.knowledge_acquisition:_extract_relationships:652 | Failed to convert relationship: {'source': 'Model Evaluation', 'relation': 'uses', 'target': 'Test Data'}: 1 validation error for Relationship
relation
  Input should be 'is_a', 'has_part' or 'related_to' [type=literal_error, input_value='uses', input_type=str]
    For further information visit https://errors.pydantic.dev/2.10/v/literal_error
Traceback (most recent call last):

  File "C:\Users\mikeb\work\sifu2\run_agents.py", line 868, in <module>
    asyncio.run(main())

  File "C:\Python313\Lib\asyncio\runners.py", line 194, in run
    return runner.run(main)
  File "C:\Python313\Lib\asyncio\runners.py", line 118, in run
    return self._loop.run_until_complete(task)
  File "C:\Python313\Lib\asyncio\base_events.py", line 707, in run_until_complete
    self.run_forever()
  File "C:\Python313\Lib\asyncio\base_events.py", line 678, in run_forever
    self._run_once()
  File "C:\Python313\Lib\asyncio\base_events.py", line 2033, in _run_once
    handle._run()
  File "C:\Python313\Lib\asyncio\events.py", line 89, in _run
    self._context.run(self._callback, *self._args)

  File "C:\Users\mikeb\work\sifu2\run_agents.py", line 857, in main
    await agent.run()

  File "C:\Users\mikeb\work\sifu2\run_agents.py", line 691, in run
    result = await getattr(self, task.tool)(**task.args)

  File "C:\Users\mikeb\work\sifu2\run_agents.py", line 344, in _synthesize_knowledge
    knowledge = await self.knowledge_system.process_source(content)

  File "C:\Users\mikeb\work\sifu2\scripts\knowledge_acquisition.py", line 466, in process_source
    relationships = await self._extract_relationships(content)

> File "C:\Users\mikeb\work\sifu2\scripts\knowledge_acquisition.py", line 650, in _extract_relationships
    converted_relationships.append(Relationship(**rel))

  File "C:\Python313\Lib\site-packages\pydantic\main.py", line 214, in __init__
    validated_self = self.__pydantic_validator__.validate_python(data, self_instance=self)

pydantic_core._pydantic_core.ValidationError: 1 validation error for Relationship
relation
  Input should be 'is_a', 'has_part' or 'related_to' [type=literal_error, input_value='uses', input_type=str]
    For further information visit https://errors.pydantic.dev/2.10/v/literal_error
2025-02-09 14:57:43.886 | 40372:34912 | ERROR    | scripts.knowledge_acquisition:_extract_relationships:652 | Failed to convert relationship: {'source': 'Model Evaluation', 'relation': 'output_of', 'target': 'Evaluation Metrics'}: 1 validation error for Relationship
relation
  Input should be 'is_a', 'has_part' or 'related_to' [type=literal_error, input_value='output_of', input_type=str]
    For further information visit https://errors.pydantic.dev/2.10/v/literal_error
Traceback (most recent call last):

  File "C:\Users\mikeb\work\sifu2\run_agents.py", line 868, in <module>
    asyncio.run(main())

  File "C:\Python313\Lib\asyncio\runners.py", line 194, in run
    return runner.run(main)
  File "C:\Python313\Lib\asyncio\runners.py", line 118, in run
    return self._loop.run_until_complete(task)
  File "C:\Python313\Lib\asyncio\base_events.py", line 707, in run_until_complete
    self.run_forever()
  File "C:\Python313\Lib\asyncio\base_events.py", line 678, in run_forever
    self._run_once()
  File "C:\Python313\Lib\asyncio\base_events.py", line 2033, in _run_once
    handle._run()
  File "C:\Python313\Lib\asyncio\events.py", line 89, in _run
    self._context.run(self._callback, *self._args)

  File "C:\Users\mikeb\work\sifu2\run_agents.py", line 857, in main
    await agent.run()

  File "C:\Users\mikeb\work\sifu2\run_agents.py", line 691, in run
    result = await getattr(self, task.tool)(**task.args)

  File "C:\Users\mikeb\work\sifu2\run_agents.py", line 344, in _synthesize_knowledge
    knowledge = await self.knowledge_system.process_source(content)

  File "C:\Users\mikeb\work\sifu2\scripts\knowledge_acquisition.py", line 466, in process_source
    relationships = await self._extract_relationships(content)

> File "C:\Users\mikeb\work\sifu2\scripts\knowledge_acquisition.py", line 650, in _extract_relationships
    converted_relationships.append(Relationship(**rel))

  File "C:\Python313\Lib\site-packages\pydantic\main.py", line 214, in __init__
    validated_self = self.__pydantic_validator__.validate_python(data, self_instance=self)

pydantic_core._pydantic_core.ValidationError: 1 validation error for Relationship
relation
  Input should be 'is_a', 'has_part' or 'related_to' [type=literal_error, input_value='output_of', input_type=str]
    For further information visit https://errors.pydantic.dev/2.10/v/literal_error
2025-02-09 14:57:43.908 | 40372:34912 | ERROR    | scripts.knowledge_acquisition:_extract_relationships:652 | Failed to convert relationship: {'source': 'CNNs', 'relation': 'applied_to', 'target': 'Image Recognition'}: 1 validation error for Relationship
relation
  Input should be 'is_a', 'has_part' or 'related_to' [type=literal_error, input_value='applied_to', input_type=str]
    For further information visit https://errors.pydantic.dev/2.10/v/literal_error
Traceback (most recent call last):

  File "C:\Users\mikeb\work\sifu2\run_agents.py", line 868, in <module>
    asyncio.run(main())

  File "C:\Python313\Lib\asyncio\runners.py", line 194, in run
    return runner.run(main)
  File "C:\Python313\Lib\asyncio\runners.py", line 118, in run
    return self._loop.run_until_complete(task)
  File "C:\Python313\Lib\asyncio\base_events.py", line 707, in run_until_complete
    self.run_forever()
  File "C:\Python313\Lib\asyncio\base_events.py", line 678, in run_forever
    self._run_once()
  File "C:\Python313\Lib\asyncio\base_events.py", line 2033, in _run_once
    handle._run()
  File "C:\Python313\Lib\asyncio\events.py", line 89, in _run
    self._context.run(self._callback, *self._args)

  File "C:\Users\mikeb\work\sifu2\run_agents.py", line 857, in main
    await agent.run()

  File "C:\Users\mikeb\work\sifu2\run_agents.py", line 691, in run
    result = await getattr(self, task.tool)(**task.args)

  File "C:\Users\mikeb\work\sifu2\run_agents.py", line 344, in _synthesize_knowledge
    knowledge = await self.knowledge_system.process_source(content)

  File "C:\Users\mikeb\work\sifu2\scripts\knowledge_acquisition.py", line 466, in process_source
    relationships = await self._extract_relationships(content)

> File "C:\Users\mikeb\work\sifu2\scripts\knowledge_acquisition.py", line 650, in _extract_relationships
    converted_relationships.append(Relationship(**rel))

  File "C:\Python313\Lib\site-packages\pydantic\main.py", line 214, in __init__
    validated_self = self.__pydantic_validator__.validate_python(data, self_instance=self)

pydantic_core._pydantic_core.ValidationError: 1 validation error for Relationship
relation
  Input should be 'is_a', 'has_part' or 'related_to' [type=literal_error, input_value='applied_to', input_type=str]
    For further information visit https://errors.pydantic.dev/2.10/v/literal_error
2025-02-09 14:57:43.932 | 40372:34912 | ERROR    | scripts.knowledge_acquisition:_extract_relationships:652 | Failed to convert relationship: {'source': 'RNNs', 'relation': 'applied_to', 'target': 'Natural Language Processing'}: 1 validation error for Relationship
relation
  Input should be 'is_a', 'has_part' or 'related_to' [type=literal_error, input_value='applied_to', input_type=str]
    For further information visit https://errors.pydantic.dev/2.10/v/literal_error
Traceback (most recent call last):

  File "C:\Users\mikeb\work\sifu2\run_agents.py", line 868, in <module>
    asyncio.run(main())

  File "C:\Python313\Lib\asyncio\runners.py", line 194, in run
    return runner.run(main)
  File "C:\Python313\Lib\asyncio\runners.py", line 118, in run
    return self._loop.run_until_complete(task)
  File "C:\Python313\Lib\asyncio\base_events.py", line 707, in run_until_complete
    self.run_forever()
  File "C:\Python313\Lib\asyncio\base_events.py", line 678, in run_forever
    self._run_once()
  File "C:\Python313\Lib\asyncio\base_events.py", line 2033, in _run_once
    handle._run()
  File "C:\Python313\Lib\asyncio\events.py", line 89, in _run
    self._context.run(self._callback, *self._args)

  File "C:\Users\mikeb\work\sifu2\run_agents.py", line 857, in main
    await agent.run()

  File "C:\Users\mikeb\work\sifu2\run_agents.py", line 691, in run
    result = await getattr(self, task.tool)(**task.args)

  File "C:\Users\mikeb\work\sifu2\run_agents.py", line 344, in _synthesize_knowledge
    knowledge = await self.knowledge_system.process_source(content)

  File "C:\Users\mikeb\work\sifu2\scripts\knowledge_acquisition.py", line 466, in process_source
    relationships = await self._extract_relationships(content)

> File "C:\Users\mikeb\work\sifu2\scripts\knowledge_acquisition.py", line 650, in _extract_relationships
    converted_relationships.append(Relationship(**rel))

  File "C:\Python313\Lib\site-packages\pydantic\main.py", line 214, in __init__
    validated_self = self.__pydantic_validator__.validate_python(data, self_instance=self)

pydantic_core._pydantic_core.ValidationError: 1 validation error for Relationship
relation
  Input should be 'is_a', 'has_part' or 'related_to' [type=literal_error, input_value='applied_to', input_type=str]
    For further information visit https://errors.pydantic.dev/2.10/v/literal_error
2025-02-09 14:57:51.067 | 40372:34912 | ERROR    | scripts.knowledge_acquisition:_extract_relationships:652 | Failed to convert relationship: {'source': 'Data Preprocessing', 'relation': 'precedes', 'target': 'Model Training'}: 1 validation error for Relationship
relation
  Input should be 'is_a', 'has_part' or 'related_to' [type=literal_error, input_value='precedes', input_type=str]
    For further information visit https://errors.pydantic.dev/2.10/v/literal_error
Traceback (most recent call last):

  File "C:\Users\mikeb\work\sifu2\run_agents.py", line 868, in <module>
    asyncio.run(main())

  File "C:\Python313\Lib\asyncio\runners.py", line 194, in run
    return runner.run(main)
  File "C:\Python313\Lib\asyncio\runners.py", line 118, in run
    return self._loop.run_until_complete(task)
  File "C:\Python313\Lib\asyncio\base_events.py", line 707, in run_until_complete
    self.run_forever()
  File "C:\Python313\Lib\asyncio\base_events.py", line 678, in run_forever
    self._run_once()
  File "C:\Python313\Lib\asyncio\base_events.py", line 2033, in _run_once
    handle._run()
  File "C:\Python313\Lib\asyncio\events.py", line 89, in _run
    self._context.run(self._callback, *self._args)

  File "C:\Users\mikeb\work\sifu2\run_agents.py", line 857, in main
    await agent.run()

  File "C:\Users\mikeb\work\sifu2\run_agents.py", line 691, in run
    result = await getattr(self, task.tool)(**task.args)

  File "C:\Users\mikeb\work\sifu2\run_agents.py", line 344, in _synthesize_knowledge
    knowledge = await self.knowledge_system.process_source(content)

  File "C:\Users\mikeb\work\sifu2\scripts\knowledge_acquisition.py", line 466, in process_source
    relationships = await self._extract_relationships(content)

> File "C:\Users\mikeb\work\sifu2\scripts\knowledge_acquisition.py", line 650, in _extract_relationships
    converted_relationships.append(Relationship(**rel))

  File "C:\Python313\Lib\site-packages\pydantic\main.py", line 214, in __init__
    validated_self = self.__pydantic_validator__.validate_python(data, self_instance=self)

pydantic_core._pydantic_core.ValidationError: 1 validation error for Relationship
relation
  Input should be 'is_a', 'has_part' or 'related_to' [type=literal_error, input_value='precedes', input_type=str]
    For further information visit https://errors.pydantic.dev/2.10/v/literal_error
2025-02-09 14:57:51.091 | 40372:34912 | ERROR    | scripts.knowledge_acquisition:_extract_relationships:652 | Failed to convert relationship: {'source': 'Model Training', 'relation': 'uses', 'target': 'Training Data'}: 1 validation error for Relationship
relation
  Input should be 'is_a', 'has_part' or 'related_to' [type=literal_error, input_value='uses', input_type=str]
    For further information visit https://errors.pydantic.dev/2.10/v/literal_error
Traceback (most recent call last):

  File "C:\Users\mikeb\work\sifu2\run_agents.py", line 868, in <module>
    asyncio.run(main())

  File "C:\Python313\Lib\asyncio\runners.py", line 194, in run
    return runner.run(main)
  File "C:\Python313\Lib\asyncio\runners.py", line 118, in run
    return self._loop.run_until_complete(task)
  File "C:\Python313\Lib\asyncio\base_events.py", line 707, in run_until_complete
    self.run_forever()
  File "C:\Python313\Lib\asyncio\base_events.py", line 678, in run_forever
    self._run_once()
  File "C:\Python313\Lib\asyncio\base_events.py", line 2033, in _run_once
    handle._run()
  File "C:\Python313\Lib\asyncio\events.py", line 89, in _run
    self._context.run(self._callback, *self._args)

  File "C:\Users\mikeb\work\sifu2\run_agents.py", line 857, in main
    await agent.run()

  File "C:\Users\mikeb\work\sifu2\run_agents.py", line 691, in run
    result = await getattr(self, task.tool)(**task.args)

  File "C:\Users\mikeb\work\sifu2\run_agents.py", line 344, in _synthesize_knowledge
    knowledge = await self.knowledge_system.process_source(content)

  File "C:\Users\mikeb\work\sifu2\scripts\knowledge_acquisition.py", line 466, in process_source
    relationships = await self._extract_relationships(content)

> File "C:\Users\mikeb\work\sifu2\scripts\knowledge_acquisition.py", line 650, in _extract_relationships
    converted_relationships.append(Relationship(**rel))

  File "C:\Python313\Lib\site-packages\pydantic\main.py", line 214, in __init__
    validated_self = self.__pydantic_validator__.validate_python(data, self_instance=self)

pydantic_core._pydantic_core.ValidationError: 1 validation error for Relationship
relation
  Input should be 'is_a', 'has_part' or 'related_to' [type=literal_error, input_value='uses', input_type=str]
    For further information visit https://errors.pydantic.dev/2.10/v/literal_error
2025-02-09 14:57:51.117 | 40372:34912 | ERROR    | scripts.knowledge_acquisition:_extract_relationships:652 | Failed to convert relationship: {'source': 'Model Training', 'relation': 'produces', 'target': 'Trained Model'}: 1 validation error for Relationship
relation
  Input should be 'is_a', 'has_part' or 'related_to' [type=literal_error, input_value='produces', input_type=str]
    For further information visit https://errors.pydantic.dev/2.10/v/literal_error
Traceback (most recent call last):

  File "C:\Users\mikeb\work\sifu2\run_agents.py", line 868, in <module>
    asyncio.run(main())

  File "C:\Python313\Lib\asyncio\runners.py", line 194, in run
    return runner.run(main)
  File "C:\Python313\Lib\asyncio\runners.py", line 118, in run
    return self._loop.run_until_complete(task)
  File "C:\Python313\Lib\asyncio\base_events.py", line 707, in run_until_complete
    self.run_forever()
  File "C:\Python313\Lib\asyncio\base_events.py", line 678, in run_forever
    self._run_once()
  File "C:\Python313\Lib\asyncio\base_events.py", line 2033, in _run_once
    handle._run()
  File "C:\Python313\Lib\asyncio\events.py", line 89, in _run
    self._context.run(self._callback, *self._args)

  File "C:\Users\mikeb\work\sifu2\run_agents.py", line 857, in main
    await agent.run()

  File "C:\Users\mikeb\work\sifu2\run_agents.py", line 691, in run
    result = await getattr(self, task.tool)(**task.args)

  File "C:\Users\mikeb\work\sifu2\run_agents.py", line 344, in _synthesize_knowledge
    knowledge = await self.knowledge_system.process_source(content)

  File "C:\Users\mikeb\work\sifu2\scripts\knowledge_acquisition.py", line 466, in process_source
    relationships = await self._extract_relationships(content)

> File "C:\Users\mikeb\work\sifu2\scripts\knowledge_acquisition.py", line 650, in _extract_relationships
    converted_relationships.append(Relationship(**rel))

  File "C:\Python313\Lib\site-packages\pydantic\main.py", line 214, in __init__
    validated_self = self.__pydantic_validator__.validate_python(data, self_instance=self)

pydantic_core._pydantic_core.ValidationError: 1 validation error for Relationship
relation
  Input should be 'is_a', 'has_part' or 'related_to' [type=literal_error, input_value='produces', input_type=str]
    For further information visit https://errors.pydantic.dev/2.10/v/literal_error
2025-02-09 14:57:51.140 | 40372:34912 | ERROR    | scripts.knowledge_acquisition:_extract_relationships:652 | Failed to convert relationship: {'source': 'Trained Model', 'relation': 'used_by', 'target': 'Model Evaluation'}: 1 validation error for Relationship
relation
  Input should be 'is_a', 'has_part' or 'related_to' [type=literal_error, input_value='used_by', input_type=str]
    For further information visit https://errors.pydantic.dev/2.10/v/literal_error
Traceback (most recent call last):

  File "C:\Users\mikeb\work\sifu2\run_agents.py", line 868, in <module>
    asyncio.run(main())

  File "C:\Python313\Lib\asyncio\runners.py", line 194, in run
    return runner.run(main)
  File "C:\Python313\Lib\asyncio\runners.py", line 118, in run
    return self._loop.run_until_complete(task)
  File "C:\Python313\Lib\asyncio\base_events.py", line 707, in run_until_complete
    self.run_forever()
  File "C:\Python313\Lib\asyncio\base_events.py", line 678, in run_forever
    self._run_once()
  File "C:\Python313\Lib\asyncio\base_events.py", line 2033, in _run_once
    handle._run()
  File "C:\Python313\Lib\asyncio\events.py", line 89, in _run
    self._context.run(self._callback, *self._args)

  File "C:\Users\mikeb\work\sifu2\run_agents.py", line 857, in main
    await agent.run()

  File "C:\Users\mikeb\work\sifu2\run_agents.py", line 691, in run
    result = await getattr(self, task.tool)(**task.args)

  File "C:\Users\mikeb\work\sifu2\run_agents.py", line 344, in _synthesize_knowledge
    knowledge = await self.knowledge_system.process_source(content)

  File "C:\Users\mikeb\work\sifu2\scripts\knowledge_acquisition.py", line 466, in process_source
    relationships = await self._extract_relationships(content)

> File "C:\Users\mikeb\work\sifu2\scripts\knowledge_acquisition.py", line 650, in _extract_relationships
    converted_relationships.append(Relationship(**rel))

  File "C:\Python313\Lib\site-packages\pydantic\main.py", line 214, in __init__
    validated_self = self.__pydantic_validator__.validate_python(data, self_instance=self)

pydantic_core._pydantic_core.ValidationError: 1 validation error for Relationship
relation
  Input should be 'is_a', 'has_part' or 'related_to' [type=literal_error, input_value='used_by', input_type=str]
    For further information visit https://errors.pydantic.dev/2.10/v/literal_error
2025-02-09 14:57:51.164 | 40372:34912 | ERROR    | scripts.knowledge_acquisition:_extract_relationships:652 | Failed to convert relationship: {'source': 'Model Evaluation', 'relation': 'uses', 'target': 'Test Data'}: 1 validation error for Relationship
relation
  Input should be 'is_a', 'has_part' or 'related_to' [type=literal_error, input_value='uses', input_type=str]
    For further information visit https://errors.pydantic.dev/2.10/v/literal_error
Traceback (most recent call last):

  File "C:\Users\mikeb\work\sifu2\run_agents.py", line 868, in <module>
    asyncio.run(main())

  File "C:\Python313\Lib\asyncio\runners.py", line 194, in run
    return runner.run(main)
  File "C:\Python313\Lib\asyncio\runners.py", line 118, in run
    return self._loop.run_until_complete(task)
  File "C:\Python313\Lib\asyncio\base_events.py", line 707, in run_until_complete
    self.run_forever()
  File "C:\Python313\Lib\asyncio\base_events.py", line 678, in run_forever
    self._run_once()
  File "C:\Python313\Lib\asyncio\base_events.py", line 2033, in _run_once
    handle._run()
  File "C:\Python313\Lib\asyncio\events.py", line 89, in _run
    self._context.run(self._callback, *self._args)

  File "C:\Users\mikeb\work\sifu2\run_agents.py", line 857, in main
    await agent.run()

  File "C:\Users\mikeb\work\sifu2\run_agents.py", line 691, in run
    result = await getattr(self, task.tool)(**task.args)

  File "C:\Users\mikeb\work\sifu2\run_agents.py", line 344, in _synthesize_knowledge
    knowledge = await self.knowledge_system.process_source(content)

  File "C:\Users\mikeb\work\sifu2\scripts\knowledge_acquisition.py", line 466, in process_source
    relationships = await self._extract_relationships(content)

> File "C:\Users\mikeb\work\sifu2\scripts\knowledge_acquisition.py", line 650, in _extract_relationships
    converted_relationships.append(Relationship(**rel))

  File "C:\Python313\Lib\site-packages\pydantic\main.py", line 214, in __init__
    validated_self = self.__pydantic_validator__.validate_python(data, self_instance=self)

pydantic_core._pydantic_core.ValidationError: 1 validation error for Relationship
relation
  Input should be 'is_a', 'has_part' or 'related_to' [type=literal_error, input_value='uses', input_type=str]
    For further information visit https://errors.pydantic.dev/2.10/v/literal_error
2025-02-09 14:57:51.188 | 40372:34912 | ERROR    | scripts.knowledge_acquisition:_extract_relationships:652 | Failed to convert relationship: {'source': 'Model Evaluation', 'relation': 'produces', 'target': 'Evaluation Metrics'}: 1 validation error for Relationship
relation
  Input should be 'is_a', 'has_part' or 'related_to' [type=literal_error, input_value='produces', input_type=str]
    For further information visit https://errors.pydantic.dev/2.10/v/literal_error
Traceback (most recent call last):

  File "C:\Users\mikeb\work\sifu2\run_agents.py", line 868, in <module>
    asyncio.run(main())

  File "C:\Python313\Lib\asyncio\runners.py", line 194, in run
    return runner.run(main)
  File "C:\Python313\Lib\asyncio\runners.py", line 118, in run
    return self._loop.run_until_complete(task)
  File "C:\Python313\Lib\asyncio\base_events.py", line 707, in run_until_complete
    self.run_forever()
  File "C:\Python313\Lib\asyncio\base_events.py", line 678, in run_forever
    self._run_once()
  File "C:\Python313\Lib\asyncio\base_events.py", line 2033, in _run_once
    handle._run()
  File "C:\Python313\Lib\asyncio\events.py", line 89, in _run
    self._context.run(self._callback, *self._args)

  File "C:\Users\mikeb\work\sifu2\run_agents.py", line 857, in main
    await agent.run()

  File "C:\Users\mikeb\work\sifu2\run_agents.py", line 691, in run
    result = await getattr(self, task.tool)(**task.args)

  File "C:\Users\mikeb\work\sifu2\run_agents.py", line 344, in _synthesize_knowledge
    knowledge = await self.knowledge_system.process_source(content)

  File "C:\Users\mikeb\work\sifu2\scripts\knowledge_acquisition.py", line 466, in process_source
    relationships = await self._extract_relationships(content)

> File "C:\Users\mikeb\work\sifu2\scripts\knowledge_acquisition.py", line 650, in _extract_relationships
    converted_relationships.append(Relationship(**rel))

  File "C:\Python313\Lib\site-packages\pydantic\main.py", line 214, in __init__
    validated_self = self.__pydantic_validator__.validate_python(data, self_instance=self)

pydantic_core._pydantic_core.ValidationError: 1 validation error for Relationship
relation
  Input should be 'is_a', 'has_part' or 'related_to' [type=literal_error, input_value='produces', input_type=str]
    For further information visit https://errors.pydantic.dev/2.10/v/literal_error
2025-02-09 14:57:51.212 | 40372:34912 | ERROR    | scripts.knowledge_acquisition:_extract_relationships:652 | Failed to convert relationship: {'source': 'CNNs', 'relation': 'applied_to', 'target': 'Image Recognition'}: 1 validation error for Relationship
relation
  Input should be 'is_a', 'has_part' or 'related_to' [type=literal_error, input_value='applied_to', input_type=str]
    For further information visit https://errors.pydantic.dev/2.10/v/literal_error
Traceback (most recent call last):

  File "C:\Users\mikeb\work\sifu2\run_agents.py", line 868, in <module>
    asyncio.run(main())

  File "C:\Python313\Lib\asyncio\runners.py", line 194, in run
    return runner.run(main)
  File "C:\Python313\Lib\asyncio\runners.py", line 118, in run
    return self._loop.run_until_complete(task)
  File "C:\Python313\Lib\asyncio\base_events.py", line 707, in run_until_complete
    self.run_forever()
  File "C:\Python313\Lib\asyncio\base_events.py", line 678, in run_forever
    self._run_once()
  File "C:\Python313\Lib\asyncio\base_events.py", line 2033, in _run_once
    handle._run()
  File "C:\Python313\Lib\asyncio\events.py", line 89, in _run
    self._context.run(self._callback, *self._args)

  File "C:\Users\mikeb\work\sifu2\run_agents.py", line 857, in main
    await agent.run()

  File "C:\Users\mikeb\work\sifu2\run_agents.py", line 691, in run
    result = await getattr(self, task.tool)(**task.args)

  File "C:\Users\mikeb\work\sifu2\run_agents.py", line 344, in _synthesize_knowledge
    knowledge = await self.knowledge_system.process_source(content)

  File "C:\Users\mikeb\work\sifu2\scripts\knowledge_acquisition.py", line 466, in process_source
    relationships = await self._extract_relationships(content)

> File "C:\Users\mikeb\work\sifu2\scripts\knowledge_acquisition.py", line 650, in _extract_relationships
    converted_relationships.append(Relationship(**rel))

  File "C:\Python313\Lib\site-packages\pydantic\main.py", line 214, in __init__
    validated_self = self.__pydantic_validator__.validate_python(data, self_instance=self)

pydantic_core._pydantic_core.ValidationError: 1 validation error for Relationship
relation
  Input should be 'is_a', 'has_part' or 'related_to' [type=literal_error, input_value='applied_to', input_type=str]
    For further information visit https://errors.pydantic.dev/2.10/v/literal_error
2025-02-09 14:57:51.236 | 40372:34912 | ERROR    | scripts.knowledge_acquisition:_extract_relationships:652 | Failed to convert relationship: {'source': 'RNNs', 'relation': 'applied_to', 'target': 'Natural Language Processing'}: 1 validation error for Relationship
relation
  Input should be 'is_a', 'has_part' or 'related_to' [type=literal_error, input_value='applied_to', input_type=str]
    For further information visit https://errors.pydantic.dev/2.10/v/literal_error
Traceback (most recent call last):

  File "C:\Users\mikeb\work\sifu2\run_agents.py", line 868, in <module>
    asyncio.run(main())

  File "C:\Python313\Lib\asyncio\runners.py", line 194, in run
    return runner.run(main)
  File "C:\Python313\Lib\asyncio\runners.py", line 118, in run
    return self._loop.run_until_complete(task)
  File "C:\Python313\Lib\asyncio\base_events.py", line 707, in run_until_complete
    self.run_forever()
  File "C:\Python313\Lib\asyncio\base_events.py", line 678, in run_forever
    self._run_once()
  File "C:\Python313\Lib\asyncio\base_events.py", line 2033, in _run_once
    handle._run()
  File "C:\Python313\Lib\asyncio\events.py", line 89, in _run
    self._context.run(self._callback, *self._args)

  File "C:\Users\mikeb\work\sifu2\run_agents.py", line 857, in main
    await agent.run()

  File "C:\Users\mikeb\work\sifu2\run_agents.py", line 691, in run
    result = await getattr(self, task.tool)(**task.args)

  File "C:\Users\mikeb\work\sifu2\run_agents.py", line 344, in _synthesize_knowledge
    knowledge = await self.knowledge_system.process_source(content)

  File "C:\Users\mikeb\work\sifu2\scripts\knowledge_acquisition.py", line 466, in process_source
    relationships = await self._extract_relationships(content)

> File "C:\Users\mikeb\work\sifu2\scripts\knowledge_acquisition.py", line 650, in _extract_relationships
    converted_relationships.append(Relationship(**rel))

  File "C:\Python313\Lib\site-packages\pydantic\main.py", line 214, in __init__
    validated_self = self.__pydantic_validator__.validate_python(data, self_instance=self)

pydantic_core._pydantic_core.ValidationError: 1 validation error for Relationship
relation
  Input should be 'is_a', 'has_part' or 'related_to' [type=literal_error, input_value='applied_to', input_type=str]
    For further information visit https://errors.pydantic.dev/2.10/v/literal_error
