2025-02-09 22:48:00.504 | 35908:53896 | ERROR    | scripts.example_generator:generate_examples:115 | Error generating examples: Invalid json output: 
For troubleshooting, visit: https://python.langchain.com/docs/troubleshooting/errors/OUTPUT_PARSING_FAILURE 
Traceback (most recent call last):

  File "C:\Python313\Lib\site-packages\langchain_core\output_parsers\json.py", line 83, in parse_result
    return parse_json_markdown(text)
  File "C:\Python313\Lib\site-packages\langchain_core\utils\json.py", line 143, in parse_json_markdown
    return _parse_json(json_str, parser=parser)
  File "C:\Python313\Lib\site-packages\langchain_core\utils\json.py", line 159, in _parse_json
    return parser(json_str)
  File "C:\Python313\Lib\site-packages\langchain_core\utils\json.py", line 117, in parse_partial_json
    return json.loads(s, strict=strict)
  File "C:\Python313\Lib\json\__init__.py", line 359, in loads
    return cls(**kw).decode(s)
  File "C:\Python313\Lib\json\decoder.py", line 345, in decode
    obj, end = self.raw_decode(s, idx=_w(s, 0).end())
  File "C:\Python313\Lib\json\decoder.py", line 363, in raw_decode
    raise JSONDecodeError("Expecting value", s, err.value) from None

json.decoder.JSONDecodeError: Expecting value: line 1 column 1 (char 0)


The above exception was the direct cause of the following exception:


Traceback (most recent call last):

  File "C:\Users\mikeb\work\sifu2\run_agents.py", line 974, in <module>
    asyncio.run(main())

  File "C:\Python313\Lib\asyncio\runners.py", line 194, in run
    return runner.run(main)
  File "C:\Python313\Lib\asyncio\runners.py", line 118, in run
    return self._loop.run_until_complete(task)
  File "C:\Python313\Lib\asyncio\base_events.py", line 707, in run_until_complete
    self.run_forever()
  File "C:\Python313\Lib\asyncio\base_events.py", line 678, in run_forever
    self._run_once()
  File "C:\Python313\Lib\asyncio\base_events.py", line 2033, in _run_once
    handle._run()
  File "C:\Python313\Lib\asyncio\events.py", line 89, in _run
    self._context.run(self._callback, *self._args)

  File "C:\Users\mikeb\work\sifu2\run_agents.py", line 963, in main
    await agent.run()

  File "C:\Users\mikeb\work\sifu2\run_agents.py", line 691, in run
    result = await getattr(self, task.tool)(**task.args)

  File "C:\Users\mikeb\work\sifu2\run_agents.py", line 438, in _generate_examples
    examples_result = await self.example_generator.generate_examples(content)

> File "C:\Users\mikeb\work\sifu2\scripts\example_generator.py", line 90, in generate_examples
    result = await chain.ainvoke({

  File "C:\Python313\Lib\site-packages\langchain_core\runnables\base.py", line 3058, in ainvoke
    input = await asyncio.create_task(part(), context=context)  # type: ignore
  File "C:\Python313\Lib\site-packages\langchain_core\output_parsers\base.py", line 216, in ainvoke
    return await self._acall_with_config(
  File "C:\Python313\Lib\site-packages\langchain_core\runnables\base.py", line 1966, in _acall_with_config
    output: Output = await asyncio.create_task(coro, context=context)  # type: ignore
  File "C:\Python313\Lib\site-packages\langchain_core\output_parsers\base.py", line 277, in aparse_result
    return await run_in_executor(None, self.parse_result, result, partial=partial)
  File "C:\Python313\Lib\site-packages\langchain_core\runnables\config.py", line 588, in run_in_executor
    return await asyncio.get_running_loop().run_in_executor(
  File "C:\Python313\Lib\concurrent\futures\thread.py", line 59, in run
    result = self.fn(*self.args, **self.kwargs)
  File "C:\Python313\Lib\site-packages\langchain_core\runnables\config.py", line 579, in wrapper
    return func(*args, **kwargs)
  File "C:\Python313\Lib\site-packages\langchain_core\output_parsers\pydantic.py", line 67, in parse_result
    json_object = super().parse_result(result)
  File "C:\Python313\Lib\site-packages\langchain_core\output_parsers\json.py", line 86, in parse_result
    raise OutputParserException(msg, llm_output=text) from e

langchain_core.exceptions.OutputParserException: Invalid json output: 
For troubleshooting, visit: https://python.langchain.com/docs/troubleshooting/errors/OUTPUT_PARSING_FAILURE 
2025-02-09 22:48:04.418 | 35908:53896 | ERROR    | scripts.example_generator:generate_examples:115 | Error generating examples: Invalid json output: 
For troubleshooting, visit: https://python.langchain.com/docs/troubleshooting/errors/OUTPUT_PARSING_FAILURE 
Traceback (most recent call last):

  File "C:\Python313\Lib\site-packages\langchain_core\output_parsers\json.py", line 83, in parse_result
    return parse_json_markdown(text)
  File "C:\Python313\Lib\site-packages\langchain_core\utils\json.py", line 143, in parse_json_markdown
    return _parse_json(json_str, parser=parser)
  File "C:\Python313\Lib\site-packages\langchain_core\utils\json.py", line 159, in _parse_json
    return parser(json_str)
  File "C:\Python313\Lib\site-packages\langchain_core\utils\json.py", line 117, in parse_partial_json
    return json.loads(s, strict=strict)
  File "C:\Python313\Lib\json\__init__.py", line 359, in loads
    return cls(**kw).decode(s)
  File "C:\Python313\Lib\json\decoder.py", line 345, in decode
    obj, end = self.raw_decode(s, idx=_w(s, 0).end())
  File "C:\Python313\Lib\json\decoder.py", line 363, in raw_decode
    raise JSONDecodeError("Expecting value", s, err.value) from None

json.decoder.JSONDecodeError: Expecting value: line 1 column 1 (char 0)


The above exception was the direct cause of the following exception:


Traceback (most recent call last):

  File "C:\Users\mikeb\work\sifu2\run_agents.py", line 974, in <module>
    asyncio.run(main())

  File "C:\Python313\Lib\asyncio\runners.py", line 194, in run
    return runner.run(main)
  File "C:\Python313\Lib\asyncio\runners.py", line 118, in run
    return self._loop.run_until_complete(task)
  File "C:\Python313\Lib\asyncio\base_events.py", line 707, in run_until_complete
    self.run_forever()
  File "C:\Python313\Lib\asyncio\base_events.py", line 678, in run_forever
    self._run_once()
  File "C:\Python313\Lib\asyncio\base_events.py", line 2033, in _run_once
    handle._run()
  File "C:\Python313\Lib\asyncio\events.py", line 89, in _run
    self._context.run(self._callback, *self._args)

  File "C:\Users\mikeb\work\sifu2\run_agents.py", line 963, in main
    await agent.run()

  File "C:\Users\mikeb\work\sifu2\run_agents.py", line 691, in run
    result = await getattr(self, task.tool)(**task.args)

  File "C:\Users\mikeb\work\sifu2\run_agents.py", line 438, in _generate_examples
    examples_result = await self.example_generator.generate_examples(content)

> File "C:\Users\mikeb\work\sifu2\scripts\example_generator.py", line 90, in generate_examples
    result = await chain.ainvoke({

  File "C:\Python313\Lib\site-packages\langchain_core\runnables\base.py", line 3058, in ainvoke
    input = await asyncio.create_task(part(), context=context)  # type: ignore
  File "C:\Python313\Lib\site-packages\langchain_core\output_parsers\base.py", line 216, in ainvoke
    return await self._acall_with_config(
  File "C:\Python313\Lib\site-packages\langchain_core\runnables\base.py", line 1966, in _acall_with_config
    output: Output = await asyncio.create_task(coro, context=context)  # type: ignore
  File "C:\Python313\Lib\site-packages\langchain_core\output_parsers\base.py", line 277, in aparse_result
    return await run_in_executor(None, self.parse_result, result, partial=partial)
  File "C:\Python313\Lib\site-packages\langchain_core\runnables\config.py", line 588, in run_in_executor
    return await asyncio.get_running_loop().run_in_executor(
  File "C:\Python313\Lib\concurrent\futures\thread.py", line 59, in run
    result = self.fn(*self.args, **self.kwargs)
  File "C:\Python313\Lib\site-packages\langchain_core\runnables\config.py", line 579, in wrapper
    return func(*args, **kwargs)
  File "C:\Python313\Lib\site-packages\langchain_core\output_parsers\pydantic.py", line 67, in parse_result
    json_object = super().parse_result(result)
  File "C:\Python313\Lib\site-packages\langchain_core\output_parsers\json.py", line 86, in parse_result
    raise OutputParserException(msg, llm_output=text) from e

langchain_core.exceptions.OutputParserException: Invalid json output: 
For troubleshooting, visit: https://python.langchain.com/docs/troubleshooting/errors/OUTPUT_PARSING_FAILURE 
2025-02-09 22:48:07.886 | 35908:53896 | ERROR    | scripts.example_generator:generate_examples:115 | Error generating examples: Invalid json output: 
For troubleshooting, visit: https://python.langchain.com/docs/troubleshooting/errors/OUTPUT_PARSING_FAILURE 
Traceback (most recent call last):

  File "C:\Python313\Lib\site-packages\langchain_core\output_parsers\json.py", line 83, in parse_result
    return parse_json_markdown(text)
  File "C:\Python313\Lib\site-packages\langchain_core\utils\json.py", line 143, in parse_json_markdown
    return _parse_json(json_str, parser=parser)
  File "C:\Python313\Lib\site-packages\langchain_core\utils\json.py", line 159, in _parse_json
    return parser(json_str)
  File "C:\Python313\Lib\site-packages\langchain_core\utils\json.py", line 117, in parse_partial_json
    return json.loads(s, strict=strict)
  File "C:\Python313\Lib\json\__init__.py", line 359, in loads
    return cls(**kw).decode(s)
  File "C:\Python313\Lib\json\decoder.py", line 345, in decode
    obj, end = self.raw_decode(s, idx=_w(s, 0).end())
  File "C:\Python313\Lib\json\decoder.py", line 363, in raw_decode
    raise JSONDecodeError("Expecting value", s, err.value) from None

json.decoder.JSONDecodeError: Expecting value: line 1 column 1 (char 0)


The above exception was the direct cause of the following exception:


Traceback (most recent call last):

  File "C:\Users\mikeb\work\sifu2\run_agents.py", line 974, in <module>
    asyncio.run(main())

  File "C:\Python313\Lib\asyncio\runners.py", line 194, in run
    return runner.run(main)
  File "C:\Python313\Lib\asyncio\runners.py", line 118, in run
    return self._loop.run_until_complete(task)
  File "C:\Python313\Lib\asyncio\base_events.py", line 707, in run_until_complete
    self.run_forever()
  File "C:\Python313\Lib\asyncio\base_events.py", line 678, in run_forever
    self._run_once()
  File "C:\Python313\Lib\asyncio\base_events.py", line 2033, in _run_once
    handle._run()
  File "C:\Python313\Lib\asyncio\events.py", line 89, in _run
    self._context.run(self._callback, *self._args)

  File "C:\Users\mikeb\work\sifu2\run_agents.py", line 963, in main
    await agent.run()

  File "C:\Users\mikeb\work\sifu2\run_agents.py", line 691, in run
    result = await getattr(self, task.tool)(**task.args)

  File "C:\Users\mikeb\work\sifu2\run_agents.py", line 438, in _generate_examples
    examples_result = await self.example_generator.generate_examples(content)

> File "C:\Users\mikeb\work\sifu2\scripts\example_generator.py", line 90, in generate_examples
    result = await chain.ainvoke({

  File "C:\Python313\Lib\site-packages\langchain_core\runnables\base.py", line 3058, in ainvoke
    input = await asyncio.create_task(part(), context=context)  # type: ignore
  File "C:\Python313\Lib\site-packages\langchain_core\output_parsers\base.py", line 216, in ainvoke
    return await self._acall_with_config(
  File "C:\Python313\Lib\site-packages\langchain_core\runnables\base.py", line 1966, in _acall_with_config
    output: Output = await asyncio.create_task(coro, context=context)  # type: ignore
  File "C:\Python313\Lib\site-packages\langchain_core\output_parsers\base.py", line 277, in aparse_result
    return await run_in_executor(None, self.parse_result, result, partial=partial)
  File "C:\Python313\Lib\site-packages\langchain_core\runnables\config.py", line 588, in run_in_executor
    return await asyncio.get_running_loop().run_in_executor(
  File "C:\Python313\Lib\concurrent\futures\thread.py", line 59, in run
    result = self.fn(*self.args, **self.kwargs)
  File "C:\Python313\Lib\site-packages\langchain_core\runnables\config.py", line 579, in wrapper
    return func(*args, **kwargs)
  File "C:\Python313\Lib\site-packages\langchain_core\output_parsers\pydantic.py", line 67, in parse_result
    json_object = super().parse_result(result)
  File "C:\Python313\Lib\site-packages\langchain_core\output_parsers\json.py", line 86, in parse_result
    raise OutputParserException(msg, llm_output=text) from e

langchain_core.exceptions.OutputParserException: Invalid json output: 
For troubleshooting, visit: https://python.langchain.com/docs/troubleshooting/errors/OUTPUT_PARSING_FAILURE 
2025-02-09 22:48:12.293 | 35908:53896 | ERROR    | scripts.example_generator:generate_examples:115 | Error generating examples: Invalid json output: 
For troubleshooting, visit: https://python.langchain.com/docs/troubleshooting/errors/OUTPUT_PARSING_FAILURE 
Traceback (most recent call last):

  File "C:\Python313\Lib\site-packages\langchain_core\output_parsers\json.py", line 83, in parse_result
    return parse_json_markdown(text)
  File "C:\Python313\Lib\site-packages\langchain_core\utils\json.py", line 143, in parse_json_markdown
    return _parse_json(json_str, parser=parser)
  File "C:\Python313\Lib\site-packages\langchain_core\utils\json.py", line 159, in _parse_json
    return parser(json_str)
  File "C:\Python313\Lib\site-packages\langchain_core\utils\json.py", line 117, in parse_partial_json
    return json.loads(s, strict=strict)
  File "C:\Python313\Lib\json\__init__.py", line 359, in loads
    return cls(**kw).decode(s)
  File "C:\Python313\Lib\json\decoder.py", line 345, in decode
    obj, end = self.raw_decode(s, idx=_w(s, 0).end())
  File "C:\Python313\Lib\json\decoder.py", line 363, in raw_decode
    raise JSONDecodeError("Expecting value", s, err.value) from None

json.decoder.JSONDecodeError: Expecting value: line 1 column 1 (char 0)


The above exception was the direct cause of the following exception:


Traceback (most recent call last):

  File "C:\Users\mikeb\work\sifu2\run_agents.py", line 974, in <module>
    asyncio.run(main())

  File "C:\Python313\Lib\asyncio\runners.py", line 194, in run
    return runner.run(main)
  File "C:\Python313\Lib\asyncio\runners.py", line 118, in run
    return self._loop.run_until_complete(task)
  File "C:\Python313\Lib\asyncio\base_events.py", line 707, in run_until_complete
    self.run_forever()
  File "C:\Python313\Lib\asyncio\base_events.py", line 678, in run_forever
    self._run_once()
  File "C:\Python313\Lib\asyncio\base_events.py", line 2033, in _run_once
    handle._run()
  File "C:\Python313\Lib\asyncio\events.py", line 89, in _run
    self._context.run(self._callback, *self._args)

  File "C:\Users\mikeb\work\sifu2\run_agents.py", line 963, in main
    await agent.run()

  File "C:\Users\mikeb\work\sifu2\run_agents.py", line 691, in run
    result = await getattr(self, task.tool)(**task.args)

  File "C:\Users\mikeb\work\sifu2\run_agents.py", line 438, in _generate_examples
    examples_result = await self.example_generator.generate_examples(content)

> File "C:\Users\mikeb\work\sifu2\scripts\example_generator.py", line 90, in generate_examples
    result = await chain.ainvoke({

  File "C:\Python313\Lib\site-packages\langchain_core\runnables\base.py", line 3058, in ainvoke
    input = await asyncio.create_task(part(), context=context)  # type: ignore
  File "C:\Python313\Lib\site-packages\langchain_core\output_parsers\base.py", line 216, in ainvoke
    return await self._acall_with_config(
  File "C:\Python313\Lib\site-packages\langchain_core\runnables\base.py", line 1966, in _acall_with_config
    output: Output = await asyncio.create_task(coro, context=context)  # type: ignore
  File "C:\Python313\Lib\site-packages\langchain_core\output_parsers\base.py", line 277, in aparse_result
    return await run_in_executor(None, self.parse_result, result, partial=partial)
  File "C:\Python313\Lib\site-packages\langchain_core\runnables\config.py", line 588, in run_in_executor
    return await asyncio.get_running_loop().run_in_executor(
  File "C:\Python313\Lib\concurrent\futures\thread.py", line 59, in run
    result = self.fn(*self.args, **self.kwargs)
  File "C:\Python313\Lib\site-packages\langchain_core\runnables\config.py", line 579, in wrapper
    return func(*args, **kwargs)
  File "C:\Python313\Lib\site-packages\langchain_core\output_parsers\pydantic.py", line 67, in parse_result
    json_object = super().parse_result(result)
  File "C:\Python313\Lib\site-packages\langchain_core\output_parsers\json.py", line 86, in parse_result
    raise OutputParserException(msg, llm_output=text) from e

langchain_core.exceptions.OutputParserException: Invalid json output: 
For troubleshooting, visit: https://python.langchain.com/docs/troubleshooting/errors/OUTPUT_PARSING_FAILURE 
2025-02-09 22:48:16.307 | 35908:53896 | ERROR    | scripts.example_generator:generate_examples:115 | Error generating examples: Invalid json output: 
For troubleshooting, visit: https://python.langchain.com/docs/troubleshooting/errors/OUTPUT_PARSING_FAILURE 
Traceback (most recent call last):

  File "C:\Python313\Lib\site-packages\langchain_core\output_parsers\json.py", line 83, in parse_result
    return parse_json_markdown(text)
  File "C:\Python313\Lib\site-packages\langchain_core\utils\json.py", line 143, in parse_json_markdown
    return _parse_json(json_str, parser=parser)
  File "C:\Python313\Lib\site-packages\langchain_core\utils\json.py", line 159, in _parse_json
    return parser(json_str)
  File "C:\Python313\Lib\site-packages\langchain_core\utils\json.py", line 117, in parse_partial_json
    return json.loads(s, strict=strict)
  File "C:\Python313\Lib\json\__init__.py", line 359, in loads
    return cls(**kw).decode(s)
  File "C:\Python313\Lib\json\decoder.py", line 345, in decode
    obj, end = self.raw_decode(s, idx=_w(s, 0).end())
  File "C:\Python313\Lib\json\decoder.py", line 363, in raw_decode
    raise JSONDecodeError("Expecting value", s, err.value) from None

json.decoder.JSONDecodeError: Expecting value: line 1 column 1 (char 0)


The above exception was the direct cause of the following exception:


Traceback (most recent call last):

  File "C:\Users\mikeb\work\sifu2\run_agents.py", line 974, in <module>
    asyncio.run(main())

  File "C:\Python313\Lib\asyncio\runners.py", line 194, in run
    return runner.run(main)
  File "C:\Python313\Lib\asyncio\runners.py", line 118, in run
    return self._loop.run_until_complete(task)
  File "C:\Python313\Lib\asyncio\base_events.py", line 707, in run_until_complete
    self.run_forever()
  File "C:\Python313\Lib\asyncio\base_events.py", line 678, in run_forever
    self._run_once()
  File "C:\Python313\Lib\asyncio\base_events.py", line 2033, in _run_once
    handle._run()
  File "C:\Python313\Lib\asyncio\events.py", line 89, in _run
    self._context.run(self._callback, *self._args)

  File "C:\Users\mikeb\work\sifu2\run_agents.py", line 963, in main
    await agent.run()

  File "C:\Users\mikeb\work\sifu2\run_agents.py", line 691, in run
    result = await getattr(self, task.tool)(**task.args)

  File "C:\Users\mikeb\work\sifu2\run_agents.py", line 438, in _generate_examples
    examples_result = await self.example_generator.generate_examples(content)

> File "C:\Users\mikeb\work\sifu2\scripts\example_generator.py", line 90, in generate_examples
    result = await chain.ainvoke({

  File "C:\Python313\Lib\site-packages\langchain_core\runnables\base.py", line 3058, in ainvoke
    input = await asyncio.create_task(part(), context=context)  # type: ignore
  File "C:\Python313\Lib\site-packages\langchain_core\output_parsers\base.py", line 216, in ainvoke
    return await self._acall_with_config(
  File "C:\Python313\Lib\site-packages\langchain_core\runnables\base.py", line 1966, in _acall_with_config
    output: Output = await asyncio.create_task(coro, context=context)  # type: ignore
  File "C:\Python313\Lib\site-packages\langchain_core\output_parsers\base.py", line 277, in aparse_result
    return await run_in_executor(None, self.parse_result, result, partial=partial)
  File "C:\Python313\Lib\site-packages\langchain_core\runnables\config.py", line 588, in run_in_executor
    return await asyncio.get_running_loop().run_in_executor(
  File "C:\Python313\Lib\concurrent\futures\thread.py", line 59, in run
    result = self.fn(*self.args, **self.kwargs)
  File "C:\Python313\Lib\site-packages\langchain_core\runnables\config.py", line 579, in wrapper
    return func(*args, **kwargs)
  File "C:\Python313\Lib\site-packages\langchain_core\output_parsers\pydantic.py", line 67, in parse_result
    json_object = super().parse_result(result)
  File "C:\Python313\Lib\site-packages\langchain_core\output_parsers\json.py", line 86, in parse_result
    raise OutputParserException(msg, llm_output=text) from e

langchain_core.exceptions.OutputParserException: Invalid json output: 
For troubleshooting, visit: https://python.langchain.com/docs/troubleshooting/errors/OUTPUT_PARSING_FAILURE 
2025-02-09 22:48:19.904 | 35908:53896 | ERROR    | scripts.example_generator:generate_examples:115 | Error generating examples: Invalid json output: 
For troubleshooting, visit: https://python.langchain.com/docs/troubleshooting/errors/OUTPUT_PARSING_FAILURE 
Traceback (most recent call last):

  File "C:\Python313\Lib\site-packages\langchain_core\output_parsers\json.py", line 83, in parse_result
    return parse_json_markdown(text)
  File "C:\Python313\Lib\site-packages\langchain_core\utils\json.py", line 143, in parse_json_markdown
    return _parse_json(json_str, parser=parser)
  File "C:\Python313\Lib\site-packages\langchain_core\utils\json.py", line 159, in _parse_json
    return parser(json_str)
  File "C:\Python313\Lib\site-packages\langchain_core\utils\json.py", line 117, in parse_partial_json
    return json.loads(s, strict=strict)
  File "C:\Python313\Lib\json\__init__.py", line 359, in loads
    return cls(**kw).decode(s)
  File "C:\Python313\Lib\json\decoder.py", line 345, in decode
    obj, end = self.raw_decode(s, idx=_w(s, 0).end())
  File "C:\Python313\Lib\json\decoder.py", line 363, in raw_decode
    raise JSONDecodeError("Expecting value", s, err.value) from None

json.decoder.JSONDecodeError: Expecting value: line 1 column 1 (char 0)


The above exception was the direct cause of the following exception:


Traceback (most recent call last):

  File "C:\Users\mikeb\work\sifu2\run_agents.py", line 974, in <module>
    asyncio.run(main())

  File "C:\Python313\Lib\asyncio\runners.py", line 194, in run
    return runner.run(main)
  File "C:\Python313\Lib\asyncio\runners.py", line 118, in run
    return self._loop.run_until_complete(task)
  File "C:\Python313\Lib\asyncio\base_events.py", line 707, in run_until_complete
    self.run_forever()
  File "C:\Python313\Lib\asyncio\base_events.py", line 678, in run_forever
    self._run_once()
  File "C:\Python313\Lib\asyncio\base_events.py", line 2033, in _run_once
    handle._run()
  File "C:\Python313\Lib\asyncio\events.py", line 89, in _run
    self._context.run(self._callback, *self._args)

  File "C:\Users\mikeb\work\sifu2\run_agents.py", line 963, in main
    await agent.run()

  File "C:\Users\mikeb\work\sifu2\run_agents.py", line 691, in run
    result = await getattr(self, task.tool)(**task.args)

  File "C:\Users\mikeb\work\sifu2\run_agents.py", line 438, in _generate_examples
    examples_result = await self.example_generator.generate_examples(content)

> File "C:\Users\mikeb\work\sifu2\scripts\example_generator.py", line 90, in generate_examples
    result = await chain.ainvoke({

  File "C:\Python313\Lib\site-packages\langchain_core\runnables\base.py", line 3058, in ainvoke
    input = await asyncio.create_task(part(), context=context)  # type: ignore
  File "C:\Python313\Lib\site-packages\langchain_core\output_parsers\base.py", line 216, in ainvoke
    return await self._acall_with_config(
  File "C:\Python313\Lib\site-packages\langchain_core\runnables\base.py", line 1966, in _acall_with_config
    output: Output = await asyncio.create_task(coro, context=context)  # type: ignore
  File "C:\Python313\Lib\site-packages\langchain_core\output_parsers\base.py", line 277, in aparse_result
    return await run_in_executor(None, self.parse_result, result, partial=partial)
  File "C:\Python313\Lib\site-packages\langchain_core\runnables\config.py", line 588, in run_in_executor
    return await asyncio.get_running_loop().run_in_executor(
  File "C:\Python313\Lib\concurrent\futures\thread.py", line 59, in run
    result = self.fn(*self.args, **self.kwargs)
  File "C:\Python313\Lib\site-packages\langchain_core\runnables\config.py", line 579, in wrapper
    return func(*args, **kwargs)
  File "C:\Python313\Lib\site-packages\langchain_core\output_parsers\pydantic.py", line 67, in parse_result
    json_object = super().parse_result(result)
  File "C:\Python313\Lib\site-packages\langchain_core\output_parsers\json.py", line 86, in parse_result
    raise OutputParserException(msg, llm_output=text) from e

langchain_core.exceptions.OutputParserException: Invalid json output: 
For troubleshooting, visit: https://python.langchain.com/docs/troubleshooting/errors/OUTPUT_PARSING_FAILURE 
2025-02-09 22:48:24.038 | 35908:53896 | ERROR    | scripts.example_generator:generate_examples:115 | Error generating examples: Invalid json output: 
For troubleshooting, visit: https://python.langchain.com/docs/troubleshooting/errors/OUTPUT_PARSING_FAILURE 
Traceback (most recent call last):

  File "C:\Python313\Lib\site-packages\langchain_core\output_parsers\json.py", line 83, in parse_result
    return parse_json_markdown(text)
  File "C:\Python313\Lib\site-packages\langchain_core\utils\json.py", line 143, in parse_json_markdown
    return _parse_json(json_str, parser=parser)
  File "C:\Python313\Lib\site-packages\langchain_core\utils\json.py", line 159, in _parse_json
    return parser(json_str)
  File "C:\Python313\Lib\site-packages\langchain_core\utils\json.py", line 117, in parse_partial_json
    return json.loads(s, strict=strict)
  File "C:\Python313\Lib\json\__init__.py", line 359, in loads
    return cls(**kw).decode(s)
  File "C:\Python313\Lib\json\decoder.py", line 345, in decode
    obj, end = self.raw_decode(s, idx=_w(s, 0).end())
  File "C:\Python313\Lib\json\decoder.py", line 363, in raw_decode
    raise JSONDecodeError("Expecting value", s, err.value) from None

json.decoder.JSONDecodeError: Expecting value: line 1 column 1 (char 0)


The above exception was the direct cause of the following exception:


Traceback (most recent call last):

  File "C:\Users\mikeb\work\sifu2\run_agents.py", line 974, in <module>
    asyncio.run(main())

  File "C:\Python313\Lib\asyncio\runners.py", line 194, in run
    return runner.run(main)
  File "C:\Python313\Lib\asyncio\runners.py", line 118, in run
    return self._loop.run_until_complete(task)
  File "C:\Python313\Lib\asyncio\base_events.py", line 707, in run_until_complete
    self.run_forever()
  File "C:\Python313\Lib\asyncio\base_events.py", line 678, in run_forever
    self._run_once()
  File "C:\Python313\Lib\asyncio\base_events.py", line 2033, in _run_once
    handle._run()
  File "C:\Python313\Lib\asyncio\events.py", line 89, in _run
    self._context.run(self._callback, *self._args)

  File "C:\Users\mikeb\work\sifu2\run_agents.py", line 963, in main
    await agent.run()

  File "C:\Users\mikeb\work\sifu2\run_agents.py", line 691, in run
    result = await getattr(self, task.tool)(**task.args)

  File "C:\Users\mikeb\work\sifu2\run_agents.py", line 438, in _generate_examples
    examples_result = await self.example_generator.generate_examples(content)

> File "C:\Users\mikeb\work\sifu2\scripts\example_generator.py", line 90, in generate_examples
    result = await chain.ainvoke({

  File "C:\Python313\Lib\site-packages\langchain_core\runnables\base.py", line 3058, in ainvoke
    input = await asyncio.create_task(part(), context=context)  # type: ignore
  File "C:\Python313\Lib\site-packages\langchain_core\output_parsers\base.py", line 216, in ainvoke
    return await self._acall_with_config(
  File "C:\Python313\Lib\site-packages\langchain_core\runnables\base.py", line 1966, in _acall_with_config
    output: Output = await asyncio.create_task(coro, context=context)  # type: ignore
  File "C:\Python313\Lib\site-packages\langchain_core\output_parsers\base.py", line 277, in aparse_result
    return await run_in_executor(None, self.parse_result, result, partial=partial)
  File "C:\Python313\Lib\site-packages\langchain_core\runnables\config.py", line 588, in run_in_executor
    return await asyncio.get_running_loop().run_in_executor(
  File "C:\Python313\Lib\concurrent\futures\thread.py", line 59, in run
    result = self.fn(*self.args, **self.kwargs)
  File "C:\Python313\Lib\site-packages\langchain_core\runnables\config.py", line 579, in wrapper
    return func(*args, **kwargs)
  File "C:\Python313\Lib\site-packages\langchain_core\output_parsers\pydantic.py", line 67, in parse_result
    json_object = super().parse_result(result)
  File "C:\Python313\Lib\site-packages\langchain_core\output_parsers\json.py", line 86, in parse_result
    raise OutputParserException(msg, llm_output=text) from e

langchain_core.exceptions.OutputParserException: Invalid json output: 
For troubleshooting, visit: https://python.langchain.com/docs/troubleshooting/errors/OUTPUT_PARSING_FAILURE 
2025-02-09 22:48:27.606 | 35908:53896 | ERROR    | scripts.example_generator:generate_examples:115 | Error generating examples: Invalid json output: 
For troubleshooting, visit: https://python.langchain.com/docs/troubleshooting/errors/OUTPUT_PARSING_FAILURE 
Traceback (most recent call last):

  File "C:\Python313\Lib\site-packages\langchain_core\output_parsers\json.py", line 83, in parse_result
    return parse_json_markdown(text)
  File "C:\Python313\Lib\site-packages\langchain_core\utils\json.py", line 143, in parse_json_markdown
    return _parse_json(json_str, parser=parser)
  File "C:\Python313\Lib\site-packages\langchain_core\utils\json.py", line 159, in _parse_json
    return parser(json_str)
  File "C:\Python313\Lib\site-packages\langchain_core\utils\json.py", line 117, in parse_partial_json
    return json.loads(s, strict=strict)
  File "C:\Python313\Lib\json\__init__.py", line 359, in loads
    return cls(**kw).decode(s)
  File "C:\Python313\Lib\json\decoder.py", line 345, in decode
    obj, end = self.raw_decode(s, idx=_w(s, 0).end())
  File "C:\Python313\Lib\json\decoder.py", line 363, in raw_decode
    raise JSONDecodeError("Expecting value", s, err.value) from None

json.decoder.JSONDecodeError: Expecting value: line 1 column 1 (char 0)


The above exception was the direct cause of the following exception:


Traceback (most recent call last):

  File "C:\Users\mikeb\work\sifu2\run_agents.py", line 974, in <module>
    asyncio.run(main())

  File "C:\Python313\Lib\asyncio\runners.py", line 194, in run
    return runner.run(main)
  File "C:\Python313\Lib\asyncio\runners.py", line 118, in run
    return self._loop.run_until_complete(task)
  File "C:\Python313\Lib\asyncio\base_events.py", line 707, in run_until_complete
    self.run_forever()
  File "C:\Python313\Lib\asyncio\base_events.py", line 678, in run_forever
    self._run_once()
  File "C:\Python313\Lib\asyncio\base_events.py", line 2033, in _run_once
    handle._run()
  File "C:\Python313\Lib\asyncio\events.py", line 89, in _run
    self._context.run(self._callback, *self._args)

  File "C:\Users\mikeb\work\sifu2\run_agents.py", line 963, in main
    await agent.run()

  File "C:\Users\mikeb\work\sifu2\run_agents.py", line 691, in run
    result = await getattr(self, task.tool)(**task.args)

  File "C:\Users\mikeb\work\sifu2\run_agents.py", line 438, in _generate_examples
    examples_result = await self.example_generator.generate_examples(content)

> File "C:\Users\mikeb\work\sifu2\scripts\example_generator.py", line 90, in generate_examples
    result = await chain.ainvoke({

  File "C:\Python313\Lib\site-packages\langchain_core\runnables\base.py", line 3058, in ainvoke
    input = await asyncio.create_task(part(), context=context)  # type: ignore
  File "C:\Python313\Lib\site-packages\langchain_core\output_parsers\base.py", line 216, in ainvoke
    return await self._acall_with_config(
  File "C:\Python313\Lib\site-packages\langchain_core\runnables\base.py", line 1966, in _acall_with_config
    output: Output = await asyncio.create_task(coro, context=context)  # type: ignore
  File "C:\Python313\Lib\site-packages\langchain_core\output_parsers\base.py", line 277, in aparse_result
    return await run_in_executor(None, self.parse_result, result, partial=partial)
  File "C:\Python313\Lib\site-packages\langchain_core\runnables\config.py", line 588, in run_in_executor
    return await asyncio.get_running_loop().run_in_executor(
  File "C:\Python313\Lib\concurrent\futures\thread.py", line 59, in run
    result = self.fn(*self.args, **self.kwargs)
  File "C:\Python313\Lib\site-packages\langchain_core\runnables\config.py", line 579, in wrapper
    return func(*args, **kwargs)
  File "C:\Python313\Lib\site-packages\langchain_core\output_parsers\pydantic.py", line 67, in parse_result
    json_object = super().parse_result(result)
  File "C:\Python313\Lib\site-packages\langchain_core\output_parsers\json.py", line 86, in parse_result
    raise OutputParserException(msg, llm_output=text) from e

langchain_core.exceptions.OutputParserException: Invalid json output: 
For troubleshooting, visit: https://python.langchain.com/docs/troubleshooting/errors/OUTPUT_PARSING_FAILURE 
2025-02-09 22:48:31.598 | 35908:53896 | ERROR    | scripts.example_generator:generate_examples:115 | Error generating examples: Invalid json output: 
For troubleshooting, visit: https://python.langchain.com/docs/troubleshooting/errors/OUTPUT_PARSING_FAILURE 
Traceback (most recent call last):

  File "C:\Python313\Lib\site-packages\langchain_core\output_parsers\json.py", line 83, in parse_result
    return parse_json_markdown(text)
  File "C:\Python313\Lib\site-packages\langchain_core\utils\json.py", line 143, in parse_json_markdown
    return _parse_json(json_str, parser=parser)
  File "C:\Python313\Lib\site-packages\langchain_core\utils\json.py", line 159, in _parse_json
    return parser(json_str)
  File "C:\Python313\Lib\site-packages\langchain_core\utils\json.py", line 117, in parse_partial_json
    return json.loads(s, strict=strict)
  File "C:\Python313\Lib\json\__init__.py", line 359, in loads
    return cls(**kw).decode(s)
  File "C:\Python313\Lib\json\decoder.py", line 345, in decode
    obj, end = self.raw_decode(s, idx=_w(s, 0).end())
  File "C:\Python313\Lib\json\decoder.py", line 363, in raw_decode
    raise JSONDecodeError("Expecting value", s, err.value) from None

json.decoder.JSONDecodeError: Expecting value: line 1 column 1 (char 0)


The above exception was the direct cause of the following exception:


Traceback (most recent call last):

  File "C:\Users\mikeb\work\sifu2\run_agents.py", line 974, in <module>
    asyncio.run(main())

  File "C:\Python313\Lib\asyncio\runners.py", line 194, in run
    return runner.run(main)
  File "C:\Python313\Lib\asyncio\runners.py", line 118, in run
    return self._loop.run_until_complete(task)
  File "C:\Python313\Lib\asyncio\base_events.py", line 707, in run_until_complete
    self.run_forever()
  File "C:\Python313\Lib\asyncio\base_events.py", line 678, in run_forever
    self._run_once()
  File "C:\Python313\Lib\asyncio\base_events.py", line 2033, in _run_once
    handle._run()
  File "C:\Python313\Lib\asyncio\events.py", line 89, in _run
    self._context.run(self._callback, *self._args)

  File "C:\Users\mikeb\work\sifu2\run_agents.py", line 963, in main
    await agent.run()

  File "C:\Users\mikeb\work\sifu2\run_agents.py", line 691, in run
    result = await getattr(self, task.tool)(**task.args)

  File "C:\Users\mikeb\work\sifu2\run_agents.py", line 438, in _generate_examples
    examples_result = await self.example_generator.generate_examples(content)

> File "C:\Users\mikeb\work\sifu2\scripts\example_generator.py", line 90, in generate_examples
    result = await chain.ainvoke({

  File "C:\Python313\Lib\site-packages\langchain_core\runnables\base.py", line 3058, in ainvoke
    input = await asyncio.create_task(part(), context=context)  # type: ignore
  File "C:\Python313\Lib\site-packages\langchain_core\output_parsers\base.py", line 216, in ainvoke
    return await self._acall_with_config(
  File "C:\Python313\Lib\site-packages\langchain_core\runnables\base.py", line 1966, in _acall_with_config
    output: Output = await asyncio.create_task(coro, context=context)  # type: ignore
  File "C:\Python313\Lib\site-packages\langchain_core\output_parsers\base.py", line 277, in aparse_result
    return await run_in_executor(None, self.parse_result, result, partial=partial)
  File "C:\Python313\Lib\site-packages\langchain_core\runnables\config.py", line 588, in run_in_executor
    return await asyncio.get_running_loop().run_in_executor(
  File "C:\Python313\Lib\concurrent\futures\thread.py", line 59, in run
    result = self.fn(*self.args, **self.kwargs)
  File "C:\Python313\Lib\site-packages\langchain_core\runnables\config.py", line 579, in wrapper
    return func(*args, **kwargs)
  File "C:\Python313\Lib\site-packages\langchain_core\output_parsers\pydantic.py", line 67, in parse_result
    json_object = super().parse_result(result)
  File "C:\Python313\Lib\site-packages\langchain_core\output_parsers\json.py", line 86, in parse_result
    raise OutputParserException(msg, llm_output=text) from e

langchain_core.exceptions.OutputParserException: Invalid json output: 
For troubleshooting, visit: https://python.langchain.com/docs/troubleshooting/errors/OUTPUT_PARSING_FAILURE 
