2025-02-09 15:00:12.343 | 42956:50400 | ERROR    | scripts.knowledge_acquisition:_extract_relationships:652 | Failed to convert relationship: {'source': 'CNNs', 'relation': 'used_for', 'target': 'Image Recognition'}: 1 validation error for Relationship
relation
  Input should be 'uses', 'applies', 'implements', 'improves', 'outperforms', 'achieves', 'contains', 'consists_of', 'part_of', 'better_than', 'similar_to', 'different_from', 'leads_to', 'causes', 'affects', 'precedes', 'follows', 'concurrent_with', 'is_a', 'has_part' or 'related_to' [type=literal_error, input_value='used_for', input_type=str]
    For further information visit https://errors.pydantic.dev/2.10/v/literal_error
Traceback (most recent call last):

  File "C:\Users\mikeb\work\sifu2\run_agents.py", line 868, in <module>
    asyncio.run(main())

  File "C:\Python313\Lib\asyncio\runners.py", line 194, in run
    return runner.run(main)
  File "C:\Python313\Lib\asyncio\runners.py", line 118, in run
    return self._loop.run_until_complete(task)
  File "C:\Python313\Lib\asyncio\base_events.py", line 707, in run_until_complete
    self.run_forever()
  File "C:\Python313\Lib\asyncio\base_events.py", line 678, in run_forever
    self._run_once()
  File "C:\Python313\Lib\asyncio\base_events.py", line 2033, in _run_once
    handle._run()
  File "C:\Python313\Lib\asyncio\events.py", line 89, in _run
    self._context.run(self._callback, *self._args)

  File "C:\Users\mikeb\work\sifu2\run_agents.py", line 857, in main
    await agent.run()

  File "C:\Users\mikeb\work\sifu2\run_agents.py", line 691, in run
    result = await getattr(self, task.tool)(**task.args)

  File "C:\Users\mikeb\work\sifu2\run_agents.py", line 344, in _synthesize_knowledge
    knowledge = await self.knowledge_system.process_source(content)

  File "C:\Users\mikeb\work\sifu2\scripts\knowledge_acquisition.py", line 466, in process_source
    relationships = await self._extract_relationships(content)

> File "C:\Users\mikeb\work\sifu2\scripts\knowledge_acquisition.py", line 650, in _extract_relationships
    converted_relationships.append(Relationship(**rel))

  File "C:\Python313\Lib\site-packages\pydantic\main.py", line 214, in __init__
    validated_self = self.__pydantic_validator__.validate_python(data, self_instance=self)

pydantic_core._pydantic_core.ValidationError: 1 validation error for Relationship
relation
  Input should be 'uses', 'applies', 'implements', 'improves', 'outperforms', 'achieves', 'contains', 'consists_of', 'part_of', 'better_than', 'similar_to', 'different_from', 'leads_to', 'causes', 'affects', 'precedes', 'follows', 'concurrent_with', 'is_a', 'has_part' or 'related_to' [type=literal_error, input_value='used_for', input_type=str]
    For further information visit https://errors.pydantic.dev/2.10/v/literal_error
2025-02-09 15:00:12.388 | 42956:50400 | ERROR    | scripts.knowledge_acquisition:_extract_relationships:652 | Failed to convert relationship: {'source': 'RNNs', 'relation': 'used_for', 'target': 'Natural Language Processing'}: 1 validation error for Relationship
relation
  Input should be 'uses', 'applies', 'implements', 'improves', 'outperforms', 'achieves', 'contains', 'consists_of', 'part_of', 'better_than', 'similar_to', 'different_from', 'leads_to', 'causes', 'affects', 'precedes', 'follows', 'concurrent_with', 'is_a', 'has_part' or 'related_to' [type=literal_error, input_value='used_for', input_type=str]
    For further information visit https://errors.pydantic.dev/2.10/v/literal_error
Traceback (most recent call last):

  File "C:\Users\mikeb\work\sifu2\run_agents.py", line 868, in <module>
    asyncio.run(main())

  File "C:\Python313\Lib\asyncio\runners.py", line 194, in run
    return runner.run(main)
  File "C:\Python313\Lib\asyncio\runners.py", line 118, in run
    return self._loop.run_until_complete(task)
  File "C:\Python313\Lib\asyncio\base_events.py", line 707, in run_until_complete
    self.run_forever()
  File "C:\Python313\Lib\asyncio\base_events.py", line 678, in run_forever
    self._run_once()
  File "C:\Python313\Lib\asyncio\base_events.py", line 2033, in _run_once
    handle._run()
  File "C:\Python313\Lib\asyncio\events.py", line 89, in _run
    self._context.run(self._callback, *self._args)

  File "C:\Users\mikeb\work\sifu2\run_agents.py", line 857, in main
    await agent.run()

  File "C:\Users\mikeb\work\sifu2\run_agents.py", line 691, in run
    result = await getattr(self, task.tool)(**task.args)

  File "C:\Users\mikeb\work\sifu2\run_agents.py", line 344, in _synthesize_knowledge
    knowledge = await self.knowledge_system.process_source(content)

  File "C:\Users\mikeb\work\sifu2\scripts\knowledge_acquisition.py", line 466, in process_source
    relationships = await self._extract_relationships(content)

> File "C:\Users\mikeb\work\sifu2\scripts\knowledge_acquisition.py", line 650, in _extract_relationships
    converted_relationships.append(Relationship(**rel))

  File "C:\Python313\Lib\site-packages\pydantic\main.py", line 214, in __init__
    validated_self = self.__pydantic_validator__.validate_python(data, self_instance=self)

pydantic_core._pydantic_core.ValidationError: 1 validation error for Relationship
relation
  Input should be 'uses', 'applies', 'implements', 'improves', 'outperforms', 'achieves', 'contains', 'consists_of', 'part_of', 'better_than', 'similar_to', 'different_from', 'leads_to', 'causes', 'affects', 'precedes', 'follows', 'concurrent_with', 'is_a', 'has_part' or 'related_to' [type=literal_error, input_value='used_for', input_type=str]
    For further information visit https://errors.pydantic.dev/2.10/v/literal_error
2025-02-09 15:00:18.829 | 42956:50400 | ERROR    | scripts.knowledge_acquisition:_extract_relationships:652 | Failed to convert relationship: {'source': 'Model Training', 'relation': 'output_of', 'target': 'Trained Model'}: 1 validation error for Relationship
relation
  Input should be 'uses', 'applies', 'implements', 'improves', 'outperforms', 'achieves', 'contains', 'consists_of', 'part_of', 'better_than', 'similar_to', 'different_from', 'leads_to', 'causes', 'affects', 'precedes', 'follows', 'concurrent_with', 'is_a', 'has_part' or 'related_to' [type=literal_error, input_value='output_of', input_type=str]
    For further information visit https://errors.pydantic.dev/2.10/v/literal_error
Traceback (most recent call last):

  File "C:\Users\mikeb\work\sifu2\run_agents.py", line 868, in <module>
    asyncio.run(main())

  File "C:\Python313\Lib\asyncio\runners.py", line 194, in run
    return runner.run(main)
  File "C:\Python313\Lib\asyncio\runners.py", line 118, in run
    return self._loop.run_until_complete(task)
  File "C:\Python313\Lib\asyncio\base_events.py", line 707, in run_until_complete
    self.run_forever()
  File "C:\Python313\Lib\asyncio\base_events.py", line 678, in run_forever
    self._run_once()
  File "C:\Python313\Lib\asyncio\base_events.py", line 2033, in _run_once
    handle._run()
  File "C:\Python313\Lib\asyncio\events.py", line 89, in _run
    self._context.run(self._callback, *self._args)

  File "C:\Users\mikeb\work\sifu2\run_agents.py", line 857, in main
    await agent.run()

  File "C:\Users\mikeb\work\sifu2\run_agents.py", line 691, in run
    result = await getattr(self, task.tool)(**task.args)

  File "C:\Users\mikeb\work\sifu2\run_agents.py", line 344, in _synthesize_knowledge
    knowledge = await self.knowledge_system.process_source(content)

  File "C:\Users\mikeb\work\sifu2\scripts\knowledge_acquisition.py", line 466, in process_source
    relationships = await self._extract_relationships(content)

> File "C:\Users\mikeb\work\sifu2\scripts\knowledge_acquisition.py", line 650, in _extract_relationships
    converted_relationships.append(Relationship(**rel))

  File "C:\Python313\Lib\site-packages\pydantic\main.py", line 214, in __init__
    validated_self = self.__pydantic_validator__.validate_python(data, self_instance=self)

pydantic_core._pydantic_core.ValidationError: 1 validation error for Relationship
relation
  Input should be 'uses', 'applies', 'implements', 'improves', 'outperforms', 'achieves', 'contains', 'consists_of', 'part_of', 'better_than', 'similar_to', 'different_from', 'leads_to', 'causes', 'affects', 'precedes', 'follows', 'concurrent_with', 'is_a', 'has_part' or 'related_to' [type=literal_error, input_value='output_of', input_type=str]
    For further information visit https://errors.pydantic.dev/2.10/v/literal_error
2025-02-09 15:00:18.850 | 42956:50400 | ERROR    | scripts.knowledge_acquisition:_extract_relationships:652 | Failed to convert relationship: {'source': 'Trained Model', 'relation': 'input_to', 'target': 'Model Evaluation'}: 1 validation error for Relationship
relation
  Input should be 'uses', 'applies', 'implements', 'improves', 'outperforms', 'achieves', 'contains', 'consists_of', 'part_of', 'better_than', 'similar_to', 'different_from', 'leads_to', 'causes', 'affects', 'precedes', 'follows', 'concurrent_with', 'is_a', 'has_part' or 'related_to' [type=literal_error, input_value='input_to', input_type=str]
    For further information visit https://errors.pydantic.dev/2.10/v/literal_error
Traceback (most recent call last):

  File "C:\Users\mikeb\work\sifu2\run_agents.py", line 868, in <module>
    asyncio.run(main())

  File "C:\Python313\Lib\asyncio\runners.py", line 194, in run
    return runner.run(main)
  File "C:\Python313\Lib\asyncio\runners.py", line 118, in run
    return self._loop.run_until_complete(task)
  File "C:\Python313\Lib\asyncio\base_events.py", line 707, in run_until_complete
    self.run_forever()
  File "C:\Python313\Lib\asyncio\base_events.py", line 678, in run_forever
    self._run_once()
  File "C:\Python313\Lib\asyncio\base_events.py", line 2033, in _run_once
    handle._run()
  File "C:\Python313\Lib\asyncio\events.py", line 89, in _run
    self._context.run(self._callback, *self._args)

  File "C:\Users\mikeb\work\sifu2\run_agents.py", line 857, in main
    await agent.run()

  File "C:\Users\mikeb\work\sifu2\run_agents.py", line 691, in run
    result = await getattr(self, task.tool)(**task.args)

  File "C:\Users\mikeb\work\sifu2\run_agents.py", line 344, in _synthesize_knowledge
    knowledge = await self.knowledge_system.process_source(content)

  File "C:\Users\mikeb\work\sifu2\scripts\knowledge_acquisition.py", line 466, in process_source
    relationships = await self._extract_relationships(content)

> File "C:\Users\mikeb\work\sifu2\scripts\knowledge_acquisition.py", line 650, in _extract_relationships
    converted_relationships.append(Relationship(**rel))

  File "C:\Python313\Lib\site-packages\pydantic\main.py", line 214, in __init__
    validated_self = self.__pydantic_validator__.validate_python(data, self_instance=self)

pydantic_core._pydantic_core.ValidationError: 1 validation error for Relationship
relation
  Input should be 'uses', 'applies', 'implements', 'improves', 'outperforms', 'achieves', 'contains', 'consists_of', 'part_of', 'better_than', 'similar_to', 'different_from', 'leads_to', 'causes', 'affects', 'precedes', 'follows', 'concurrent_with', 'is_a', 'has_part' or 'related_to' [type=literal_error, input_value='input_to', input_type=str]
    For further information visit https://errors.pydantic.dev/2.10/v/literal_error
2025-02-09 15:00:18.871 | 42956:50400 | ERROR    | scripts.knowledge_acquisition:_extract_relationships:652 | Failed to convert relationship: {'source': 'Model Evaluation', 'relation': 'output_of', 'target': 'Evaluation Metrics'}: 1 validation error for Relationship
relation
  Input should be 'uses', 'applies', 'implements', 'improves', 'outperforms', 'achieves', 'contains', 'consists_of', 'part_of', 'better_than', 'similar_to', 'different_from', 'leads_to', 'causes', 'affects', 'precedes', 'follows', 'concurrent_with', 'is_a', 'has_part' or 'related_to' [type=literal_error, input_value='output_of', input_type=str]
    For further information visit https://errors.pydantic.dev/2.10/v/literal_error
Traceback (most recent call last):

  File "C:\Users\mikeb\work\sifu2\run_agents.py", line 868, in <module>
    asyncio.run(main())

  File "C:\Python313\Lib\asyncio\runners.py", line 194, in run
    return runner.run(main)
  File "C:\Python313\Lib\asyncio\runners.py", line 118, in run
    return self._loop.run_until_complete(task)
  File "C:\Python313\Lib\asyncio\base_events.py", line 707, in run_until_complete
    self.run_forever()
  File "C:\Python313\Lib\asyncio\base_events.py", line 678, in run_forever
    self._run_once()
  File "C:\Python313\Lib\asyncio\base_events.py", line 2033, in _run_once
    handle._run()
  File "C:\Python313\Lib\asyncio\events.py", line 89, in _run
    self._context.run(self._callback, *self._args)

  File "C:\Users\mikeb\work\sifu2\run_agents.py", line 857, in main
    await agent.run()

  File "C:\Users\mikeb\work\sifu2\run_agents.py", line 691, in run
    result = await getattr(self, task.tool)(**task.args)

  File "C:\Users\mikeb\work\sifu2\run_agents.py", line 344, in _synthesize_knowledge
    knowledge = await self.knowledge_system.process_source(content)

  File "C:\Users\mikeb\work\sifu2\scripts\knowledge_acquisition.py", line 466, in process_source
    relationships = await self._extract_relationships(content)

> File "C:\Users\mikeb\work\sifu2\scripts\knowledge_acquisition.py", line 650, in _extract_relationships
    converted_relationships.append(Relationship(**rel))

  File "C:\Python313\Lib\site-packages\pydantic\main.py", line 214, in __init__
    validated_self = self.__pydantic_validator__.validate_python(data, self_instance=self)

pydantic_core._pydantic_core.ValidationError: 1 validation error for Relationship
relation
  Input should be 'uses', 'applies', 'implements', 'improves', 'outperforms', 'achieves', 'contains', 'consists_of', 'part_of', 'better_than', 'similar_to', 'different_from', 'leads_to', 'causes', 'affects', 'precedes', 'follows', 'concurrent_with', 'is_a', 'has_part' or 'related_to' [type=literal_error, input_value='output_of', input_type=str]
    For further information visit https://errors.pydantic.dev/2.10/v/literal_error
2025-02-09 15:00:18.893 | 42956:50400 | ERROR    | scripts.knowledge_acquisition:_extract_relationships:652 | Failed to convert relationship: {'source': 'CNNs', 'relation': 'applied_to', 'target': 'Image Recognition'}: 1 validation error for Relationship
relation
  Input should be 'uses', 'applies', 'implements', 'improves', 'outperforms', 'achieves', 'contains', 'consists_of', 'part_of', 'better_than', 'similar_to', 'different_from', 'leads_to', 'causes', 'affects', 'precedes', 'follows', 'concurrent_with', 'is_a', 'has_part' or 'related_to' [type=literal_error, input_value='applied_to', input_type=str]
    For further information visit https://errors.pydantic.dev/2.10/v/literal_error
Traceback (most recent call last):

  File "C:\Users\mikeb\work\sifu2\run_agents.py", line 868, in <module>
    asyncio.run(main())

  File "C:\Python313\Lib\asyncio\runners.py", line 194, in run
    return runner.run(main)
  File "C:\Python313\Lib\asyncio\runners.py", line 118, in run
    return self._loop.run_until_complete(task)
  File "C:\Python313\Lib\asyncio\base_events.py", line 707, in run_until_complete
    self.run_forever()
  File "C:\Python313\Lib\asyncio\base_events.py", line 678, in run_forever
    self._run_once()
  File "C:\Python313\Lib\asyncio\base_events.py", line 2033, in _run_once
    handle._run()
  File "C:\Python313\Lib\asyncio\events.py", line 89, in _run
    self._context.run(self._callback, *self._args)

  File "C:\Users\mikeb\work\sifu2\run_agents.py", line 857, in main
    await agent.run()

  File "C:\Users\mikeb\work\sifu2\run_agents.py", line 691, in run
    result = await getattr(self, task.tool)(**task.args)

  File "C:\Users\mikeb\work\sifu2\run_agents.py", line 344, in _synthesize_knowledge
    knowledge = await self.knowledge_system.process_source(content)

  File "C:\Users\mikeb\work\sifu2\scripts\knowledge_acquisition.py", line 466, in process_source
    relationships = await self._extract_relationships(content)

> File "C:\Users\mikeb\work\sifu2\scripts\knowledge_acquisition.py", line 650, in _extract_relationships
    converted_relationships.append(Relationship(**rel))

  File "C:\Python313\Lib\site-packages\pydantic\main.py", line 214, in __init__
    validated_self = self.__pydantic_validator__.validate_python(data, self_instance=self)

pydantic_core._pydantic_core.ValidationError: 1 validation error for Relationship
relation
  Input should be 'uses', 'applies', 'implements', 'improves', 'outperforms', 'achieves', 'contains', 'consists_of', 'part_of', 'better_than', 'similar_to', 'different_from', 'leads_to', 'causes', 'affects', 'precedes', 'follows', 'concurrent_with', 'is_a', 'has_part' or 'related_to' [type=literal_error, input_value='applied_to', input_type=str]
    For further information visit https://errors.pydantic.dev/2.10/v/literal_error
2025-02-09 15:00:18.915 | 42956:50400 | ERROR    | scripts.knowledge_acquisition:_extract_relationships:652 | Failed to convert relationship: {'source': 'RNNs', 'relation': 'applied_to', 'target': 'Natural Language Processing'}: 1 validation error for Relationship
relation
  Input should be 'uses', 'applies', 'implements', 'improves', 'outperforms', 'achieves', 'contains', 'consists_of', 'part_of', 'better_than', 'similar_to', 'different_from', 'leads_to', 'causes', 'affects', 'precedes', 'follows', 'concurrent_with', 'is_a', 'has_part' or 'related_to' [type=literal_error, input_value='applied_to', input_type=str]
    For further information visit https://errors.pydantic.dev/2.10/v/literal_error
Traceback (most recent call last):

  File "C:\Users\mikeb\work\sifu2\run_agents.py", line 868, in <module>
    asyncio.run(main())

  File "C:\Python313\Lib\asyncio\runners.py", line 194, in run
    return runner.run(main)
  File "C:\Python313\Lib\asyncio\runners.py", line 118, in run
    return self._loop.run_until_complete(task)
  File "C:\Python313\Lib\asyncio\base_events.py", line 707, in run_until_complete
    self.run_forever()
  File "C:\Python313\Lib\asyncio\base_events.py", line 678, in run_forever
    self._run_once()
  File "C:\Python313\Lib\asyncio\base_events.py", line 2033, in _run_once
    handle._run()
  File "C:\Python313\Lib\asyncio\events.py", line 89, in _run
    self._context.run(self._callback, *self._args)

  File "C:\Users\mikeb\work\sifu2\run_agents.py", line 857, in main
    await agent.run()

  File "C:\Users\mikeb\work\sifu2\run_agents.py", line 691, in run
    result = await getattr(self, task.tool)(**task.args)

  File "C:\Users\mikeb\work\sifu2\run_agents.py", line 344, in _synthesize_knowledge
    knowledge = await self.knowledge_system.process_source(content)

  File "C:\Users\mikeb\work\sifu2\scripts\knowledge_acquisition.py", line 466, in process_source
    relationships = await self._extract_relationships(content)

> File "C:\Users\mikeb\work\sifu2\scripts\knowledge_acquisition.py", line 650, in _extract_relationships
    converted_relationships.append(Relationship(**rel))

  File "C:\Python313\Lib\site-packages\pydantic\main.py", line 214, in __init__
    validated_self = self.__pydantic_validator__.validate_python(data, self_instance=self)

pydantic_core._pydantic_core.ValidationError: 1 validation error for Relationship
relation
  Input should be 'uses', 'applies', 'implements', 'improves', 'outperforms', 'achieves', 'contains', 'consists_of', 'part_of', 'better_than', 'similar_to', 'different_from', 'leads_to', 'causes', 'affects', 'precedes', 'follows', 'concurrent_with', 'is_a', 'has_part' or 'related_to' [type=literal_error, input_value='applied_to', input_type=str]
    For further information visit https://errors.pydantic.dev/2.10/v/literal_error
2025-02-09 15:00:28.887 | 42956:50400 | ERROR    | scripts.knowledge_acquisition:_extract_relationships:652 | Failed to convert relationship: {'source': 'Model Training', 'relation': 'produces', 'target': 'Trained Model'}: 1 validation error for Relationship
relation
  Input should be 'uses', 'applies', 'implements', 'improves', 'outperforms', 'achieves', 'contains', 'consists_of', 'part_of', 'better_than', 'similar_to', 'different_from', 'leads_to', 'causes', 'affects', 'precedes', 'follows', 'concurrent_with', 'is_a', 'has_part' or 'related_to' [type=literal_error, input_value='produces', input_type=str]
    For further information visit https://errors.pydantic.dev/2.10/v/literal_error
Traceback (most recent call last):

  File "C:\Users\mikeb\work\sifu2\run_agents.py", line 868, in <module>
    asyncio.run(main())

  File "C:\Python313\Lib\asyncio\runners.py", line 194, in run
    return runner.run(main)
  File "C:\Python313\Lib\asyncio\runners.py", line 118, in run
    return self._loop.run_until_complete(task)
  File "C:\Python313\Lib\asyncio\base_events.py", line 707, in run_until_complete
    self.run_forever()
  File "C:\Python313\Lib\asyncio\base_events.py", line 678, in run_forever
    self._run_once()
  File "C:\Python313\Lib\asyncio\base_events.py", line 2033, in _run_once
    handle._run()
  File "C:\Python313\Lib\asyncio\events.py", line 89, in _run
    self._context.run(self._callback, *self._args)

  File "C:\Users\mikeb\work\sifu2\run_agents.py", line 857, in main
    await agent.run()

  File "C:\Users\mikeb\work\sifu2\run_agents.py", line 691, in run
    result = await getattr(self, task.tool)(**task.args)

  File "C:\Users\mikeb\work\sifu2\run_agents.py", line 344, in _synthesize_knowledge
    knowledge = await self.knowledge_system.process_source(content)

  File "C:\Users\mikeb\work\sifu2\scripts\knowledge_acquisition.py", line 466, in process_source
    relationships = await self._extract_relationships(content)

> File "C:\Users\mikeb\work\sifu2\scripts\knowledge_acquisition.py", line 650, in _extract_relationships
    converted_relationships.append(Relationship(**rel))

  File "C:\Python313\Lib\site-packages\pydantic\main.py", line 214, in __init__
    validated_self = self.__pydantic_validator__.validate_python(data, self_instance=self)

pydantic_core._pydantic_core.ValidationError: 1 validation error for Relationship
relation
  Input should be 'uses', 'applies', 'implements', 'improves', 'outperforms', 'achieves', 'contains', 'consists_of', 'part_of', 'better_than', 'similar_to', 'different_from', 'leads_to', 'causes', 'affects', 'precedes', 'follows', 'concurrent_with', 'is_a', 'has_part' or 'related_to' [type=literal_error, input_value='produces', input_type=str]
    For further information visit https://errors.pydantic.dev/2.10/v/literal_error
2025-02-09 15:00:28.911 | 42956:50400 | ERROR    | scripts.knowledge_acquisition:_extract_relationships:652 | Failed to convert relationship: {'source': 'Trained Model', 'relation': 'used_by', 'target': 'Model Evaluation'}: 1 validation error for Relationship
relation
  Input should be 'uses', 'applies', 'implements', 'improves', 'outperforms', 'achieves', 'contains', 'consists_of', 'part_of', 'better_than', 'similar_to', 'different_from', 'leads_to', 'causes', 'affects', 'precedes', 'follows', 'concurrent_with', 'is_a', 'has_part' or 'related_to' [type=literal_error, input_value='used_by', input_type=str]
    For further information visit https://errors.pydantic.dev/2.10/v/literal_error
Traceback (most recent call last):

  File "C:\Users\mikeb\work\sifu2\run_agents.py", line 868, in <module>
    asyncio.run(main())

  File "C:\Python313\Lib\asyncio\runners.py", line 194, in run
    return runner.run(main)
  File "C:\Python313\Lib\asyncio\runners.py", line 118, in run
    return self._loop.run_until_complete(task)
  File "C:\Python313\Lib\asyncio\base_events.py", line 707, in run_until_complete
    self.run_forever()
  File "C:\Python313\Lib\asyncio\base_events.py", line 678, in run_forever
    self._run_once()
  File "C:\Python313\Lib\asyncio\base_events.py", line 2033, in _run_once
    handle._run()
  File "C:\Python313\Lib\asyncio\events.py", line 89, in _run
    self._context.run(self._callback, *self._args)

  File "C:\Users\mikeb\work\sifu2\run_agents.py", line 857, in main
    await agent.run()

  File "C:\Users\mikeb\work\sifu2\run_agents.py", line 691, in run
    result = await getattr(self, task.tool)(**task.args)

  File "C:\Users\mikeb\work\sifu2\run_agents.py", line 344, in _synthesize_knowledge
    knowledge = await self.knowledge_system.process_source(content)

  File "C:\Users\mikeb\work\sifu2\scripts\knowledge_acquisition.py", line 466, in process_source
    relationships = await self._extract_relationships(content)

> File "C:\Users\mikeb\work\sifu2\scripts\knowledge_acquisition.py", line 650, in _extract_relationships
    converted_relationships.append(Relationship(**rel))

  File "C:\Python313\Lib\site-packages\pydantic\main.py", line 214, in __init__
    validated_self = self.__pydantic_validator__.validate_python(data, self_instance=self)

pydantic_core._pydantic_core.ValidationError: 1 validation error for Relationship
relation
  Input should be 'uses', 'applies', 'implements', 'improves', 'outperforms', 'achieves', 'contains', 'consists_of', 'part_of', 'better_than', 'similar_to', 'different_from', 'leads_to', 'causes', 'affects', 'precedes', 'follows', 'concurrent_with', 'is_a', 'has_part' or 'related_to' [type=literal_error, input_value='used_by', input_type=str]
    For further information visit https://errors.pydantic.dev/2.10/v/literal_error
2025-02-09 15:00:28.935 | 42956:50400 | ERROR    | scripts.knowledge_acquisition:_extract_relationships:652 | Failed to convert relationship: {'source': 'Model Evaluation', 'relation': 'produces', 'target': 'Performance Metrics'}: 1 validation error for Relationship
relation
  Input should be 'uses', 'applies', 'implements', 'improves', 'outperforms', 'achieves', 'contains', 'consists_of', 'part_of', 'better_than', 'similar_to', 'different_from', 'leads_to', 'causes', 'affects', 'precedes', 'follows', 'concurrent_with', 'is_a', 'has_part' or 'related_to' [type=literal_error, input_value='produces', input_type=str]
    For further information visit https://errors.pydantic.dev/2.10/v/literal_error
Traceback (most recent call last):

  File "C:\Users\mikeb\work\sifu2\run_agents.py", line 868, in <module>
    asyncio.run(main())

  File "C:\Python313\Lib\asyncio\runners.py", line 194, in run
    return runner.run(main)
  File "C:\Python313\Lib\asyncio\runners.py", line 118, in run
    return self._loop.run_until_complete(task)
  File "C:\Python313\Lib\asyncio\base_events.py", line 707, in run_until_complete
    self.run_forever()
  File "C:\Python313\Lib\asyncio\base_events.py", line 678, in run_forever
    self._run_once()
  File "C:\Python313\Lib\asyncio\base_events.py", line 2033, in _run_once
    handle._run()
  File "C:\Python313\Lib\asyncio\events.py", line 89, in _run
    self._context.run(self._callback, *self._args)

  File "C:\Users\mikeb\work\sifu2\run_agents.py", line 857, in main
    await agent.run()

  File "C:\Users\mikeb\work\sifu2\run_agents.py", line 691, in run
    result = await getattr(self, task.tool)(**task.args)

  File "C:\Users\mikeb\work\sifu2\run_agents.py", line 344, in _synthesize_knowledge
    knowledge = await self.knowledge_system.process_source(content)

  File "C:\Users\mikeb\work\sifu2\scripts\knowledge_acquisition.py", line 466, in process_source
    relationships = await self._extract_relationships(content)

> File "C:\Users\mikeb\work\sifu2\scripts\knowledge_acquisition.py", line 650, in _extract_relationships
    converted_relationships.append(Relationship(**rel))

  File "C:\Python313\Lib\site-packages\pydantic\main.py", line 214, in __init__
    validated_self = self.__pydantic_validator__.validate_python(data, self_instance=self)

pydantic_core._pydantic_core.ValidationError: 1 validation error for Relationship
relation
  Input should be 'uses', 'applies', 'implements', 'improves', 'outperforms', 'achieves', 'contains', 'consists_of', 'part_of', 'better_than', 'similar_to', 'different_from', 'leads_to', 'causes', 'affects', 'precedes', 'follows', 'concurrent_with', 'is_a', 'has_part' or 'related_to' [type=literal_error, input_value='produces', input_type=str]
    For further information visit https://errors.pydantic.dev/2.10/v/literal_error
2025-02-09 15:00:28.958 | 42956:50400 | ERROR    | scripts.knowledge_acquisition:_extract_relationships:652 | Failed to convert relationship: {'source': 'CNNs', 'relation': 'applied_to', 'target': 'Image Recognition'}: 1 validation error for Relationship
relation
  Input should be 'uses', 'applies', 'implements', 'improves', 'outperforms', 'achieves', 'contains', 'consists_of', 'part_of', 'better_than', 'similar_to', 'different_from', 'leads_to', 'causes', 'affects', 'precedes', 'follows', 'concurrent_with', 'is_a', 'has_part' or 'related_to' [type=literal_error, input_value='applied_to', input_type=str]
    For further information visit https://errors.pydantic.dev/2.10/v/literal_error
Traceback (most recent call last):

  File "C:\Users\mikeb\work\sifu2\run_agents.py", line 868, in <module>
    asyncio.run(main())

  File "C:\Python313\Lib\asyncio\runners.py", line 194, in run
    return runner.run(main)
  File "C:\Python313\Lib\asyncio\runners.py", line 118, in run
    return self._loop.run_until_complete(task)
  File "C:\Python313\Lib\asyncio\base_events.py", line 707, in run_until_complete
    self.run_forever()
  File "C:\Python313\Lib\asyncio\base_events.py", line 678, in run_forever
    self._run_once()
  File "C:\Python313\Lib\asyncio\base_events.py", line 2033, in _run_once
    handle._run()
  File "C:\Python313\Lib\asyncio\events.py", line 89, in _run
    self._context.run(self._callback, *self._args)

  File "C:\Users\mikeb\work\sifu2\run_agents.py", line 857, in main
    await agent.run()

  File "C:\Users\mikeb\work\sifu2\run_agents.py", line 691, in run
    result = await getattr(self, task.tool)(**task.args)

  File "C:\Users\mikeb\work\sifu2\run_agents.py", line 344, in _synthesize_knowledge
    knowledge = await self.knowledge_system.process_source(content)

  File "C:\Users\mikeb\work\sifu2\scripts\knowledge_acquisition.py", line 466, in process_source
    relationships = await self._extract_relationships(content)

> File "C:\Users\mikeb\work\sifu2\scripts\knowledge_acquisition.py", line 650, in _extract_relationships
    converted_relationships.append(Relationship(**rel))

  File "C:\Python313\Lib\site-packages\pydantic\main.py", line 214, in __init__
    validated_self = self.__pydantic_validator__.validate_python(data, self_instance=self)

pydantic_core._pydantic_core.ValidationError: 1 validation error for Relationship
relation
  Input should be 'uses', 'applies', 'implements', 'improves', 'outperforms', 'achieves', 'contains', 'consists_of', 'part_of', 'better_than', 'similar_to', 'different_from', 'leads_to', 'causes', 'affects', 'precedes', 'follows', 'concurrent_with', 'is_a', 'has_part' or 'related_to' [type=literal_error, input_value='applied_to', input_type=str]
    For further information visit https://errors.pydantic.dev/2.10/v/literal_error
2025-02-09 15:00:28.980 | 42956:50400 | ERROR    | scripts.knowledge_acquisition:_extract_relationships:652 | Failed to convert relationship: {'source': 'RNNs', 'relation': 'applied_to', 'target': 'Natural Language Processing'}: 1 validation error for Relationship
relation
  Input should be 'uses', 'applies', 'implements', 'improves', 'outperforms', 'achieves', 'contains', 'consists_of', 'part_of', 'better_than', 'similar_to', 'different_from', 'leads_to', 'causes', 'affects', 'precedes', 'follows', 'concurrent_with', 'is_a', 'has_part' or 'related_to' [type=literal_error, input_value='applied_to', input_type=str]
    For further information visit https://errors.pydantic.dev/2.10/v/literal_error
Traceback (most recent call last):

  File "C:\Users\mikeb\work\sifu2\run_agents.py", line 868, in <module>
    asyncio.run(main())

  File "C:\Python313\Lib\asyncio\runners.py", line 194, in run
    return runner.run(main)
  File "C:\Python313\Lib\asyncio\runners.py", line 118, in run
    return self._loop.run_until_complete(task)
  File "C:\Python313\Lib\asyncio\base_events.py", line 707, in run_until_complete
    self.run_forever()
  File "C:\Python313\Lib\asyncio\base_events.py", line 678, in run_forever
    self._run_once()
  File "C:\Python313\Lib\asyncio\base_events.py", line 2033, in _run_once
    handle._run()
  File "C:\Python313\Lib\asyncio\events.py", line 89, in _run
    self._context.run(self._callback, *self._args)

  File "C:\Users\mikeb\work\sifu2\run_agents.py", line 857, in main
    await agent.run()

  File "C:\Users\mikeb\work\sifu2\run_agents.py", line 691, in run
    result = await getattr(self, task.tool)(**task.args)

  File "C:\Users\mikeb\work\sifu2\run_agents.py", line 344, in _synthesize_knowledge
    knowledge = await self.knowledge_system.process_source(content)

  File "C:\Users\mikeb\work\sifu2\scripts\knowledge_acquisition.py", line 466, in process_source
    relationships = await self._extract_relationships(content)

> File "C:\Users\mikeb\work\sifu2\scripts\knowledge_acquisition.py", line 650, in _extract_relationships
    converted_relationships.append(Relationship(**rel))

  File "C:\Python313\Lib\site-packages\pydantic\main.py", line 214, in __init__
    validated_self = self.__pydantic_validator__.validate_python(data, self_instance=self)

pydantic_core._pydantic_core.ValidationError: 1 validation error for Relationship
relation
  Input should be 'uses', 'applies', 'implements', 'improves', 'outperforms', 'achieves', 'contains', 'consists_of', 'part_of', 'better_than', 'similar_to', 'different_from', 'leads_to', 'causes', 'affects', 'precedes', 'follows', 'concurrent_with', 'is_a', 'has_part' or 'related_to' [type=literal_error, input_value='applied_to', input_type=str]
    For further information visit https://errors.pydantic.dev/2.10/v/literal_error
2025-02-09 15:00:39.497 | 42956:50400 | ERROR    | scripts.knowledge_acquisition:_extract_relationships:652 | Failed to convert relationship: {'source': 'CNNs', 'relation': 'used_for', 'target': 'Image Recognition'}: 1 validation error for Relationship
relation
  Input should be 'uses', 'applies', 'implements', 'improves', 'outperforms', 'achieves', 'contains', 'consists_of', 'part_of', 'better_than', 'similar_to', 'different_from', 'leads_to', 'causes', 'affects', 'precedes', 'follows', 'concurrent_with', 'is_a', 'has_part' or 'related_to' [type=literal_error, input_value='used_for', input_type=str]
    For further information visit https://errors.pydantic.dev/2.10/v/literal_error
Traceback (most recent call last):

  File "C:\Users\mikeb\work\sifu2\run_agents.py", line 868, in <module>
    asyncio.run(main())

  File "C:\Python313\Lib\asyncio\runners.py", line 194, in run
    return runner.run(main)
  File "C:\Python313\Lib\asyncio\runners.py", line 118, in run
    return self._loop.run_until_complete(task)
  File "C:\Python313\Lib\asyncio\base_events.py", line 707, in run_until_complete
    self.run_forever()
  File "C:\Python313\Lib\asyncio\base_events.py", line 678, in run_forever
    self._run_once()
  File "C:\Python313\Lib\asyncio\base_events.py", line 2033, in _run_once
    handle._run()
  File "C:\Python313\Lib\asyncio\events.py", line 89, in _run
    self._context.run(self._callback, *self._args)

  File "C:\Users\mikeb\work\sifu2\run_agents.py", line 857, in main
    await agent.run()

  File "C:\Users\mikeb\work\sifu2\run_agents.py", line 691, in run
    result = await getattr(self, task.tool)(**task.args)

  File "C:\Users\mikeb\work\sifu2\run_agents.py", line 344, in _synthesize_knowledge
    knowledge = await self.knowledge_system.process_source(content)

  File "C:\Users\mikeb\work\sifu2\scripts\knowledge_acquisition.py", line 466, in process_source
    relationships = await self._extract_relationships(content)

> File "C:\Users\mikeb\work\sifu2\scripts\knowledge_acquisition.py", line 650, in _extract_relationships
    converted_relationships.append(Relationship(**rel))

  File "C:\Python313\Lib\site-packages\pydantic\main.py", line 214, in __init__
    validated_self = self.__pydantic_validator__.validate_python(data, self_instance=self)

pydantic_core._pydantic_core.ValidationError: 1 validation error for Relationship
relation
  Input should be 'uses', 'applies', 'implements', 'improves', 'outperforms', 'achieves', 'contains', 'consists_of', 'part_of', 'better_than', 'similar_to', 'different_from', 'leads_to', 'causes', 'affects', 'precedes', 'follows', 'concurrent_with', 'is_a', 'has_part' or 'related_to' [type=literal_error, input_value='used_for', input_type=str]
    For further information visit https://errors.pydantic.dev/2.10/v/literal_error
2025-02-09 15:00:39.521 | 42956:50400 | ERROR    | scripts.knowledge_acquisition:_extract_relationships:652 | Failed to convert relationship: {'source': 'RNNs', 'relation': 'used_for', 'target': 'Natural Language Processing'}: 1 validation error for Relationship
relation
  Input should be 'uses', 'applies', 'implements', 'improves', 'outperforms', 'achieves', 'contains', 'consists_of', 'part_of', 'better_than', 'similar_to', 'different_from', 'leads_to', 'causes', 'affects', 'precedes', 'follows', 'concurrent_with', 'is_a', 'has_part' or 'related_to' [type=literal_error, input_value='used_for', input_type=str]
    For further information visit https://errors.pydantic.dev/2.10/v/literal_error
Traceback (most recent call last):

  File "C:\Users\mikeb\work\sifu2\run_agents.py", line 868, in <module>
    asyncio.run(main())

  File "C:\Python313\Lib\asyncio\runners.py", line 194, in run
    return runner.run(main)
  File "C:\Python313\Lib\asyncio\runners.py", line 118, in run
    return self._loop.run_until_complete(task)
  File "C:\Python313\Lib\asyncio\base_events.py", line 707, in run_until_complete
    self.run_forever()
  File "C:\Python313\Lib\asyncio\base_events.py", line 678, in run_forever
    self._run_once()
  File "C:\Python313\Lib\asyncio\base_events.py", line 2033, in _run_once
    handle._run()
  File "C:\Python313\Lib\asyncio\events.py", line 89, in _run
    self._context.run(self._callback, *self._args)

  File "C:\Users\mikeb\work\sifu2\run_agents.py", line 857, in main
    await agent.run()

  File "C:\Users\mikeb\work\sifu2\run_agents.py", line 691, in run
    result = await getattr(self, task.tool)(**task.args)

  File "C:\Users\mikeb\work\sifu2\run_agents.py", line 344, in _synthesize_knowledge
    knowledge = await self.knowledge_system.process_source(content)

  File "C:\Users\mikeb\work\sifu2\scripts\knowledge_acquisition.py", line 466, in process_source
    relationships = await self._extract_relationships(content)

> File "C:\Users\mikeb\work\sifu2\scripts\knowledge_acquisition.py", line 650, in _extract_relationships
    converted_relationships.append(Relationship(**rel))

  File "C:\Python313\Lib\site-packages\pydantic\main.py", line 214, in __init__
    validated_self = self.__pydantic_validator__.validate_python(data, self_instance=self)

pydantic_core._pydantic_core.ValidationError: 1 validation error for Relationship
relation
  Input should be 'uses', 'applies', 'implements', 'improves', 'outperforms', 'achieves', 'contains', 'consists_of', 'part_of', 'better_than', 'similar_to', 'different_from', 'leads_to', 'causes', 'affects', 'precedes', 'follows', 'concurrent_with', 'is_a', 'has_part' or 'related_to' [type=literal_error, input_value='used_for', input_type=str]
    For further information visit https://errors.pydantic.dev/2.10/v/literal_error
2025-02-09 15:00:45.784 | 42956:50400 | ERROR    | scripts.knowledge_acquisition:_extract_relationships:652 | Failed to convert relationship: {'source': 'Model Training', 'relation': 'produces', 'target': 'Trained Model'}: 1 validation error for Relationship
relation
  Input should be 'uses', 'applies', 'implements', 'improves', 'outperforms', 'achieves', 'contains', 'consists_of', 'part_of', 'better_than', 'similar_to', 'different_from', 'leads_to', 'causes', 'affects', 'precedes', 'follows', 'concurrent_with', 'is_a', 'has_part' or 'related_to' [type=literal_error, input_value='produces', input_type=str]
    For further information visit https://errors.pydantic.dev/2.10/v/literal_error
Traceback (most recent call last):

  File "C:\Users\mikeb\work\sifu2\run_agents.py", line 868, in <module>
    asyncio.run(main())

  File "C:\Python313\Lib\asyncio\runners.py", line 194, in run
    return runner.run(main)
  File "C:\Python313\Lib\asyncio\runners.py", line 118, in run
    return self._loop.run_until_complete(task)
  File "C:\Python313\Lib\asyncio\base_events.py", line 707, in run_until_complete
    self.run_forever()
  File "C:\Python313\Lib\asyncio\base_events.py", line 678, in run_forever
    self._run_once()
  File "C:\Python313\Lib\asyncio\base_events.py", line 2033, in _run_once
    handle._run()
  File "C:\Python313\Lib\asyncio\events.py", line 89, in _run
    self._context.run(self._callback, *self._args)

  File "C:\Users\mikeb\work\sifu2\run_agents.py", line 857, in main
    await agent.run()

  File "C:\Users\mikeb\work\sifu2\run_agents.py", line 691, in run
    result = await getattr(self, task.tool)(**task.args)

  File "C:\Users\mikeb\work\sifu2\run_agents.py", line 344, in _synthesize_knowledge
    knowledge = await self.knowledge_system.process_source(content)

  File "C:\Users\mikeb\work\sifu2\scripts\knowledge_acquisition.py", line 466, in process_source
    relationships = await self._extract_relationships(content)

> File "C:\Users\mikeb\work\sifu2\scripts\knowledge_acquisition.py", line 650, in _extract_relationships
    converted_relationships.append(Relationship(**rel))

  File "C:\Python313\Lib\site-packages\pydantic\main.py", line 214, in __init__
    validated_self = self.__pydantic_validator__.validate_python(data, self_instance=self)

pydantic_core._pydantic_core.ValidationError: 1 validation error for Relationship
relation
  Input should be 'uses', 'applies', 'implements', 'improves', 'outperforms', 'achieves', 'contains', 'consists_of', 'part_of', 'better_than', 'similar_to', 'different_from', 'leads_to', 'causes', 'affects', 'precedes', 'follows', 'concurrent_with', 'is_a', 'has_part' or 'related_to' [type=literal_error, input_value='produces', input_type=str]
    For further information visit https://errors.pydantic.dev/2.10/v/literal_error
2025-02-09 15:00:45.996 | 42956:50400 | ERROR    | scripts.knowledge_acquisition:_extract_relationships:652 | Failed to convert relationship: {'source': 'Trained Model', 'relation': 'used_by', 'target': 'Model Inference'}: 1 validation error for Relationship
relation
  Input should be 'uses', 'applies', 'implements', 'improves', 'outperforms', 'achieves', 'contains', 'consists_of', 'part_of', 'better_than', 'similar_to', 'different_from', 'leads_to', 'causes', 'affects', 'precedes', 'follows', 'concurrent_with', 'is_a', 'has_part' or 'related_to' [type=literal_error, input_value='used_by', input_type=str]
    For further information visit https://errors.pydantic.dev/2.10/v/literal_error
Traceback (most recent call last):

  File "C:\Users\mikeb\work\sifu2\run_agents.py", line 868, in <module>
    asyncio.run(main())

  File "C:\Python313\Lib\asyncio\runners.py", line 194, in run
    return runner.run(main)
  File "C:\Python313\Lib\asyncio\runners.py", line 118, in run
    return self._loop.run_until_complete(task)
  File "C:\Python313\Lib\asyncio\base_events.py", line 707, in run_until_complete
    self.run_forever()
  File "C:\Python313\Lib\asyncio\base_events.py", line 678, in run_forever
    self._run_once()
  File "C:\Python313\Lib\asyncio\base_events.py", line 2033, in _run_once
    handle._run()
  File "C:\Python313\Lib\asyncio\events.py", line 89, in _run
    self._context.run(self._callback, *self._args)

  File "C:\Users\mikeb\work\sifu2\run_agents.py", line 857, in main
    await agent.run()

  File "C:\Users\mikeb\work\sifu2\run_agents.py", line 691, in run
    result = await getattr(self, task.tool)(**task.args)

  File "C:\Users\mikeb\work\sifu2\run_agents.py", line 344, in _synthesize_knowledge
    knowledge = await self.knowledge_system.process_source(content)

  File "C:\Users\mikeb\work\sifu2\scripts\knowledge_acquisition.py", line 466, in process_source
    relationships = await self._extract_relationships(content)

> File "C:\Users\mikeb\work\sifu2\scripts\knowledge_acquisition.py", line 650, in _extract_relationships
    converted_relationships.append(Relationship(**rel))

  File "C:\Python313\Lib\site-packages\pydantic\main.py", line 214, in __init__
    validated_self = self.__pydantic_validator__.validate_python(data, self_instance=self)

pydantic_core._pydantic_core.ValidationError: 1 validation error for Relationship
relation
  Input should be 'uses', 'applies', 'implements', 'improves', 'outperforms', 'achieves', 'contains', 'consists_of', 'part_of', 'better_than', 'similar_to', 'different_from', 'leads_to', 'causes', 'affects', 'precedes', 'follows', 'concurrent_with', 'is_a', 'has_part' or 'related_to' [type=literal_error, input_value='used_by', input_type=str]
    For further information visit https://errors.pydantic.dev/2.10/v/literal_error
2025-02-09 15:00:46.018 | 42956:50400 | ERROR    | scripts.knowledge_acquisition:_extract_relationships:652 | Failed to convert relationship: {'source': 'Model Inference', 'relation': 'produces', 'target': 'Predictions'}: 1 validation error for Relationship
relation
  Input should be 'uses', 'applies', 'implements', 'improves', 'outperforms', 'achieves', 'contains', 'consists_of', 'part_of', 'better_than', 'similar_to', 'different_from', 'leads_to', 'causes', 'affects', 'precedes', 'follows', 'concurrent_with', 'is_a', 'has_part' or 'related_to' [type=literal_error, input_value='produces', input_type=str]
    For further information visit https://errors.pydantic.dev/2.10/v/literal_error
Traceback (most recent call last):

  File "C:\Users\mikeb\work\sifu2\run_agents.py", line 868, in <module>
    asyncio.run(main())

  File "C:\Python313\Lib\asyncio\runners.py", line 194, in run
    return runner.run(main)
  File "C:\Python313\Lib\asyncio\runners.py", line 118, in run
    return self._loop.run_until_complete(task)
  File "C:\Python313\Lib\asyncio\base_events.py", line 707, in run_until_complete
    self.run_forever()
  File "C:\Python313\Lib\asyncio\base_events.py", line 678, in run_forever
    self._run_once()
  File "C:\Python313\Lib\asyncio\base_events.py", line 2033, in _run_once
    handle._run()
  File "C:\Python313\Lib\asyncio\events.py", line 89, in _run
    self._context.run(self._callback, *self._args)

  File "C:\Users\mikeb\work\sifu2\run_agents.py", line 857, in main
    await agent.run()

  File "C:\Users\mikeb\work\sifu2\run_agents.py", line 691, in run
    result = await getattr(self, task.tool)(**task.args)

  File "C:\Users\mikeb\work\sifu2\run_agents.py", line 344, in _synthesize_knowledge
    knowledge = await self.knowledge_system.process_source(content)

  File "C:\Users\mikeb\work\sifu2\scripts\knowledge_acquisition.py", line 466, in process_source
    relationships = await self._extract_relationships(content)

> File "C:\Users\mikeb\work\sifu2\scripts\knowledge_acquisition.py", line 650, in _extract_relationships
    converted_relationships.append(Relationship(**rel))

  File "C:\Python313\Lib\site-packages\pydantic\main.py", line 214, in __init__
    validated_self = self.__pydantic_validator__.validate_python(data, self_instance=self)

pydantic_core._pydantic_core.ValidationError: 1 validation error for Relationship
relation
  Input should be 'uses', 'applies', 'implements', 'improves', 'outperforms', 'achieves', 'contains', 'consists_of', 'part_of', 'better_than', 'similar_to', 'different_from', 'leads_to', 'causes', 'affects', 'precedes', 'follows', 'concurrent_with', 'is_a', 'has_part' or 'related_to' [type=literal_error, input_value='produces', input_type=str]
    For further information visit https://errors.pydantic.dev/2.10/v/literal_error
2025-02-09 15:00:46.040 | 42956:50400 | ERROR    | scripts.knowledge_acquisition:_extract_relationships:652 | Failed to convert relationship: {'source': 'CNNs', 'relation': 'used_by', 'target': 'Image Recognition'}: 1 validation error for Relationship
relation
  Input should be 'uses', 'applies', 'implements', 'improves', 'outperforms', 'achieves', 'contains', 'consists_of', 'part_of', 'better_than', 'similar_to', 'different_from', 'leads_to', 'causes', 'affects', 'precedes', 'follows', 'concurrent_with', 'is_a', 'has_part' or 'related_to' [type=literal_error, input_value='used_by', input_type=str]
    For further information visit https://errors.pydantic.dev/2.10/v/literal_error
Traceback (most recent call last):

  File "C:\Users\mikeb\work\sifu2\run_agents.py", line 868, in <module>
    asyncio.run(main())

  File "C:\Python313\Lib\asyncio\runners.py", line 194, in run
    return runner.run(main)
  File "C:\Python313\Lib\asyncio\runners.py", line 118, in run
    return self._loop.run_until_complete(task)
  File "C:\Python313\Lib\asyncio\base_events.py", line 707, in run_until_complete
    self.run_forever()
  File "C:\Python313\Lib\asyncio\base_events.py", line 678, in run_forever
    self._run_once()
  File "C:\Python313\Lib\asyncio\base_events.py", line 2033, in _run_once
    handle._run()
  File "C:\Python313\Lib\asyncio\events.py", line 89, in _run
    self._context.run(self._callback, *self._args)

  File "C:\Users\mikeb\work\sifu2\run_agents.py", line 857, in main
    await agent.run()

  File "C:\Users\mikeb\work\sifu2\run_agents.py", line 691, in run
    result = await getattr(self, task.tool)(**task.args)

  File "C:\Users\mikeb\work\sifu2\run_agents.py", line 344, in _synthesize_knowledge
    knowledge = await self.knowledge_system.process_source(content)

  File "C:\Users\mikeb\work\sifu2\scripts\knowledge_acquisition.py", line 466, in process_source
    relationships = await self._extract_relationships(content)

> File "C:\Users\mikeb\work\sifu2\scripts\knowledge_acquisition.py", line 650, in _extract_relationships
    converted_relationships.append(Relationship(**rel))

  File "C:\Python313\Lib\site-packages\pydantic\main.py", line 214, in __init__
    validated_self = self.__pydantic_validator__.validate_python(data, self_instance=self)

pydantic_core._pydantic_core.ValidationError: 1 validation error for Relationship
relation
  Input should be 'uses', 'applies', 'implements', 'improves', 'outperforms', 'achieves', 'contains', 'consists_of', 'part_of', 'better_than', 'similar_to', 'different_from', 'leads_to', 'causes', 'affects', 'precedes', 'follows', 'concurrent_with', 'is_a', 'has_part' or 'related_to' [type=literal_error, input_value='used_by', input_type=str]
    For further information visit https://errors.pydantic.dev/2.10/v/literal_error
2025-02-09 15:00:46.061 | 42956:50400 | ERROR    | scripts.knowledge_acquisition:_extract_relationships:652 | Failed to convert relationship: {'source': 'RNNs', 'relation': 'used_by', 'target': 'Natural Language Processing'}: 1 validation error for Relationship
relation
  Input should be 'uses', 'applies', 'implements', 'improves', 'outperforms', 'achieves', 'contains', 'consists_of', 'part_of', 'better_than', 'similar_to', 'different_from', 'leads_to', 'causes', 'affects', 'precedes', 'follows', 'concurrent_with', 'is_a', 'has_part' or 'related_to' [type=literal_error, input_value='used_by', input_type=str]
    For further information visit https://errors.pydantic.dev/2.10/v/literal_error
Traceback (most recent call last):

  File "C:\Users\mikeb\work\sifu2\run_agents.py", line 868, in <module>
    asyncio.run(main())

  File "C:\Python313\Lib\asyncio\runners.py", line 194, in run
    return runner.run(main)
  File "C:\Python313\Lib\asyncio\runners.py", line 118, in run
    return self._loop.run_until_complete(task)
  File "C:\Python313\Lib\asyncio\base_events.py", line 707, in run_until_complete
    self.run_forever()
  File "C:\Python313\Lib\asyncio\base_events.py", line 678, in run_forever
    self._run_once()
  File "C:\Python313\Lib\asyncio\base_events.py", line 2033, in _run_once
    handle._run()
  File "C:\Python313\Lib\asyncio\events.py", line 89, in _run
    self._context.run(self._callback, *self._args)

  File "C:\Users\mikeb\work\sifu2\run_agents.py", line 857, in main
    await agent.run()

  File "C:\Users\mikeb\work\sifu2\run_agents.py", line 691, in run
    result = await getattr(self, task.tool)(**task.args)

  File "C:\Users\mikeb\work\sifu2\run_agents.py", line 344, in _synthesize_knowledge
    knowledge = await self.knowledge_system.process_source(content)

  File "C:\Users\mikeb\work\sifu2\scripts\knowledge_acquisition.py", line 466, in process_source
    relationships = await self._extract_relationships(content)

> File "C:\Users\mikeb\work\sifu2\scripts\knowledge_acquisition.py", line 650, in _extract_relationships
    converted_relationships.append(Relationship(**rel))

  File "C:\Python313\Lib\site-packages\pydantic\main.py", line 214, in __init__
    validated_self = self.__pydantic_validator__.validate_python(data, self_instance=self)

pydantic_core._pydantic_core.ValidationError: 1 validation error for Relationship
relation
  Input should be 'uses', 'applies', 'implements', 'improves', 'outperforms', 'achieves', 'contains', 'consists_of', 'part_of', 'better_than', 'similar_to', 'different_from', 'leads_to', 'causes', 'affects', 'precedes', 'follows', 'concurrent_with', 'is_a', 'has_part' or 'related_to' [type=literal_error, input_value='used_by', input_type=str]
    For further information visit https://errors.pydantic.dev/2.10/v/literal_error
2025-02-09 15:00:56.315 | 42956:50400 | ERROR    | scripts.knowledge_acquisition:_extract_relationships:652 | Failed to convert relationship: {'source': 'Model evaluation', 'relation': 'informs', 'target': 'Model deployment'}: 1 validation error for Relationship
relation
  Input should be 'uses', 'applies', 'implements', 'improves', 'outperforms', 'achieves', 'contains', 'consists_of', 'part_of', 'better_than', 'similar_to', 'different_from', 'leads_to', 'causes', 'affects', 'precedes', 'follows', 'concurrent_with', 'is_a', 'has_part' or 'related_to' [type=literal_error, input_value='informs', input_type=str]
    For further information visit https://errors.pydantic.dev/2.10/v/literal_error
Traceback (most recent call last):

  File "C:\Users\mikeb\work\sifu2\run_agents.py", line 868, in <module>
    asyncio.run(main())

  File "C:\Python313\Lib\asyncio\runners.py", line 194, in run
    return runner.run(main)
  File "C:\Python313\Lib\asyncio\runners.py", line 118, in run
    return self._loop.run_until_complete(task)
  File "C:\Python313\Lib\asyncio\base_events.py", line 707, in run_until_complete
    self.run_forever()
  File "C:\Python313\Lib\asyncio\base_events.py", line 678, in run_forever
    self._run_once()
  File "C:\Python313\Lib\asyncio\base_events.py", line 2033, in _run_once
    handle._run()
  File "C:\Python313\Lib\asyncio\events.py", line 89, in _run
    self._context.run(self._callback, *self._args)

  File "C:\Users\mikeb\work\sifu2\run_agents.py", line 857, in main
    await agent.run()

  File "C:\Users\mikeb\work\sifu2\run_agents.py", line 691, in run
    result = await getattr(self, task.tool)(**task.args)

  File "C:\Users\mikeb\work\sifu2\run_agents.py", line 344, in _synthesize_knowledge
    knowledge = await self.knowledge_system.process_source(content)

  File "C:\Users\mikeb\work\sifu2\scripts\knowledge_acquisition.py", line 466, in process_source
    relationships = await self._extract_relationships(content)

> File "C:\Users\mikeb\work\sifu2\scripts\knowledge_acquisition.py", line 650, in _extract_relationships
    converted_relationships.append(Relationship(**rel))

  File "C:\Python313\Lib\site-packages\pydantic\main.py", line 214, in __init__
    validated_self = self.__pydantic_validator__.validate_python(data, self_instance=self)

pydantic_core._pydantic_core.ValidationError: 1 validation error for Relationship
relation
  Input should be 'uses', 'applies', 'implements', 'improves', 'outperforms', 'achieves', 'contains', 'consists_of', 'part_of', 'better_than', 'similar_to', 'different_from', 'leads_to', 'causes', 'affects', 'precedes', 'follows', 'concurrent_with', 'is_a', 'has_part' or 'related_to' [type=literal_error, input_value='informs', input_type=str]
    For further information visit https://errors.pydantic.dev/2.10/v/literal_error
2025-02-09 15:00:56.337 | 42956:50400 | ERROR    | scripts.knowledge_acquisition:_extract_relationships:652 | Failed to convert relationship: {'source': 'CNNs', 'relation': 'used_for', 'target': 'Image classification'}: 1 validation error for Relationship
relation
  Input should be 'uses', 'applies', 'implements', 'improves', 'outperforms', 'achieves', 'contains', 'consists_of', 'part_of', 'better_than', 'similar_to', 'different_from', 'leads_to', 'causes', 'affects', 'precedes', 'follows', 'concurrent_with', 'is_a', 'has_part' or 'related_to' [type=literal_error, input_value='used_for', input_type=str]
    For further information visit https://errors.pydantic.dev/2.10/v/literal_error
Traceback (most recent call last):

  File "C:\Users\mikeb\work\sifu2\run_agents.py", line 868, in <module>
    asyncio.run(main())

  File "C:\Python313\Lib\asyncio\runners.py", line 194, in run
    return runner.run(main)
  File "C:\Python313\Lib\asyncio\runners.py", line 118, in run
    return self._loop.run_until_complete(task)
  File "C:\Python313\Lib\asyncio\base_events.py", line 707, in run_until_complete
    self.run_forever()
  File "C:\Python313\Lib\asyncio\base_events.py", line 678, in run_forever
    self._run_once()
  File "C:\Python313\Lib\asyncio\base_events.py", line 2033, in _run_once
    handle._run()
  File "C:\Python313\Lib\asyncio\events.py", line 89, in _run
    self._context.run(self._callback, *self._args)

  File "C:\Users\mikeb\work\sifu2\run_agents.py", line 857, in main
    await agent.run()

  File "C:\Users\mikeb\work\sifu2\run_agents.py", line 691, in run
    result = await getattr(self, task.tool)(**task.args)

  File "C:\Users\mikeb\work\sifu2\run_agents.py", line 344, in _synthesize_knowledge
    knowledge = await self.knowledge_system.process_source(content)

  File "C:\Users\mikeb\work\sifu2\scripts\knowledge_acquisition.py", line 466, in process_source
    relationships = await self._extract_relationships(content)

> File "C:\Users\mikeb\work\sifu2\scripts\knowledge_acquisition.py", line 650, in _extract_relationships
    converted_relationships.append(Relationship(**rel))

  File "C:\Python313\Lib\site-packages\pydantic\main.py", line 214, in __init__
    validated_self = self.__pydantic_validator__.validate_python(data, self_instance=self)

pydantic_core._pydantic_core.ValidationError: 1 validation error for Relationship
relation
  Input should be 'uses', 'applies', 'implements', 'improves', 'outperforms', 'achieves', 'contains', 'consists_of', 'part_of', 'better_than', 'similar_to', 'different_from', 'leads_to', 'causes', 'affects', 'precedes', 'follows', 'concurrent_with', 'is_a', 'has_part' or 'related_to' [type=literal_error, input_value='used_for', input_type=str]
    For further information visit https://errors.pydantic.dev/2.10/v/literal_error
2025-02-09 15:00:56.358 | 42956:50400 | ERROR    | scripts.knowledge_acquisition:_extract_relationships:652 | Failed to convert relationship: {'source': 'RNNs', 'relation': 'used_for', 'target': 'Sequential data processing'}: 1 validation error for Relationship
relation
  Input should be 'uses', 'applies', 'implements', 'improves', 'outperforms', 'achieves', 'contains', 'consists_of', 'part_of', 'better_than', 'similar_to', 'different_from', 'leads_to', 'causes', 'affects', 'precedes', 'follows', 'concurrent_with', 'is_a', 'has_part' or 'related_to' [type=literal_error, input_value='used_for', input_type=str]
    For further information visit https://errors.pydantic.dev/2.10/v/literal_error
Traceback (most recent call last):

  File "C:\Users\mikeb\work\sifu2\run_agents.py", line 868, in <module>
    asyncio.run(main())

  File "C:\Python313\Lib\asyncio\runners.py", line 194, in run
    return runner.run(main)
  File "C:\Python313\Lib\asyncio\runners.py", line 118, in run
    return self._loop.run_until_complete(task)
  File "C:\Python313\Lib\asyncio\base_events.py", line 707, in run_until_complete
    self.run_forever()
  File "C:\Python313\Lib\asyncio\base_events.py", line 678, in run_forever
    self._run_once()
  File "C:\Python313\Lib\asyncio\base_events.py", line 2033, in _run_once
    handle._run()
  File "C:\Python313\Lib\asyncio\events.py", line 89, in _run
    self._context.run(self._callback, *self._args)

  File "C:\Users\mikeb\work\sifu2\run_agents.py", line 857, in main
    await agent.run()

  File "C:\Users\mikeb\work\sifu2\run_agents.py", line 691, in run
    result = await getattr(self, task.tool)(**task.args)

  File "C:\Users\mikeb\work\sifu2\run_agents.py", line 344, in _synthesize_knowledge
    knowledge = await self.knowledge_system.process_source(content)

  File "C:\Users\mikeb\work\sifu2\scripts\knowledge_acquisition.py", line 466, in process_source
    relationships = await self._extract_relationships(content)

> File "C:\Users\mikeb\work\sifu2\scripts\knowledge_acquisition.py", line 650, in _extract_relationships
    converted_relationships.append(Relationship(**rel))

  File "C:\Python313\Lib\site-packages\pydantic\main.py", line 214, in __init__
    validated_self = self.__pydantic_validator__.validate_python(data, self_instance=self)

pydantic_core._pydantic_core.ValidationError: 1 validation error for Relationship
relation
  Input should be 'uses', 'applies', 'implements', 'improves', 'outperforms', 'achieves', 'contains', 'consists_of', 'part_of', 'better_than', 'similar_to', 'different_from', 'leads_to', 'causes', 'affects', 'precedes', 'follows', 'concurrent_with', 'is_a', 'has_part' or 'related_to' [type=literal_error, input_value='used_for', input_type=str]
    For further information visit https://errors.pydantic.dev/2.10/v/literal_error
2025-02-09 15:00:56.380 | 42956:50400 | ERROR    | scripts.knowledge_acquisition:_extract_relationships:652 | Failed to convert relationship: {'source': 'Backpropagation', 'relation': 'used_in', 'target': 'Model training'}: 1 validation error for Relationship
relation
  Input should be 'uses', 'applies', 'implements', 'improves', 'outperforms', 'achieves', 'contains', 'consists_of', 'part_of', 'better_than', 'similar_to', 'different_from', 'leads_to', 'causes', 'affects', 'precedes', 'follows', 'concurrent_with', 'is_a', 'has_part' or 'related_to' [type=literal_error, input_value='used_in', input_type=str]
    For further information visit https://errors.pydantic.dev/2.10/v/literal_error
Traceback (most recent call last):

  File "C:\Users\mikeb\work\sifu2\run_agents.py", line 868, in <module>
    asyncio.run(main())

  File "C:\Python313\Lib\asyncio\runners.py", line 194, in run
    return runner.run(main)
  File "C:\Python313\Lib\asyncio\runners.py", line 118, in run
    return self._loop.run_until_complete(task)
  File "C:\Python313\Lib\asyncio\base_events.py", line 707, in run_until_complete
    self.run_forever()
  File "C:\Python313\Lib\asyncio\base_events.py", line 678, in run_forever
    self._run_once()
  File "C:\Python313\Lib\asyncio\base_events.py", line 2033, in _run_once
    handle._run()
  File "C:\Python313\Lib\asyncio\events.py", line 89, in _run
    self._context.run(self._callback, *self._args)

  File "C:\Users\mikeb\work\sifu2\run_agents.py", line 857, in main
    await agent.run()

  File "C:\Users\mikeb\work\sifu2\run_agents.py", line 691, in run
    result = await getattr(self, task.tool)(**task.args)

  File "C:\Users\mikeb\work\sifu2\run_agents.py", line 344, in _synthesize_knowledge
    knowledge = await self.knowledge_system.process_source(content)

  File "C:\Users\mikeb\work\sifu2\scripts\knowledge_acquisition.py", line 466, in process_source
    relationships = await self._extract_relationships(content)

> File "C:\Users\mikeb\work\sifu2\scripts\knowledge_acquisition.py", line 650, in _extract_relationships
    converted_relationships.append(Relationship(**rel))

  File "C:\Python313\Lib\site-packages\pydantic\main.py", line 214, in __init__
    validated_self = self.__pydantic_validator__.validate_python(data, self_instance=self)

pydantic_core._pydantic_core.ValidationError: 1 validation error for Relationship
relation
  Input should be 'uses', 'applies', 'implements', 'improves', 'outperforms', 'achieves', 'contains', 'consists_of', 'part_of', 'better_than', 'similar_to', 'different_from', 'leads_to', 'causes', 'affects', 'precedes', 'follows', 'concurrent_with', 'is_a', 'has_part' or 'related_to' [type=literal_error, input_value='used_in', input_type=str]
    For further information visit https://errors.pydantic.dev/2.10/v/literal_error
2025-02-09 15:00:56.401 | 42956:50400 | ERROR    | scripts.knowledge_acquisition:_extract_relationships:652 | Failed to convert relationship: {'source': 'Gradient descent', 'relation': 'used_in', 'target': 'Backpropagation'}: 1 validation error for Relationship
relation
  Input should be 'uses', 'applies', 'implements', 'improves', 'outperforms', 'achieves', 'contains', 'consists_of', 'part_of', 'better_than', 'similar_to', 'different_from', 'leads_to', 'causes', 'affects', 'precedes', 'follows', 'concurrent_with', 'is_a', 'has_part' or 'related_to' [type=literal_error, input_value='used_in', input_type=str]
    For further information visit https://errors.pydantic.dev/2.10/v/literal_error
Traceback (most recent call last):

  File "C:\Users\mikeb\work\sifu2\run_agents.py", line 868, in <module>
    asyncio.run(main())

  File "C:\Python313\Lib\asyncio\runners.py", line 194, in run
    return runner.run(main)
  File "C:\Python313\Lib\asyncio\runners.py", line 118, in run
    return self._loop.run_until_complete(task)
  File "C:\Python313\Lib\asyncio\base_events.py", line 707, in run_until_complete
    self.run_forever()
  File "C:\Python313\Lib\asyncio\base_events.py", line 678, in run_forever
    self._run_once()
  File "C:\Python313\Lib\asyncio\base_events.py", line 2033, in _run_once
    handle._run()
  File "C:\Python313\Lib\asyncio\events.py", line 89, in _run
    self._context.run(self._callback, *self._args)

  File "C:\Users\mikeb\work\sifu2\run_agents.py", line 857, in main
    await agent.run()

  File "C:\Users\mikeb\work\sifu2\run_agents.py", line 691, in run
    result = await getattr(self, task.tool)(**task.args)

  File "C:\Users\mikeb\work\sifu2\run_agents.py", line 344, in _synthesize_knowledge
    knowledge = await self.knowledge_system.process_source(content)

  File "C:\Users\mikeb\work\sifu2\scripts\knowledge_acquisition.py", line 466, in process_source
    relationships = await self._extract_relationships(content)

> File "C:\Users\mikeb\work\sifu2\scripts\knowledge_acquisition.py", line 650, in _extract_relationships
    converted_relationships.append(Relationship(**rel))

  File "C:\Python313\Lib\site-packages\pydantic\main.py", line 214, in __init__
    validated_self = self.__pydantic_validator__.validate_python(data, self_instance=self)

pydantic_core._pydantic_core.ValidationError: 1 validation error for Relationship
relation
  Input should be 'uses', 'applies', 'implements', 'improves', 'outperforms', 'achieves', 'contains', 'consists_of', 'part_of', 'better_than', 'similar_to', 'different_from', 'leads_to', 'causes', 'affects', 'precedes', 'follows', 'concurrent_with', 'is_a', 'has_part' or 'related_to' [type=literal_error, input_value='used_in', input_type=str]
    For further information visit https://errors.pydantic.dev/2.10/v/literal_error
2025-02-09 15:00:56.422 | 42956:50400 | ERROR    | scripts.knowledge_acquisition:_extract_relationships:652 | Failed to convert relationship: {'source': 'Large datasets', 'relation': 'required_for', 'target': 'Effective model training'}: 1 validation error for Relationship
relation
  Input should be 'uses', 'applies', 'implements', 'improves', 'outperforms', 'achieves', 'contains', 'consists_of', 'part_of', 'better_than', 'similar_to', 'different_from', 'leads_to', 'causes', 'affects', 'precedes', 'follows', 'concurrent_with', 'is_a', 'has_part' or 'related_to' [type=literal_error, input_value='required_for', input_type=str]
    For further information visit https://errors.pydantic.dev/2.10/v/literal_error
Traceback (most recent call last):

  File "C:\Users\mikeb\work\sifu2\run_agents.py", line 868, in <module>
    asyncio.run(main())

  File "C:\Python313\Lib\asyncio\runners.py", line 194, in run
    return runner.run(main)
  File "C:\Python313\Lib\asyncio\runners.py", line 118, in run
    return self._loop.run_until_complete(task)
  File "C:\Python313\Lib\asyncio\base_events.py", line 707, in run_until_complete
    self.run_forever()
  File "C:\Python313\Lib\asyncio\base_events.py", line 678, in run_forever
    self._run_once()
  File "C:\Python313\Lib\asyncio\base_events.py", line 2033, in _run_once
    handle._run()
  File "C:\Python313\Lib\asyncio\events.py", line 89, in _run
    self._context.run(self._callback, *self._args)

  File "C:\Users\mikeb\work\sifu2\run_agents.py", line 857, in main
    await agent.run()

  File "C:\Users\mikeb\work\sifu2\run_agents.py", line 691, in run
    result = await getattr(self, task.tool)(**task.args)

  File "C:\Users\mikeb\work\sifu2\run_agents.py", line 344, in _synthesize_knowledge
    knowledge = await self.knowledge_system.process_source(content)

  File "C:\Users\mikeb\work\sifu2\scripts\knowledge_acquisition.py", line 466, in process_source
    relationships = await self._extract_relationships(content)

> File "C:\Users\mikeb\work\sifu2\scripts\knowledge_acquisition.py", line 650, in _extract_relationships
    converted_relationships.append(Relationship(**rel))

  File "C:\Python313\Lib\site-packages\pydantic\main.py", line 214, in __init__
    validated_self = self.__pydantic_validator__.validate_python(data, self_instance=self)

pydantic_core._pydantic_core.ValidationError: 1 validation error for Relationship
relation
  Input should be 'uses', 'applies', 'implements', 'improves', 'outperforms', 'achieves', 'contains', 'consists_of', 'part_of', 'better_than', 'similar_to', 'different_from', 'leads_to', 'causes', 'affects', 'precedes', 'follows', 'concurrent_with', 'is_a', 'has_part' or 'related_to' [type=literal_error, input_value='required_for', input_type=str]
    For further information visit https://errors.pydantic.dev/2.10/v/literal_error
2025-02-09 15:00:56.443 | 42956:50400 | ERROR    | scripts.knowledge_acquisition:_extract_relationships:652 | Failed to convert relationship: {'source': 'Computational resources', 'relation': 'required_for', 'target': 'Model training'}: 1 validation error for Relationship
relation
  Input should be 'uses', 'applies', 'implements', 'improves', 'outperforms', 'achieves', 'contains', 'consists_of', 'part_of', 'better_than', 'similar_to', 'different_from', 'leads_to', 'causes', 'affects', 'precedes', 'follows', 'concurrent_with', 'is_a', 'has_part' or 'related_to' [type=literal_error, input_value='required_for', input_type=str]
    For further information visit https://errors.pydantic.dev/2.10/v/literal_error
Traceback (most recent call last):

  File "C:\Users\mikeb\work\sifu2\run_agents.py", line 868, in <module>
    asyncio.run(main())

  File "C:\Python313\Lib\asyncio\runners.py", line 194, in run
    return runner.run(main)
  File "C:\Python313\Lib\asyncio\runners.py", line 118, in run
    return self._loop.run_until_complete(task)
  File "C:\Python313\Lib\asyncio\base_events.py", line 707, in run_until_complete
    self.run_forever()
  File "C:\Python313\Lib\asyncio\base_events.py", line 678, in run_forever
    self._run_once()
  File "C:\Python313\Lib\asyncio\base_events.py", line 2033, in _run_once
    handle._run()
  File "C:\Python313\Lib\asyncio\events.py", line 89, in _run
    self._context.run(self._callback, *self._args)

  File "C:\Users\mikeb\work\sifu2\run_agents.py", line 857, in main
    await agent.run()

  File "C:\Users\mikeb\work\sifu2\run_agents.py", line 691, in run
    result = await getattr(self, task.tool)(**task.args)

  File "C:\Users\mikeb\work\sifu2\run_agents.py", line 344, in _synthesize_knowledge
    knowledge = await self.knowledge_system.process_source(content)

  File "C:\Users\mikeb\work\sifu2\scripts\knowledge_acquisition.py", line 466, in process_source
    relationships = await self._extract_relationships(content)

> File "C:\Users\mikeb\work\sifu2\scripts\knowledge_acquisition.py", line 650, in _extract_relationships
    converted_relationships.append(Relationship(**rel))

  File "C:\Python313\Lib\site-packages\pydantic\main.py", line 214, in __init__
    validated_self = self.__pydantic_validator__.validate_python(data, self_instance=self)

pydantic_core._pydantic_core.ValidationError: 1 validation error for Relationship
relation
  Input should be 'uses', 'applies', 'implements', 'improves', 'outperforms', 'achieves', 'contains', 'consists_of', 'part_of', 'better_than', 'similar_to', 'different_from', 'leads_to', 'causes', 'affects', 'precedes', 'follows', 'concurrent_with', 'is_a', 'has_part' or 'related_to' [type=literal_error, input_value='required_for', input_type=str]
    For further information visit https://errors.pydantic.dev/2.10/v/literal_error
